Workbook

Sheet SIS-SS-CE-H-2026
J1: Informe Mensual de Actividades Realizadas en la Unidad Médica SINBA-SIS-CE-H | AH1: Sección III
J2: Aplicación de biológicos | AH2: Hoja 8 de 8
A3: Nombre de la unidad: | F3: =IF([1]ÍNDICE!C4=0," ",[1]ÍNDICE!C4) | X3: CLUES: | Y3: =IF([1]ÍNDICE!G4=0," ",[1]ÍNDICE!G4)
A4: Nombre de la persona responsable de la información: | K4: =IF([1]ÍNDICE!J4=0," ",[1]ÍNDICE!J4) | X4: Mes: | Y4: =IF([1]ÍNDICE!O4=0," ",[1]ÍNDICE!O4) | AF4: Año: | AG4: =TEXT(IF([1]ÍNDICE!$U$3=0," ",[1]ÍNDICE!$U$3),"AAAA") -> 2026
A5: SIS-2026
J7: Variable | M7: Clave | N7: Total de dosis | O7: Clave | P7: A Afromexicanos | Q7: Clave | R7: A Indígenas | S7: Clave | T7: A Migrantes | Z7: Variable | AA7: Clave | AB7: Total de dosis | AC7: Clave | AD7: A Afromexicanos | AE7: Clave | AF7: A Indígenas | AG7: Clave | AH7: A Migrantes
A8: Aplicación de biológicos | C8: 119 BCG | J8: Recién nacido (primeras 24 horas) | M8: VBC01 | N8: =IF('[1]SINBA-SIS-06-P'!Y11=0," ",'[1]SINBA-SIS-06-P'!Y11) | O8: VBF51 | P8: =IF('[1]SINBA-SIS-06-P'!V11=0," ",'[1]SINBA-SIS-06-P'!V11) | Q8: VBI51 | R8: =IF('[1]SINBA-SIS-06-P'!W11=0," ",'[1]SINBA-SIS-06-P'!W11) | S8: VBC51 | T8: =IF('[1]SINBA-SIS-06-P'!X11=0," ",'[1]SINBA-SIS-06-P'!X11) | W8: 129 VPHa | X8: Única | Y8: Personas de quinto año de primaria o de 11 años no escolarizadas a | AA8: VPH05 | AB8: =IF('[1]SINBA-SIS-06-P'!Y75=0," ",'[1]SINBA-SIS-06-P'!Y75) | AC8: VPF01 | AD8: =IF('[1]SINBA-SIS-06-P'!V75=0," ",'[1]SINBA-SIS-06-P'!V75) | AE8: VPI01 | AF8: =IF('[1]SINBA-SIS-06-P'!W75=0," ",'[1]SINBA-SIS-06-P'!W75) | AG8: VPH51 | AH8: =IF('[1]SINBA-SIS-06-P'!X75=0," ",'[1]SINBA-SIS-06-P'!X75)
J9: Recién nacido (de 2 a 28 días) | M9: VBC02 | N9: =IF('[1]SINBA-SIS-06-P'!Y12=0," ",'[1]SINBA-SIS-06-P'!Y12) | O9: VBF52 | P9: =IF('[1]SINBA-SIS-06-P'!V12=0," ",'[1]SINBA-SIS-06-P'!V12) | Q9: VBI52 | R9: =IF('[1]SINBA-SIS-06-P'!W12=0," ",'[1]SINBA-SIS-06-P'!W12) | S9: VBC52 | T9: =IF('[1]SINBA-SIS-06-P'!X12=0," ",'[1]SINBA-SIS-06-P'!X12) | Y9: Niñas y/o adolescentes de 12 a 16 años (rezagadas) | AA9: VPH06 | AB9: =IF('[1]SINBA-SIS-06-P'!Y76=0," ",'[1]SINBA-SIS-06-P'!Y76) | AC9: VPF02 | AD9: =IF('[1]SINBA-SIS-06-P'!V76=0," ",'[1]SINBA-SIS-06-P'!V76) | AE9: VPI02 | AF9: =IF('[1]SINBA-SIS-06-P'!W76=0," ",'[1]SINBA-SIS-06-P'!W76) | AG9: VPH52 | AH9: =IF('[1]SINBA-SIS-06-P'!X76=0," ",'[1]SINBA-SIS-06-P'!X76)
J10: 29 días a 11 meses | M10: BIO50 | N10: =IF('[1]SINBA-SIS-06-P'!Y13=0," ",'[1]SINBA-SIS-06-P'!Y13) | O10: VBF53 | P10: =IF('[1]SINBA-SIS-06-P'!V13=0," ",'[1]SINBA-SIS-06-P'!V13) | Q10: VBI53 | R10: =IF('[1]SINBA-SIS-06-P'!W13=0," ",'[1]SINBA-SIS-06-P'!W13) | S10: VBC53 | T10: =IF('[1]SINBA-SIS-06-P'!X13=0," ",'[1]SINBA-SIS-06-P'!X13) | Y10: Niñas y/o adolescentes víctimas de violación sexual de 9 a 14 años b | AA10: VPH07 | AB10: =IF('[1]SINBA-SIS-06-P'!Y77=0," ",'[1]SINBA-SIS-06-P'!Y77) | AC10: VPF03 | AD10: =IF('[1]SINBA-SIS-06-P'!V77=0," ",'[1]SINBA-SIS-06-P'!V77) | AE10: VPI03 | AF10: =IF('[1]SINBA-SIS-06-P'!W77=0," ",'[1]SINBA-SIS-06-P'!W77) | AG10: VPH53 | AH10: =IF('[1]SINBA-SIS-06-P'!X77=0," ",'[1]SINBA-SIS-06-P'!X77)
J11: 1 a 4 años | M11: BIO03 | N11: =IF('[1]SINBA-SIS-06-P'!Y14=0," ",'[1]SINBA-SIS-06-P'!Y14) | O11: VBF54 | P11: =IF('[1]SINBA-SIS-06-P'!V14=0," ",'[1]SINBA-SIS-06-P'!V14) | Q11: VBI54 | R11: =IF('[1]SINBA-SIS-06-P'!W14=0," ",'[1]SINBA-SIS-06-P'!W14) | S11: VBC54 | T11: =IF('[1]SINBA-SIS-06-P'!X14=0," ",'[1]SINBA-SIS-06-P'!X14) | Y11: Niñas y/o adolescentes víctimas de violación sexual de 15 a 19 años b | AA11: VPH08 | AB11: =IF('[1]SINBA-SIS-06-P'!Y78=0," ",'[1]SINBA-SIS-06-P'!Y78) | AC11: VPF04 | AD11: =IF('[1]SINBA-SIS-06-P'!V78=0," ",'[1]SINBA-SIS-06-P'!V78) | AE11: VPI04 | AF11: =IF('[1]SINBA-SIS-06-P'!W78=0," ",'[1]SINBA-SIS-06-P'!W78) | AG11: VPH54 | AH11: =IF('[1]SINBA-SIS-06-P'!X78=0," ",'[1]SINBA-SIS-06-P'!X78)
J12: 5 a 13 años | M12: VBC03 | N12: =IF('[1]SINBA-SIS-06-P'!Y15=0," ",'[1]SINBA-SIS-06-P'!Y15) | O12: VBF55 | P12: =IF('[1]SINBA-SIS-06-P'!V15=0," ",'[1]SINBA-SIS-06-P'!V15) | Q12: VBI55 | R12: =IF('[1]SINBA-SIS-06-P'!W15=0," ",'[1]SINBA-SIS-06-P'!W15) | S12: VBC55 | T12: =IF('[1]SINBA-SIS-06-P'!X15=0," ",'[1]SINBA-SIS-06-P'!X15) | X12: Personas de 11 a 49 años que viven con VIH | Z12: Primera | AA12: VPH12 | AB12: =IF('[1]SINBA-SIS-06-P'!Y79=0," ",'[1]SINBA-SIS-06-P'!Y79) | AC12: VPF05 | AD12: =IF('[1]SINBA-SIS-06-P'!V79=0," ",'[1]SINBA-SIS-06-P'!V79) | AE12: VPI05 | AF12: =IF('[1]SINBA-SIS-06-P'!W79=0," ",'[1]SINBA-SIS-06-P'!W79) | AG12: VPH61 | AH12: =IF('[1]SINBA-SIS-06-P'!X79=0," ",'[1]SINBA-SIS-06-P'!X79)
C13: 121 Hepatitis B | J13: Única recién nacido (0 a 7 días) | M13: VAC06 | N13: =IF('[1]SINBA-SIS-06-P'!Y16=0," ",'[1]SINBA-SIS-06-P'!Y16) | O13: VHF51 | P13: =IF('[1]SINBA-SIS-06-P'!V16=0," ",'[1]SINBA-SIS-06-P'!V16) | Q13: VHI51 | R13: =IF('[1]SINBA-SIS-06-P'!W16=0," ",'[1]SINBA-SIS-06-P'!W16) | S13: VHB51 | T13: =IF('[1]SINBA-SIS-06-P'!X16=0," ",'[1]SINBA-SIS-06-P'!X16) | Z13: Segunda | AA13: VPH13 | AB13: =IF('[1]SINBA-SIS-06-P'!Y80=0," ",'[1]SINBA-SIS-06-P'!Y80) | AC13: VPF06 | AD13: =IF('[1]SINBA-SIS-06-P'!V80=0," ",'[1]SINBA-SIS-06-P'!V80) | AE13: VPI06 | AF13: =IF('[1]SINBA-SIS-06-P'!W80=0," ",'[1]SINBA-SIS-06-P'!W80) | AG13: VPH62 | AH13: =IF('[1]SINBA-SIS-06-P'!X80=0," ",'[1]SINBA-SIS-06-P'!X80)
J14: Mayores de 11 años (sin antecedente vacunal) | L14: Primera | M14: VHB01 | N14: =IF('[1]SINBA-SIS-06-P'!Y17=0," ",'[1]SINBA-SIS-06-P'!Y17) | O14: VHF52 | P14: =IF('[1]SINBA-SIS-06-P'!V17=0," ",'[1]SINBA-SIS-06-P'!V17) | Q14: VHI52 | R14: =IF('[1]SINBA-SIS-06-P'!W17=0," ",'[1]SINBA-SIS-06-P'!W17) | S14: VHB52 | T14: =IF('[1]SINBA-SIS-06-P'!X17=0," ",'[1]SINBA-SIS-06-P'!X17) | Z14: Tercera | AA14: VPH14 | AB14: =IF('[1]SINBA-SIS-06-P'!Y81=0," ",'[1]SINBA-SIS-06-P'!Y81) | AC14: VPF07 | AD14: =IF('[1]SINBA-SIS-06-P'!V81=0," ",'[1]SINBA-SIS-06-P'!V81) | AE14: VPI07 | AF14: =IF('[1]SINBA-SIS-06-P'!W81=0," ",'[1]SINBA-SIS-06-P'!W81) | AG14: VPH63 | AH14: =IF('[1]SINBA-SIS-06-P'!X81=0," ",'[1]SINBA-SIS-06-P'!X81)
L15: Segunda | M15: VHB02 | N15: =IF('[1]SINBA-SIS-06-P'!Y18=0," ",'[1]SINBA-SIS-06-P'!Y18) | O15: VHF53 | P15: =IF('[1]SINBA-SIS-06-P'!V18=0," ",'[1]SINBA-SIS-06-P'!V18) | Q15: VHI53 | R15: =IF('[1]SINBA-SIS-06-P'!W18=0," ",'[1]SINBA-SIS-06-P'!W18) | S15: VHB53 | T15: =IF('[1]SINBA-SIS-06-P'!X18=0," ",'[1]SINBA-SIS-06-P'!X18) | W15: 131 Varicela* | Y15: Única 1 año | AA15: VAR02 | AB15: =IF('[1]SINBA-SIS-06-P'!Y63=0," ",'[1]SINBA-SIS-06-P'!Y63) | AC15: VAR61 | AD15: =IF('[1]SINBA-SIS-06-P'!V63=0," ",'[1]SINBA-SIS-06-P'!V63) | AE15: VAR71 | AF15: =IF('[1]SINBA-SIS-06-P'!W63=0," ",'[1]SINBA-SIS-06-P'!W63) | AG15: VAR54 | AH15: =IF('[1]SINBA-SIS-06-P'!X63=0," ",'[1]SINBA-SIS-06-P'!X63)
J16: Población en riesgo | L16: Primera | M16: VHB03 | N16: =IF('[1]SINBA-SIS-06-P'!Y19=0," ",'[1]SINBA-SIS-06-P'!Y19) | O16: VHF54 | P16: =IF('[1]SINBA-SIS-06-P'!V19=0," ",'[1]SINBA-SIS-06-P'!V19) | Q16: VHI54 | R16: =IF('[1]SINBA-SIS-06-P'!W19=0," ",'[1]SINBA-SIS-06-P'!W19) | S16: VHB54 | T16: =IF('[1]SINBA-SIS-06-P'!X19=0," ",'[1]SINBA-SIS-06-P'!X19) | Y16: Rezagos de 2 a 4 años | AA16: VAR03 | AB16: =IF('[1]SINBA-SIS-06-P'!Y64=0," ",'[1]SINBA-SIS-06-P'!Y64) | AC16: VAR62 | AD16: =IF('[1]SINBA-SIS-06-P'!V64=0," ",'[1]SINBA-SIS-06-P'!V64) | AE16: VAR72 | AF16: =IF('[1]SINBA-SIS-06-P'!W64=0," ",'[1]SINBA-SIS-06-P'!W64) | AG16: VAR55 | AH16: =IF('[1]SINBA-SIS-06-P'!X64=0," ",'[1]SINBA-SIS-06-P'!X64)
L17: Segunda | M17: VHB04 | N17: =IF('[1]SINBA-SIS-06-P'!Y20=0," ",'[1]SINBA-SIS-06-P'!Y20) | O17: VHF55 | P17: =IF('[1]SINBA-SIS-06-P'!V20=0," ",'[1]SINBA-SIS-06-P'!V20) | Q17: VHI55 | R17: =IF('[1]SINBA-SIS-06-P'!W20=0," ",'[1]SINBA-SIS-06-P'!W20) | S17: VHB55 | T17: =IF('[1]SINBA-SIS-06-P'!X20=0," ",'[1]SINBA-SIS-06-P'!X20) | W17: 122 Hepatitis A | Y17: Única 18 meses | AA17: VHA01 | AB17: =IF('[1]SINBA-SIS-06-P'!Y65=0," ",'[1]SINBA-SIS-06-P'!Y65) | AC17: VAF01 | AD17: =IF('[1]SINBA-SIS-06-P'!V65=0," ",'[1]SINBA-SIS-06-P'!V65) | AE17: VAI01 | AF17: =IF('[1]SINBA-SIS-06-P'!W65=0," ",'[1]SINBA-SIS-06-P'!W65) | AG17: VHA53 | AH17: =IF('[1]SINBA-SIS-06-P'!X65=0," ",'[1]SINBA-SIS-06-P'!X65)
J18: Personal de salud | L18: Primera | M18: VHB05 | N18: =IF('[1]SINBA-SIS-06-P'!Y21=0," ",'[1]SINBA-SIS-06-P'!Y21) | O18: VHF56 | P18: =IF('[1]SINBA-SIS-06-P'!V21=0," ",'[1]SINBA-SIS-06-P'!V21) | Q18: VHI56 | R18: =IF('[1]SINBA-SIS-06-P'!W21=0," ",'[1]SINBA-SIS-06-P'!W21) | S18: VHB56 | T18: =IF('[1]SINBA-SIS-06-P'!X21=0," ",'[1]SINBA-SIS-06-P'!X21) | Y18: Rezagos de 2 a 4 años | AA18: VHA02 | AB18: =IF('[1]SINBA-SIS-06-P'!Y66=0," ",'[1]SINBA-SIS-06-P'!Y66) | AC18: VAF02 | AD18: =IF('[1]SINBA-SIS-06-P'!V66=0," ",'[1]SINBA-SIS-06-P'!V66) | AE18: VAI02 | AF18: =IF('[1]SINBA-SIS-06-P'!W66=0," ",'[1]SINBA-SIS-06-P'!W66) | AG18: VHA54 | AH18: =IF('[1]SINBA-SIS-06-P'!X66=0," ",'[1]SINBA-SIS-06-P'!X66)
L19: Segunda | M19: VHB06 | N19: =IF('[1]SINBA-SIS-06-P'!Y22=0," ",'[1]SINBA-SIS-06-P'!Y22) | O19: VHF57 | P19: =IF('[1]SINBA-SIS-06-P'!V22=0," ",'[1]SINBA-SIS-06-P'!V22) | Q19: VHI57 | R19: =IF('[1]SINBA-SIS-06-P'!W22=0," ",'[1]SINBA-SIS-06-P'!W22) | S19: VHB57 | T19: =IF('[1]SINBA-SIS-06-P'!X22=0," ",'[1]SINBA-SIS-06-P'!X22) | Y19: Población en riesgo | AA19: BIO88 | AB19: =IF('[1]SINBA-SIS-06-P'!Y67=0," ",'[1]SINBA-SIS-06-P'!Y67) | AC19: VAF03 | AD19: =IF('[1]SINBA-SIS-06-P'!V67=0," ",'[1]SINBA-SIS-06-P'!V67) | AE19: VAI03 | AF19: =IF('[1]SINBA-SIS-06-P'!W67=0," ",'[1]SINBA-SIS-06-P'!W67) | AG19: VHA52 | AH19: =IF('[1]SINBA-SIS-06-P'!X67=0," ",'[1]SINBA-SIS-06-P'!X67)
C20: 275 Hexavalente acelular DPaT + IPV + Hib + HB | J20: Primera 2 a 11 meses | M20: VAC67 | N20: =IF('[1]SINBA-SIS-06-P'!Y23=0," ",'[1]SINBA-SIS-06-P'!Y23) | O20: VXF51 | P20: =IF('[1]SINBA-SIS-06-P'!V23=0," ",'[1]SINBA-SIS-06-P'!V23) | Q20: VXI51 | R20: =IF('[1]SINBA-SIS-06-P'!W23=0," ",'[1]SINBA-SIS-06-P'!W23) | S20: VHX51 | T20: =IF('[1]SINBA-SIS-06-P'!X23=0," ",'[1]SINBA-SIS-06-P'!X23) | W20: 132 T d | X20: Embarazadas | Y20: Primera | Z20: 10 a 19 años | AA20: VAC39 | AB20: =IF('[1]SINBA-SIS-06-P'!Y82=0," ",'[1]SINBA-SIS-06-P'!Y82) | AC20: VTF01 | AD20: =IF('[1]SINBA-SIS-06-P'!V82=0," ",'[1]SINBA-SIS-06-P'!V82) | AE20: VTI01 | AF20: =IF('[1]SINBA-SIS-06-P'!W82=0," ",'[1]SINBA-SIS-06-P'!W82) | AG20: VTD51 | AH20: =IF('[1]SINBA-SIS-06-P'!X82=0," ",'[1]SINBA-SIS-06-P'!X82)
J21: Segunda 4 a 11 meses | M21: VAC68 | N21: =IF('[1]SINBA-SIS-06-P'!Y24=0," ",'[1]SINBA-SIS-06-P'!Y24) | O21: VXF52 | P21: =IF('[1]SINBA-SIS-06-P'!V24=0," ",'[1]SINBA-SIS-06-P'!V24) | Q21: VXI52 | R21: =IF('[1]SINBA-SIS-06-P'!W24=0," ",'[1]SINBA-SIS-06-P'!W24) | S21: VHX52 | T21: =IF('[1]SINBA-SIS-06-P'!X24=0," ",'[1]SINBA-SIS-06-P'!X24) | Z21: 20 y más años | AA21: VAC40 | AB21: =IF('[1]SINBA-SIS-06-P'!Y83=0," ",'[1]SINBA-SIS-06-P'!Y83) | AC21: VTF02 | AD21: =IF('[1]SINBA-SIS-06-P'!V83=0," ",'[1]SINBA-SIS-06-P'!V83) | AE21: VTI02 | AF21: =IF('[1]SINBA-SIS-06-P'!W83=0," ",'[1]SINBA-SIS-06-P'!W83) | AG21: VTD52 | AH21: =IF('[1]SINBA-SIS-06-P'!X83=0," ",'[1]SINBA-SIS-06-P'!X83)
J22: Tercera 6 a 11 meses | M22: VAC69 | N22: =IF('[1]SINBA-SIS-06-P'!Y25=0," ",'[1]SINBA-SIS-06-P'!Y25) | O22: VXF53 | P22: =IF('[1]SINBA-SIS-06-P'!V25=0," ",'[1]SINBA-SIS-06-P'!V25) | Q22: VXI53 | R22: =IF('[1]SINBA-SIS-06-P'!W25=0," ",'[1]SINBA-SIS-06-P'!W25) | S22: VHX53 | T22: =IF('[1]SINBA-SIS-06-P'!X25=0," ",'[1]SINBA-SIS-06-P'!X25) | Y22: Segunda | Z22: 10 a 19 años | AA22: VAC47 | AB22: =IF('[1]SINBA-SIS-06-P'!Y84=0," ",'[1]SINBA-SIS-06-P'!Y84) | AC22: VTF03 | AD22: =IF('[1]SINBA-SIS-06-P'!V84=0," ",'[1]SINBA-SIS-06-P'!V84) | AE22: VTI03 | AF22: =IF('[1]SINBA-SIS-06-P'!W84=0," ",'[1]SINBA-SIS-06-P'!W84) | AG22: VTD53 | AH22: =IF('[1]SINBA-SIS-06-P'!X84=0," ",'[1]SINBA-SIS-06-P'!X84)
J23: Refuerzo 18 a 23 meses | M23: VAC70 | N23: =IF('[1]SINBA-SIS-06-P'!Y26=0," ",'[1]SINBA-SIS-06-P'!Y26) | O23: VXF54 | P23: =IF('[1]SINBA-SIS-06-P'!V26=0," ",'[1]SINBA-SIS-06-P'!V26) | Q23: VXI54 | R23: =IF('[1]SINBA-SIS-06-P'!W26=0," ",'[1]SINBA-SIS-06-P'!W26) | S23: VHX54 | T23: =IF('[1]SINBA-SIS-06-P'!X26=0," ",'[1]SINBA-SIS-06-P'!X26) | Z23: 20 y más años | AA23: VAC48 | AB23: =IF('[1]SINBA-SIS-06-P'!Y85=0," ",'[1]SINBA-SIS-06-P'!Y85) | AC23: VTF04 | AD23: =IF('[1]SINBA-SIS-06-P'!V85=0," ",'[1]SINBA-SIS-06-P'!V85) | AE23: VTI04 | AF23: =IF('[1]SINBA-SIS-06-P'!W85=0," ",'[1]SINBA-SIS-06-P'!W85) | AG23: VTD54 | AH23: =IF('[1]SINBA-SIS-06-P'!X85=0," ",'[1]SINBA-SIS-06-P'!X85)
J24: Para iniciar o completar esquema 1 a 4 años | L24: Primera | M24: VHX01 | N24: =IF('[1]SINBA-SIS-06-P'!Y27=0," ",'[1]SINBA-SIS-06-P'!Y27) | O24: VXF55 | P24: =IF('[1]SINBA-SIS-06-P'!V27=0," ",'[1]SINBA-SIS-06-P'!V27) | Q24: VXI55 | R24: =IF('[1]SINBA-SIS-06-P'!W27=0," ",'[1]SINBA-SIS-06-P'!W27) | S24: VHX55 | T24: =IF('[1]SINBA-SIS-06-P'!X27=0," ",'[1]SINBA-SIS-06-P'!X27) | Y24: Tercera | Z24: 10 a 19 años | AA24: VTD01 | AB24: =IF('[1]SINBA-SIS-06-P'!Y86=0," ",'[1]SINBA-SIS-06-P'!Y86) | AC24: VTF05 | AD24: =IF('[1]SINBA-SIS-06-P'!V86=0," ",'[1]SINBA-SIS-06-P'!V86) | AE24: VTI05 | AF24: =IF('[1]SINBA-SIS-06-P'!W86=0," ",'[1]SINBA-SIS-06-P'!W86) | AG24: VTD55 | AH24: =IF('[1]SINBA-SIS-06-P'!X86=0," ",'[1]SINBA-SIS-06-P'!X86)
L25: Segunda | M25: VHX02 | N25: =IF('[1]SINBA-SIS-06-P'!Y28=0," ",'[1]SINBA-SIS-06-P'!Y28) | O25: VXF56 | P25: =IF('[1]SINBA-SIS-06-P'!V28=0," ",'[1]SINBA-SIS-06-P'!V28) | Q25: VXI56 | R25: =IF('[1]SINBA-SIS-06-P'!W28=0," ",'[1]SINBA-SIS-06-P'!W28) | S25: VHX56 | T25: =IF('[1]SINBA-SIS-06-P'!X28=0," ",'[1]SINBA-SIS-06-P'!X28) | Z25: 20 y más años | AA25: VTD02 | AB25: =IF('[1]SINBA-SIS-06-P'!Y87=0," ",'[1]SINBA-SIS-06-P'!Y87) | AC25: VTF06 | AD25: =IF('[1]SINBA-SIS-06-P'!V87=0," ",'[1]SINBA-SIS-06-P'!V87) | AE25: VTI06 | AF25: =IF('[1]SINBA-SIS-06-P'!W87=0," ",'[1]SINBA-SIS-06-P'!W87) | AG25: VTD56 | AH25: =IF('[1]SINBA-SIS-06-P'!X87=0," ",'[1]SINBA-SIS-06-P'!X87)
L26: Tercera | M26: VHX03 | N26: =IF('[1]SINBA-SIS-06-P'!Y29=0," ",'[1]SINBA-SIS-06-P'!Y29) | O26: VXF57 | P26: =IF('[1]SINBA-SIS-06-P'!V29=0," ",'[1]SINBA-SIS-06-P'!V29) | Q26: VXI57 | R26: =IF('[1]SINBA-SIS-06-P'!W29=0," ",'[1]SINBA-SIS-06-P'!W29) | S26: VHX57 | T26: =IF('[1]SINBA-SIS-06-P'!X29=0," ",'[1]SINBA-SIS-06-P'!X29) | Y26: Refuerzo | Z26: 10 a 19 años | AA26: VAC55 | AB26: =IF('[1]SINBA-SIS-06-P'!Y88=0," ",'[1]SINBA-SIS-06-P'!Y88) | AC26: VTF07 | AD26: =IF('[1]SINBA-SIS-06-P'!V88=0," ",'[1]SINBA-SIS-06-P'!V88) | AE26: VTI07 | AF26: =IF('[1]SINBA-SIS-06-P'!W88=0," ",'[1]SINBA-SIS-06-P'!W88) | AG26: VTD57 | AH26: =IF('[1]SINBA-SIS-06-P'!X88=0," ",'[1]SINBA-SIS-06-P'!X88)
L27: Refuerzo | M27: VHX04 | N27: =IF('[1]SINBA-SIS-06-P'!Y30=0," ",'[1]SINBA-SIS-06-P'!Y30) | O27: VXF58 | P27: =IF('[1]SINBA-SIS-06-P'!V30=0," ",'[1]SINBA-SIS-06-P'!V30) | Q27: VXI58 | R27: =IF('[1]SINBA-SIS-06-P'!W30=0," ",'[1]SINBA-SIS-06-P'!W30) | S27: VHX58 | T27: =IF('[1]SINBA-SIS-06-P'!X30=0," ",'[1]SINBA-SIS-06-P'!X30) | Z27: 20 y más años | AA27: VAC56 | AB27: =IF('[1]SINBA-SIS-06-P'!Y89=0," ",'[1]SINBA-SIS-06-P'!Y89) | AC27: VTF08 | AD27: =IF('[1]SINBA-SIS-06-P'!V89=0," ",'[1]SINBA-SIS-06-P'!V89) | AE27: VTI08 | AF27: =IF('[1]SINBA-SIS-06-P'!W89=0," ",'[1]SINBA-SIS-06-P'!W89) | AG27: VTD58 | AH27: =IF('[1]SINBA-SIS-06-P'!X89=0," ",'[1]SINBA-SIS-06-P'!X89)
C28: 123 DPT | J28: Única 4 años | M28: VAC12 | N28: =IF('[1]SINBA-SIS-06-P'!Y31=0," ",'[1]SINBA-SIS-06-P'!Y31) | O28: VPD53 | P28: =IF('[1]SINBA-SIS-06-P'!V31=0," ",'[1]SINBA-SIS-06-P'!V31) | Q28: VPD55 | R28: =IF('[1]SINBA-SIS-06-P'!W31=0," ",'[1]SINBA-SIS-06-P'!W31) | S28: VPD51 | T28: =IF('[1]SINBA-SIS-06-P'!X31=0," ",'[1]SINBA-SIS-06-P'!X31) | X28: Población | Y28: Primera | Z28: 15 a 19 años | AA28: VTT01 | AB28: =IF('[1]SINBA-SIS-06-P'!Y90=0," ",'[1]SINBA-SIS-06-P'!Y90) | AC28: VTF09 | AD28: =IF('[1]SINBA-SIS-06-P'!V90=0," ",'[1]SINBA-SIS-06-P'!V90) | AE28: VTI09 | AF28: =IF('[1]SINBA-SIS-06-P'!W90=0," ",'[1]SINBA-SIS-06-P'!W90) | AG28: VTM01 | AH28: =IF('[1]SINBA-SIS-06-P'!X90=0," ",'[1]SINBA-SIS-06-P'!X90)
J29: Para iniciar o completar esquema 5 a 6 años única | M29: VAC13 | N29: =IF('[1]SINBA-SIS-06-P'!Y32=0," ",'[1]SINBA-SIS-06-P'!Y32) | O29: VPD54 | P29: =IF('[1]SINBA-SIS-06-P'!V32=0," ",'[1]SINBA-SIS-06-P'!V32) | Q29: VPD56 | R29: =IF('[1]SINBA-SIS-06-P'!W32=0," ",'[1]SINBA-SIS-06-P'!W32) | S29: VPD52 | T29: =IF('[1]SINBA-SIS-06-P'!X32=0," ",'[1]SINBA-SIS-06-P'!X32) | Z29: 20 a 59 años | AA29: VTT02 | AB29: =IF('[1]SINBA-SIS-06-P'!Y91=0," ",'[1]SINBA-SIS-06-P'!Y91) | AC29: VTF10 | AD29: =IF('[1]SINBA-SIS-06-P'!V91=0," ",'[1]SINBA-SIS-06-P'!V91) | AE29: VTI10 | AF29: =IF('[1]SINBA-SIS-06-P'!W91=0," ",'[1]SINBA-SIS-06-P'!W91) | AG29: VTM02 | AH29: =IF('[1]SINBA-SIS-06-P'!X91=0," ",'[1]SINBA-SIS-06-P'!X91)
C30: 274 Rotavirus RV1 | J30: Primera 2 meses | M30: VRV01 | N30: =IF('[1]SINBA-SIS-06-P'!Y33=0," ",'[1]SINBA-SIS-06-P'!Y33) | O30: VRF51 | P30: =IF('[1]SINBA-SIS-06-P'!V33=0," ",'[1]SINBA-SIS-06-P'!V33) | Q30: VRI51 | R30: =IF('[1]SINBA-SIS-06-P'!W33=0," ",'[1]SINBA-SIS-06-P'!W33) | S30: VRV51 | T30: =IF('[1]SINBA-SIS-06-P'!X33=0," ",'[1]SINBA-SIS-06-P'!X33) | Z30: 60 y más años | AA30: VTT03 | AB30: =IF('[1]SINBA-SIS-06-P'!Y92=0," ",'[1]SINBA-SIS-06-P'!Y92) | AC30: VTF11 | AD30: =IF('[1]SINBA-SIS-06-P'!V92=0," ",'[1]SINBA-SIS-06-P'!V92) | AE30: VTI11 | AF30: =IF('[1]SINBA-SIS-06-P'!W92=0," ",'[1]SINBA-SIS-06-P'!W92) | AG30: VTM03 | AH30: =IF('[1]SINBA-SIS-06-P'!X92=0," ",'[1]SINBA-SIS-06-P'!X92)
J31: Segunda 4 meses | M31: VRV02 | N31: =IF('[1]SINBA-SIS-06-P'!Y34=0," ",'[1]SINBA-SIS-06-P'!Y34) | O31: VRF52 | P31: =IF('[1]SINBA-SIS-06-P'!V34=0," ",'[1]SINBA-SIS-06-P'!V34) | Q31: VRI52 | R31: =IF('[1]SINBA-SIS-06-P'!W34=0," ",'[1]SINBA-SIS-06-P'!W34) | S31: VRV52 | T31: =IF('[1]SINBA-SIS-06-P'!X34=0," ",'[1]SINBA-SIS-06-P'!X34) | Y31: Segunda (1 a 2 meses despuès de la 1er dosis) | Z31: 15 a 19 años | AA31: VTT04 | AB31: =IF('[1]SINBA-SIS-06-P'!Y93=0," ",'[1]SINBA-SIS-06-P'!Y93) | AC31: VTF12 | AD31: =IF('[1]SINBA-SIS-06-P'!V93=0," ",'[1]SINBA-SIS-06-P'!V93) | AE31: VTI12 | AF31: =IF('[1]SINBA-SIS-06-P'!W93=0," ",'[1]SINBA-SIS-06-P'!W93) | AG31: VTM04 | AH31: =IF('[1]SINBA-SIS-06-P'!X93=0," ",'[1]SINBA-SIS-06-P'!X93)
J32: Para iniciar o completar esquema | L32: Primera 3 a 7 meses | M32: VRV03 | N32: =IF('[1]SINBA-SIS-06-P'!Y35=0," ",'[1]SINBA-SIS-06-P'!Y35) | O32: VRF53 | P32: =IF('[1]SINBA-SIS-06-P'!V35=0," ",'[1]SINBA-SIS-06-P'!V35) | Q32: VRI53 | R32: =IF('[1]SINBA-SIS-06-P'!W35=0," ",'[1]SINBA-SIS-06-P'!W35) | S32: VRV53 | T32: =IF('[1]SINBA-SIS-06-P'!X35=0," ",'[1]SINBA-SIS-06-P'!X35) | Z32: 20 a 59 años | AA32: VTT05 | AB32: =IF('[1]SINBA-SIS-06-P'!Y94=0," ",'[1]SINBA-SIS-06-P'!Y94) | AC32: VTF13 | AD32: =IF('[1]SINBA-SIS-06-P'!V94=0," ",'[1]SINBA-SIS-06-P'!V94) | AE32: VTI13 | AF32: =IF('[1]SINBA-SIS-06-P'!W94=0," ",'[1]SINBA-SIS-06-P'!W94) | AG32: VTM05 | AH32: =IF('[1]SINBA-SIS-06-P'!X94=0," ",'[1]SINBA-SIS-06-P'!X94)
L33: Segunda 5 a 7 meses | M33: VRV04 | N33: =IF('[1]SINBA-SIS-06-P'!Y36=0," ",'[1]SINBA-SIS-06-P'!Y36) | O33: VRF54 | P33: =IF('[1]SINBA-SIS-06-P'!V36=0," ",'[1]SINBA-SIS-06-P'!V36) | Q33: VRI54 | R33: =IF('[1]SINBA-SIS-06-P'!W36=0," ",'[1]SINBA-SIS-06-P'!W36) | S33: VRV54 | T33: =IF('[1]SINBA-SIS-06-P'!X36=0," ",'[1]SINBA-SIS-06-P'!X36) | Z33: 60 y más años | AA33: VTT06 | AB33: =IF('[1]SINBA-SIS-06-P'!Y95=0," ",'[1]SINBA-SIS-06-P'!Y95) | AC33: VTF14 | AD33: =IF('[1]SINBA-SIS-06-P'!V95=0," ",'[1]SINBA-SIS-06-P'!V95) | AE33: VTI14 | AF33: =IF('[1]SINBA-SIS-06-P'!W95=0," ",'[1]SINBA-SIS-06-P'!W95) | AG33: VTM06 | AH33: =IF('[1]SINBA-SIS-06-P'!X95=0," ",'[1]SINBA-SIS-06-P'!X95)
C34: 125 Neumocócica Conjugada (13 valente) | J34: Primera 2 a 11 meses | M34: VAC17 | N34: =IF('[1]SINBA-SIS-06-P'!Y37=0," ",'[1]SINBA-SIS-06-P'!Y37) | O34: VNF51 | P34: =IF('[1]SINBA-SIS-06-P'!V37=0," ",'[1]SINBA-SIS-06-P'!V37) | Q34: VNI51 | R34: =IF('[1]SINBA-SIS-06-P'!W37=0," ",'[1]SINBA-SIS-06-P'!W37) | S34: VNC51 | T34: =IF('[1]SINBA-SIS-06-P'!X37=0," ",'[1]SINBA-SIS-06-P'!X37) | Y34: Tercera (1 año después de la 2a dosis) | Z34: 15 a 19 años | AA34: VTT07 | AB34: =IF('[1]SINBA-SIS-06-P'!Y96=0," ",'[1]SINBA-SIS-06-P'!Y96) | AC34: VTF15 | AD34: =IF('[1]SINBA-SIS-06-P'!V96=0," ",'[1]SINBA-SIS-06-P'!V96) | AE34: VTI15 | AF34: =IF('[1]SINBA-SIS-06-P'!W96=0," ",'[1]SINBA-SIS-06-P'!W96) | AG34: VTM07 | AH34: =IF('[1]SINBA-SIS-06-P'!X96=0," ",'[1]SINBA-SIS-06-P'!X96)
J35: Segunda 4 a 11 meses | M35: VAC18 | N35: =IF('[1]SINBA-SIS-06-P'!Y38=0," ",'[1]SINBA-SIS-06-P'!Y38) | O35: VNF52 | P35: =IF('[1]SINBA-SIS-06-P'!V38=0," ",'[1]SINBA-SIS-06-P'!V38) | Q35: VNI52 | R35: =IF('[1]SINBA-SIS-06-P'!W38=0," ",'[1]SINBA-SIS-06-P'!W38) | S35: VNC52 | T35: =IF('[1]SINBA-SIS-06-P'!X38=0," ",'[1]SINBA-SIS-06-P'!X38) | Z35: 20 a 59 años | AA35: VTT08 | AB35: =IF('[1]SINBA-SIS-06-P'!Y97=0," ",'[1]SINBA-SIS-06-P'!Y97) | AC35: VTF16 | AD35: =IF('[1]SINBA-SIS-06-P'!V97=0," ",'[1]SINBA-SIS-06-P'!V97) | AE35: VTI16 | AF35: =IF('[1]SINBA-SIS-06-P'!W97=0," ",'[1]SINBA-SIS-06-P'!W97) | AG35: VTM08 | AH35: =IF('[1]SINBA-SIS-06-P'!X97=0," ",'[1]SINBA-SIS-06-P'!X97)
J36: Tercera 12 a 23 meses | M36: VAC19 | N36: =IF('[1]SINBA-SIS-06-P'!Y39=0," ",'[1]SINBA-SIS-06-P'!Y39) | O36: VNF53 | P36: =IF('[1]SINBA-SIS-06-P'!V39=0," ",'[1]SINBA-SIS-06-P'!V39) | Q36: VNI53 | R36: =IF('[1]SINBA-SIS-06-P'!W39=0," ",'[1]SINBA-SIS-06-P'!W39) | S36: VNC53 | T36: =IF('[1]SINBA-SIS-06-P'!X39=0," ",'[1]SINBA-SIS-06-P'!X39) | Z36: 60 y más años | AA36: VTT09 | AB36: =IF('[1]SINBA-SIS-06-P'!Y98=0," ",'[1]SINBA-SIS-06-P'!Y98) | AC36: VTF17 | AD36: =IF('[1]SINBA-SIS-06-P'!V98=0," ",'[1]SINBA-SIS-06-P'!V98) | AE36: VTI17 | AF36: =IF('[1]SINBA-SIS-06-P'!W98=0," ",'[1]SINBA-SIS-06-P'!W98) | AG36: VTM09 | AH36: =IF('[1]SINBA-SIS-06-P'!X98=0," ",'[1]SINBA-SIS-06-P'!X98)
J37: Para iniciar o completar esquema 1 a 4 años | L37: Primera | M37: VNC01 | N37: =IF('[1]SINBA-SIS-06-P'!Y40=0," ",'[1]SINBA-SIS-06-P'!Y40) | O37: VNF54 | P37: =IF('[1]SINBA-SIS-06-P'!V40=0," ",'[1]SINBA-SIS-06-P'!V40) | Q37: VNI54 | R37: =IF('[1]SINBA-SIS-06-P'!W40=0," ",'[1]SINBA-SIS-06-P'!W40) | S37: VNC54 | T37: =IF('[1]SINBA-SIS-06-P'!X40=0," ",'[1]SINBA-SIS-06-P'!X40) | Y37: Refuerzo (Cada 10 años, hasta completar 5 dosis) | Z37: 15 a 19 años | AA37: VTT10 | AB37: =IF('[1]SINBA-SIS-06-P'!Y99=0," ",'[1]SINBA-SIS-06-P'!Y99) | AC37: VTF18 | AD37: =IF('[1]SINBA-SIS-06-P'!V99=0," ",'[1]SINBA-SIS-06-P'!V99) | AE37: VTI18 | AF37: =IF('[1]SINBA-SIS-06-P'!W99=0," ",'[1]SINBA-SIS-06-P'!W99) | AG37: VTM10 | AH37: =IF('[1]SINBA-SIS-06-P'!X99=0," ",'[1]SINBA-SIS-06-P'!X99)
L38: Segunda | M38: VNC02 | N38: =IF('[1]SINBA-SIS-06-P'!Y41=0," ",'[1]SINBA-SIS-06-P'!Y41) | O38: VNF55 | P38: =IF('[1]SINBA-SIS-06-P'!V41=0," ",'[1]SINBA-SIS-06-P'!V41) | Q38: VNI55 | R38: =IF('[1]SINBA-SIS-06-P'!W41=0," ",'[1]SINBA-SIS-06-P'!W41) | S38: VNC55 | T38: =IF('[1]SINBA-SIS-06-P'!X41=0," ",'[1]SINBA-SIS-06-P'!X41) | Z38: 20 a 59 años | AA38: VTT11 | AB38: =IF('[1]SINBA-SIS-06-P'!Y100=0," ",'[1]SINBA-SIS-06-P'!Y100) | AC38: VTF19 | AD38: =IF('[1]SINBA-SIS-06-P'!V100=0," ",'[1]SINBA-SIS-06-P'!V100) | AE38: VTI19 | AF38: =IF('[1]SINBA-SIS-06-P'!W100=0," ",'[1]SINBA-SIS-06-P'!W100) | AG38: VTM11 | AH38: =IF('[1]SINBA-SIS-06-P'!X100=0," ",'[1]SINBA-SIS-06-P'!X100)
L39: Tercera | M39: VNC03 | N39: =IF('[1]SINBA-SIS-06-P'!Y42=0," ",'[1]SINBA-SIS-06-P'!Y42) | O39: VNF56 | P39: =IF('[1]SINBA-SIS-06-P'!V42=0," ",'[1]SINBA-SIS-06-P'!V42) | Q39: VNI56 | R39: =IF('[1]SINBA-SIS-06-P'!W42=0," ",'[1]SINBA-SIS-06-P'!W42) | S39: VNC56 | T39: =IF('[1]SINBA-SIS-06-P'!X42=0," ",'[1]SINBA-SIS-06-P'!X42) | Z39: 60 y más años | AA39: VTT12 | AB39: =IF('[1]SINBA-SIS-06-P'!Y101=0," ",'[1]SINBA-SIS-06-P'!Y101) | AC39: VTF20 | AD39: =IF('[1]SINBA-SIS-06-P'!V101=0," ",'[1]SINBA-SIS-06-P'!V101) | AE39: VTI20 | AF39: =IF('[1]SINBA-SIS-06-P'!W101=0," ",'[1]SINBA-SIS-06-P'!W101) | AG39: VTM12 | AH39: =IF('[1]SINBA-SIS-06-P'!X101=0," ",'[1]SINBA-SIS-06-P'!X101)
J40: Personas de 60 años y más | L40: Única | M40: VNC04 | N40: =IF('[1]SINBA-SIS-06-P'!Y43=0," ",'[1]SINBA-SIS-06-P'!Y43) | O40: VNF57 | P40: =IF('[1]SINBA-SIS-06-P'!V43=0," ",'[1]SINBA-SIS-06-P'!V43) | Q40: VNI57 | R40: =IF('[1]SINBA-SIS-06-P'!W43=0," ",'[1]SINBA-SIS-06-P'!W43) | S40: VNC59 | T40: =IF('[1]SINBA-SIS-06-P'!X43=0," ",'[1]SINBA-SIS-06-P'!X43) | W40: 133 Tdpa | Y40: Embarazada a partir de la semana 20 de gestación | AA40: VAC63 | AB40: =IF('[1]SINBA-SIS-06-P'!Y102=0," ",'[1]SINBA-SIS-06-P'!Y102) | AC40: VDP52 | AD40: =IF('[1]SINBA-SIS-06-P'!V102=0," ",'[1]SINBA-SIS-06-P'!V102) | AE40: VDP54 | AF40: =IF('[1]SINBA-SIS-06-P'!W102=0," ",'[1]SINBA-SIS-06-P'!W102) | AG40: VDP51 | AH40: =IF('[1]SINBA-SIS-06-P'!X102=0," ",'[1]SINBA-SIS-06-P'!X102)
C41: 354 Neumocócica Conjugada (20 valente) | J41: Primera 2 a 11 meses | M41: VCC01 | N41: =IF('[1]SINBA-SIS-06-P'!Y44=0," ",'[1]SINBA-SIS-06-P'!Y44) | O41: VCF01 | P41: =IF('[1]SINBA-SIS-06-P'!V44=0," ",'[1]SINBA-SIS-06-P'!V44) | Q41: VCI01 | R41: =IF('[1]SINBA-SIS-06-P'!W44=0," ",'[1]SINBA-SIS-06-P'!W44) | S41: VCC51 | T41: =IF('[1]SINBA-SIS-06-P'!X44=0," ",'[1]SINBA-SIS-06-P'!X44) | Y41: Personal en riesgo c | AA41: VDP01 | AB41: =IF('[1]SINBA-SIS-06-P'!Y103=0," ",'[1]SINBA-SIS-06-P'!Y103) | AC41: VDP53 | AD41: =IF('[1]SINBA-SIS-06-P'!V103=0," ",'[1]SINBA-SIS-06-P'!V103) | AE41: VDP55 | AF41: =IF('[1]SINBA-SIS-06-P'!W103=0," ",'[1]SINBA-SIS-06-P'!W103) | AG41: VDP56 | AH41: =IF('[1]SINBA-SIS-06-P'!X103=0," ",'[1]SINBA-SIS-06-P'!X103)
...
