Workbook

Sheet SANTA BÁRBARA
A1: SERVICIOS DE SALUD DEL ESTADO DE QUERÉTARO
A2: COORDINACION GENERAL
A3: SUBDIRECCION DE ADQUISICIONES
A5: SOLICITUD Y SURTIMIENTO DE LA CÁMARA DE FRÍO ESTATAL
A7: ORIGEN: | B7: JURISDICCIÓN SANITARIA N.1 | G7: AREA: | H7: VACUNAS
A8: DIRECCIÓN: | B8: Circuito Moises Solana S/N, Col. Vista Alegre, Santiago de Querétaro. Qro. | G8: FECHA DE ENVIO: | H8: =IF(GENERAL!H8=0," ",GENERAL!H8) -> 46272
A9: DESTINO: | B9: C.S SANTA BÁRBARA | G9: FOLIO ORACLE:
A10: DIRECCIÓN: | B10: Luis Echeverria S/N, Santa Barbara, Corregidora. | G10: MES A SURTIR: | H10: =GENERAL!H10 -> SEPTIEMBRE
A12: NÚM | B12: CLAVE DE ARTÍCULO | C12: NOMBRE DEL ARTÍCULO | D12: PRESENTACIÓN | E12: FORMA | F12: CANTIDAD | K12: FIRMA DE RECEPCION
E13: FARMACÉUTICA | F13: SOLICITADO | G13: AUTORIZADO | H13: SURTIDO | I13: LOTE | J13: CADUCIDAD
A14: 25311.020-000-0146-03 | B14: 146 | C14: VACUNA ANTINEUMOCOCCICA 23 1DS | D14: UNIDOSIS | E14: Susp. Inyectable (Fco. Ampula) | G14: =IF(F14=0," ",F14) | H14: =IF(F14=0," ",F14) | I14: =IF(GENERAL!I14=0," ",GENERAL!I14) | J14: =IF(GENERAL!J14=0," ",GENERAL!J14) | M14: =SUM(F14+(F44*10)+(F32*10)+F22+F34+(F36*10)+F48) -> 31 | N14: JERINGA | O14: 2715 | P14: 22X32
I15: =IF(GENERAL!I15=0," ",GENERAL!I15) | J15: =IF(GENERAL!J15=0," ",GENERAL!J15) | M15: =SUM((F44/3)*20+F20) -> 70 | N15: JERINGA | O15: 2707 | P15: 23X25
A16: 25311.020-000-0148-01 | B16: 148 | C16: VACUNA ANTINEUMOCOCCICA 13 | D16: UNIDOSIS | E16: Susp. Inyectable (Jer. prellenada) | F16: 50 | G16: =IF(F16=0," ",F16) -> 50 | H16: =IF(F16=0," ",F16) -> 50 | I16: =IF(GENERAL!I16=0," ",GENERAL!I16) -> LC5884 | J16: =IF(GENERAL!J16=0," ",GENERAL!J16) -> 46388 | M16: =SUM(F24) -> 15 | N16: JERINGA | O16: 2699 | P16: 25X16
M17: =SUM(F26+F40) -> 52 | N17: JERINGA | O17: 2657 | P17: 27X13
A18: 25311.020-000-0150-05 | B18: 150 | C18: VACUNA ROTAVIRUS MONOVALENTE | D18: UNIDOSIS | E18: Susp. Inyectable (Jer. prellenada) | F18: 30 | G18: =IF(F18=0," ",F18) -> 30 | H18: =IF(F18=0," ",F18) -> 30 | I18: =IF(GENERAL!I18=0," ",GENERAL!I18) -> AROLE168AH | J18: =IF(GENERAL!J18=0," ",GENERAL!J18) -> 46419 | M18: =SUM(F28*10) -> 0 | N18: JERINGA | O18: 59 | P18: 30GX1/2
I19: =IF(GENERAL!I19=0," ",GENERAL!I19) | J19: =IF(GENERAL!J19=0," ",GENERAL!J19)
A20: 25311.020-000-6135-00 | B20: 6135 | C20: VACUNA HEXAVALENTE | D20: UNIDOSIS | E20: Susp. Inyectable (Fco. Ampula) | F20: 70 | G20: =IF(F20=0," ",F20) -> 70 | H20: =IF(F20=0," ",F20) -> 70 | I20: =IF(GENERAL!I20=0," ",GENERAL!I20) -> Y3C48D1 | J20: =IF(GENERAL!J20=0," ",GENERAL!J20) -> 46722
I21: =IF(GENERAL!I21=0," ",GENERAL!I21) | J21: =IF(GENERAL!J21=0," ",GENERAL!J21)
A22: 25311.020-000-2526-00 | B22: 2526 | C22: VACUNA HEPATITIS B MULTIDOSIS | D22: MULTIDOSIS | E22: Susp. Inyectable (Fco. Ampula) | F22: 1 | G22: =IF(F22=0," ",F22) -> 1 | H22: =IF(F22=0," ",F22) -> 1 | I22: =IF(GENERAL!I22=0," ",GENERAL!I22) -> 2526250606 | J22: 46919
I23: =IF(GENERAL!I23=0," ",GENERAL!I23) | J23: =IF(GENERAL!J23=0," ",GENERAL!J23)
A24: 25311.020-000-3825-01 | B24: 3825 | C24: VACUNA HEPATITIS A UNIDOSIS | D24: UNIDOSIS | E24: Susp. Inyectable (Fco. Ampula) | F24: 15 | G24: =IF(F24=0," ",F24) -> 15 | H24: =IF(F24=0," ",F24) -> 15 | I24: =IF(GENERAL!I24=0," ",GENERAL!I24) -> AHAVC215AA | J24: =IF(GENERAL!J24=0," ",GENERAL!J24) -> 46813
I25: =IF(GENERAL!I25=0," ",GENERAL!I25) | J25: =IF(GENERAL!J25=0," ",GENERAL!J25)
A26: 25311.020-000-3800-00 | B26: 3800 | C26: VACUNA DOBLE VIRAL (SR) | D26: MULTIDOSIS | E26: Fco. Amp Leofilizado+Diluy. | F26: 2 | G26: =IF(F26=0," ",F26) -> 2 | H26: =IF(F26=0," ",F26) -> 2 | I26: =IF(GENERAL!I26=0," ",GENERAL!I26) -> 0125N120A | J26: =IF(GENERAL!J26=0," ",GENERAL!J26) -> 46784
I27: =IF(GENERAL!I27=0," ",GENERAL!I27) | J27: =IF(GENERAL!J27=0," ",GENERAL!J27)
A28: 25311.020-000-3801-01 | B28: 3801 | C28: VACUNA BCG | D28: MULTIDOSIS | E28: Fco. Amp Leofilizado+Diluy. | G28: =IF(F28=0," ",F28) | H28: =IF(F28=0," ",F28)
A30: 25311.020-000-3802-00 | B30: 3802 | C30: VACUNA ANTIPOLIOMELITICA (SABIN) | D30: MULTIDOSIS | E30: Susp. (gotero de plastico) | G30: =IF(F30=0," ",F30) | H30: =IF(F30=0," ",F30) | I30: =IF(GENERAL!I30=0," ",GENERAL!I30) | J30: =IF(GENERAL!J30=0," ",GENERAL!J30)
I31: =IF(GENERAL!I31=0," ",GENERAL!I31) | J31: =IF(GENERAL!J31=0," ",GENERAL!J31)
A32: 25311.020-000-3805-00 | B32: 3805 | C32: VACUNA VACUNA DPT | D32: MULTIDOSIS | E32: Susp. Inyectable (Fco. Ampula) | F32: 1 | G32: =IF(F32=0," ",F32) -> 1 | H32: =IF(F32=0," ",F32) -> 1 | I32: =IF(GENERAL!I32=0," ",GENERAL!I32) -> 2825Q001A | J32: =IF(GENERAL!J32=0," ",GENERAL!J32) -> 46784
I33: =IF(GENERAL!I33=0," ",GENERAL!I33) | J33: =IF(GENERAL!J33=0," ",GENERAL!J33)
A34: 25311.020-000-3808-02 | B34: 3808 | C34: VACUNA TDPA | D34: UNIDOSIS | E34: Susp. Inyectable (Fco. Ampula) | F34: 20 | G34: =IF(F34=0," ",F34) -> 20 | H34: =IF(F34=0," ",F34) -> 20 | I34: =IF(GENERAL!I34=0," ",GENERAL!I34) -> AC37B542BD | J34: =IF(GENERAL!J34=0," ",GENERAL!J34) -> 46784
I35: =IF(GENERAL!I35=0," ",GENERAL!I35) | J35: =IF(GENERAL!J35=0," ",GENERAL!J35)
A36: 25311.020-000-3810-00 | B36: 3810 | C36: VACUNA TD | D36: MULTIDOSIS | E36: Susp. Inyectable (Fco. Ampula) | G36: =IF(F36=0," ",F36) | H36: =IF(F36=0," ",F36)
A38: 25311.020-000-6056-00 | B38: 6056 | C38: VACUNA ANTIVARICELA | D38: UNIDOSIS | E38: Fco. Amp Leofilizado+Diluy. | G38: =IF(F38=0," ",F38) | H38: =IF(F38=0," ",F38) | I38: =IF(GENERAL!I38=0," ",GENERAL!I38) | J38: =IF(GENERAL!J38=0," ",GENERAL!J38)
A40: 25311.020-000-3820-00 | B40: 3820 | C40: VACUNA TRIPLE VIRAL 1DS (SRP) | D40: UNIDOSIS | E40: Fco. Amp Leofilizado+Diluy. | F40: 50 | G40: =IF(F40=0," ",F40) -> 50 | H40: =IF(F40=0," ",F40) -> 50 | I40: =IF(GENERAL!I40=0," ",GENERAL!I40) -> 0135N027B | J40: =IF(GENERAL!J40=0," ",GENERAL!J40) -> 46600
A42: 25311.020-000-3821-00 | B42: 3821 | C42: VACUNATRIPLEVIRAL MULTI DOSIS | D42: MULTIDOSIS | E42: Fco. Amp Leofilizado+Diluy. | G42: =IF(F42=0," ",F42) | H42: =IF(F42=0," ",F42) | I42: =IF(GENERAL!I42=0," ",GENERAL!I42) | J42: =IF(GENERAL!J42=0," ",GENERAL!J42)
I43: =IF(GENERAL!I43=0," ",GENERAL!I43) | J43: =IF(GENERAL!J43=0," ",GENERAL!J43)
A44: 25311.020-000-6317-01 | B44: 6317 | C44: VACUNA ANTIINFLUENZA 10/D | D44: MULTIDOSIS | E44: Susp. Inyectable (Fco. Ampula) | G44: =IF(F44=0," ",F44) | H44: =IF(F44=0," ",F44) | I44: =IF(GENERAL!I44=0," ",GENERAL!I44) | J44: =IF(GENERAL!J44=0," ",GENERAL!J44)
I45: =IF(GENERAL!I45=0," ",GENERAL!I45) | J45: =IF(GENERAL!J45=0," ",GENERAL!J45)
A46: 25311.020-000-3832-00 | B46: 3832 | C46: VACUNA INMUNOGLOBULINA ANTITETANICA | D46: UNIDOSIS | E46: Susp. Inyectable (Fco. Ampula) | G46: =IF(F46=0," ",F46) | H46: =IF(F46=0," ",F46) | I46: =IF(GENERAL!I46=0," ",GENERAL!I46) | J46: =IF(GENERAL!J46=0," ",GENERAL!J46)
A48: 25311.020-000-6501-02 | B48: 6501 | C48: VACUNA VPH | D48: UNIDOSIS | E48: Susp. Inyectable (Fco. Ampula) | G48: =IF(F48=0," ",F48) | H48: =IF(F48=0," ",F48) | I48: =IF(GENERAL!I48=0," ",GENERAL!I48) | J48: =IF(GENERAL!J48=0," ",GENERAL!J48)
...

Sheet LOS ÁNGELES
A1: SERVICIOS DE SALUD DEL ESTADO DE QUERÉTARO
A2: COORDINACION GENERAL
A3: SUBDIRECCION DE ADQUISICIONES
A5: SOLICITUD Y SURTIMIENTO DE LA CÁMARA DE FRÍO ESTATAL
A7: ORIGEN: | B7: JURISDICCIÓN SANITARIA N.1 | G7: AREA: | H7: VACUNAS
A8: DIRECCIÓN: | B8: Circuito Moises Solana S/N, Col. Vista Alegre, Santiago de Querétaro. Qro. | G8: FECHA DE ENVIO: | H8: =IF(GENERAL!H8=0," ",GENERAL!H8) -> 46272
A9: DESTINO: | B9: C.S LOS ÁNGELES | G9: FOLIO ORACLE:
A10: DIRECCIÓN: | B10: San Francisco S/N, Los Angeles, Corregidora. | G10: MES A SURTIR: | H10: =GENERAL!H10 -> SEPTIEMBRE
A12: NÚM | B12: CLAVE DE ARTÍCULO | C12: NOMBRE DEL ARTÍCULO | D12: PRESENTACIÓN | E12: FORMA | F12: CANTIDAD | K12: FIRMA DE RECEPCION
E13: FARMACÉUTICA | F13: SOLICITADO | G13: AUTORIZADO | H13: SURTIDO | I13: LOTE | J13: CADUCIDAD
A14: 25311.020-000-0146-03 | B14: 146 | C14: VACUNA ANTINEUMOCOCCICA 23 1DS | D14: UNIDOSIS | E14: Susp. Inyectable (Fco. Ampula) | G14: =IF(F14=0," ",F14) | H14: =IF(F14=0," ",F14) | I14: =IF(GENERAL!I14=0," ",GENERAL!I14) | J14: =IF(GENERAL!J14=0," ",GENERAL!J14) | M14: =SUM(F14+(F44*10)+(F32*10)+F22+F34+(F36*10)+F48) -> 30 | N14: JERINGA | O14: 2715 | P14: 22X32
I15: =IF(GENERAL!I15=0," ",GENERAL!I15) | J15: =IF(GENERAL!J15=0," ",GENERAL!J15) | M15: =SUM((F44/3)*20+F20) -> 10 | N15: JERINGA | O15: 2707 | P15: 23X25
A16: 25311.020-000-0148-01 | B16: 148 | C16: VACUNA ANTINEUMOCOCCICA 13 | D16: UNIDOSIS | E16: Susp. Inyectable (Jer. prellenada) | F16: 10 | G16: =IF(F16=0," ",F16) -> 10 | H16: =IF(F16=0," ",F16) -> 10 | I16: =IF(GENERAL!I16=0," ",GENERAL!I16) -> LC5884 | J16: =IF(GENERAL!J16=0," ",GENERAL!J16) -> 46388 | M16: =SUM(F24) -> 10 | N16: JERINGA | O16: 2699 | P16: 25X16
M17: =SUM(F26+F40) -> 2 | N17: JERINGA | O17: 2657 | P17: 27X13
A18: 25311.020-000-0150-05 | B18: 150 | C18: VACUNA ROTAVIRUS MONOVALENTE | D18: UNIDOSIS | E18: Susp. Inyectable (Jer. prellenada) | F18: 10 | G18: =IF(F18=0," ",F18) -> 10 | H18: =IF(F18=0," ",F18) -> 10 | I18: =IF(GENERAL!I18=0," ",GENERAL!I18) -> AROLE168AH | J18: =IF(GENERAL!J18=0," ",GENERAL!J18) -> 46419 | M18: =SUM(F28*10) -> 40 | N18: JERINGA | O18: 59 | P18: 30GX1/2
A20: 25311.020-000-6135-00 | B20: 6135 | C20: VACUNA HEXAVALENTE | D20: UNIDOSIS | E20: Susp. Inyectable (Fco. Ampula) | F20: 10 | G20: =IF(F20=0," ",F20) -> 10 | H20: =IF(F20=0," ",F20) -> 10 | I20: =IF(GENERAL!I20=0," ",GENERAL!I20) -> Y3C48D1 | J20: =IF(GENERAL!J20=0," ",GENERAL!J20) -> 46722
I21: =IF(GENERAL!I21=0," ",GENERAL!I21) | J21: =IF(GENERAL!J21=0," ",GENERAL!J21)
A22: 25311.020-000-2526-00 | B22: 2526 | C22: VACUNA HEPATITIS B MULTIDOSIS | D22: MULTIDOSIS | E22: Susp. Inyectable (Fco. Ampula) | G22: =IF(F22=0," ",F22) | H22: =IF(F22=0," ",F22)
A24: 25311.020-000-3825-01 | B24: 3825 | C24: VACUNA HEPATITIS A UNIDOSIS | D24: UNIDOSIS | E24: Susp. Inyectable (Fco. Ampula) | F24: 10 | G24: =IF(F24=0," ",F24) -> 10 | H24: =IF(F24=0," ",F24) -> 10 | I24: =IF(GENERAL!I24=0," ",GENERAL!I24) -> AHAVC215AA | J24: =IF(GENERAL!J24=0," ",GENERAL!J24) -> 46813
I25: =IF(GENERAL!I25=0," ",GENERAL!I25) | J25: =IF(GENERAL!J25=0," ",GENERAL!J25)
A26: 25311.020-000-3800-00 | B26: 3800 | C26: VACUNA DOBLE VIRAL (SR) | D26: MULTIDOSIS | E26: Fco. Amp Leofilizado+Diluy. | F26: 2 | G26: =IF(F26=0," ",F26) -> 2 | H26: =IF(F26=0," ",F26) -> 2 | I26: =IF(GENERAL!I26=0," ",GENERAL!I26) -> 0125N120A | J26: =IF(GENERAL!J26=0," ",GENERAL!J26) -> 46784
I27: =IF(GENERAL!I27=0," ",GENERAL!I27) | J27: =IF(GENERAL!J27=0," ",GENERAL!J27)
A28: 25311.020-000-3801-01 | B28: 3801 | C28: VACUNA BCG | D28: MULTIDOSIS | E28: Fco. Amp Leofilizado+Diluy. | F28: 4 | G28: =IF(F28=0," ",F28) -> 4 | H28: =IF(F28=0," ",F28) -> 4 | I28: =IF(GENERAL!I28=0," ",GENERAL!I28) -> 0374MA108 | J28: =IF(GENERAL!J28=0," ",GENERAL!J28) -> 46447
I29: =IF(GENERAL!I29=0," ",GENERAL!I29) | J29: =IF(GENERAL!J29=0," ",GENERAL!J29)
A30: 25311.020-000-3802-00 | B30: 3802 | C30: VACUNA ANTIPOLIOMELITICA (SABIN) | D30: MULTIDOSIS | E30: Susp. (gotero de plastico) | G30: =IF(F30=0," ",F30) | H30: =IF(F30=0," ",F30) | I30: =IF(GENERAL!I30=0," ",GENERAL!I30) | J30: =IF(GENERAL!J30=0," ",GENERAL!J30)
I31: =IF(GENERAL!I31=0," ",GENERAL!I31) | J31: =IF(GENERAL!J31=0," ",GENERAL!J31)
A32: 25311.020-000-3805-00 | B32: 3805 | C32: VACUNA VACUNA DPT | D32: MULTIDOSIS | E32: Susp. Inyectable (Fco. Ampula) | F32: 2 | G32: =IF(F32=0," ",F32) -> 2 | H32: =IF(F32=0," ",F32) -> 2 | I32: =IF(GENERAL!I32=0," ",GENERAL!I32) -> 2825Q001A | J32: =IF(GENERAL!J32=0," ",GENERAL!J32) -> 46784
I33: =IF(GENERAL!I33=0," ",GENERAL!I33) | J33: =IF(GENERAL!J33=0," ",GENERAL!J33)
A34: 25311.020-000-3808-02 | B34: 3808 | C34: VACUNA TDPA | D34: UNIDOSIS | E34: Susp. Inyectable (Fco. Ampula) | G34: =IF(F34=0," ",F34) | H34: =IF(F34=0," ",F34)
A36: 25311.020-000-3810-00 | B36: 3810 | C36: VACUNA TD | D36: MULTIDOSIS | E36: Susp. Inyectable (Fco. Ampula) | F36: 1 | G36: =IF(F36=0," ",F36) -> 1 | H36: =IF(F36=0," ",F36) -> 1 | I36: =IF(GENERAL!I36=0," ",GENERAL!I36) -> 2805X003A | J36: =IF(GENERAL!J36=0," ",GENERAL!J36) -> 46388
I37: =IF(GENERAL!I37=0," ",GENERAL!I37) | J37: =IF(GENERAL!J37=0," ",GENERAL!J37)
A38: 25311.020-000-6056-00 | B38: 6056 | C38: VACUNA ANTIVARICELA | D38: UNIDOSIS | E38: Fco. Amp Leofilizado+Diluy. | G38: =IF(F38=0," ",F38) | H38: =IF(F38=0," ",F38) | I38: =IF(GENERAL!I38=0," ",GENERAL!I38) | J38: =IF(GENERAL!J38=0," ",GENERAL!J38)
A40: 25311.020-000-3820-00 | B40: 3820 | C40: VACUNA TRIPLE VIRAL 1DS (SRP) | D40: UNIDOSIS | E40: Fco. Amp Leofilizado+Diluy. | G40: =IF(F40=0," ",F40) | H40: =IF(F40=0," ",F40)
A42: 25311.020-000-3821-00 | B42: 3821 | C42: VACUNATRIPLEVIRAL MULTI DOSIS | D42: MULTIDOSIS | E42: Fco. Amp Leofilizado+Diluy. | G42: =IF(F42=0," ",F42) | H42: =IF(F42=0," ",F42)
A44: 25311.020-000-6317-01 | B44: 6317 | C44: VACUNA ANTIINFLUENZA 10/D | D44: MULTIDOSIS | E44: Susp. Inyectable (Fco. Ampula) | G44: =IF(F44=0," ",F44) | H44: =IF(F44=0," ",F44) | I44: =IF(GENERAL!I44=0," ",GENERAL!I44) | J44: =IF(GENERAL!J44=0," ",GENERAL!J44)
I45: =IF(GENERAL!I45=0," ",GENERAL!I45) | J45: =IF(GENERAL!J45=0," ",GENERAL!J45)
A46: 25311.020-000-3832-00 | B46: 3832 | C46: VACUNA INMUNOGLOBULINA ANTITETANICA | D46: UNIDOSIS | E46: Susp. Inyectable (Fco. Ampula) | G46: =IF(F46=0," ",F46) | H46: =IF(F46=0," ",F46) | I46: =IF(GENERAL!I46=0," ",GENERAL!I46) | J46: =IF(GENERAL!J46=0," ",GENERAL!J46)
I47: =IF(GENERAL!I47=0," ",GENERAL!I47) | J47: =IF(GENERAL!J47=0," ",GENERAL!J47)
A48: 25311.020-000-6501-02 | B48: 6501 | C48: VACUNA VPH | D48: UNIDOSIS | E48: Susp. Inyectable (Fco. Ampula) | G48: =IF(F48=0," ",F48) | H48: =IF(F48=0," ",F48) | I48: =IF(GENERAL!I48=0," ",GENERAL!I48) | J48: =IF(GENERAL!J48=0," ",GENERAL!J48)
A50: 25331.020-X-0002-00-E | B50: 2 | C50: VACUNA ANTIAMARILICA | D50: UNIDOSIS | E50: Fco. Amp Leofilizado + Jer.prellenada. | G50: =IF(F50=0," ",F50) | H50: =IF(F50=0," ",F50) | I50: =IF(GENERAL!I50=0," ",GENERAL!I50) | J50: =IF(GENERAL!J50=0," ",GENERAL!J50)
...

Sheet JOAQUÍN H.
A1: SERVICIOS DE SALUD DEL ESTADO DE QUERÉTARO
A2: COORDINACION GENERAL
A3: SUBDIRECCION DE ADQUISICIONES
A5: SOLICITUD Y SURTIMIENTO DE LA CÁMARA DE FRÍO ESTATAL
A7: ORIGEN: | B7: JURISDICCIÓN SANITARIA N.1 | G7: AREA: | H7: VACUNAS
A8: DIRECCIÓN: | B8: Circuito Moises Solana S/N, Col. Vista Alegre, Santiago de Querétaro. Qro. | G8: FECHA DE ENVIO: | H8: =IF(GENERAL!H8=0," ",GENERAL!H8) -> 46272
A9: DESTINO: | B9: C.S JOAQUÍN HERRERA (LA CUEVA) | G9: FOLIO ORACLE:
A10: DIRECCIÓN: | B10: SIN DOMICILIO | G10: MES A SURTIR: | H10: =GENERAL!H10 -> SEPTIEMBRE
A12: NÚM | B12: CLAVE DE ARTÍCULO | C12: NOMBRE DEL ARTÍCULO | D12: PRESENTACIÓN | E12: FORMA | F12: CANTIDAD | K12: FIRMA DE RECEPCION
E13: FARMACÉUTICA | F13: SOLICITADO | G13: AUTORIZADO | H13: SURTIDO | I13: LOTE | J13: CADUCIDAD
A14: 25311.020-000-0146-03 | B14: 146 | C14: VACUNA ANTINEUMOCOCCICA 23 1DS | D14: UNIDOSIS | E14: Susp. Inyectable (Fco. Ampula) | G14: =IF(F14=0," ",F14) | H14: =IF(F14=0," ",F14) | I14: =IF(GENERAL!I14=0," ",GENERAL!I14) | J14: =IF(GENERAL!J14=0," ",GENERAL!J14) | M14: =SUM(F14+(F44*10)+(F32*10)+F22+F34+(F36*10)+F48) -> 40 | N14: JERINGA | O14: 2715 | P14: 22X32
M15: =SUM((F44/3)*20+F20) -> 30 | N15: JERINGA | O15: 2707 | P15: 23X25
A16: 25311.020-000-0148-01 | B16: 148 | C16: VACUNA ANTINEUMOCOCCICA 13 | D16: UNIDOSIS | E16: Susp. Inyectable (Jer. prellenada) | F16: 30 | G16: =IF(F16=0," ",F16) -> 30 | H16: =IF(F16=0," ",F16) -> 30 | I16: =IF(GENERAL!I16=0," ",GENERAL!I16) -> LC5884 | J16: =IF(GENERAL!J16=0," ",GENERAL!J16) -> 46388 | M16: =SUM(F24) -> 20 | N16: JERINGA | O16: 2699 | P16: 25X16
M17: =SUM(F26+F40) -> 31 | N17: JERINGA | O17: 2657 | P17: 27X13
A18: 25311.020-000-0150-05 | B18: 150 | C18: VACUNA ROTAVIRUS MONOVALENTE | D18: UNIDOSIS | E18: Susp. Inyectable (Jer. prellenada) | F18: 10 | G18: =IF(F18=0," ",F18) -> 10 | H18: =IF(F18=0," ",F18) -> 10 | I18: =IF(GENERAL!I18=0," ",GENERAL!I18) -> AROLE168AH | J18: =IF(GENERAL!J18=0," ",GENERAL!J18) -> 46419 | M18: =SUM(F28*10) -> 50 | N18: JERINGA | O18: 59 | P18: 30GX1/2
I19: =IF(GENERAL!I19=0," ",GENERAL!I19) | J19: =IF(GENERAL!J19=0," ",GENERAL!J19)
A20: 25311.020-000-6135-00 | B20: 6135 | C20: VACUNA HEXAVALENTE | D20: UNIDOSIS | E20: Susp. Inyectable (Fco. Ampula) | F20: 30 | G20: =IF(F20=0," ",F20) -> 30 | H20: =IF(F20=0," ",F20) -> 30 | I20: =IF(GENERAL!I20=0," ",GENERAL!I20) -> Y3C48D1 | J20: =IF(GENERAL!J20=0," ",GENERAL!J20) -> 46722
I21: =IF(GENERAL!I21=0," ",GENERAL!I21) | J21: =IF(GENERAL!J21=0," ",GENERAL!J21)
A22: 25311.020-000-2526-00 | B22: 2526 | C22: VACUNA HEPATITIS B MULTIDOSIS | D22: MULTIDOSIS | E22: Susp. Inyectable (Fco. Ampula) | G22: =IF(F22=0," ",F22) | H22: =IF(F22=0," ",F22)
A24: 25311.020-000-3825-01 | B24: 3825 | C24: VACUNA HEPATITIS A UNIDOSIS | D24: UNIDOSIS | E24: Susp. Inyectable (Fco. Ampula) | F24: 20 | G24: =IF(F24=0," ",F24) -> 20 | H24: =IF(F24=0," ",F24) -> 20 | I24: =IF(GENERAL!I24=0," ",GENERAL!I24) -> AHAVC215AA | J24: =IF(GENERAL!J24=0," ",GENERAL!J24) -> 46813
I25: =IF(GENERAL!I25=0," ",GENERAL!I25) | J25: =IF(GENERAL!J25=0," ",GENERAL!J25)
A26: 25311.020-000-3800-00 | B26: 3800 | C26: VACUNA DOBLE VIRAL (SR) | D26: MULTIDOSIS | E26: Fco. Amp Leofilizado+Diluy. | F26: 1 | G26: =IF(F26=0," ",F26) -> 1 | H26: =IF(F26=0," ",F26) -> 1 | I26: =IF(GENERAL!I26=0," ",GENERAL!I26) -> 0125N120A | J26: =IF(GENERAL!J26=0," ",GENERAL!J26) -> 46784
A28: 25311.020-000-3801-01 | B28: 3801 | C28: VACUNA BCG | D28: MULTIDOSIS | E28: Fco. Amp Leofilizado+Diluy. | F28: 5 | G28: =IF(F28=0," ",F28) -> 5 | H28: =IF(F28=0," ",F28) -> 5 | I28: =IF(GENERAL!I28=0," ",GENERAL!I28) -> 0374MA108 | J28: =IF(GENERAL!J28=0," ",GENERAL!J28) -> 46447
A30: 25311.020-000-3802-00 | B30: 3802 | C30: VACUNA ANTIPOLIOMELITICA (SABIN) | D30: MULTIDOSIS | E30: Susp. (gotero de plastico) | G30: =IF(F30=0," ",F30) | H30: =IF(F30=0," ",F30) | I30: =IF(GENERAL!I30=0," ",GENERAL!I30) | J30: =IF(GENERAL!J30=0," ",GENERAL!J30)
A32: 25311.020-000-3805-00 | B32: 3805 | C32: VACUNA VACUNA DPT | D32: MULTIDOSIS | E32: Susp. Inyectable (Fco. Ampula) | F32: 2 | G32: =IF(F32=0," ",F32) -> 2 | H32: =IF(F32=0," ",F32) -> 2 | I32: =IF(GENERAL!I32=0," ",GENERAL!I32) -> 2825Q001A | J32: =IF(GENERAL!J32=0," ",GENERAL!J32) -> 46784
I33: =IF(GENERAL!I33=0," ",GENERAL!I33) | J33: =IF(GENERAL!J33=0," ",GENERAL!J33)
A34: 25311.020-000-3808-02 | B34: 3808 | C34: VACUNA TDPA | D34: UNIDOSIS | E34: Susp. Inyectable (Fco. Ampula) | F34: 10 | G34: =IF(F34=0," ",F34) -> 10 | H34: =IF(F34=0," ",F34) -> 10 | I34: =IF(GENERAL!I34=0," ",GENERAL!I34) -> AC37B542BD | J34: =IF(GENERAL!J34=0," ",GENERAL!J34) -> 46784
A36: 25311.020-000-3810-00 | B36: 3810 | C36: VACUNA TD | D36: MULTIDOSIS | E36: Susp. Inyectable (Fco. Ampula) | F36: 1 | G36: =IF(F36=0," ",F36) -> 1 | H36: =IF(F36=0," ",F36) -> 1 | I36: =IF(GENERAL!I36=0," ",GENERAL!I36) -> 2805X003A | J36: =IF(GENERAL!J36=0," ",GENERAL!J36) -> 46388
I37: =IF(GENERAL!I37=0," ",GENERAL!I37) | J37: =IF(GENERAL!J37=0," ",GENERAL!J37)
A38: 25311.020-000-6056-00 | B38: 6056 | C38: VACUNA ANTIVARICELA | D38: UNIDOSIS | E38: Fco. Amp Leofilizado+Diluy. | G38: =IF(F38=0," ",F38) | H38: =IF(F38=0," ",F38) | I38: =IF(GENERAL!I38=0," ",GENERAL!I38) | J38: =IF(GENERAL!J38=0," ",GENERAL!J38)
I39: =IF(GENERAL!I39=0," ",GENERAL!I39) | J39: =IF(GENERAL!J39=0," ",GENERAL!J39)
A40: 25311.020-000-3820-00 | B40: 3820 | C40: VACUNA TRIPLE VIRAL 1DS (SRP) | D40: UNIDOSIS | E40: Fco. Amp Leofilizado+Diluy. | F40: 30 | G40: =IF(F40=0," ",F40) -> 30 | H40: =IF(F40=0," ",F40) -> 30 | I40: =IF(GENERAL!I40=0," ",GENERAL!I40) -> 0135N027B | J40: =IF(GENERAL!J40=0," ",GENERAL!J40) -> 46600
A42: 25311.020-000-3821-00 | B42: 3821 | C42: VACUNATRIPLEVIRAL MULTI DOSIS | D42: MULTIDOSIS | E42: Fco. Amp Leofilizado+Diluy. | G42: =IF(F42=0," ",F42) | H42: =IF(F42=0," ",F42) | I42: =IF(GENERAL!I42=0," ",GENERAL!I42) | J42: =IF(GENERAL!J42=0," ",GENERAL!J42)
I43: =IF(GENERAL!I43=0," ",GENERAL!I43) | J43: =IF(GENERAL!J43=0," ",GENERAL!J43)
A44: 25311.020-000-6317-01 | B44: 6317 | C44: VACUNA ANTIINFLUENZA 10/D | D44: MULTIDOSIS | E44: Susp. Inyectable (Fco. Ampula) | G44: =IF(F44=0," ",F44) | H44: =IF(F44=0," ",F44) | I44: =IF(GENERAL!I44=0," ",GENERAL!I44) | J44: =IF(GENERAL!J44=0," ",GENERAL!J44)
I45: =IF(GENERAL!I45=0," ",GENERAL!I45) | J45: =IF(GENERAL!J45=0," ",GENERAL!J45)
A46: 25311.020-000-3832-00 | B46: 3832 | C46: VACUNA INMUNOGLOBULINA ANTITETANICA | D46: UNIDOSIS | E46: Susp. Inyectable (Fco. Ampula) | G46: =IF(F46=0," ",F46) | H46: =IF(F46=0," ",F46) | I46: =IF(GENERAL!I46=0," ",GENERAL!I46) | J46: =IF(GENERAL!J46=0," ",GENERAL!J46)
I47: =IF(GENERAL!I47=0," ",GENERAL!I47) | J47: =IF(GENERAL!J47=0," ",GENERAL!J47)
A48: 25311.020-000-6501-02 | B48: 6501 | C48: VACUNA VPH | D48: UNIDOSIS | E48: Susp. Inyectable (Fco. Ampula) | G48: =IF(F48=0," ",F48) | H48: =IF(F48=0," ",F48) | I48: =IF(GENERAL!I48=0," ",GENERAL!I48) | J48: =IF(GENERAL!J48=0," ",GENERAL!J48)
A50: 25331.020-X-0002-00-E | B50: 2 | C50: VACUNA ANTIAMARILICA | D50: UNIDOSIS | E50: Fco. Amp Leofilizado + Jer.prellenada. | G50: =IF(F50=0," ",F50) | H50: =IF(F50=0," ",F50) | I50: =IF(GENERAL!I50=0," ",GENERAL!I50) | J50: =IF(GENERAL!J50=0," ",GENERAL!J50)
...

Sheet LOS OLVERA
A1: SERVICIOS DE SALUD DEL ESTADO DE QUERÉTARO
A2: COORDINACION GENERAL
A3: SUBDIRECCION DE ADQUISICIONES
A5: SOLICITUD Y SURTIMIENTO DE LA CÁMARA DE FRÍO ESTATAL
A7: ORIGEN: | B7: JURISDICCIÓN SANITARIA N.1 | G7: AREA: | H7: VACUNAS
A8: DIRECCIÓN: | B8: Circuito Moises Solana S/N, Col. Vista Alegre, Santiago de Querétaro. Qro. | G8: FECHA DE ENVIO: | H8: =IF(GENERAL!H8=0," ",GENERAL!H8) -> 46272
A9: DESTINO: | B9: C.S LOS OLVERA | G9: FOLIO ORACLE:
A10: DIRECCIÓN: | B10: Sabino S/N, Los Olvera, Corregidora. | G10: MES A SURTIR: | H10: =GENERAL!H10 -> SEPTIEMBRE
A12: NÚM | B12: CLAVE DE ARTÍCULO | C12: NOMBRE DEL ARTÍCULO | D12: PRESENTACIÓN | E12: FORMA | F12: CANTIDAD | K12: FIRMA DE RECEPCION
E13: FARMACÉUTICA | F13: SOLICITADO | G13: AUTORIZADO | H13: SURTIDO | I13: LOTE | J13: CADUCIDAD
A14: 25311.020-000-0146-03 | B14: 146 | C14: VACUNA ANTINEUMOCOCCICA 23 1DS | D14: UNIDOSIS | E14: Susp. Inyectable (Fco. Ampula) | G14: =IF(F14=0," ",F14) | H14: =IF(F14=0," ",F14) | I14: =IF(GENERAL!I14=0," ",GENERAL!I14) | J14: =IF(GENERAL!J14=0," ",GENERAL!J14) | M14: =SUM(F14+(F44*10)+(F32*10)+F22+F34+(F36*10)+F48) -> 10 | N14: JERINGA | O14: 2715 | P14: 22X32
I15: =IF(GENERAL!I15=0," ",GENERAL!I15) | J15: =IF(GENERAL!J15=0," ",GENERAL!J15) | M15: =SUM((F44/3)*20+F20) -> 20 | N15: JERINGA | O15: 2707 | P15: 23X25
A16: 25311.020-000-0148-01 | B16: 148 | C16: VACUNA ANTINEUMOCOCCICA 13 | D16: UNIDOSIS | E16: Susp. Inyectable (Jer. prellenada) | G16: =IF(F16=0," ",F16) | H16: =IF(F16=0," ",F16) | M16: =SUM(F24) -> 0 | N16: JERINGA | O16: 2699 | P16: 25X16
M17: =SUM(F26+F40) -> 0 | N17: JERINGA | O17: 2657 | P17: 27X13
A18: 25311.020-000-0150-05 | B18: 150 | C18: VACUNA ROTAVIRUS MONOVALENTE | D18: UNIDOSIS | E18: Susp. Inyectable (Jer. prellenada) | F18: 10 | G18: =IF(F18=0," ",F18) -> 10 | H18: =IF(F18=0," ",F18) -> 10 | I18: =IF(GENERAL!I18=0," ",GENERAL!I18) -> AROLE168AH | J18: =IF(GENERAL!J18=0," ",GENERAL!J18) -> 46419 | M18: =SUM(F28*10) -> 40 | N18: JERINGA | O18: 59 | P18: 30GX1/2
I19: =IF(GENERAL!I19=0," ",GENERAL!I19) | J19: =IF(GENERAL!J19=0," ",GENERAL!J19)
A20: 25311.020-000-6135-00 | B20: 6135 | C20: VACUNA HEXAVALENTE | D20: UNIDOSIS | E20: Susp. Inyectable (Fco. Ampula) | F20: 20 | G20: =IF(F20=0," ",F20) -> 20 | H20: =IF(F20=0," ",F20) -> 20 | I20: =IF(GENERAL!I20=0," ",GENERAL!I20) -> Y3C48D1 | J20: =IF(GENERAL!J20=0," ",GENERAL!J20) -> 46722
I21: =IF(GENERAL!I21=0," ",GENERAL!I21) | J21: =IF(GENERAL!J21=0," ",GENERAL!J21)
A22: 25311.020-000-2526-00 | B22: 2526 | C22: VACUNA HEPATITIS B MULTIDOSIS | D22: MULTIDOSIS | E22: Susp. Inyectable (Fco. Ampula) | G22: =IF(F22=0," ",F22) | H22: =IF(F22=0," ",F22)
A24: 25311.020-000-3825-01 | B24: 3825 | C24: VACUNA HEPATITIS A UNIDOSIS | D24: UNIDOSIS | E24: Susp. Inyectable (Fco. Ampula) | G24: =IF(F24=0," ",F24) | H24: =IF(F24=0," ",F24)
A26: 25311.020-000-3800-00 | B26: 3800 | C26: VACUNA DOBLE VIRAL (SR) | D26: MULTIDOSIS | E26: Fco. Amp Leofilizado+Diluy. | G26: =IF(F26=0," ",F26) | H26: =IF(F26=0," ",F26)
I27: =IF(GENERAL!I27=0," ",GENERAL!I27) | J27: =IF(GENERAL!J27=0," ",GENERAL!J27)
A28: 25311.020-000-3801-01 | B28: 3801 | C28: VACUNA BCG | D28: MULTIDOSIS | E28: Fco. Amp Leofilizado+Diluy. | F28: 4 | G28: =IF(F28=0," ",F28) -> 4 | H28: =IF(F28=0," ",F28) -> 4 | I28: =IF(GENERAL!I28=0," ",GENERAL!I28) -> 0374MA108 | J28: =IF(GENERAL!J28=0," ",GENERAL!J28) -> 46447
I29: =IF(GENERAL!I29=0," ",GENERAL!I29) | J29: =IF(GENERAL!J29=0," ",GENERAL!J29)
A30: 25311.020-000-3802-00 | B30: 3802 | C30: VACUNA ANTIPOLIOMELITICA (SABIN) | D30: MULTIDOSIS | E30: Susp. (gotero de plastico) | G30: =IF(F30=0," ",F30) | H30: =IF(F30=0," ",F30) | I30: =IF(GENERAL!I30=0," ",GENERAL!I30) | J30: =IF(GENERAL!J30=0," ",GENERAL!J30)
I31: =IF(GENERAL!I31=0," ",GENERAL!I31) | J31: =IF(GENERAL!J31=0," ",GENERAL!J31)
A32: 25311.020-000-3805-00 | B32: 3805 | C32: VACUNA VACUNA DPT | D32: MULTIDOSIS | E32: Susp. Inyectable (Fco. Ampula) | F32: 1 | G32: =IF(F32=0," ",F32) -> 1 | H32: =IF(F32=0," ",F32) -> 1 | I32: =IF(GENERAL!I32=0," ",GENERAL!I32) -> 2825Q001A | J32: =IF(GENERAL!J32=0," ",GENERAL!J32) -> 46784
A34: 25311.020-000-3808-02 | B34: 3808 | C34: VACUNA TDPA | D34: UNIDOSIS | E34: Susp. Inyectable (Fco. Ampula) | G34: =IF(F34=0," ",F34) | H34: =IF(F34=0," ",F34)
A36: 25311.020-000-3810-00 | B36: 3810 | C36: VACUNA TD | D36: MULTIDOSIS | E36: Susp. Inyectable (Fco. Ampula) | G36: =IF(F36=0," ",F36) | H36: =IF(F36=0," ",F36)
A38: 25311.020-000-6056-00 | B38: 6056 | C38: VACUNA ANTIVARICELA | D38: UNIDOSIS | E38: Fco. Amp Leofilizado+Diluy. | G38: =IF(F38=0," ",F38) | H38: =IF(F38=0," ",F38)
A40: 25311.020-000-3820-00 | B40: 3820 | C40: VACUNA TRIPLE VIRAL 1DS (SRP) | D40: UNIDOSIS | E40: Fco. Amp Leofilizado+Diluy. | G40: =IF(F40=0," ",F40) | H40: =IF(F40=0," ",F40)
A42: 25311.020-000-3821-00 | B42: 3821 | C42: VACUNATRIPLEVIRAL MULTI DOSIS | D42: MULTIDOSIS | E42: Fco. Amp Leofilizado+Diluy. | G42: =IF(F42=0," ",F42) | H42: =IF(F42=0," ",F42)
I43: =IF(GENERAL!I43=0," ",GENERAL!I43) | J43: =IF(GENERAL!J43=0," ",GENERAL!J43)
A44: 25311.020-000-6317-01 | B44: 6317 | C44: VACUNA ANTIINFLUENZA 10/D | D44: MULTIDOSIS | E44: Susp. Inyectable (Fco. Ampula) | G44: =IF(F44=0," ",F44) | H44: =IF(F44=0," ",F44) | I44: =IF(GENERAL!I44=0," ",GENERAL!I44) | J44: =IF(GENERAL!J44=0," ",GENERAL!J44)
I45: =IF(GENERAL!I45=0," ",GENERAL!I45) | J45: =IF(GENERAL!J45=0," ",GENERAL!J45)
A46: 25311.020-000-3832-00 | B46: 3832 | C46: VACUNA INMUNOGLOBULINA ANTITETANICA | D46: UNIDOSIS | E46: Susp. Inyectable (Fco. Ampula) | G46: =IF(F46=0," ",F46) | H46: =IF(F46=0," ",F46) | I46: =IF(GENERAL!I46=0," ",GENERAL!I46) | J46: =IF(GENERAL!J46=0," ",GENERAL!J46)
I47: =IF(GENERAL!I47=0," ",GENERAL!I47) | J47: =IF(GENERAL!J47=0," ",GENERAL!J47)
A48: 25311.020-000-6501-02 | B48: 6501 | C48: VACUNA VPH | D48: UNIDOSIS | E48: Susp. Inyectable (Fco. Ampula) | G48: =IF(F48=0," ",F48) | H48: =IF(F48=0," ",F48) | I48: =IF(GENERAL!I48=0," ",GENERAL!I48) | J48: =IF(GENERAL!J48=0," ",GENERAL!J48)
A50: 25331.020-X-0002-00-E | B50: 2 | C50: VACUNA ANTIAMARILICA | D50: UNIDOSIS | E50: Fco. Amp Leofilizado + Jer.prellenada. | G50: =IF(F50=0," ",F50) | H50: =IF(F50=0," ",F50) | I50: =IF(GENERAL!I50=0," ",GENERAL!I50) | J50: =IF(GENERAL!J50=0," ",GENERAL!J50)
I51: =IF(GENERAL!I51=0," ",GENERAL!I51) | J51: =IF(GENERAL!J51=0," ",GENERAL!J51)
...

Sheet SAN JOSÉ DE LOS OLVERA
A1: SERVICIOS DE SALUD DEL ESTADO DE QUERÉTARO
A2: COORDINACION GENERAL
A3: SUBDIRECCION DE ADQUISICIONES
A5: SOLICITUD Y SURTIMIENTO DE LA CÁMARA DE FRÍO ESTATAL
A7: ORIGEN: | B7: JURISDICCIÓN SANITARIA N.1 | G7: AREA: | H7: VACUNAS
A8: DIRECCIÓN: | B8: Circuito Moises Solana S/N, Col. Vista Alegre, Santiago de Querétaro. Qro. | G8: FECHA DE ENVIO: | H8: =IF(GENERAL!H8=0," ",GENERAL!H8) -> 46272
A9: DESTINO: | B9: C.S. SAN JOSÉ DE LOS OLVERA | G9: FOLIO ORACLE:
A10: DIRECCIÓN: | B10: Monterrey S/N, San José de los Olvera, Corregidora | G10: MES A SURTIR: | H10: =GENERAL!H10 -> SEPTIEMBRE
A12: NÚM | B12: CLAVE DE ARTÍCULO | C12: NOMBRE DEL ARTÍCULO | D12: PRESENTACIÓN | E12: FORMA | F12: CANTIDAD | K12: FIRMA DE RECEPCION
E13: FARMACÉUTICA | F13: SOLICITADO | G13: AUTORIZADO | H13: SURTIDO | I13: LOTE | J13: CADUCIDAD
A14: 25311.020-000-0146-03 | B14: 146 | C14: VACUNA ANTINEUMOCOCCICA 23 1DS | D14: UNIDOSIS | E14: Susp. Inyectable (Fco. Ampula) | G14: =IF(F14=0," ",F14) | H14: =IF(F14=0," ",F14) | I14: =IF(GENERAL!I14=0," ",GENERAL!I14) | J14: =IF(GENERAL!J14=0," ",GENERAL!J14) | M14: =SUM(F14+(F44*10)+(F32*10)+F22+F34+(F36*10)+F48) -> 52 | N14: JERINGA | O14: 2715 | P14: 22X32
I15: =IF(GENERAL!I15=0," ",GENERAL!I15) | J15: =IF(GENERAL!J15=0," ",GENERAL!J15) | M15: =SUM((F44/3)*20+F20) -> 40 | N15: JERINGA | O15: 2707 | P15: 23X25
A16: 25311.020-000-0148-01 | B16: 148 | C16: VACUNA ANTINEUMOCOCCICA 13 | D16: UNIDOSIS | E16: Susp. Inyectable (Jer. prellenada) | F16: 20 | G16: =IF(F16=0," ",F16) -> 20 | H16: =IF(F16=0," ",F16) -> 20 | I16: =IF(GENERAL!I16=0," ",GENERAL!I16) -> LC5884 | J16: =IF(GENERAL!J16=0," ",GENERAL!J16) -> 46388 | M16: =SUM(F24) -> 10 | N16: JERINGA | O16: 2699 | P16: 25X16
M17: =SUM(F26+F40) -> 52 | N17: JERINGA | O17: 2657 | P17: 27X13
A18: 25311.020-000-0150-05 | B18: 150 | C18: VACUNA ROTAVIRUS MONOVALENTE | D18: UNIDOSIS | E18: Susp. Inyectable (Jer. prellenada) | F18: 30 | G18: =IF(F18=0," ",F18) -> 30 | H18: =IF(F18=0," ",F18) -> 30 | I18: =IF(GENERAL!I18=0," ",GENERAL!I18) -> AROLE168AH | J18: =IF(GENERAL!J18=0," ",GENERAL!J18) -> 46419 | M18: =SUM(F28*10) -> 40 | N18: JERINGA | O18: 59 | P18: 30GX1/2
I19: =IF(GENERAL!I19=0," ",GENERAL!I19) | J19: =IF(GENERAL!J19=0," ",GENERAL!J19)
A20: 25311.020-000-6135-00 | B20: 6135 | C20: VACUNA HEXAVALENTE | D20: UNIDOSIS | E20: Susp. Inyectable (Fco. Ampula) | F20: 40 | G20: =IF(F20=0," ",F20) -> 40 | H20: =IF(F20=0," ",F20) -> 40 | I20: =IF(GENERAL!I20=0," ",GENERAL!I20) -> Y3C48D1 | J20: =IF(GENERAL!J20=0," ",GENERAL!J20) -> 46722
I21: =IF(GENERAL!I21=0," ",GENERAL!I21) | J21: =IF(GENERAL!J21=0," ",GENERAL!J21)
A22: 25311.020-000-2526-00 | B22: 2526 | C22: VACUNA HEPATITIS B MULTIDOSIS | D22: MULTIDOSIS | E22: Susp. Inyectable (Fco. Ampula) | F22: 2 | G22: =IF(F22=0," ",F22) -> 2 | H22: =IF(F22=0," ",F22) -> 2 | I22: =IF(GENERAL!I22=0," ",GENERAL!I22) -> 2526250606 | J22: 46919
I23: =IF(GENERAL!I23=0," ",GENERAL!I23) | J23: =IF(GENERAL!J23=0," ",GENERAL!J23)
A24: 25311.020-000-3825-01 | B24: 3825 | C24: VACUNA HEPATITIS A UNIDOSIS | D24: UNIDOSIS | E24: Susp. Inyectable (Fco. Ampula) | F24: 10 | G24: =IF(F24=0," ",F24) -> 10 | H24: =IF(F24=0," ",F24) -> 10 | I24: =IF(GENERAL!I24=0," ",GENERAL!I24) -> AHAVC215AA | J24: =IF(GENERAL!J24=0," ",GENERAL!J24) -> 46813
I25: =IF(GENERAL!I25=0," ",GENERAL!I25) | J25: =IF(GENERAL!J25=0," ",GENERAL!J25)
A26: 25311.020-000-3800-00 | B26: 3800 | C26: VACUNA DOBLE VIRAL (SR) | D26: MULTIDOSIS | E26: Fco. Amp Leofilizado+Diluy. | F26: 2 | G26: =IF(F26=0," ",F26) -> 2 | H26: =IF(F26=0," ",F26) -> 2 | I26: =IF(GENERAL!I26=0," ",GENERAL!I26) -> 0125N120A | J26: =IF(GENERAL!J26=0," ",GENERAL!J26) -> 46784
I27: =IF(GENERAL!I27=0," ",GENERAL!I27) | J27: =IF(GENERAL!J27=0," ",GENERAL!J27)
A28: 25311.020-000-3801-01 | B28: 3801 | C28: VACUNA BCG | D28: MULTIDOSIS | E28: Fco. Amp Leofilizado+Diluy. | F28: 4 | G28: =IF(F28=0," ",F28) -> 4 | H28: =IF(F28=0," ",F28) -> 4 | I28: =IF(GENERAL!I28=0," ",GENERAL!I28) -> 0374MA108 | J28: =IF(GENERAL!J28=0," ",GENERAL!J28) -> 46447
I29: =IF(GENERAL!I29=0," ",GENERAL!I29) | J29: =IF(GENERAL!J29=0," ",GENERAL!J29)
A30: 25311.020-000-3802-00 | B30: 3802 | C30: VACUNA ANTIPOLIOMELITICA (SABIN) | D30: MULTIDOSIS | E30: Susp. (gotero de plastico) | G30: =IF(F30=0," ",F30) | H30: =IF(F30=0," ",F30) | I30: =IF(GENERAL!I30=0," ",GENERAL!I30) | J30: =IF(GENERAL!J30=0," ",GENERAL!J30)
I31: =IF(GENERAL!I31=0," ",GENERAL!I31) | J31: =IF(GENERAL!J31=0," ",GENERAL!J31)
A32: 25311.020-000-3805-00 | B32: 3805 | C32: VACUNA VACUNA DPT | D32: MULTIDOSIS | E32: Susp. Inyectable (Fco. Ampula) | G32: =IF(F32=0," ",F32) | H32: =IF(F32=0," ",F32)
A34: 25311.020-000-3808-02 | B34: 3808 | C34: VACUNA TDPA | D34: UNIDOSIS | E34: Susp. Inyectable (Fco. Ampula) | F34: 10 | G34: =IF(F34=0," ",F34) -> 10 | H34: =IF(F34=0," ",F34) -> 10 | I34: =IF(GENERAL!I34=0," ",GENERAL!I34) -> AC37B542BD | J34: =IF(GENERAL!J34=0," ",GENERAL!J34) -> 46784
I35: =IF(GENERAL!I35=0," ",GENERAL!I35) | J35: =IF(GENERAL!J35=0," ",GENERAL!J35)
A36: 25311.020-000-3810-00 | B36: 3810 | C36: VACUNA TD | D36: MULTIDOSIS | E36: Susp. Inyectable (Fco. Ampula) | F36: 4 | G36: =IF(F36=0," ",F36) -> 4 | H36: =IF(F36=0," ",F36) -> 4 | I36: =IF(GENERAL!I36=0," ",GENERAL!I36) -> 2805X003A | J36: =IF(GENERAL!J36=0," ",GENERAL!J36) -> 46388
I37: =IF(GENERAL!I37=0," ",GENERAL!I37) | J37: =IF(GENERAL!J37=0," ",GENERAL!J37)
A38: 25311.020-000-6056-00 | B38: 6056 | C38: VACUNA ANTIVARICELA | D38: UNIDOSIS | E38: Fco. Amp Leofilizado+Diluy. | G38: =IF(F38=0," ",F38) | H38: =IF(F38=0," ",F38) | I38: =IF(GENERAL!I38=0," ",GENERAL!I38) | J38: =IF(GENERAL!J38=0," ",GENERAL!J38)
I39: =IF(GENERAL!I39=0," ",GENERAL!I39) | J39: =IF(GENERAL!J39=0," ",GENERAL!J39)
A40: 25311.020-000-3820-00 | B40: 3820 | C40: VACUNA TRIPLE VIRAL 1DS (SRP) | D40: UNIDOSIS | E40: Fco. Amp Leofilizado+Diluy. | F40: 50 | G40: =IF(F40=0," ",F40) -> 50 | H40: =IF(F40=0," ",F40) -> 50 | I40: =IF(GENERAL!I40=0," ",GENERAL!I40) -> 0135N027B | J40: =IF(GENERAL!J40=0," ",GENERAL!J40) -> 46600
A42: 25311.020-000-3821-00 | B42: 3821 | C42: VACUNATRIPLEVIRAL MULTI DOSIS | D42: MULTIDOSIS | E42: Fco. Amp Leofilizado+Diluy. | G42: =IF(F42=0," ",F42) | H42: =IF(F42=0," ",F42) | I42: =IF(GENERAL!I42=0," ",GENERAL!I42) | J42: =IF(GENERAL!J42=0," ",GENERAL!J42)
I43: =IF(GENERAL!I43=0," ",GENERAL!I43) | J43: =IF(GENERAL!J43=0," ",GENERAL!J43)
A44: 25311.020-000-6317-01 | B44: 6317 | C44: VACUNA ANTIINFLUENZA 10/D | D44: MULTIDOSIS | E44: Susp. Inyectable (Fco. Ampula) | G44: =IF(F44=0," ",F44) | H44: =IF(F44=0," ",F44) | I44: =IF(GENERAL!I44=0," ",GENERAL!I44) | J44: =IF(GENERAL!J44=0," ",GENERAL!J44)
I45: =IF(GENERAL!I45=0," ",GENERAL!I45) | J45: =IF(GENERAL!J45=0," ",GENERAL!J45)
...

Sheet PRESA DE BRAVO
A1: SERVICIOS DE SALUD DEL ESTADO DE QUERÉTARO
A2: COORDINACION GENERAL
A3: SUBDIRECCION DE ADQUISICIONES
A5: SOLICITUD Y SURTIMIENTO DE LA CÁMARA DE FRÍO ESTATAL
A7: ORIGEN: | B7: JURISDICCIÓN SANITARIA N.1 | G7: AREA: | H7: VACUNAS
A8: DIRECCIÓN: | B8: Circuito Moises Solana S/N, Col. Vista Alegre, Santiago de Querétaro. Qro. | G8: FECHA DE ENVIO: | H8: =IF(GENERAL!H8=0," ",GENERAL!H8) -> 46272
A9: DESTINO: | B9: C.S PRESA DE BRAVO | G9: FOLIO ORACLE:
A10: DIRECCIÓN: | B10: Carretera a Coronero S/N, KM 13.5, Corregidora | G10: MES A SURTIR: | H10: =GENERAL!H10 -> SEPTIEMBRE
A12: NÚM | B12: CLAVE DE ARTÍCULO | C12: NOMBRE DEL ARTÍCULO | D12: PRESENTACIÓN | E12: FORMA | F12: CANTIDAD | K12: FIRMA DE RECEPCION
E13: FARMACÉUTICA | F13: SOLICITADO | G13: AUTORIZADO | H13: SURTIDO | I13: LOTE | J13: CADUCIDAD
A14: 25311.020-000-0146-03 | B14: 146 | C14: VACUNA ANTINEUMOCOCCICA 23 1DS | D14: UNIDOSIS | E14: Susp. Inyectable (Fco. Ampula) | G14: =IF(F14=0," ",F14) | H14: =IF(F14=0," ",F14) | I14: =IF(GENERAL!I14=0," ",GENERAL!I14) | J14: =IF(GENERAL!J14=0," ",GENERAL!J14) | M14: =SUM(F14+(F44*10)+(F32*10)+F22+F34+(F36*10)+F48) -> 37 | N14: JERINGA | O14: 2715 | P14: 22X32
I15: =IF(GENERAL!I15=0," ",GENERAL!I15) | J15: =IF(GENERAL!J15=0," ",GENERAL!J15) | M15: =SUM((F44/3)*20+F20) -> 20 | N15: JERINGA | O15: 2707 | P15: 23X25
A16: 25311.020-000-0148-01 | B16: 148 | C16: VACUNA ANTINEUMOCOCCICA 13 | D16: UNIDOSIS | E16: Susp. Inyectable (Jer. prellenada) | F16: 20 | G16: =IF(F16=0," ",F16) -> 20 | H16: =IF(F16=0," ",F16) -> 20 | I16: =IF(GENERAL!I16=0," ",GENERAL!I16) -> LC5884 | J16: =IF(GENERAL!J16=0," ",GENERAL!J16) -> 46388 | M16: =SUM(F24) -> 5 | N16: JERINGA | O16: 2699 | P16: 25X16
M17: =SUM(F26+F40) -> 31 | N17: JERINGA | O17: 2657 | P17: 27X13
A18: 25311.020-000-0150-05 | B18: 150 | C18: VACUNA ROTAVIRUS MONOVALENTE | D18: UNIDOSIS | E18: Susp. Inyectable (Jer. prellenada) | F18: 20 | G18: =IF(F18=0," ",F18) -> 20 | H18: =IF(F18=0," ",F18) -> 20 | I18: =IF(GENERAL!I18=0," ",GENERAL!I18) -> AROLE168AH | J18: =IF(GENERAL!J18=0," ",GENERAL!J18) -> 46419 | M18: =SUM(F28*10) -> 30 | N18: JERINGA | O18: 59 | P18: 30GX1/2
I19: =IF(GENERAL!I19=0," ",GENERAL!I19) | J19: =IF(GENERAL!J19=0," ",GENERAL!J19)
A20: 25311.020-000-6135-00 | B20: 6135 | C20: VACUNA HEXAVALENTE | D20: UNIDOSIS | E20: Susp. Inyectable (Fco. Ampula) | F20: 20 | G20: =IF(F20=0," ",F20) -> 20 | H20: =IF(F20=0," ",F20) -> 20 | I20: =IF(GENERAL!I20=0," ",GENERAL!I20) -> Y3C48D1 | J20: =IF(GENERAL!J20=0," ",GENERAL!J20) -> 46722
I21: =IF(GENERAL!I21=0," ",GENERAL!I21) | J21: =IF(GENERAL!J21=0," ",GENERAL!J21)
A22: 25311.020-000-2526-00 | B22: 2526 | C22: VACUNA HEPATITIS B MULTIDOSIS | D22: MULTIDOSIS | E22: Susp. Inyectable (Fco. Ampula) | F22: 2 | G22: =IF(F22=0," ",F22) -> 2 | H22: =IF(F22=0," ",F22) -> 2 | I22: =IF(GENERAL!I22=0," ",GENERAL!I22) -> 2526250606 | J22: 46919
I23: =IF(GENERAL!I23=0," ",GENERAL!I23) | J23: =IF(GENERAL!J23=0," ",GENERAL!J23)
A24: 25311.020-000-3825-01 | B24: 3825 | C24: VACUNA HEPATITIS A UNIDOSIS | D24: UNIDOSIS | E24: Susp. Inyectable (Fco. Ampula) | F24: 5 | G24: =IF(F24=0," ",F24) -> 5 | H24: =IF(F24=0," ",F24) -> 5 | I24: =IF(GENERAL!I24=0," ",GENERAL!I24) -> AHAVC215AA | J24: =IF(GENERAL!J24=0," ",GENERAL!J24) -> 46813
I25: =IF(GENERAL!I25=0," ",GENERAL!I25) | J25: =IF(GENERAL!J25=0," ",GENERAL!J25)
A26: 25311.020-000-3800-00 | B26: 3800 | C26: VACUNA DOBLE VIRAL (SR) | D26: MULTIDOSIS | E26: Fco. Amp Leofilizado+Diluy. | F26: 1 | G26: =IF(F26=0," ",F26) -> 1 | H26: =IF(F26=0," ",F26) -> 1 | I26: =IF(GENERAL!I26=0," ",GENERAL!I26) -> 0125N120A | J26: =IF(GENERAL!J26=0," ",GENERAL!J26) -> 46784
I27: =IF(GENERAL!I27=0," ",GENERAL!I27) | J27: =IF(GENERAL!J27=0," ",GENERAL!J27)
A28: 25311.020-000-3801-01 | B28: 3801 | C28: VACUNA BCG | D28: MULTIDOSIS | E28: Fco. Amp Leofilizado+Diluy. | F28: 3 | G28: =IF(F28=0," ",F28) -> 3 | H28: =IF(F28=0," ",F28) -> 3 | I28: =IF(GENERAL!I28=0," ",GENERAL!I28) -> 0374MA108 | J28: =IF(GENERAL!J28=0," ",GENERAL!J28) -> 46447
I29: =IF(GENERAL!I29=0," ",GENERAL!I29) | J29: =IF(GENERAL!J29=0," ",GENERAL!J29)
A30: 25311.020-000-3802-00 | B30: 3802 | C30: VACUNA ANTIPOLIOMELITICA (SABIN) | D30: MULTIDOSIS | E30: Susp. (gotero de plastico) | G30: =IF(F30=0," ",F30) | H30: =IF(F30=0," ",F30) | I30: =IF(GENERAL!I30=0," ",GENERAL!I30) | J30: =IF(GENERAL!J30=0," ",GENERAL!J30)
I31: =IF(GENERAL!I31=0," ",GENERAL!I31) | J31: =IF(GENERAL!J31=0," ",GENERAL!J31)
A32: 25311.020-000-3805-00 | B32: 3805 | C32: VACUNA VACUNA DPT | D32: MULTIDOSIS | E32: Susp. Inyectable (Fco. Ampula) | F32: 1 | G32: =IF(F32=0," ",F32) -> 1 | H32: =IF(F32=0," ",F32) -> 1 | I32: =IF(GENERAL!I32=0," ",GENERAL!I32) -> 2825Q001A | J32: =IF(GENERAL!J32=0," ",GENERAL!J32) -> 46784
A34: 25311.020-000-3808-02 | B34: 3808 | C34: VACUNA TDPA | D34: UNIDOSIS | E34: Susp. Inyectable (Fco. Ampula) | F34: 5 | G34: =IF(F34=0," ",F34) -> 5 | H34: =IF(F34=0," ",F34) -> 5 | I34: =IF(GENERAL!I34=0," ",GENERAL!I34) -> AC37B542BD | J34: =IF(GENERAL!J34=0," ",GENERAL!J34) -> 46784
A36: 25311.020-000-3810-00 | B36: 3810 | C36: VACUNA TD | D36: MULTIDOSIS | E36: Susp. Inyectable (Fco. Ampula) | F36: 2 | G36: =IF(F36=0," ",F36) -> 2 | H36: =IF(F36=0," ",F36) -> 2 | I36: =IF(GENERAL!I36=0," ",GENERAL!I36) -> 2805X003A | J36: =IF(GENERAL!J36=0," ",GENERAL!J36) -> 46388
I37: =IF(GENERAL!I37=0," ",GENERAL!I37) | J37: =IF(GENERAL!J37=0," ",GENERAL!J37)
A38: 25311.020-000-6056-00 | B38: 6056 | C38: VACUNA ANTIVARICELA | D38: UNIDOSIS | E38: Fco. Amp Leofilizado+Diluy. | G38: =IF(F38=0," ",F38) | H38: =IF(F38=0," ",F38) | I38: =IF(GENERAL!I38=0," ",GENERAL!I38) | J38: =IF(GENERAL!J38=0," ",GENERAL!J38)
I39: =IF(GENERAL!I39=0," ",GENERAL!I39) | J39: =IF(GENERAL!J39=0," ",GENERAL!J39)
A40: 25311.020-000-3820-00 | B40: 3820 | C40: VACUNA TRIPLE VIRAL 1DS (SRP) | D40: UNIDOSIS | E40: Fco. Amp Leofilizado+Diluy. | F40: 30 | G40: =IF(F40=0," ",F40) -> 30 | H40: =IF(F40=0," ",F40) -> 30 | I40: =IF(GENERAL!I40=0," ",GENERAL!I40) -> 0135N027B | J40: =IF(GENERAL!J40=0," ",GENERAL!J40) -> 46600
I41: =IF(GENERAL!I41=0," ",GENERAL!I41)
A42: 25311.020-000-3821-00 | B42: 3821 | C42: VACUNATRIPLEVIRAL MULTI DOSIS | D42: MULTIDOSIS | E42: Fco. Amp Leofilizado+Diluy. | G42: =IF(F42=0," ",F42) | H42: =IF(F42=0," ",F42) | I42: =IF(GENERAL!I42=0," ",GENERAL!I42) | J42: =IF(GENERAL!J42=0," ",GENERAL!J42)
I43: =IF(GENERAL!I43=0," ",GENERAL!I43) | J43: =IF(GENERAL!J43=0," ",GENERAL!J43)
A44: 25311.020-000-6317-01 | B44: 6317 | C44: VACUNA ANTIINFLUENZA 10/D | D44: MULTIDOSIS | E44: Susp. Inyectable (Fco. Ampula) | G44: =IF(F44=0," ",F44) | H44: =IF(F44=0," ",F44) | I44: =IF(GENERAL!I44=0," ",GENERAL!I44) | J44: =IF(GENERAL!J44=0," ",GENERAL!J44)
I45: =IF(GENERAL!I45=0," ",GENERAL!I45) | J45: =IF(GENERAL!J45=0," ",GENERAL!J45)
...

Sheet LA NEGRETA
A1: SERVICIOS DE SALUD DEL ESTADO DE QUERÉTARO
A2: COORDINACION GENERAL
A3: SUBDIRECCION DE ADQUISICIONES
A5: SOLICITUD Y SURTIMIENTO DE LA CÁMARA DE FRÍO ESTATAL
A7: ORIGEN: | B7: JURISDICCIÓN SANITARIA N.1 | G7: AREA: | H7: VACUNAS
A8: DIRECCIÓN: | B8: Circuito Moises Solana S/N, Col. Vista Alegre, Santiago de Querétaro. Qro. | G8: FECHA DE ENVIO: | H8: =IF(GENERAL!H8=0," ",GENERAL!H8) -> 46272
A9: DESTINO: | B9: C.S LA NEGRETA | G9: FOLIO ORACLE:
A10: DIRECCIÓN: | B10: 21 de Marzo S/N, La Negreta, Corregidora | G10: MES A SURTIR: | H10: =GENERAL!H10 -> SEPTIEMBRE
A12: NÚM | B12: CLAVE DE ARTÍCULO | C12: NOMBRE DEL ARTÍCULO | D12: PRESENTACIÓN | E12: FORMA | F12: CANTIDAD | K12: FIRMA DE RECEPCION
E13: FARMACÉUTICA | F13: SOLICITADO | G13: AUTORIZADO | H13: SURTIDO | I13: LOTE | J13: CADUCIDAD
A14: 25311.020-000-0146-03 | B14: 146 | C14: VACUNA ANTINEUMOCOCCICA 23 1DS | D14: UNIDOSIS | E14: Susp. Inyectable (Fco. Ampula) | G14: =IF(F14=0," ",F14) | H14: =IF(F14=0," ",F14) | I14: =IF(GENERAL!I14=0," ",GENERAL!I14) | J14: =IF(GENERAL!J14=0," ",GENERAL!J14) | M14: =SUM(F14+(F44*10)+(F32*10)+F22+F34+(F36*10)+F48) -> 52 | N14: JERINGA | O14: 2715 | P14: 22X32
M15: =SUM((F44/3)*20+F20) -> 80 | N15: JERINGA | O15: 2707 | P15: 23X25
A16: 25311.020-000-0148-01 | B16: 148 | C16: VACUNA ANTINEUMOCOCCICA 13 | D16: UNIDOSIS | E16: Susp. Inyectable (Jer. prellenada) | F16: 70 | G16: =IF(F16=0," ",F16) -> 70 | H16: =IF(F16=0," ",F16) -> 70 | I16: =IF(GENERAL!I16=0," ",GENERAL!I16) -> LC5884 | J16: =IF(GENERAL!J16=0," ",GENERAL!J16) -> 46388 | M16: =SUM(F24) -> 30 | N16: JERINGA | O16: 2699 | P16: 25X16
M17: =SUM(F26+F40) -> 53 | N17: JERINGA | O17: 2657 | P17: 27X13
A18: 25311.020-000-0150-05 | B18: 150 | C18: VACUNA ROTAVIRUS MONOVALENTE | D18: UNIDOSIS | E18: Susp. Inyectable (Jer. prellenada) | F18: 30 | G18: =IF(F18=0," ",F18) -> 30 | H18: =IF(F18=0," ",F18) -> 30 | I18: =IF(GENERAL!I18=0," ",GENERAL!I18) -> AROLE168AH | J18: =IF(GENERAL!J18=0," ",GENERAL!J18) -> 46419 | M18: =SUM(F28*10) -> 40 | N18: JERINGA | O18: 59 | P18: 30GX1/2
I19: =IF(GENERAL!I19=0," ",GENERAL!I19) | J19: =IF(GENERAL!J19=0," ",GENERAL!J19)
A20: 25311.020-000-6135-00 | B20: 6135 | C20: VACUNA HEXAVALENTE | D20: UNIDOSIS | E20: Susp. Inyectable (Fco. Ampula) | F20: 80 | G20: =IF(F20=0," ",F20) -> 80 | H20: =IF(F20=0," ",F20) -> 80 | I20: =IF(GENERAL!I20=0," ",GENERAL!I20) -> Y3C48D1 | J20: =IF(GENERAL!J20=0," ",GENERAL!J20) -> 46722
I21: =IF(GENERAL!I21=0," ",GENERAL!I21) | J21: =IF(GENERAL!J21=0," ",GENERAL!J21)
A22: 25311.020-000-2526-00 | B22: 2526 | C22: VACUNA HEPATITIS B MULTIDOSIS | D22: MULTIDOSIS | E22: Susp. Inyectable (Fco. Ampula) | F22: 2 | G22: =IF(F22=0," ",F22) -> 2 | H22: =IF(F22=0," ",F22) -> 2 | I22: =IF(GENERAL!I22=0," ",GENERAL!I22) -> 2526250606 | J22: 46919
I23: =IF(GENERAL!I23=0," ",GENERAL!I23) | J23: =IF(GENERAL!J23=0," ",GENERAL!J23)
A24: 25311.020-000-3825-01 | B24: 3825 | C24: VACUNA HEPATITIS A UNIDOSIS | D24: UNIDOSIS | E24: Susp. Inyectable (Fco. Ampula) | F24: 30 | G24: =IF(F24=0," ",F24) -> 30 | H24: =IF(F24=0," ",F24) -> 30 | I24: =IF(GENERAL!I24=0," ",GENERAL!I24) -> AHAVC215AA | J24: =IF(GENERAL!J24=0," ",GENERAL!J24) -> 46813
I25: =IF(GENERAL!I25=0," ",GENERAL!I25) | J25: =IF(GENERAL!J25=0," ",GENERAL!J25)
A26: 25311.020-000-3800-00 | B26: 3800 | C26: VACUNA DOBLE VIRAL (SR) | D26: MULTIDOSIS | E26: Fco. Amp Leofilizado+Diluy. | F26: 3 | G26: =IF(F26=0," ",F26) -> 3 | H26: =IF(F26=0," ",F26) -> 3 | I26: =IF(GENERAL!I26=0," ",GENERAL!I26) -> 0125N120A | J26: =IF(GENERAL!J26=0," ",GENERAL!J26) -> 46784
I27: =IF(GENERAL!I27=0," ",GENERAL!I27) | J27: =IF(GENERAL!J27=0," ",GENERAL!J27)
A28: 25311.020-000-3801-01 | B28: 3801 | C28: VACUNA BCG | D28: MULTIDOSIS | E28: Fco. Amp Leofilizado+Diluy. | F28: 4 | G28: =IF(F28=0," ",F28) -> 4 | H28: =IF(F28=0," ",F28) -> 4 | I28: =IF(GENERAL!I28=0," ",GENERAL!I28) -> 0374MA108 | J28: =IF(GENERAL!J28=0," ",GENERAL!J28) -> 46447
I29: =IF(GENERAL!I29=0," ",GENERAL!I29) | J29: =IF(GENERAL!J29=0," ",GENERAL!J29)
A30: 25311.020-000-3802-00 | B30: 3802 | C30: VACUNA ANTIPOLIOMELITICA (SABIN) | D30: MULTIDOSIS | E30: Susp. (gotero de plastico) | G30: =IF(F30=0," ",F30) | H30: =IF(F30=0," ",F30) | I30: =IF(GENERAL!I30=0," ",GENERAL!I30) | J30: =IF(GENERAL!J30=0," ",GENERAL!J30)
I31: =IF(GENERAL!I31=0," ",GENERAL!I31) | J31: =IF(GENERAL!J31=0," ",GENERAL!J31)
A32: 25311.020-000-3805-00 | B32: 3805 | C32: VACUNA VACUNA DPT | D32: MULTIDOSIS | E32: Susp. Inyectable (Fco. Ampula) | F32: 2 | G32: =IF(F32=0," ",F32) -> 2 | H32: =IF(F32=0," ",F32) -> 2 | I32: =IF(GENERAL!I32=0," ",GENERAL!I32) -> 2825Q001A | J32: =IF(GENERAL!J32=0," ",GENERAL!J32) -> 46784
I33: =IF(GENERAL!I33=0," ",GENERAL!I33) | J33: =IF(GENERAL!J33=0," ",GENERAL!J33)
A34: 25311.020-000-3808-02 | B34: 3808 | C34: VACUNA TDPA | D34: UNIDOSIS | E34: Susp. Inyectable (Fco. Ampula) | F34: 10 | G34: =IF(F34=0," ",F34) -> 10 | H34: =IF(F34=0," ",F34) -> 10 | I34: =IF(GENERAL!I34=0," ",GENERAL!I34) -> AC37B542BD | J34: =IF(GENERAL!J34=0," ",GENERAL!J34) -> 46784
I35: =IF(GENERAL!I35=0," ",GENERAL!I35) | J35: =IF(GENERAL!J35=0," ",GENERAL!J35)
A36: 25311.020-000-3810-00 | B36: 3810 | C36: VACUNA TD | D36: MULTIDOSIS | E36: Susp. Inyectable (Fco. Ampula) | F36: 2 | G36: =IF(F36=0," ",F36) -> 2 | H36: =IF(F36=0," ",F36) -> 2 | I36: =IF(GENERAL!I36=0," ",GENERAL!I36) -> 2805X003A | J36: =IF(GENERAL!J36=0," ",GENERAL!J36) -> 46388
I37: =IF(GENERAL!I37=0," ",GENERAL!I37) | J37: =IF(GENERAL!J37=0," ",GENERAL!J37)
A38: 25311.020-000-6056-00 | B38: 6056 | C38: VACUNA ANTIVARICELA | D38: UNIDOSIS | E38: Fco. Amp Leofilizado+Diluy. | G38: =IF(F38=0," ",F38) | H38: =IF(F38=0," ",F38) | I38: =IF(GENERAL!I38=0," ",GENERAL!I38) | J38: =IF(GENERAL!J38=0," ",GENERAL!J38)
I39: =IF(GENERAL!I39=0," ",GENERAL!I39) | J39: =IF(GENERAL!J39=0," ",GENERAL!J39)
A40: 25311.020-000-3820-00 | B40: 3820 | C40: VACUNA TRIPLE VIRAL 1DS (SRP) | D40: UNIDOSIS | E40: Fco. Amp Leofilizado+Diluy. | F40: 50 | G40: =IF(F40=0," ",F40) -> 50 | H40: =IF(F40=0," ",F40) -> 50 | I40: =IF(GENERAL!I40=0," ",GENERAL!I40) -> 0135N027B | J40: =IF(GENERAL!J40=0," ",GENERAL!J40) -> 46600
I41: =IF(GENERAL!I41=0," ",GENERAL!I41)
A42: 25311.020-000-3821-00 | B42: 3821 | C42: VACUNATRIPLEVIRAL MULTI DOSIS | D42: MULTIDOSIS | E42: Fco. Amp Leofilizado+Diluy. | G42: =IF(F42=0," ",F42) | H42: =IF(F42=0," ",F42) | I42: =IF(GENERAL!I42=0," ",GENERAL!I42) | J42: =IF(GENERAL!J42=0," ",GENERAL!J42)
I43: =IF(GENERAL!I43=0," ",GENERAL!I43) | J43: =IF(GENERAL!J43=0," ",GENERAL!J43)
...

Sheet FAM CORREGIDORA
A1: SERVICIOS DE SALUD DEL ESTADO DE QUERÉTARO
A2: COORDINACION GENERAL
A3: SUBDIRECCION DE ADQUISICIONES
A5: SOLICITUD Y SURTIMIENTO DE LA CÁMARA DE FRÍO ESTATAL
A7: ORIGEN: | B7: JURISDICCIÓN SANITARIA N.1 | G7: AREA: | H7: VACUNAS
A8: DIRECCIÓN: | B8: Circuito Moises Solana S/N, Col. Vista Alegre, Santiago de Querétaro. Qro. | G8: FECHA DE ENVIO: | H8: =IF(GENERAL!H8=0," ",GENERAL!H8) -> 46272
A9: DESTINO: | B9: FAM CORREGIDORA | G9: FOLIO ORACLE:
A10: DIRECCIÓN: | G10: MES A SURTIR: | H10: =GENERAL!H10 -> SEPTIEMBRE
A12: NÚM | B12: CLAVE DE ARTÍCULO | C12: NOMBRE DEL ARTÍCULO | D12: PRESENTACIÓN | E12: FORMA | F12: CANTIDAD | K12: FIRMA DE RECEPCION
E13: FARMACÉUTICA | F13: SOLICITADO | G13: AUTORIZADO | H13: SURTIDO | I13: LOTE | J13: CADUCIDAD
A14: 25311.020-000-0146-03 | B14: 146 | C14: VACUNA ANTINEUMOCOCCICA 23 1DS | D14: UNIDOSIS | E14: Susp. Inyectable (Fco. Ampula) | G14: =IF(F14=0," ",F14) | H14: =IF(F14=0," ",F14) | I14: =IF(GENERAL!I14=0," ",GENERAL!I14) | J14: =IF(GENERAL!J14=0," ",GENERAL!J14) | M14: =SUM(F14+(F44*10)+(F32*10)+F22+F34+(F36*10)+F48) -> 10 | N14: JERINGA | O14: 2715 | P14: 22X32
I15: =IF(GENERAL!I15=0," ",GENERAL!I15) | J15: =IF(GENERAL!J15=0," ",GENERAL!J15) | M15: =SUM((F44/3)*20+F20) -> 0 | N15: JERINGA | O15: 2707 | P15: 23X25
A16: 25311.020-000-0148-01 | B16: 148 | C16: VACUNA ANTINEUMOCOCCICA 13 | D16: UNIDOSIS | E16: Susp. Inyectable (Jer. prellenada) | G16: =IF(F16=0," ",F16) | H16: =IF(F16=0," ",F16) | M16: =SUM(F24) -> 5 | N16: JERINGA | O16: 2699 | P16: 25X16
M17: =SUM(F26+F40) -> 0 | N17: JERINGA | O17: 2657 | P17: 27X13
A18: 25311.020-000-0150-05 | B18: 150 | C18: VACUNA ROTAVIRUS MONOVALENTE | D18: UNIDOSIS | E18: Susp. Inyectable (Jer. prellenada) | G18: =IF(F18=0," ",F18) | H18: =IF(F18=0," ",F18) | M18: =SUM(F28*10) -> 0 | N18: JERINGA | O18: 59 | P18: 30GX1/2
A20: 25311.020-000-6135-00 | B20: 6135 | C20: VACUNA HEXAVALENTE | D20: UNIDOSIS | E20: Susp. Inyectable (Fco. Ampula) | G20: =IF(F20=0," ",F20) | H20: =IF(F20=0," ",F20)
A22: 25311.020-000-2526-00 | B22: 2526 | C22: VACUNA HEPATITIS B MULTIDOSIS | D22: MULTIDOSIS | E22: Susp. Inyectable (Fco. Ampula) | G22: =IF(F22=0," ",F22) | H22: =IF(F22=0," ",F22)
A24: 25311.020-000-3825-01 | B24: 3825 | C24: VACUNA HEPATITIS A UNIDOSIS | D24: UNIDOSIS | E24: Susp. Inyectable (Fco. Ampula) | F24: 5 | G24: =IF(F24=0," ",F24) -> 5 | H24: =IF(F24=0," ",F24) -> 5 | I24: =IF(GENERAL!I24=0," ",GENERAL!I24) -> AHAVC215AA | J24: =IF(GENERAL!J24=0," ",GENERAL!J24) -> 46813
A26: 25311.020-000-3800-00 | B26: 3800 | C26: VACUNA DOBLE VIRAL (SR) | D26: MULTIDOSIS | E26: Fco. Amp Leofilizado+Diluy. | G26: =IF(F26=0," ",F26) | H26: =IF(F26=0," ",F26)
A28: 25311.020-000-3801-01 | B28: 3801 | C28: VACUNA BCG | D28: MULTIDOSIS | E28: Fco. Amp Leofilizado+Diluy. | G28: =IF(F28=0," ",F28) | H28: =IF(F28=0," ",F28)
A30: 25311.020-000-3802-00 | B30: 3802 | C30: VACUNA ANTIPOLIOMELITICA (SABIN) | D30: MULTIDOSIS | E30: Susp. (gotero de plastico) | G30: =IF(F30=0," ",F30) | H30: =IF(F30=0," ",F30)
A32: 25311.020-000-3805-00 | B32: 3805 | C32: VACUNA VACUNA DPT | D32: MULTIDOSIS | E32: Susp. Inyectable (Fco. Ampula) | G32: =IF(F32=0," ",F32) | H32: =IF(F32=0," ",F32)
A34: 25311.020-000-3808-02 | B34: 3808 | C34: VACUNA TDPA | D34: UNIDOSIS | E34: Susp. Inyectable (Fco. Ampula) | G34: =IF(F34=0," ",F34) | H34: =IF(F34=0," ",F34)
A36: 25311.020-000-3810-00 | B36: 3810 | C36: VACUNA TD | D36: MULTIDOSIS | E36: Susp. Inyectable (Fco. Ampula) | F36: 1 | G36: =IF(F36=0," ",F36) -> 1 | H36: =IF(F36=0," ",F36) -> 1 | I36: =IF(GENERAL!I36=0," ",GENERAL!I36) -> 2805X003A | J36: =IF(GENERAL!J36=0," ",GENERAL!J36) -> 46388
A38: 25311.020-000-6056-00 | B38: 6056 | C38: VACUNA ANTIVARICELA | D38: UNIDOSIS | E38: Fco. Amp Leofilizado+Diluy. | G38: =IF(F38=0," ",F38) | H38: =IF(F38=0," ",F38) | I38: =IF(GENERAL!I38=0," ",GENERAL!I38) | J38: =IF(GENERAL!J38=0," ",GENERAL!J38)
I39: =IF(GENERAL!I39=0," ",GENERAL!I39) | J39: =IF(GENERAL!J39=0," ",GENERAL!J39)
A40: 25311.020-000-3820-00 | B40: 3820 | C40: VACUNA TRIPLE VIRAL 1DS (SRP) | D40: UNIDOSIS | E40: Fco. Amp Leofilizado+Diluy. | G40: =IF(F40=0," ",F40) | H40: =IF(F40=0," ",F40)
A42: 25311.020-000-3821-00 | B42: 3821 | C42: VACUNATRIPLEVIRAL MULTI DOSIS | D42: MULTIDOSIS | E42: Fco. Amp Leofilizado+Diluy. | G42: =IF(F42=0," ",F42) | H42: =IF(F42=0," ",F42) | I42: =IF(GENERAL!I42=0," ",GENERAL!I42) | J42: =IF(GENERAL!J42=0," ",GENERAL!J42)
I43: =IF(GENERAL!I43=0," ",GENERAL!I43) | J43: =IF(GENERAL!J43=0," ",GENERAL!J43)
A44: 25311.020-000-6317-01 | B44: 6317 | C44: VACUNA ANTIINFLUENZA 10/D | D44: MULTIDOSIS | E44: Susp. Inyectable (Fco. Ampula) | G44: =IF(F44=0," ",F44) | H44: =IF(F44=0," ",F44) | I44: =IF(GENERAL!I44=0," ",GENERAL!I44) | J44: =IF(GENERAL!J44=0," ",GENERAL!J44)
I45: =IF(GENERAL!I45=0," ",GENERAL!I45) | J45: =IF(GENERAL!J45=0," ",GENERAL!J45)
A46: 25311.020-000-3832-00 | B46: 3832 | C46: VACUNA INMUNOGLOBULINA ANTITETANICA | D46: UNIDOSIS | E46: Susp. Inyectable (Fco. Ampula) | G46: =IF(F46=0," ",F46) | H46: =IF(F46=0," ",F46) | I46: =IF(GENERAL!I46=0," ",GENERAL!I46) | J46: =IF(GENERAL!J46=0," ",GENERAL!J46)
I47: =IF(GENERAL!I47=0," ",GENERAL!I47) | J47: =IF(GENERAL!J47=0," ",GENERAL!J47)
A48: 25311.020-000-6501-02 | B48: 6501 | C48: VACUNA VPH | D48: UNIDOSIS | E48: Susp. Inyectable (Fco. Ampula) | G48: =IF(F48=0," ",F48) | H48: =IF(F48=0," ",F48) | I48: =IF(GENERAL!I48=0," ",GENERAL!I48) | J48: =IF(GENERAL!J48=0," ",GENERAL!J48)
A50: 25331.020-X-0002-00-E | B50: 2 | C50: VACUNA ANTIAMARILICA | D50: UNIDOSIS | E50: Fco. Amp Leofilizado + Jer.prellenada. | G50: =IF(F50=0," ",F50) | H50: =IF(F50=0," ",F50) | I50: =IF(GENERAL!I50=0," ",GENERAL!I50) | J50: =IF(GENERAL!J50=0," ",GENERAL!J50)
I51: =IF(GENERAL!I51=0," ",GENERAL!I51) | J51: =IF(GENERAL!J51=0," ",GENERAL!J51)
A52: 25311.020-000-6509-01 | B52: 6509 | C52: VACUNA VRS | D52: UNIDOSIS | E52: Susp. Inyectable (Fco. Ampula) | G52: =IF(F52=0," ",F52) | H52: =IF(F52=0," ",F52)
B54: CONDICIONES DE TRANSPORTE Y ALMACENAMIENTO: MANTENGASE EN TODO MOMENTO A TEMPERATURA ENTRE 2°C - 8 °C
C56: TEMPERATURA A LA RECEPCIÓN: | G56: FECHA DE RECEPCIÓN:
A58: OBSERVACIONES:
...

Sheet EMILIANO ZAPATA
A1: SERVICIOS DE SALUD DEL ESTADO DE QUERÉTARO
A2: COORDINACION GENERAL
A3: SUBDIRECCION DE ADQUISICIONES
A5: SOLICITUD Y SURTIMIENTO DE LA CÁMARA DE FRÍO ESTATAL
A7: ORIGEN: | B7: JURISDICCIÓN SANITARIA N.1 | G7: AREA: | H7: VACUNAS
A8: DIRECCIÓN: | B8: Circuito Moises Solana S/N, Col. Vista Alegre, Santiago de Querétaro. Qro. | G8: FECHA DE ENVIO: | H8: =IF(GENERAL!H8=0," ",GENERAL!H8) -> 46272
A9: DESTINO: | B9: EMILIANO ZAPATA | G9: FOLIO ORACLE:
A10: DIRECCIÓN: | B10: Av. El Jacal S/N, Emiliano Zapata, Corregidora. | G10: MES A SURTIR: | H10: =GENERAL!H10 -> SEPTIEMBRE
A12: NÚM | B12: CLAVE DE ARTÍCULO | C12: NOMBRE DEL ARTÍCULO | D12: PRESENTACIÓN | E12: FORMA | F12: CANTIDAD | K12: FIRMA DE RECEPCION
E13: FARMACÉUTICA | F13: SOLICITADO | G13: AUTORIZADO | H13: SURTIDO | I13: LOTE | J13: CADUCIDAD
A14: 25311.020-000-0146-03 | B14: 146 | C14: VACUNA ANTINEUMOCOCCICA 23 1DS | D14: UNIDOSIS | E14: Susp. Inyectable (Fco. Ampula) | G14: =IF(F14=0," ",F14) | H14: =IF(F14=0," ",F14) | I14: =IF(GENERAL!I14=0," ",GENERAL!I14) | J14: =IF(GENERAL!J14=0," ",GENERAL!J14) | M14: =SUM(F14+(F44*10)+(F32*10)+F22+F34+(F36*10)+F48) -> 107 | N14: JERINGA | O14: 2715 | P14: 22X32
I15: =IF(GENERAL!I15=0," ",GENERAL!I15) | J15: =IF(GENERAL!J15=0," ",GENERAL!J15) | M15: =SUM((F44/3)*20+F20) -> 150 | N15: JERINGA | O15: 2707 | P15: 23X25
A16: 25311.020-000-0148-01 | B16: 148 | C16: VACUNA ANTINEUMOCOCCICA 13 | D16: UNIDOSIS | E16: Susp. Inyectable (Jer. prellenada) | F16: 80 | G16: =IF(F16=0," ",F16) -> 80 | H16: =IF(F16=0," ",F16) -> 80 | I16: =IF(GENERAL!I16=0," ",GENERAL!I16) -> LC5884 | J16: =IF(GENERAL!J16=0," ",GENERAL!J16) -> 46388 | M16: =SUM(F24) -> 0 | N16: JERINGA | O16: 2699 | P16: 25X16
M17: =SUM(F26+F40) -> 0 | N17: JERINGA | O17: 2657 | P17: 27X13
A18: 25311.020-000-0150-05 | B18: 150 | C18: VACUNA ROTAVIRUS MONOVALENTE | D18: UNIDOSIS | E18: Susp. Inyectable (Jer. prellenada) | F18: 80 | G18: =IF(F18=0," ",F18) -> 80 | H18: =IF(F18=0," ",F18) -> 80 | I18: =IF(GENERAL!I18=0," ",GENERAL!I18) -> AROLE168AH | J18: =IF(GENERAL!J18=0," ",GENERAL!J18) -> 46419 | M18: =SUM(F28*10) -> 100 | N18: JERINGA | O18: 59 | P18: 30GX1/2
I19: =IF(GENERAL!I19=0," ",GENERAL!I19) | J19: =IF(GENERAL!J19=0," ",GENERAL!J19)
A20: 25311.020-000-6135-00 | B20: 6135 | C20: VACUNA HEXAVALENTE | D20: UNIDOSIS | E20: Susp. Inyectable (Fco. Ampula) | F20: 150 | G20: =IF(F20=0," ",F20) -> 150 | H20: =IF(F20=0," ",F20) -> 150 | I20: =IF(GENERAL!I20=0," ",GENERAL!I20) -> Y3C48D1 | J20: =IF(GENERAL!J20=0," ",GENERAL!J20) -> 46722
I21: =IF(GENERAL!I21=0," ",GENERAL!I21) | J21: =IF(GENERAL!J21=0," ",GENERAL!J21)
A22: 25311.020-000-2526-00 | B22: 2526 | C22: VACUNA HEPATITIS B MULTIDOSIS | D22: MULTIDOSIS | E22: Susp. Inyectable (Fco. Ampula) | F22: 2 | G22: =IF(F22=0," ",F22) -> 2 | H22: =IF(F22=0," ",F22) -> 2 | I22: =IF(GENERAL!I22=0," ",GENERAL!I22) -> 2526250606 | J22: 46919
A24: 25311.020-000-3825-01 | B24: 3825 | C24: VACUNA HEPATITIS A UNIDOSIS | D24: UNIDOSIS | E24: Susp. Inyectable (Fco. Ampula) | G24: =IF(F24=0," ",F24) | H24: =IF(F24=0," ",F24)
A26: 25311.020-000-3800-00 | B26: 3800 | C26: VACUNA DOBLE VIRAL (SR) | D26: MULTIDOSIS | E26: Fco. Amp Leofilizado+Diluy. | G26: =IF(F26=0," ",F26) | H26: =IF(F26=0," ",F26)
I27: =IF(GENERAL!I27=0," ",GENERAL!I27) | J27: =IF(GENERAL!J27=0," ",GENERAL!J27)
A28: 25311.020-000-3801-01 | B28: 3801 | C28: VACUNA BCG | D28: MULTIDOSIS | E28: Fco. Amp Leofilizado+Diluy. | F28: 10 | G28: =IF(F28=0," ",F28) -> 10 | H28: =IF(F28=0," ",F28) -> 10 | I28: =IF(GENERAL!I28=0," ",GENERAL!I28) -> 0374MA108 | J28: =IF(GENERAL!J28=0," ",GENERAL!J28) -> 46447
I29: =IF(GENERAL!I29=0," ",GENERAL!I29) | J29: =IF(GENERAL!J29=0," ",GENERAL!J29)
A30: 25311.020-000-3802-00 | B30: 3802 | C30: VACUNA ANTIPOLIOMELITICA (SABIN) | D30: MULTIDOSIS | E30: Susp. (gotero de plastico) | G30: =IF(F30=0," ",F30) | H30: =IF(F30=0," ",F30) | I30: =IF(GENERAL!I30=0," ",GENERAL!I30) | J30: =IF(GENERAL!J30=0," ",GENERAL!J30)
I31: =IF(GENERAL!I31=0," ",GENERAL!I31) | J31: =IF(GENERAL!J31=0," ",GENERAL!J31)
A32: 25311.020-000-3805-00 | B32: 3805 | C32: VACUNA VACUNA DPT | D32: MULTIDOSIS | E32: Susp. Inyectable (Fco. Ampula) | F32: 4 | G32: =IF(F32=0," ",F32) -> 4 | H32: =IF(F32=0," ",F32) -> 4 | I32: =IF(GENERAL!I32=0," ",GENERAL!I32) -> 2825Q001A | J32: =IF(GENERAL!J32=0," ",GENERAL!J32) -> 46784
I33: =IF(GENERAL!I33=0," ",GENERAL!I33) | J33: =IF(GENERAL!J33=0," ",GENERAL!J33)
A34: 25311.020-000-3808-02 | B34: 3808 | C34: VACUNA TDPA | D34: UNIDOSIS | E34: Susp. Inyectable (Fco. Ampula) | F34: 15 | G34: =IF(F34=0," ",F34) -> 15 | H34: =IF(F34=0," ",F34) -> 15 | I34: =IF(GENERAL!I34=0," ",GENERAL!I34) -> AC37B542BD | J34: =IF(GENERAL!J34=0," ",GENERAL!J34) -> 46784
I35: =IF(GENERAL!I35=0," ",GENERAL!I35) | J35: =IF(GENERAL!J35=0," ",GENERAL!J35)
A36: 25311.020-000-3810-00 | B36: 3810 | C36: VACUNA TD | D36: MULTIDOSIS | E36: Susp. Inyectable (Fco. Ampula) | F36: 5 | G36: =IF(F36=0," ",F36) -> 5 | H36: =IF(F36=0," ",F36) -> 5 | I36: =IF(GENERAL!I36=0," ",GENERAL!I36) -> 2805X003A | J36: =IF(GENERAL!J36=0," ",GENERAL!J36) -> 46388
I37: =IF(GENERAL!I37=0," ",GENERAL!I37) | J37: =IF(GENERAL!J37=0," ",GENERAL!J37)
A38: 25311.020-000-6056-00 | B38: 6056 | C38: VACUNA ANTIVARICELA | D38: UNIDOSIS | E38: Fco. Amp Leofilizado+Diluy. | G38: =IF(F38=0," ",F38) | H38: =IF(F38=0," ",F38)
A40: 25311.020-000-3820-00 | B40: 3820 | C40: VACUNA TRIPLE VIRAL 1DS (SRP) | D40: UNIDOSIS | E40: Fco. Amp Leofilizado+Diluy. | G40: =IF(F40=0," ",F40) | H40: =IF(F40=0," ",F40)
A42: 25311.020-000-3821-00 | B42: 3821 | C42: VACUNATRIPLEVIRAL MULTI DOSIS | D42: MULTIDOSIS | E42: Fco. Amp Leofilizado+Diluy. | G42: =IF(F42=0," ",F42) | H42: =IF(F42=0," ",F42)
A44: 25311.020-000-6317-01 | B44: 6317 | C44: VACUNA ANTIINFLUENZA 10/D | D44: MULTIDOSIS | E44: Susp. Inyectable (Fco. Ampula) | G44: =IF(F44=0," ",F44) | H44: =IF(F44=0," ",F44)
I45: =IF(GENERAL!I45=0," ",GENERAL!I45) | J45: =IF(GENERAL!J45=0," ",GENERAL!J45)
