Workbook

Sheet PALOTEO
I3: UMME UMQ | J3: JURICA | K3: MENCHACA | L3: SAN ANTONIO DE LA PUNTA | M3: SAN PABLO | N3: FELIPE CARRILLO PUERTO | O3: LOMA BONITA | P3: PEDRO ESCOBEDO | Q3: JOFRITO | R3: MONTENEGRO | S3: PIE DE GALLO | T3: SAN JOSÉ BUENAVISTA | U3: SAN MIGUELITO | V3: SANTA MARÍA MAGTDALENA | W3: LA SOLANA | X3: TINAJA DE LA ESTANCIA | Y3: LÁZARO CÁRDENAS | Z3: SAN PEDRITO PEÑUELAS | AA3: MENCHACA NORTE | AB3: UMME LA BARRETA | AC3: UMME CERRO DE LA CRUZ | AD3: UMME LA LUZ | AE3: UMME SAN PEDRITO | AF3: UMME RANCHO LARGO | AG3: LA GOTERA | AH3: SAN JOSÉ EL ALTO | AI3: FAM SAN JOSÉ BUENAVISTA | AJ3: FAM PEDRO ESCOBEDO | AK3: FAM PALO ALTO | AL3: UMME MF1 | AM3: UMME AMB1 | AN3: UMME AMB2 | AO3: UMME UMD | AP3: SANTA ROSA | AQ3: SATÉLITE | AR3: SAN PEDRO MARTIR | AS3: LOMAS DE CASABLANCA | AT3: TLACOTE EL BAJO | AU3: Total Municipal
A4: Aplicación de biológicos | B4: Biológico | C4: Clave | D4: Variable | I4: QTSSA001764 | J4: QTSSA001793 | K4: QTSSA001810 | L4: QTSSA001822 | M4: QTSSA001834 | N4: QTSSA001846 | O4: QTSSA001851 | P4: QTSSA001863 | Q4: QTSSA001904 | R4: QTSSA001916 | S4: QTSSA001921 | T4: QTSSA001945 | U4: QTSSA001962 | V4: QTSSA001974 | W4: QTSSA002003 | X4: QTSSA002015 | Y4: QTSSA002522 | Z4: QTSSA002534 | AA4: QTSSA002703 | AB4: QTSSA003544 | AC4: QTSSA003553 | AD4: QTSSA003562 | AE4: QTSSA003595 | AF4: QTSSA003604 | AG4: QTSSA003715 | AH4: QTSSA012240 | AI4: QTSSA012276 | AJ4: QTSSA012281 | AK4: QTSSA012544 | AL4: QTSSA012556 | AM4: QTSSA012561 | AN4: QTSSA012585 | AO4: QTSSA012631 | AP4: QTSSA012655 | AQ4: QTSSA012923 | AR4: QTSSA012976 | AS4: QTSSA012982 | AT4: QTSSA013034
B5: BCG | C5: VBC01 | D5: TOTAL | F5: Recién nacido (primeras 24 horas) | AU5: =SUM(I5:AT5) -> 47
C6: VBC02 | F6: Recién nacido (de 2 a 28 días) | AU6: =SUM(I6:AT6) -> 176
C7: BIO50 | F7: 29 días a 11 meses | AU7: =SUM(I7:AT7) -> 40
C8: BIO03 | F8: 1 a 4 años | AU8: =SUM(I8:AT8) -> 10
C9: VBC03 | F9: 5 a 13 años | AU9: =SUM(I9:AT9) -> 2
C10: VBC51 | D10: MIGRANTES | F10: Recién nacido (primeras 24 horas) | AU10: =SUM(I10:AT10)
C11: VBC52 | F11: Recién nacido (de 2 a 28 días) | AU11: =SUM(I11:AT11)
C12: VBC53 | F12: 29 días a 11 meses | AU12: =SUM(I12:AT12)
C13: VBC54 | F13: 1 a 4 años | AU13: =SUM(I13:AT13)
C14: VBC55 | F14: 5 a 13 años | AU14: =SUM(I14:AT14)
C15: VBF51 | D15: AFROMEXICANOS | F15: Recién nacido (primeras 24 horas) | AU15: =SUM(I15:AT15)
C16: VBF52 | F16: Recién nacido (de 2 a 28 días) | AU16: =SUM(I16:AT16)
C17: VBF53 | F17: 29 días a 11 meses | AU17: =SUM(I17:AT17)
C18: VBF54 | F18: 1 a 4 años | AU18: =SUM(I18:AT18)
C19: VBF55 | F19: 5 a 13 años | AU19: =SUM(I19:AT19)
C20: VBI51 | D20: INDÍGENAS | F20: Recién nacido (primeras 24 horas) | AU20: =SUM(I20:AT20)
C21: VBI52 | F21: Recién nacido (de 2 a 28 días) | AU21: =SUM(I21:AT21)
C22: VBI53 | F22: 29 días a 11 meses | AU22: =SUM(I22:AT22)
C23: VBI54 | F23: 1 a 4 años | AU23: =SUM(I23:AT23)
C24: VBI55 | F24: 5 a 13 años | AU24: =SUM(I24:AT24)
B25: TOTAL BCG | I25: =SUM(I5:I9) | J25: =SUM(J5:J9) -> 20 | K25: =SUM(K5:K9) -> 3 | L25: =SUM(L5:L9) -> 4 | M25: =SUM(M5:M9) -> 3 | N25: =SUM(N5:N9) -> 5 | O25: =SUM(O5:O9) -> 20 | P25: =SUM(P5:P9) -> 53 | ... AT25: =SUM(AT5:AT9) -> 1 | AU25: =SUM(I25:AT25) -> 275
B26: Hepatitis B | C26: VAC06 | D26: TOTAL | F26: Única recién nacido (0 a 7 días) | AU26: =SUM(I26:AT26) -> 152
C27: VHB01 | F27: Mayores de 11 años (sin antecedente vacunal) | H27: Primera | AU27: =SUM(I27:AT27) -> 49
C28: VHB02 | H28: Segunda | AU28: =SUM(I28:AT28) -> 19
C29: VHB03 | F29: Población en riesgo | H29: Primera | AU29: =SUM(I29:AT29) -> 38
C30: VHB04 | H30: Segunda | AU30: =SUM(I30:AT30) -> 11
C31: VHB05 | F31: Personal de salud | H31: Primera | AU31: =SUM(I31:AT31) -> 26
C32: VHB06 | H32: Segunda | AU32: =SUM(I32:AT32) -> 11
C33: VHB51 | D33: MIGRANTES | F33: Única recién nacido (0 a 7 días) | AU33: =SUM(I33:AT33)
C34: VHB52 | F34: Mayores de 11 años (sin antecedente vacunal) | H34: Primera | AU34: =SUM(I34:AT34)
C35: VHB53 | H35: Segunda | AU35: =SUM(I35:AT35)
C36: VHB54 | F36: Población en riesgo | H36: Primera | AU36: =SUM(I36:AT36)
C37: VHB55 | H37: Segunda | AU37: =SUM(I37:AT37)
C38: VHB56 | F38: Personal de salud | H38: Primera | AU38: =SUM(I38:AT38)
C39: VHB57 | H39: Segunda | AU39: =SUM(I39:AT39)
C40: VHF51 | D40: AFROMEXICANOS | F40: Única recién nacido (0 a 7 días) | AU40: =SUM(I40:AT40)
C41: VHF52 | F41: Mayores de 11 años (sin antecedente vacunal) | H41: Primera | AU41: =SUM(I41:AT41)
C42: VHF53 | H42: Segunda | AU42: =SUM(I42:AT42)
...

Sheet SEGUIMIENTO DE BIOLOGICO
A1: MUNICIPIO QUERÉTARO
A2: BIOLÓGICO | B2: UMME UMQ | C2: JURICA | D2: MENCHACA | E2: SAN ANTONIO DE LA PUNTA | F2: SAN PABLO | G2: FELIPE CARRILLO PUERTO | H2: LOMA BONITA | I2: PEDRO ESCOBEDO | J2: JOFRITO | K2: MONTENEGRO | L2: PIE DE GALLO | M2: SAN JOSÉ BUENAVISTA | N2: SAN MIGUELITO | O2: SANTA MARÍA MAGTDALENA | P2: LA SOLANA | Q2: TINAJA DE LA ESTANCIA | R2: LÁZARO CÁRDENAS | S2: SAN PEDRITO PEÑUELAS | T2: MENCHACA NORTE | U2: UMME LA BARRETA | V2: UMME CERRO DE LA CRUZ | W2: UMME LA LUZ | X2: UMME SAN PEDRITO | Y2: UMME RANCHO LARGO | Z2: LA GOTERA | AA2: SAN JOSÉ EL ALTO | AB2: FAM SAN JOSÉ BUENAVISTA | AC2: FAM PEDRO ESCOBEDO | AD2: FAM PALO ALTO | AE2: UMME MF1 | AF2: UMME AMB1 | AG2: UMME AMB2 | AH2: UMME UMD | AI2: SANTA ROSA | AJ2: SATÉLITE | AK2: SAN PEDRO MARTIR | AL2: LOMAS DE CASABLANCA | AM2: TLACOTE EL BAJO | AN2: Total | AO2: VALIDACIÓN
A3: EXISTENCIA ANTERIOR (FRASCOS)
A4: BCG | AN4: =SUM(B4:AM4) -> 122
A5: HEPATITIS 10 | AN5: =SUM(B5:AM5) -> 67.95
A6: HEXAVALENTE | AN6: =SUM(B6:AM6) -> 1650
A7: DPT | AN7: =SUM(B7:AM7) -> 80.3
A8: ROTAVIRUS | AN8: =SUM(B8:AM8) -> 998
A9: NEUMOCOCICA 13 | AN9: =SUM(B9:AM9) -> 2748
A10: NEUMOCOCICA 20 | AN10: =SUM(B10:AM10)
A11: SRP (UNIDOSIS) | AN11: =SUM(B11:AM11) -> 7784
A12: INFLUENZA 10 | AN12: =SUM(B12:AM12)
A13: SR (MULTIDOSIS) | AN13: =SUM(B13:AM13) -> 1002
A14: VPH BIVALENTE | AN14: =SUM(B14:AM14) -> 341
A15: TD | AN15: =SUM(B15:AM15) -> 95.3
... A21: VSR | AN21: =SUM(B21:AM21) -> 665
A22: RECIBIDO (FRASCOS)
A23: BCG | AN23: =SUM(B23:AM23) -> 90
A24: HEPATITIS 10 | AN24: =SUM(B24:AM24) -> 22
A25: HEXAVALENTE | AN25: =SUM(B25:AM25) -> 1230
A26: DPT | AN26: =SUM(B26:AM26) -> 24
A27: ROTAVIRUS | AN27: =SUM(B27:AM27) -> 750
A28: NEUMOCOCICA 13 | AN28: =SUM(B28:AM28) -> 700
A29: NEUMOCOCICA 20 | AN29: =SUM(B29:AM29)
A30: SRP (UNIDOSIS) | AN30: =SUM(B30:AM30) -> 560
A31: INFLUENZA 10 | AN31: =SUM(B31:AM31)
A32: SR (MULTIDOSIS) | AN32: =SUM(B32:AM32) -> 33
A33: VPH BIVALENTE | AN33: =SUM(B33:AM33) -> 130
A34: TD | AN34: =SUM(B34:AM34) -> 36
... A40: VSR | AN40: =SUM(B40:AM40) -> 160
A41: APLICADO (DOSIS)
A42: BCG | AN42: =SUM(B42:AM42) -> 275 | AO42: =PALOTEO!AU25 -> 275
A43: HEPATITIS 10 | AN43: =SUM(B43:AM43) -> 230 | AO43: =((PALOTEO!AU26)/2)+(SUM(PALOTEO!AU27:AU32)) -> 230
A44: HEXAVALENTE | AN44: =SUM(B44:AM44) -> 1699 | AO44: =PALOTEO!AU87 -> 1699
A45: DPT | AN45: =SUM(B45:AM45) -> 381 | AO45: =PALOTEO!AU96 -> 404
A46: ROTAVIRUS | AN46: =SUM(B46:AM46) -> 868 | AO46: =PALOTEO!AU113 -> 868
A47: NEUMOCOCICA 13 | AN47: =SUM(B47:AM47) -> 1378 | AO47: =PALOTEO!AU142 -> 1378
A48: NEUMOCOCICA 20 | AN48: =SUM(B48:AM48) | AO48: =PALOTEO!AU171
A49: SRP (UNIDOSIS) | AN49: =SUM(B49:AM49) -> 1078 | AO49: =PALOTEO!AU188 -> 1038
A50: INFLUENZA 10 | AN50: =SUM(B50:AM50) | AO50: =PALOTEO!AU443
...
