Workbook
Name CLUES: DATOS!$D$5:$D$46
Name Print_Area: 'MOV-DE-BIOLÓGICO'!$A$1:$P$111
Name Print_Area: 'SINBA-SIS-06-P'!$A$1:$Y$121
Name Print_Area: 'SIS-SS-IE Mensual'!$A$1:$L$60
Name Print_Titles: 'SIS-SS-IE Mensual'!$B:$E
Name UNIDADES: DATOS!$C$5:$C$46

Sheet ÍNDICE
S3: =IFERROR(VLOOKUP(T3,DATOS!K81:L92,2,0)," ") -> 31 | T3: =IFERROR(VLOOKUP(ÍNDICE!O4,DATOS!J81:K92,2,0)," ") -> 08 | U3: =TODAY() -> 46266
B4: QUERÉTARO | C4: LOMAS DE CASA BLANCA | G4: =IFERROR(VLOOKUP(C4,DATOS!G12:H88,2,0)," ") -> QTSSA012982 | J4: LE. ANA MELISSA SALAZAR SERRANO | O4: AGOSTO | S4: DÍA | T4: MES | U4: AÑO

Sheet DATOS
B2: MUNICIPIO | C2: UNIDAD | D2: CLUE | F2: Municipios
C3: HOSPITAL DE ESPECIALIDADES | D3: QTSSA001740 | F3: QUERÉTARO
C4: HOSPITAL GENERAL DE QUERÉTARO | D4: QTSSA002901 | F4: MARQUÉS
B5: QUERETARO | C5: UMME QUERETARO | D5: QTSSA001764 | F5: CORREGIDORA | G5: Jurisdicción Sanitaria #1 Querétaro | I5: ENERO | K5: 2018
C6: JURICA | D6: QTSSA001793 | F6: HUIMILPAN | G6: Jurisdicción Sanitaria #2 San Juan del Río | I6: FEBRERO | K6: 2019
C7: MENCHACA | D7: QTSSA001810 | G7: Jurisdicción Sanitaria #3 Cadereyta | I7: MARZO | K7: 2020
C8: SAN ANTONIO DE LA PUNTA | D8: QTSSA001822 | G8: Jurisdicción Sanitaria #4 Jalpan | I8: ABRIL | K8: 2021
C9: SAN PABLO | D9: QTSSA001834 | I9: MAYO | K9: 2022
C10: FELIPE CARRILLO PUERTO | D10: QTSSA001846 | I10: JUNIO | K10: 2023
C11: LOMA BONITA | D11: QTSSA001851 | G11: UNIDAD | H11: CLUE | I11: JULIO | K11: 2024
C12: PEDRO ESCOBEDO | D12: QTSSA001863 | G12: HOSPITAL DE ESPECIALIDADES | H12: QTSSA001740 | I12: AGOSTO | K12: 2025
C13: JOFRITO | D13: QTSSA001904 | G13: HOSPITAL GENERAL DE QUERÉTARO | H13: QTSSA002901 | I13: SEPTIEMBRE | K13: 2026
C14: MONTENEGRO | D14: QTSSA001916 | G14: UMME QUERETARO | H14: QTSSA001764 | I14: OCTUBRE | K14: 2027
C15: PIE DE GALLO | D15: QTSSA001921 | G15: JURICA | H15: QTSSA001793 | I15: NOVIEMBRE | K15: 2028
C16: SAN JOSÉ BUENAVISTA | D16: QTSSA001945 | G16: MENCHACA | H16: QTSSA001810 | I16: DICIEMBRE | K16: 2029
C17: SAN MIGUELITO | D17: QTSSA001962 | G17: SAN ANTONIO DE LA PUNTA | H17: QTSSA001822 | K17: 2030
C18: SANTA MARÍA MAGDALENA | D18: QTSSA001974 | G18: SAN PABLO | H18: QTSSA001834 | K18: 2031
C19: LA SOLANA | D19: QTSSA002003 | G19: FELIPE CARRILLO PUERTO | H19: QTSSA001846 | K19: 2032
C20: TINAJA DE LA ESTANCIA | D20: QTSSA002015 | G20: LOMA BONITA | H20: QTSSA001851 | K20: 2033
C21: LÁZARO CÁRDENAS | D21: QTSSA002522 | G21: PEDRO ESCOBEDO | H21: QTSSA001863 | K21: 2034
C22: SAN PEDRITO PEÑUELAS | D22: QTSSA002534 | G22: JOFRITO | H22: QTSSA001904 | K22: 2035
C23: CEREDI LOMAS DE CASA BLANCA | D23: QTSSA002621 | G23: MONTENEGRO | H23: QTSSA001916 | K23: 2036
C24: MENCHACA NORTE | D24: QTSSA002703 | G24: PIE DE GALLO | H24: QTSSA001921 | K24: 2037
C25: UMME LA BARRETA | D25: QTSSA003544 | G25: SAN JOSÉ BUENAVISTA | H25: QTSSA001945 | K25: 2038
C26: UMME CERRO DE LA CRUZ | D26: QTSSA003553 | G26: SAN MIGUELITO | H26: QTSSA001962
C27: UMME LA LUZ | D27: QTSSA003562 | G27: SANTA MARÍA MAGDALENA | H27: QTSSA001974 | K27: 2039
C28: UMME SAN PEDRITO | D28: QTSSA003595 | G28: LA SOLANA | H28: QTSSA002003 | K28: 2040
C29: UMME RANCHO LARGO | D29: QTSSA003604 | G29: TINAJA DE LA ESTANCIA | H29: QTSSA002015 | K29: 2041
C30: LA GOTERA | D30: QTSSA003715 | G30: LÁZARO CÁRDENAS | H30: QTSSA002522 | K30: 2042
C31: SAN JOSÉ EL ALTO | D31: QTSSA012240 | G31: SAN PEDRITO PEÑUELAS | H31: QTSSA002534 | K31: 2043
C32: FAM SAN JOSE BUENAVISTA | D32: QTSSA012276 | G32: CEREDI LOMAS DE CASA BLANCA | H32: QTSSA002621 | K32: 2044
C33: FAM PEDRO ESCOBEDO | D33: QTSSA012281 | G33: MENCHACA NORTE | H33: QTSSA002703 | K33: 2045
C34: FAM EL MARQUES 2 (QUERETARO) | D34: QTSSA012544 | G34: NUEVO HOSPITAL GENERAL DE QUERÉTARO | H34: QTSSA002901 | K34: 2046
C35: UMME MF1 | D35: QTSSA012556 | G35: UMME LA BARRETA | H35: QTSSA003544 | K35: 2047
C36: UMME AMBULANCIA 1 | D36: QTSSA012561 | G36: UMME CERRO DE LA CRUZ | H36: QTSSA003553 | K36: 2048
C37: UMME AMBULANCIA 2 | D37: QTSSA012585 | G37: UMME LA LUZ | H37: QTSSA003562 | K37: 2049
C38: UMME MEDICO DENTAL | D38: QTSSA012631 | G38: UMME SAN PEDRITO | H38: QTSSA003595 | K38: 2050
... C44: TLACOTE EL BAJO | D44: QTSSA013034 | G44: FAM EL MARQUES 2 (QUERETARO) | H44: QTSSA012544 | K44: 2056
G45: UMME MF1 | H45: QTSSA012556 | K45: 2057
G46: UMME AMBULANCIA 1 | H46: QTSSA012561
...

Sheet SINBA-SIS-06-P
B1: REGISTRO DE APLICACIÓN DE BIOLÓGICOS PRIMERA PARTE | Y1: SINBA-SIS-06-P
Y2: SIS-2026
V3: =IFERROR(VLOOKUP(W3,DATOS!K81:L92,2,0)," ") -> 31 | W3: =IFERROR(VLOOKUP(ÍNDICE!O4,DATOS!J81:K92,2,0)," ") -> 08 | X3: =TODAY() -> 46266
V4: DÍA | W4: MES | X4: AÑO
A5: UNIDAD: | B5: CLUES: | D5: JURISDICCIÓN SANITARIA O DISTRITO SANITARIO: | H5: LOCALIDAD: | L5: NOMBRE DE LA PERSONA RESPONSABLE:
A6: =IF(ÍNDICE!C4=0," ",ÍNDICE!C4) -> LOMAS DE CASA BLANCA | B6: =IF(ÍNDICE!G4=0," ",ÍNDICE!G4) -> QTSSA012982 | D6: JURISDICCIÓN SANITARIA 1, QUERÉTARO | H6: =IFERROR(VLOOKUP(ÍNDICE!C4,DATOS!E94:F168,2,0)," ") -> REFORMA AGRARIA 1RA SECCIÓN | L6: =IF(ÍNDICE!J4=0," ",ÍNDICE!J4) -> LE. ANA MELISSA SALAZAR SERRANO
A8: BIOLÓGICO | B8: DOSIS / GRUPO POBLACIONAL | D8: REGISTRO DE DOSIS APLICADAS | V8: AFRO AMERICANOS | W8: INDÍGENAS | X8: MIGRANTES | Y8: TOTAL (INCLUYE AFROAMERICANOS, INDÍGENAS Y MIGRANTES)
D9: RECIEN NACIDO | G9: 29 días-3 meses | H9: 4-6 meses | I9: 7-11 meses | J9: 12-17 meses | K9: 18 meses | L9: 19-23 meses | M9: 2 años | N9: 3 años | O9: 4 años | P9: 5 años | Q9: 6 años | R9: 7 años | S9: 8 años | T9: 9 años | U9: 10 a 13 años
D10: Primeras 24 hrs | E10: 2 -7 días | F10: 8-28 días
A11: BCG | B11: RECIÉN NACIDO (PRIMERAS 24 HORAS) | C11: ÚNICA | Y11: 4
B12: RECIÉN NACIDO (DE 2 A 28 DÍAS) | C12: ÚNICA | Y12: 21
B13: 29 DÍAS A 11 MESES | C13: ÚNICA | Y13: 1
B14: 1 A 4 AÑOS | C14: ÚNICA
B15: 5 A 13 AÑOS | C15: ÚNICA | D15: EXCEPCIONALMENTE HASTA LOS 13 AÑOS, 11 MESES, 29 DÍAS.
A16: HEPATITIS B | B16: ÚNICA | Y16: 14
B17: MAYORES DE 11 AÑOS (SIN ANTECEDENTE VACUNAL) | C17: PRIMERA | Y17: 5
C18: SEGUNDA
B19: POBLACIÓN EN RIESGO | C19: PRIMERA | Y19: 3
C20: SEGUNDA | Y20: 2
B21: PERSONAL DE SALUD | C21: PRIMERA
C22: SEGUNDA
A23: HEXAVALENTE ACELULAR DPaT + IPV + Hib + HB | B23: PRIMERA 2 A 11 MESES | Y23: 48
B24: SEGUNDA 4 A 11 MESES | Y24: 44
B25: TERCERA 6 A 11 MESES | Y25: 45
B26: REFUERZO 18 A 23 MESES | Y26: 30
B27: PARA INICIAR O COMPLETAR ESQUEMA 1 A 4 AÑOS | C27: PRIMERA | D27: PARA INICIAR O COMPLETAR ESQUEMA 1 A 4 AÑOS | P27: APLICACIÓN HASTA 59 MESES, 29 DÍAS DE EDAD | Y27: 2
C28: SEGUNDA | Y28: 1
C29: TERCERA | Y29: 5
C30: REFUERZO | Y30: 14
A31: DPT | B31: ÚNICA (4 AÑOS) | Y31: 15
B32: PARA INICIAR O COMPLETAR ESQUEMA 5 A 6 AÑOS | C32: ÚNICA | D32: APLICACIÓN HASTA 6 AÑOS, 11 MESES Y 29 DÍAS | Y32: 6
A33: ROTAVIRUS RV1 | B33: PRIMERA 2 MESES | Y33: 45
B34: SEGUNDA 4 MESES | Y34: 42
B35: PARA INICIAR O COMPLETAR ESQUEMAS | C35: PRIMERA 3 A 7 MESES | J35: APLICACIÓN HASTA 7 MESES, 29 DÍAS DE EDAD | Y35: 1
C36: SEGUNDA 5 A 7 MESES
A37: NEUMOCÓCICA CONJUGADA (13 VALENTE) | B37: PRIMERA 2 A 11 MESES | Y37: 50
B38: SEGUNDA 4 A 11 MESES | Y38: 42
B39: TERCERA 12 A 23 MESES | D39: APLICACIÓN A PARTIR DE 12 MESES DE EDAD | Y39: 40
B40: PARA INICIAR O COMPLETAR ESQUEMA 1 A 4 AÑOS | C40: PRIMERA | D40: PARA INICIAR O COMPLETAR ESQUEMA 1 A 4 AÑOS | Y40: 3
C41: SEGUNDA | Y41: 2
...

Sheet MOV-DE-BIOLÓGICO
A1: Anverso
A2: SERVICIOS DE SALUD DEL ESTADO DE QUERÉTARO
A3: CENTRO NACIONAL PARA LA SALUD DE LA INFANCIA Y ADOLESCENCIA
A4: INFORME MENSUAL DE MOVIMIENTO DE BIOLOGICO
A5: 1. Identificación: JURISDICCION SANITARIA N° 1 | K5: MES QUE SE REPORTA: | N5: =IF(ÍNDICE!O4=0," ",ÍNDICE!O4) -> AGOSTO
A6: Entidad Federativa: QUERÉTARO
A7: Fecha del corte: | B7: DIA: | C7: =IF(ÍNDICE!S3=0," ",ÍNDICE!S3) -> 31 | E7: MES: | F7: =N5 -> AGOSTO | H7: AÑO: | I7: =IF(ÍNDICE!U3=0," ",ÍNDICE!U3) -> 46266 | K7: UNIDAD DE SALUD: | N7: =IF(ÍNDICE!C4=0," ",ÍNDICE!C4) -> LOMAS DE CASA BLANCA
A8: Responsable de la Elaboración del Informe: | D8: =IF(ÍNDICE!J4=0," ",ÍNDICE!J4) -> LE. ANA MELISSA SALAZAR SERRANO
A9: Movimiento de Biológico
A10: Biológico | B10: Existencia Anterior en FRASCOS | E10: FRASCOS recibidos SOLO CON FORMATO DE REQUISICIÓN de biológico | H10: DOSIS Aplicadas | K10: DOSIS Desechadas | N10: Existencia final al corte del informe en FRASCOS | Q10: Observaciones
B12: Cantidad | C12: Lote | D12: Caducidad | E12: Cantidad | F12: Lote | G12: Caducidad | N12: Cantidad | O12: Lote | P12: Caducidad
A13: B.C.G. frasco multidosis | B13: 3 | C13: 0374MA108 | D13: 46447 | E13: 20 | F13: 0374MA108 | G13: 46447 | H13: 26 | K13: 94 | N13: =IF((((B13+E13)*10)-(H13+K13))/10=0," ",(((B13+E13)*10)-(H13+K13))/10) -> 11 | O13: 0374MA108 | P13: 46447
N14: =IF((((B14+E14)*10)-(H14+K14))/10=0," ",(((B14+E14)*10)-(H14+K14))/10) | O14: =IF(F14=0," ",F14) | P14: =IF(G14=0," ",G14)
N15: =IF((((B15+E15)*10)-(H15+K15))/10=0," ",(((B15+E15)*10)-(H15+K15))/10) | O15: =IF(F15=0," ",F15) | P15: =IF(G15=0," ",G15)
A16: A.R.F. En dictamen o canje | N16: =IF((((B16+E16)*10)-(H16+K16))/10=0," ",(((B16+E16)*10)-(H16+K16))/10) | O16: =IF(F16=0," ",F16) | P16: =IF(G16=0," ",G16)
N17: =IF((((B17+E17)*10)-(H17+K17))/10=0," ",(((B17+E17)*10)-(H17+K17))/10) | O17: =IF(F17=0," ",F17) | P17: =IF(G17=0," ",G17)
A18: Total | B18: =IF(SUM(B13:B17)=0," ",SUM(B13:B17)) -> 3 | E18: =IF(SUM(E13:E17)=0," ",SUM(E13:E17)) -> 20 | H18: =IF(SUM('SINBA-SIS-06-P'!Y11:Y15)=0," ",SUM('SINBA-SIS-06-P'!Y11:Y15)) -> 26 | K18: =IF(SUM(K13:M17)=0," ",SUM(K13:M17)) -> 94 | N18: =IF(SUM(N13:N17)=0," ",SUM(N13:N17)) -> 11
A19: Hepatitis "B" frasco multidosis | B19: 9.2 | C19: 2526250606 | D19: 46905 | H19: 14 | I19: 10 | J19: =(((H19/2)+(I19))) -> 17 | M19: =(((K19/2)+(L19))) -> 0 | N19: =IFERROR(IF((((B19+E19)*10)-(J19+M19))/10=0," ",(((B19+E19)*10)-(J19+M19))/10)," ") -> 7.5 | O19: 2526250606 | P19: 46905
J20: =(((H20/2)+(I20))) -> 0 | M20: =(((K20/2)+(L20))) -> 0 | N20: =IFERROR(IF((((B20+E20)*10)-(J20+M20))/10=0," ",(((B20+E20)*10)-(J20+M20))/10)," ") | O20: =IF(F20=0," ",F20) | P20: =IF(G20=0," ",G20)
J21: =(((H21/2)+(I21))) -> 0 | M21: =(((K21/2)+(L21))) -> 0 | N21: =IFERROR(IF((((B21+E21)*10)-(J21+M21))/10=0," ",(((B21+E21)*10)-(J21+M21))/10)," ") | O21: =IF(F21=0," ",F21) | P21: =IF(G21=0," ",G21)
A22: A.R.F. En dictamen o canje | J22: =(((H22/2)+(I22))) -> 0 | M22: =(((K22/2)+(L22))) -> 0 | N22: =IFERROR(IF((((B22+E22)*10)-(J22+M22))/10=0," ",(((B22+E22)*10)-(J22+M22))/10)," ") | O22: =IF(F22=0," ",F22) | P22: =IF(G22=0," ",G22)
J23: =(((H23/2)+(I23))) -> 0 | M23: =(((K23/2)+(L23))) -> 0 | N23: =IFERROR(IF((((B23+E23)*10)-(J23+M23))/10=0," ",(((B23+E23)*10)-(J23+M23))/10)," ") | O23: =IF(F23=0," ",F23) | P23: =IF(G23=0," ",G23)
A24: Total | B24: =IF(SUM(B19:B23)=0," ",SUM(B19:B23)) -> 9.2 | E24: =IF(SUM(E19:E23)=0," ",SUM(E19:E23)) | H24: =IF((('SINBA-SIS-06-P'!Y16)/2+(SUM('SINBA-SIS-06-P'!Y17:Y22)))=0," ",(('SINBA-SIS-06-P'!Y16)/2+(SUM('SINBA-SIS-06-P'!Y17:Y22)))) -> 17 | K24: =IF(SUM(M19:M23)=0," ",SUM(M19:M23)) | N24: =IF(SUM(N19:N23)=0," ",SUM(N19:N23)) -> 7.5
A25: Hexavalente frasco unidosis | B25: 165 | C25: Y3A532V | D25: 46661 | E25: 100 | F25: Y3A532V | G25: 46661 | H25: 189 | N25: =IF(((B25+E25)-(H25+K25))=0," ",((B25+E25)-(H25+K25))) -> 76 | O25: Y3A532V | P25: 46661
N26: =IF(((B26+E26)-(H26+K26))=0," ",((B26+E26)-(H26+K26))) | O26: =IF(F26=0," ",F26) | P26: =IF(G26=0," ",G26)
N27: =IF(((B27+E27)-(H27+K27))=0," ",((B27+E27)-(H27+K27))) | O27: =IF(F27=0," ",F27) | P27: =IF(G27=0," ",G27)
A28: A.R.F. En dictamen o canje | N28: =IF(((B28+E28)-(H28+K28))=0," ",((B28+E28)-(H28+K28))) | O28: =IF(F28=0," ",F28) | P28: =IF(G28=0," ",G28)
N29: =IF(((B29+E29)-(H29+K29))=0," ",((B29+E29)-(H29+K29))) | O29: =IF(F29=0," ",F29) | P29: =IF(G29=0," ",G29)
A30: Total | B30: =IF(SUM(B25:B29)=0," ",SUM(B25:B29)) -> 165 | E30: =IF(SUM(E25:E29)=0," ",SUM(E25:E29)) -> 100 | H30: =IF(SUM('SINBA-SIS-06-P'!Y23:Y30)=0," ",SUM('SINBA-SIS-06-P'!Y23:Y30)) -> 189 | K30: =IF(SUM(K25:M29)=0," ",SUM(K25:M29)) | N30: =IF(SUM(N25:N29)=0," ",SUM(N25:N29)) -> 76
A31: DPT frasco multidosis | B31: 6.7 | C31: 2825Q001A | D31: 46419 | E31: 3 | F31: 2825Q001A | G31: 46419 | H31: 21 | K31: 17 | N31: =IF((((B31+E31)*10)-(H31+K31))/10=0," ",(((B31+E31)*10)-(H31+K31))/10) -> 5.9 | O31: 2825Q001A | P31: 46419
N32: =IF((((B32+E32)*10)-(H32+K32))/10=0," ",(((B32+E32)*10)-(H32+K32))/10) | O32: =IF(F32=0," ",F32) | P32: =IF(G32=0," ",G32)
N33: =IF((((B33+E33)*10)-(H33+K33))/10=0," ",(((B33+E33)*10)-(H33+K33))/10) | O33: =IF(F33=0," ",F33) | P33: =IF(G33=0," ",G33)
A34: A.R.F. En dictamen o canje | N34: =IF((((B34+E34)*10)-(H34+K34))/10=0," ",(((B34+E34)*10)-(H34+K34))/10) | O34: =IF(F34=0," ",F34) | P34: =IF(G34=0," ",G34)
N35: =IF((((B35+E35)*10)-(H35+K35))/10=0," ",(((B35+E35)*10)-(H35+K35))/10) | O35: =IF(F35=0," ",F35) | P35: =IF(G35=0," ",G35)
A36: Total | B36: =IF(SUM(B31:B35)=0," ",SUM(B31:B35)) -> 6.7 | E36: =IF(SUM(E31:E35)=0," ",SUM(E31:E35)) -> 3 | H36: =IF(SUM('SINBA-SIS-06-P'!Y31:Y32)=0," ",SUM('SINBA-SIS-06-P'!Y31:Y32)) -> 21 | K36: =IF(SUM(K31:M35)=0," ",SUM(K31:M35)) -> 17 | N36: =IF(SUM(N31:N35)=0," ",SUM(N31:N35)) -> 5.9
A37: Rotavirus RV1 frasco unidosis | B37: 40 | C37: AROLE111BA | D37: 46388 | E37: 100 | F37: AROEL111BA | G37: 46388 | H37: 88 | N37: =IF(((B37+E37)-(H37+K37))=0," ",((B37+E37)-(H37+K37))) -> 52 | O37: AROLE111BA | P37: 46388
N38: =IF(((B38+E38)-(H38+K38))=0," ",((B38+E38)-(H38+K38))) | O38: =IF(F38=0," ",F38) | P38: =IF(G38=0," ",G38)
N39: =IF(((B39+E39)-(H39+K39))=0," ",((B39+E39)-(H39+K39))) | O39: =IF(F39=0," ",F39) | P39: =IF(G39=0," ",G39)
A40: A.R.F. En dictamen o canje | N40: =IF(((B40+E40)-(H40+K40))=0," ",((B40+E40)-(H40+K40))) | O40: =IF(F40=0," ",F40) | P40: =IF(G40=0," ",G40)
N41: =IF(((B41+E41)-(H41+K41))=0," ",((B41+E41)-(H41+K41))) | O41: =IF(F41=0," ",F41) | P41: =IF(G41=0," ",G41)
...

Sheet SIS-SS-CE-H-2026
J1: Informe Mensual de Actividades Realizadas en la Unidad Médica SINBA-SIS-CE-H | AH1: Sección III
J2: Aplicación de biológicos | AH2: Hoja 8 de 8
A3: Nombre de la unidad: | F3: =IF(ÍNDICE!C4=0," ",ÍNDICE!C4) -> LOMAS DE CASA BLANCA | X3: CLUES: | Y3: =IF(ÍNDICE!G4=0," ",ÍNDICE!G4) -> QTSSA012982
A4: Nombre de la persona responsable de la información: | K4: =IF(ÍNDICE!J4=0," ",ÍNDICE!J4) -> LE. ANA MELISSA SALAZAR SERRANO | X4: Mes: | Y4: =IF(ÍNDICE!O4=0," ",ÍNDICE!O4) -> AGOSTO | AF4: Año: | AG4: =TEXT(IF(ÍNDICE!$U$3=0," ",ÍNDICE!$U$3),"AAAA") -> 2026
A5: SIS-2026
J7: Variable | M7: Clave | N7: Total de dosis | O7: Clave | P7: A Afromexicanos | Q7: Clave | R7: A Indígenas | S7: Clave | T7: A Migrantes | Z7: Variable | AA7: Clave | AB7: Total de dosis | AC7: Clave | AD7: A Afromexicanos | AE7: Clave | AF7: A Indígenas | AG7: Clave | AH7: A Migrantes
A8: Aplicación de biológicos | C8: 119 BCG | J8: Recién nacido (primeras 24 horas) | M8: VBC01 | N8: =IF('SINBA-SIS-06-P'!Y11=0," ",'SINBA-SIS-06-P'!Y11) -> 4 | O8: VBF51 | P8: =IF('SINBA-SIS-06-P'!V11=0," ",'SINBA-SIS-06-P'!V11) | Q8: VBI51 | R8: =IF('SINBA-SIS-06-P'!W11=0," ",'SINBA-SIS-06-P'!W11) | S8: VBC51 | T8: =IF('SINBA-SIS-06-P'!X11=0," ",'SINBA-SIS-06-P'!X11) | W8: 129 VPHa | X8: Única | Y8: Personas de quinto año de primaria o de 11 años no escolarizadas a | AA8: VPH05 | AB8: =IF('SINBA-SIS-06-P'!Y75=0," ",'SINBA-SIS-06-P'!Y75) -> 2 | AC8: VPF01 | AD8: =IF('SINBA-SIS-06-P'!V75=0," ",'SINBA-SIS-06-P'!V75) | AE8: VPI01 | AF8: =IF('SINBA-SIS-06-P'!W75=0," ",'SINBA-SIS-06-P'!W75) | AG8: VPH51 | AH8: =IF('SINBA-SIS-06-P'!X75=0," ",'SINBA-SIS-06-P'!X75)
J9: Recién nacido (de 2 a 28 días) | M9: VBC02 | N9: =IF('SINBA-SIS-06-P'!Y12=0," ",'SINBA-SIS-06-P'!Y12) -> 21 | O9: VBF52 | P9: =IF('SINBA-SIS-06-P'!V12=0," ",'SINBA-SIS-06-P'!V12) | Q9: VBI52 | R9: =IF('SINBA-SIS-06-P'!W12=0," ",'SINBA-SIS-06-P'!W12) | S9: VBC52 | T9: =IF('SINBA-SIS-06-P'!X12=0," ",'SINBA-SIS-06-P'!X12) | Y9: Niñas y/o adolescentes de 12 a 16 años (rezagadas) | AA9: VPH06 | AB9: =IF('SINBA-SIS-06-P'!Y76=0," ",'SINBA-SIS-06-P'!Y76) | AC9: VPF02 | AD9: =IF('SINBA-SIS-06-P'!V76=0," ",'SINBA-SIS-06-P'!V76) | AE9: VPI02 | AF9: =IF('SINBA-SIS-06-P'!W76=0," ",'SINBA-SIS-06-P'!W76) | AG9: VPH52 | AH9: =IF('SINBA-SIS-06-P'!X76=0," ",'SINBA-SIS-06-P'!X76)
J10: 29 días a 11 meses | M10: BIO50 | N10: =IF('SINBA-SIS-06-P'!Y13=0," ",'SINBA-SIS-06-P'!Y13) -> 1 | O10: VBF53 | P10: =IF('SINBA-SIS-06-P'!V13=0," ",'SINBA-SIS-06-P'!V13) | Q10: VBI53 | R10: =IF('SINBA-SIS-06-P'!W13=0," ",'SINBA-SIS-06-P'!W13) | S10: VBC53 | T10: =IF('SINBA-SIS-06-P'!X13=0," ",'SINBA-SIS-06-P'!X13) | Y10: Niñas y/o adolescentes víctimas de violación sexual de 9 a 14 años b | AA10: VPH07 | AB10: =IF('SINBA-SIS-06-P'!Y77=0," ",'SINBA-SIS-06-P'!Y77) | AC10: VPF03 | AD10: =IF('SINBA-SIS-06-P'!V77=0," ",'SINBA-SIS-06-P'!V77) | AE10: VPI03 | AF10: =IF('SINBA-SIS-06-P'!W77=0," ",'SINBA-SIS-06-P'!W77) | AG10: VPH53 | AH10: =IF('SINBA-SIS-06-P'!X77=0," ",'SINBA-SIS-06-P'!X77)
J11: 1 a 4 años | M11: BIO03 | N11: =IF('SINBA-SIS-06-P'!Y14=0," ",'SINBA-SIS-06-P'!Y14) | O11: VBF54 | P11: =IF('SINBA-SIS-06-P'!V14=0," ",'SINBA-SIS-06-P'!V14) | Q11: VBI54 | R11: =IF('SINBA-SIS-06-P'!W14=0," ",'SINBA-SIS-06-P'!W14) | S11: VBC54 | T11: =IF('SINBA-SIS-06-P'!X14=0," ",'SINBA-SIS-06-P'!X14) | Y11: Niñas y/o adolescentes víctimas de violación sexual de 15 a 19 años b | AA11: VPH08 | AB11: =IF('SINBA-SIS-06-P'!Y78=0," ",'SINBA-SIS-06-P'!Y78) | AC11: VPF04 | AD11: =IF('SINBA-SIS-06-P'!V78=0," ",'SINBA-SIS-06-P'!V78) | AE11: VPI04 | AF11: =IF('SINBA-SIS-06-P'!W78=0," ",'SINBA-SIS-06-P'!W78) | AG11: VPH54 | AH11: =IF('SINBA-SIS-06-P'!X78=0," ",'SINBA-SIS-06-P'!X78)
J12: 5 a 13 años | M12: VBC03 | N12: =IF('SINBA-SIS-06-P'!Y15=0," ",'SINBA-SIS-06-P'!Y15) | O12: VBF55 | P12: =IF('SINBA-SIS-06-P'!V15=0," ",'SINBA-SIS-06-P'!V15) | Q12: VBI55 | R12: =IF('SINBA-SIS-06-P'!W15=0," ",'SINBA-SIS-06-P'!W15) | S12: VBC55 | T12: =IF('SINBA-SIS-06-P'!X15=0," ",'SINBA-SIS-06-P'!X15) | X12: Personas de 11 a 49 años que viven con VIH | Z12: Primera | AA12: VPH12 | AB12: =IF('SINBA-SIS-06-P'!Y79=0," ",'SINBA-SIS-06-P'!Y79) | AC12: VPF05 | AD12: =IF('SINBA-SIS-06-P'!V79=0," ",'SINBA-SIS-06-P'!V79) | AE12: VPI05 | AF12: =IF('SINBA-SIS-06-P'!W79=0," ",'SINBA-SIS-06-P'!W79) | AG12: VPH61 | AH12: =IF('SINBA-SIS-06-P'!X79=0," ",'SINBA-SIS-06-P'!X79)
C13: 121 Hepatitis B | J13: Única recién nacido (0 a 7 días) | M13: VAC06 | N13: =IF('SINBA-SIS-06-P'!Y16=0," ",'SINBA-SIS-06-P'!Y16) -> 14 | O13: VHF51 | P13: =IF('SINBA-SIS-06-P'!V16=0," ",'SINBA-SIS-06-P'!V16) | Q13: VHI51 | R13: =IF('SINBA-SIS-06-P'!W16=0," ",'SINBA-SIS-06-P'!W16) | S13: VHB51 | T13: =IF('SINBA-SIS-06-P'!X16=0," ",'SINBA-SIS-06-P'!X16) | Z13: Segunda | AA13: VPH13 | AB13: =IF('SINBA-SIS-06-P'!Y80=0," ",'SINBA-SIS-06-P'!Y80) | AC13: VPF06 | AD13: =IF('SINBA-SIS-06-P'!V80=0," ",'SINBA-SIS-06-P'!V80) | AE13: VPI06 | AF13: =IF('SINBA-SIS-06-P'!W80=0," ",'SINBA-SIS-06-P'!W80) | AG13: VPH62 | AH13: =IF('SINBA-SIS-06-P'!X80=0," ",'SINBA-SIS-06-P'!X80)
J14: Mayores de 11 años (sin antecedente vacunal) | L14: Primera | M14: VHB01 | N14: =IF('SINBA-SIS-06-P'!Y17=0," ",'SINBA-SIS-06-P'!Y17) -> 5 | O14: VHF52 | P14: =IF('SINBA-SIS-06-P'!V17=0," ",'SINBA-SIS-06-P'!V17) | Q14: VHI52 | R14: =IF('SINBA-SIS-06-P'!W17=0," ",'SINBA-SIS-06-P'!W17) | S14: VHB52 | T14: =IF('SINBA-SIS-06-P'!X17=0," ",'SINBA-SIS-06-P'!X17) | Z14: Tercera | AA14: VPH14 | AB14: =IF('SINBA-SIS-06-P'!Y81=0," ",'SINBA-SIS-06-P'!Y81) | AC14: VPF07 | AD14: =IF('SINBA-SIS-06-P'!V81=0," ",'SINBA-SIS-06-P'!V81) | AE14: VPI07 | AF14: =IF('SINBA-SIS-06-P'!W81=0," ",'SINBA-SIS-06-P'!W81) | AG14: VPH63 | AH14: =IF('SINBA-SIS-06-P'!X81=0," ",'SINBA-SIS-06-P'!X81)
L15: Segunda | M15: VHB02 | N15: =IF('SINBA-SIS-06-P'!Y18=0," ",'SINBA-SIS-06-P'!Y18) | O15: VHF53 | P15: =IF('SINBA-SIS-06-P'!V18=0," ",'SINBA-SIS-06-P'!V18) | Q15: VHI53 | R15: =IF('SINBA-SIS-06-P'!W18=0," ",'SINBA-SIS-06-P'!W18) | S15: VHB53 | T15: =IF('SINBA-SIS-06-P'!X18=0," ",'SINBA-SIS-06-P'!X18) | W15: 131 Varicela* | Y15: Única 1 año | AA15: VAR02 | AB15: =IF('SINBA-SIS-06-P'!Y63=0," ",'SINBA-SIS-06-P'!Y63) | AC15: VAR61 | AD15: =IF('SINBA-SIS-06-P'!V63=0," ",'SINBA-SIS-06-P'!V63) | AE15: VAR71 | AF15: =IF('SINBA-SIS-06-P'!W63=0," ",'SINBA-SIS-06-P'!W63) | AG15: VAR54 | AH15: =IF('SINBA-SIS-06-P'!X63=0," ",'SINBA-SIS-06-P'!X63)
J16: Población en riesgo | L16: Primera | M16: VHB03 | N16: =IF('SINBA-SIS-06-P'!Y19=0," ",'SINBA-SIS-06-P'!Y19) -> 3 | O16: VHF54 | P16: =IF('SINBA-SIS-06-P'!V19=0," ",'SINBA-SIS-06-P'!V19) | Q16: VHI54 | R16: =IF('SINBA-SIS-06-P'!W19=0," ",'SINBA-SIS-06-P'!W19) | S16: VHB54 | T16: =IF('SINBA-SIS-06-P'!X19=0," ",'SINBA-SIS-06-P'!X19) | Y16: Rezagos de 2 a 4 años | AA16: VAR03 | AB16: =IF('SINBA-SIS-06-P'!Y64=0," ",'SINBA-SIS-06-P'!Y64) | AC16: VAR62 | AD16: =IF('SINBA-SIS-06-P'!V64=0," ",'SINBA-SIS-06-P'!V64) | AE16: VAR72 | AF16: =IF('SINBA-SIS-06-P'!W64=0," ",'SINBA-SIS-06-P'!W64) | AG16: VAR55 | AH16: =IF('SINBA-SIS-06-P'!X64=0," ",'SINBA-SIS-06-P'!X64)
L17: Segunda | M17: VHB04 | N17: =IF('SINBA-SIS-06-P'!Y20=0," ",'SINBA-SIS-06-P'!Y20) -> 2 | O17: VHF55 | P17: =IF('SINBA-SIS-06-P'!V20=0," ",'SINBA-SIS-06-P'!V20) | Q17: VHI55 | R17: =IF('SINBA-SIS-06-P'!W20=0," ",'SINBA-SIS-06-P'!W20) | S17: VHB55 | T17: =IF('SINBA-SIS-06-P'!X20=0," ",'SINBA-SIS-06-P'!X20) | W17: 122 Hepatitis A | Y17: Única 18 meses | AA17: VHA01 | AB17: =IF('SINBA-SIS-06-P'!Y65=0," ",'SINBA-SIS-06-P'!Y65) -> 6 | AC17: VAF01 | AD17: =IF('SINBA-SIS-06-P'!V65=0," ",'SINBA-SIS-06-P'!V65) | AE17: VAI01 | AF17: =IF('SINBA-SIS-06-P'!W65=0," ",'SINBA-SIS-06-P'!W65) | AG17: VHA53 | AH17: =IF('SINBA-SIS-06-P'!X65=0," ",'SINBA-SIS-06-P'!X65)
J18: Personal de salud | L18: Primera | M18: VHB05 | N18: =IF('SINBA-SIS-06-P'!Y21=0," ",'SINBA-SIS-06-P'!Y21) | O18: VHF56 | P18: =IF('SINBA-SIS-06-P'!V21=0," ",'SINBA-SIS-06-P'!V21) | Q18: VHI56 | R18: =IF('SINBA-SIS-06-P'!W21=0," ",'SINBA-SIS-06-P'!W21) | S18: VHB56 | T18: =IF('SINBA-SIS-06-P'!X21=0," ",'SINBA-SIS-06-P'!X21) | Y18: Rezagos de 2 a 4 años | AA18: VHA02 | AB18: =IF('SINBA-SIS-06-P'!Y66=0," ",'SINBA-SIS-06-P'!Y66) | AC18: VAF02 | AD18: =IF('SINBA-SIS-06-P'!V66=0," ",'SINBA-SIS-06-P'!V66) | AE18: VAI02 | AF18: =IF('SINBA-SIS-06-P'!W66=0," ",'SINBA-SIS-06-P'!W66) | AG18: VHA54 | AH18: =IF('SINBA-SIS-06-P'!X66=0," ",'SINBA-SIS-06-P'!X66)
L19: Segunda | M19: VHB06 | N19: =IF('SINBA-SIS-06-P'!Y22=0," ",'SINBA-SIS-06-P'!Y22) | O19: VHF57 | P19: =IF('SINBA-SIS-06-P'!V22=0," ",'SINBA-SIS-06-P'!V22) | Q19: VHI57 | R19: =IF('SINBA-SIS-06-P'!W22=0," ",'SINBA-SIS-06-P'!W22) | S19: VHB57 | T19: =IF('SINBA-SIS-06-P'!X22=0," ",'SINBA-SIS-06-P'!X22) | Y19: Población en riesgo | AA19: BIO88 | AB19: =IF('SINBA-SIS-06-P'!Y67=0," ",'SINBA-SIS-06-P'!Y67) | AC19: VAF03 | AD19: =IF('SINBA-SIS-06-P'!V67=0," ",'SINBA-SIS-06-P'!V67) | AE19: VAI03 | AF19: =IF('SINBA-SIS-06-P'!W67=0," ",'SINBA-SIS-06-P'!W67) | AG19: VHA52 | AH19: =IF('SINBA-SIS-06-P'!X67=0," ",'SINBA-SIS-06-P'!X67)
C20: 275 Hexavalente acelular DPaT + IPV + Hib + HB | J20: Primera 2 a 11 meses | M20: VAC67 | N20: =IF('SINBA-SIS-06-P'!Y23=0," ",'SINBA-SIS-06-P'!Y23) -> 48 | O20: VXF51 | P20: =IF('SINBA-SIS-06-P'!V23=0," ",'SINBA-SIS-06-P'!V23) | Q20: VXI51 | R20: =IF('SINBA-SIS-06-P'!W23=0," ",'SINBA-SIS-06-P'!W23) | S20: VHX51 | T20: =IF('SINBA-SIS-06-P'!X23=0," ",'SINBA-SIS-06-P'!X23) | W20: 132 T d | X20: Embarazadas | Y20: Primera | Z20: 10 a 19 años | AA20: VAC39 | AB20: =IF('SINBA-SIS-06-P'!Y82=0," ",'SINBA-SIS-06-P'!Y82) | AC20: VTF01 | AD20: =IF('SINBA-SIS-06-P'!V82=0," ",'SINBA-SIS-06-P'!V82) | AE20: VTI01 | AF20: =IF('SINBA-SIS-06-P'!W82=0," ",'SINBA-SIS-06-P'!W82) | AG20: VTD51 | AH20: =IF('SINBA-SIS-06-P'!X82=0," ",'SINBA-SIS-06-P'!X82)
J21: Segunda 4 a 11 meses | M21: VAC68 | N21: =IF('SINBA-SIS-06-P'!Y24=0," ",'SINBA-SIS-06-P'!Y24) -> 44 | O21: VXF52 | P21: =IF('SINBA-SIS-06-P'!V24=0," ",'SINBA-SIS-06-P'!V24) | Q21: VXI52 | R21: =IF('SINBA-SIS-06-P'!W24=0," ",'SINBA-SIS-06-P'!W24) | S21: VHX52 | T21: =IF('SINBA-SIS-06-P'!X24=0," ",'SINBA-SIS-06-P'!X24) | Z21: 20 y más años | AA21: VAC40 | AB21: =IF('SINBA-SIS-06-P'!Y83=0," ",'SINBA-SIS-06-P'!Y83) | AC21: VTF02 | AD21: =IF('SINBA-SIS-06-P'!V83=0," ",'SINBA-SIS-06-P'!V83) | AE21: VTI02 | AF21: =IF('SINBA-SIS-06-P'!W83=0," ",'SINBA-SIS-06-P'!W83) | AG21: VTD52 | AH21: =IF('SINBA-SIS-06-P'!X83=0," ",'SINBA-SIS-06-P'!X83)
J22: Tercera 6 a 11 meses | M22: VAC69 | N22: =IF('SINBA-SIS-06-P'!Y25=0," ",'SINBA-SIS-06-P'!Y25) -> 45 | O22: VXF53 | P22: =IF('SINBA-SIS-06-P'!V25=0," ",'SINBA-SIS-06-P'!V25) | Q22: VXI53 | R22: =IF('SINBA-SIS-06-P'!W25=0," ",'SINBA-SIS-06-P'!W25) | S22: VHX53 | T22: =IF('SINBA-SIS-06-P'!X25=0," ",'SINBA-SIS-06-P'!X25) | Y22: Segunda | Z22: 10 a 19 años | AA22: VAC47 | AB22: =IF('SINBA-SIS-06-P'!Y84=0," ",'SINBA-SIS-06-P'!Y84) | AC22: VTF03 | AD22: =IF('SINBA-SIS-06-P'!V84=0," ",'SINBA-SIS-06-P'!V84) | AE22: VTI03 | AF22: =IF('SINBA-SIS-06-P'!W84=0," ",'SINBA-SIS-06-P'!W84) | AG22: VTD53 | AH22: =IF('SINBA-SIS-06-P'!X84=0," ",'SINBA-SIS-06-P'!X84)
J23: Refuerzo 18 a 23 meses | M23: VAC70 | N23: =IF('SINBA-SIS-06-P'!Y26=0," ",'SINBA-SIS-06-P'!Y26) -> 30 | O23: VXF54 | P23: =IF('SINBA-SIS-06-P'!V26=0," ",'SINBA-SIS-06-P'!V26) | Q23: VXI54 | R23: =IF('SINBA-SIS-06-P'!W26=0," ",'SINBA-SIS-06-P'!W26) | S23: VHX54 | T23: =IF('SINBA-SIS-06-P'!X26=0," ",'SINBA-SIS-06-P'!X26) | Z23: 20 y más años | AA23: VAC48 | AB23: =IF('SINBA-SIS-06-P'!Y85=0," ",'SINBA-SIS-06-P'!Y85) | AC23: VTF04 | AD23: =IF('SINBA-SIS-06-P'!V85=0," ",'SINBA-SIS-06-P'!V85) | AE23: VTI04 | AF23: =IF('SINBA-SIS-06-P'!W85=0," ",'SINBA-SIS-06-P'!W85) | AG23: VTD54 | AH23: =IF('SINBA-SIS-06-P'!X85=0," ",'SINBA-SIS-06-P'!X85)
J24: Para iniciar o completar esquema 1 a 4 años | L24: Primera | M24: VHX01 | N24: =IF('SINBA-SIS-06-P'!Y27=0," ",'SINBA-SIS-06-P'!Y27) -> 2 | O24: VXF55 | P24: =IF('SINBA-SIS-06-P'!V27=0," ",'SINBA-SIS-06-P'!V27) | Q24: VXI55 | R24: =IF('SINBA-SIS-06-P'!W27=0," ",'SINBA-SIS-06-P'!W27) | S24: VHX55 | T24: =IF('SINBA-SIS-06-P'!X27=0," ",'SINBA-SIS-06-P'!X27) | Y24: Tercera | Z24: 10 a 19 años | AA24: VTD01 | AB24: =IF('SINBA-SIS-06-P'!Y86=0," ",'SINBA-SIS-06-P'!Y86) | AC24: VTF05 | AD24: =IF('SINBA-SIS-06-P'!V86=0," ",'SINBA-SIS-06-P'!V86) | AE24: VTI05 | AF24: =IF('SINBA-SIS-06-P'!W86=0," ",'SINBA-SIS-06-P'!W86) | AG24: VTD55 | AH24: =IF('SINBA-SIS-06-P'!X86=0," ",'SINBA-SIS-06-P'!X86)
L25: Segunda | M25: VHX02 | N25: =IF('SINBA-SIS-06-P'!Y28=0," ",'SINBA-SIS-06-P'!Y28) -> 1 | O25: VXF56 | P25: =IF('SINBA-SIS-06-P'!V28=0," ",'SINBA-SIS-06-P'!V28) | Q25: VXI56 | R25: =IF('SINBA-SIS-06-P'!W28=0," ",'SINBA-SIS-06-P'!W28) | S25: VHX56 | T25: =IF('SINBA-SIS-06-P'!X28=0," ",'SINBA-SIS-06-P'!X28) | Z25: 20 y más años | AA25: VTD02 | AB25: =IF('SINBA-SIS-06-P'!Y87=0," ",'SINBA-SIS-06-P'!Y87) | AC25: VTF06 | AD25: =IF('SINBA-SIS-06-P'!V87=0," ",'SINBA-SIS-06-P'!V87) | AE25: VTI06 | AF25: =IF('SINBA-SIS-06-P'!W87=0," ",'SINBA-SIS-06-P'!W87) | AG25: VTD56 | AH25: =IF('SINBA-SIS-06-P'!X87=0," ",'SINBA-SIS-06-P'!X87)
L26: Tercera | M26: VHX03 | N26: =IF('SINBA-SIS-06-P'!Y29=0," ",'SINBA-SIS-06-P'!Y29) -> 5 | O26: VXF57 | P26: =IF('SINBA-SIS-06-P'!V29=0," ",'SINBA-SIS-06-P'!V29) | Q26: VXI57 | R26: =IF('SINBA-SIS-06-P'!W29=0," ",'SINBA-SIS-06-P'!W29) | S26: VHX57 | T26: =IF('SINBA-SIS-06-P'!X29=0," ",'SINBA-SIS-06-P'!X29) | Y26: Refuerzo | Z26: 10 a 19 años | AA26: VAC55 | AB26: =IF('SINBA-SIS-06-P'!Y88=0," ",'SINBA-SIS-06-P'!Y88) | AC26: VTF07 | AD26: =IF('SINBA-SIS-06-P'!V88=0," ",'SINBA-SIS-06-P'!V88) | AE26: VTI07 | AF26: =IF('SINBA-SIS-06-P'!W88=0," ",'SINBA-SIS-06-P'!W88) | AG26: VTD57 | AH26: =IF('SINBA-SIS-06-P'!X88=0," ",'SINBA-SIS-06-P'!X88)
L27: Refuerzo | M27: VHX04 | N27: =IF('SINBA-SIS-06-P'!Y30=0," ",'SINBA-SIS-06-P'!Y30) -> 14 | O27: VXF58 | P27: =IF('SINBA-SIS-06-P'!V30=0," ",'SINBA-SIS-06-P'!V30) | Q27: VXI58 | R27: =IF('SINBA-SIS-06-P'!W30=0," ",'SINBA-SIS-06-P'!W30) | S27: VHX58 | T27: =IF('SINBA-SIS-06-P'!X30=0," ",'SINBA-SIS-06-P'!X30) | Z27: 20 y más años | AA27: VAC56 | AB27: =IF('SINBA-SIS-06-P'!Y89=0," ",'SINBA-SIS-06-P'!Y89) | AC27: VTF08 | AD27: =IF('SINBA-SIS-06-P'!V89=0," ",'SINBA-SIS-06-P'!V89) | AE27: VTI08 | AF27: =IF('SINBA-SIS-06-P'!W89=0," ",'SINBA-SIS-06-P'!W89) | AG27: VTD58 | AH27: =IF('SINBA-SIS-06-P'!X89=0," ",'SINBA-SIS-06-P'!X89)
C28: 123 DPT | J28: Única 4 años | M28: VAC12 | N28: =IF('SINBA-SIS-06-P'!Y31=0," ",'SINBA-SIS-06-P'!Y31) -> 15 | O28: VPD53 | P28: =IF('SINBA-SIS-06-P'!V31=0," ",'SINBA-SIS-06-P'!V31) | Q28: VPD55 | R28: =IF('SINBA-SIS-06-P'!W31=0," ",'SINBA-SIS-06-P'!W31) | S28: VPD51 | T28: =IF('SINBA-SIS-06-P'!X31=0," ",'SINBA-SIS-06-P'!X31) | X28: Población | Y28: Primera | Z28: 15 a 19 años | AA28: VTT01 | AB28: =IF('SINBA-SIS-06-P'!Y90=0," ",'SINBA-SIS-06-P'!Y90) -> 3 | AC28: VTF09 | AD28: =IF('SINBA-SIS-06-P'!V90=0," ",'SINBA-SIS-06-P'!V90) | AE28: VTI09 | AF28: =IF('SINBA-SIS-06-P'!W90=0," ",'SINBA-SIS-06-P'!W90) | AG28: VTM01 | AH28: =IF('SINBA-SIS-06-P'!X90=0," ",'SINBA-SIS-06-P'!X90)
J29: Para iniciar o completar esquema 5 a 6 años única | M29: VAC13 | N29: =IF('SINBA-SIS-06-P'!Y32=0," ",'SINBA-SIS-06-P'!Y32) -> 6 | O29: VPD54 | P29: =IF('SINBA-SIS-06-P'!V32=0," ",'SINBA-SIS-06-P'!V32) | Q29: VPD56 | R29: =IF('SINBA-SIS-06-P'!W32=0," ",'SINBA-SIS-06-P'!W32) | S29: VPD52 | T29: =IF('SINBA-SIS-06-P'!X32=0," ",'SINBA-SIS-06-P'!X32) | Z29: 20 a 59 años | AA29: VTT02 | AB29: =IF('SINBA-SIS-06-P'!Y91=0," ",'SINBA-SIS-06-P'!Y91) -> 4 | AC29: VTF10 | AD29: =IF('SINBA-SIS-06-P'!V91=0," ",'SINBA-SIS-06-P'!V91) | AE29: VTI10 | AF29: =IF('SINBA-SIS-06-P'!W91=0," ",'SINBA-SIS-06-P'!W91) | AG29: VTM02 | AH29: =IF('SINBA-SIS-06-P'!X91=0," ",'SINBA-SIS-06-P'!X91)
C30: 274 Rotavirus RV1 | J30: Primera 2 meses | M30: VRV01 | N30: =IF('SINBA-SIS-06-P'!Y33=0," ",'SINBA-SIS-06-P'!Y33) -> 45 | O30: VRF51 | P30: =IF('SINBA-SIS-06-P'!V33=0," ",'SINBA-SIS-06-P'!V33) | Q30: VRI51 | R30: =IF('SINBA-SIS-06-P'!W33=0," ",'SINBA-SIS-06-P'!W33) | S30: VRV51 | T30: =IF('SINBA-SIS-06-P'!X33=0," ",'SINBA-SIS-06-P'!X33) | Z30: 60 y más años | AA30: VTT03 | AB30: =IF('SINBA-SIS-06-P'!Y92=0," ",'SINBA-SIS-06-P'!Y92) -> 1 | AC30: VTF11 | AD30: =IF('SINBA-SIS-06-P'!V92=0," ",'SINBA-SIS-06-P'!V92) | AE30: VTI11 | AF30: =IF('SINBA-SIS-06-P'!W92=0," ",'SINBA-SIS-06-P'!W92) | AG30: VTM03 | AH30: =IF('SINBA-SIS-06-P'!X92=0," ",'SINBA-SIS-06-P'!X92)
J31: Segunda 4 meses | M31: VRV02 | N31: =IF('SINBA-SIS-06-P'!Y34=0," ",'SINBA-SIS-06-P'!Y34) -> 42 | O31: VRF52 | P31: =IF('SINBA-SIS-06-P'!V34=0," ",'SINBA-SIS-06-P'!V34) | Q31: VRI52 | R31: =IF('SINBA-SIS-06-P'!W34=0," ",'SINBA-SIS-06-P'!W34) | S31: VRV52 | T31: =IF('SINBA-SIS-06-P'!X34=0," ",'SINBA-SIS-06-P'!X34) | Y31: Segunda (1 a 2 meses despuès de la 1er dosis) | Z31: 15 a 19 años | AA31: VTT04 | AB31: =IF('SINBA-SIS-06-P'!Y93=0," ",'SINBA-SIS-06-P'!Y93) -> 1 | AC31: VTF12 | AD31: =IF('SINBA-SIS-06-P'!V93=0," ",'SINBA-SIS-06-P'!V93) | AE31: VTI12 | AF31: =IF('SINBA-SIS-06-P'!W93=0," ",'SINBA-SIS-06-P'!W93) | AG31: VTM04 | AH31: =IF('SINBA-SIS-06-P'!X93=0," ",'SINBA-SIS-06-P'!X93)
J32: Para iniciar o completar esquema | L32: Primera 3 a 7 meses | M32: VRV03 | N32: =IF('SINBA-SIS-06-P'!Y35=0," ",'SINBA-SIS-06-P'!Y35) -> 1 | O32: VRF53 | P32: =IF('SINBA-SIS-06-P'!V35=0," ",'SINBA-SIS-06-P'!V35) | Q32: VRI53 | R32: =IF('SINBA-SIS-06-P'!W35=0," ",'SINBA-SIS-06-P'!W35) | S32: VRV53 | T32: =IF('SINBA-SIS-06-P'!X35=0," ",'SINBA-SIS-06-P'!X35) | Z32: 20 a 59 años | AA32: VTT05 | AB32: =IF('SINBA-SIS-06-P'!Y94=0," ",'SINBA-SIS-06-P'!Y94) -> 1 | AC32: VTF13 | AD32: =IF('SINBA-SIS-06-P'!V94=0," ",'SINBA-SIS-06-P'!V94) | AE32: VTI13 | AF32: =IF('SINBA-SIS-06-P'!W94=0," ",'SINBA-SIS-06-P'!W94) | AG32: VTM05 | AH32: =IF('SINBA-SIS-06-P'!X94=0," ",'SINBA-SIS-06-P'!X94)
L33: Segunda 5 a 7 meses | M33: VRV04 | N33: =IF('SINBA-SIS-06-P'!Y36=0," ",'SINBA-SIS-06-P'!Y36) | O33: VRF54 | P33: =IF('SINBA-SIS-06-P'!V36=0," ",'SINBA-SIS-06-P'!V36) | Q33: VRI54 | R33: =IF('SINBA-SIS-06-P'!W36=0," ",'SINBA-SIS-06-P'!W36) | S33: VRV54 | T33: =IF('SINBA-SIS-06-P'!X36=0," ",'SINBA-SIS-06-P'!X36) | Z33: 60 y más años | AA33: VTT06 | AB33: =IF('SINBA-SIS-06-P'!Y95=0," ",'SINBA-SIS-06-P'!Y95) | AC33: VTF14 | AD33: =IF('SINBA-SIS-06-P'!V95=0," ",'SINBA-SIS-06-P'!V95) | AE33: VTI14 | AF33: =IF('SINBA-SIS-06-P'!W95=0," ",'SINBA-SIS-06-P'!W95) | AG33: VTM06 | AH33: =IF('SINBA-SIS-06-P'!X95=0," ",'SINBA-SIS-06-P'!X95)
C34: 125 Neumocócica Conjugada (13 valente) | J34: Primera 2 a 11 meses | M34: VAC17 | N34: =IF('SINBA-SIS-06-P'!Y37=0," ",'SINBA-SIS-06-P'!Y37) -> 50 | O34: VNF51 | P34: =IF('SINBA-SIS-06-P'!V37=0," ",'SINBA-SIS-06-P'!V37) | Q34: VNI51 | R34: =IF('SINBA-SIS-06-P'!W37=0," ",'SINBA-SIS-06-P'!W37) | S34: VNC51 | T34: =IF('SINBA-SIS-06-P'!X37=0," ",'SINBA-SIS-06-P'!X37) | Y34: Tercera (1 año después de la 2a dosis) | Z34: 15 a 19 años | AA34: VTT07 | AB34: =IF('SINBA-SIS-06-P'!Y96=0," ",'SINBA-SIS-06-P'!Y96) | AC34: VTF15 | AD34: =IF('SINBA-SIS-06-P'!V96=0," ",'SINBA-SIS-06-P'!V96) | AE34: VTI15 | AF34: =IF('SINBA-SIS-06-P'!W96=0," ",'SINBA-SIS-06-P'!W96) | AG34: VTM07 | AH34: =IF('SINBA-SIS-06-P'!X96=0," ",'SINBA-SIS-06-P'!X96)
J35: Segunda 4 a 11 meses | M35: VAC18 | N35: =IF('SINBA-SIS-06-P'!Y38=0," ",'SINBA-SIS-06-P'!Y38) -> 42 | O35: VNF52 | P35: =IF('SINBA-SIS-06-P'!V38=0," ",'SINBA-SIS-06-P'!V38) | Q35: VNI52 | R35: =IF('SINBA-SIS-06-P'!W38=0," ",'SINBA-SIS-06-P'!W38) | S35: VNC52 | T35: =IF('SINBA-SIS-06-P'!X38=0," ",'SINBA-SIS-06-P'!X38) | Z35: 20 a 59 años | AA35: VTT08 | AB35: =IF('SINBA-SIS-06-P'!Y97=0," ",'SINBA-SIS-06-P'!Y97) | AC35: VTF16 | AD35: =IF('SINBA-SIS-06-P'!V97=0," ",'SINBA-SIS-06-P'!V97) | AE35: VTI16 | AF35: =IF('SINBA-SIS-06-P'!W97=0," ",'SINBA-SIS-06-P'!W97) | AG35: VTM08 | AH35: =IF('SINBA-SIS-06-P'!X97=0," ",'SINBA-SIS-06-P'!X97)
J36: Tercera 12 a 23 meses | M36: VAC19 | N36: =IF('SINBA-SIS-06-P'!Y39=0," ",'SINBA-SIS-06-P'!Y39) -> 40 | O36: VNF53 | P36: =IF('SINBA-SIS-06-P'!V39=0," ",'SINBA-SIS-06-P'!V39) | Q36: VNI53 | R36: =IF('SINBA-SIS-06-P'!W39=0," ",'SINBA-SIS-06-P'!W39) | S36: VNC53 | T36: =IF('SINBA-SIS-06-P'!X39=0," ",'SINBA-SIS-06-P'!X39) | Z36: 60 y más años | AA36: VTT09 | AB36: =IF('SINBA-SIS-06-P'!Y98=0," ",'SINBA-SIS-06-P'!Y98) | AC36: VTF17 | AD36: =IF('SINBA-SIS-06-P'!V98=0," ",'SINBA-SIS-06-P'!V98) | AE36: VTI17 | AF36: =IF('SINBA-SIS-06-P'!W98=0," ",'SINBA-SIS-06-P'!W98) | AG36: VTM09 | AH36: =IF('SINBA-SIS-06-P'!X98=0," ",'SINBA-SIS-06-P'!X98)
J37: Para iniciar o completar esquema 1 a 4 años | L37: Primera | M37: VNC01 | N37: =IF('SINBA-SIS-06-P'!Y40=0," ",'SINBA-SIS-06-P'!Y40) -> 3 | O37: VNF54 | P37: =IF('SINBA-SIS-06-P'!V40=0," ",'SINBA-SIS-06-P'!V40) | Q37: VNI54 | R37: =IF('SINBA-SIS-06-P'!W40=0," ",'SINBA-SIS-06-P'!W40) | S37: VNC54 | T37: =IF('SINBA-SIS-06-P'!X40=0," ",'SINBA-SIS-06-P'!X40) | Y37: Refuerzo (Cada 10 años, hasta completar 5 dosis) | Z37: 15 a 19 años | AA37: VTT10 | AB37: =IF('SINBA-SIS-06-P'!Y99=0," ",'SINBA-SIS-06-P'!Y99) -> 15 | AC37: VTF18 | AD37: =IF('SINBA-SIS-06-P'!V99=0," ",'SINBA-SIS-06-P'!V99) | AE37: VTI18 | AF37: =IF('SINBA-SIS-06-P'!W99=0," ",'SINBA-SIS-06-P'!W99) | AG37: VTM10 | AH37: =IF('SINBA-SIS-06-P'!X99=0," ",'SINBA-SIS-06-P'!X99)
L38: Segunda | M38: VNC02 | N38: =IF('SINBA-SIS-06-P'!Y41=0," ",'SINBA-SIS-06-P'!Y41) -> 2 | O38: VNF55 | P38: =IF('SINBA-SIS-06-P'!V41=0," ",'SINBA-SIS-06-P'!V41) | Q38: VNI55 | R38: =IF('SINBA-SIS-06-P'!W41=0," ",'SINBA-SIS-06-P'!W41) | S38: VNC55 | T38: =IF('SINBA-SIS-06-P'!X41=0," ",'SINBA-SIS-06-P'!X41) | Z38: 20 a 59 años | AA38: VTT11 | AB38: =IF('SINBA-SIS-06-P'!Y100=0," ",'SINBA-SIS-06-P'!Y100) -> 20 | AC38: VTF19 | AD38: =IF('SINBA-SIS-06-P'!V100=0," ",'SINBA-SIS-06-P'!V100) | AE38: VTI19 | AF38: =IF('SINBA-SIS-06-P'!W100=0," ",'SINBA-SIS-06-P'!W100) | AG38: VTM11 | AH38: =IF('SINBA-SIS-06-P'!X100=0," ",'SINBA-SIS-06-P'!X100)
L39: Tercera | M39: VNC03 | N39: =IF('SINBA-SIS-06-P'!Y42=0," ",'SINBA-SIS-06-P'!Y42) -> 2 | O39: VNF56 | P39: =IF('SINBA-SIS-06-P'!V42=0," ",'SINBA-SIS-06-P'!V42) | Q39: VNI56 | R39: =IF('SINBA-SIS-06-P'!W42=0," ",'SINBA-SIS-06-P'!W42) | S39: VNC56 | T39: =IF('SINBA-SIS-06-P'!X42=0," ",'SINBA-SIS-06-P'!X42) | Z39: 60 y más años | AA39: VTT12 | AB39: =IF('SINBA-SIS-06-P'!Y101=0," ",'SINBA-SIS-06-P'!Y101) -> 6 | AC39: VTF20 | AD39: =IF('SINBA-SIS-06-P'!V101=0," ",'SINBA-SIS-06-P'!V101) | AE39: VTI20 | AF39: =IF('SINBA-SIS-06-P'!W101=0," ",'SINBA-SIS-06-P'!W101) | AG39: VTM12 | AH39: =IF('SINBA-SIS-06-P'!X101=0," ",'SINBA-SIS-06-P'!X101)
J40: Personas de 60 años y más | L40: Única | M40: VNC04 | N40: =IF('SINBA-SIS-06-P'!Y43=0," ",'SINBA-SIS-06-P'!Y43) -> 1 | O40: VNF57 | P40: =IF('SINBA-SIS-06-P'!V43=0," ",'SINBA-SIS-06-P'!V43) | Q40: VNI57 | R40: =IF('SINBA-SIS-06-P'!W43=0," ",'SINBA-SIS-06-P'!W43) | S40: VNC59 | T40: =IF('SINBA-SIS-06-P'!X43=0," ",'SINBA-SIS-06-P'!X43) | W40: 133 Tdpa | Y40: Embarazada a partir de la semana 20 de gestación | AA40: VAC63 | AB40: =IF('SINBA-SIS-06-P'!Y102=0," ",'SINBA-SIS-06-P'!Y102) -> 26 | AC40: VDP52 | AD40: =IF('SINBA-SIS-06-P'!V102=0," ",'SINBA-SIS-06-P'!V102) | AE40: VDP54 | AF40: =IF('SINBA-SIS-06-P'!W102=0," ",'SINBA-SIS-06-P'!W102) | AG40: VDP51 | AH40: =IF('SINBA-SIS-06-P'!X102=0," ",'SINBA-SIS-06-P'!X102)
C41: 354 Neumocócica Conjugada (20 valente) | J41: Primera 2 a 11 meses | M41: VCC01 | N41: =IF('SINBA-SIS-06-P'!Y44=0," ",'SINBA-SIS-06-P'!Y44) | O41: VCF01 | P41: =IF('SINBA-SIS-06-P'!V44=0," ",'SINBA-SIS-06-P'!V44) | Q41: VCI01 | R41: =IF('SINBA-SIS-06-P'!W44=0," ",'SINBA-SIS-06-P'!W44) | S41: VCC51 | T41: =IF('SINBA-SIS-06-P'!X44=0," ",'SINBA-SIS-06-P'!X44) | Y41: Personal en riesgo c | AA41: VDP01 | AB41: =IF('SINBA-SIS-06-P'!Y103=0," ",'SINBA-SIS-06-P'!Y103) -> 2 | AC41: VDP53 | AD41: =IF('SINBA-SIS-06-P'!V103=0," ",'SINBA-SIS-06-P'!V103) | AE41: VDP55 | AF41: =IF('SINBA-SIS-06-P'!W103=0," ",'SINBA-SIS-06-P'!W103) | AG41: VDP56 | AH41: =IF('SINBA-SIS-06-P'!X103=0," ",'SINBA-SIS-06-P'!X103)
...

Sheet SIS-SS-IE Mensual
A1: Subsecretaria de Prevención y Promoción de la Salud
A2: Centro Nacional para la Salud de la Infancia y la Adolescencia
A3: Programa de Vacunación Universal
A4: Concentrado Mensual de Dosis Aplicadas de Vacuna Anti influenza Estacional por Unidad de Salud Temporada Invernal 2025-2026
A6: Nombre del responsable de vacunación: | D6: =IF(ÍNDICE!J4=0," ",ÍNDICE!J4) -> LE. ANA MELISSA SALAZAR SERRANO | I6: Unidad de Salud: | J6: =IF(ÍNDICE!C4=0," ",ÍNDICE!C4) -> LOMAS DE CASA BLANCA
C7: Servicio: | D7: MEDICINA PREVENTIVA | I7: Clues | J7: =IF(ÍNDICE!G4=0," ",ÍNDICE!G4) -> QTSSA012982
A8: SIS 2025 - 2026 | J8: ="Del 1ro al "&IF(SUM(ÍNDICE!S3)=0," ",SUM(ÍNDICE!S3)&" de") -> Del 1ro al 31 de | K8: =IF(ÍNDICE!O4=0," ",ÍNDICE!O4) -> AGOSTO | L8: ="del "&TEXT(ÍNDICE!$U$3,"aaaa") -> del 2026
B10: BIOLÓGICO | C10: DOSIS / GRUPO POBLACIONAL | E10: Clave | F10: Variable | G10: TOTAL | H10: SEMANA 1 | I10: SEMANA 2 | J10: SEMANA 3 | K10: SEMANA 4 | L10: SEMANA 5
A11: 225 Aplicación de Antiinfluenza Estacional | B11: Población blanco | C11: Pimera dosis | E11: BIE01 | F11: 6 a 11 meses | G11: =SUM(H11:L11) -> 0
E12: BIE28 | F12: 12 a 23 meses | G12: =SUM(H12:L12) -> 0
E13: BIE29 | F13: 24 a 35 meses | G13: =SUM(H13:L13) -> 0
E14: BIE30 | F14: 36 a 47 meses | G14: =SUM(H14:L14) -> 0
E15: BIE31 | F15: 48 a 59 meses | G15: =SUM(H15:L15) -> 0
C16: Segunda dosis | E16: BIE04 | F16: 7 a 11 meses | G16: =SUM(H16:L16) -> 0
E17: BIE32 | F17: 12 a 23 meses | G17: =SUM(H17:L17) -> 0
E18: BIE33 | F18: 24 a 35 meses | G18: =SUM(H18:L18) -> 0
E19: BIE34 | F19: 36 a 47 meses | G19: =SUM(H19:L19) -> 0
E20: BIE35 | F20: 48 a 59 meses | G20: =SUM(H20:L20) -> 0
C21: Revacunación | E21: BIE36 | F21: 18 a 23 meses | G21: =SUM(H21:L21) -> 0
E22: BIE37 | F22: 24 a 35 meses | G22: =SUM(H22:L22) -> 0
E23: BIE38 | F23: 36 a 47 meses | G23: =SUM(H23:L23) -> 0
E24: BIE39 | F24: 48 a 59 meses | G24: =SUM(H24:L24) -> 0
E25: BIE40 | F25: 60 años y más | G25: =SUM(H25:L25) -> 0
B26: Población de riesgo de 5 a 59 años | C26: Grupos Riesgo | E26: BIO96 | F26: Embarazadas | G26: =SUM(H26:L26) -> 0
E27: BIO97 | F27: Personal de salud UM | G27: =SUM(H27:L27) -> 0
C28: Personas que viven con VIH/SIDA | E28: BIE09 | F28: 5 a 9 años | G28: =SUM(H28:L28) -> 0
E29: BIE10 | F29: 10 a 19 años | G29: =SUM(H29:L29) -> 0
E30: BIE41 | F30: 20 a 59 años | G30: =SUM(H30:L30) -> 0
C31: Personas que viven con Diabetes Mellitus | E31: BIE12 | F31: 5 a 9 años | G31: =SUM(H31:L31) -> 0
E32: BIE13 | F32: 10 a 19 años | G32: =SUM(H32:L32) -> 0
E33: BIE42 | F33: 20 a 59 años | G33: =SUM(H33:L33) -> 0
C34: Personas que viven con obesidad mórbida | E34: BIE15 | F34: 5 a 9 años | G34: =SUM(H34:L34) -> 0
E35: BIE16 | F35: 10 a 19 años | G35: =SUM(H35:L35) -> 0
E36: BIE43 | F36: 20 a 59 años | G36: =SUM(H36:L36) -> 0
C37: Personas que viven con cardiopatías agudas o crónicas excepto hipertensión arterial esencial | E37: BIE18 | F37: 5 a 9 años | G37: =SUM(H37:L37) -> 0
E38: BIE19 | F38: 10 a 19 años | G38: =SUM(H38:L38) -> 0
E39: BIE44 | F39: 20 a 59 años | G39: =SUM(H39:L39) -> 0
C40: Personas que viven con enfermedad pulmonar crónica, incluye EPOC y asma | E40: BIE48 | F40: 5 a 9 años | G40: =SUM(H40:L40) -> 0
E41: BIE49 | F41: 10 a 19 años | G41: =SUM(H41:L41) -> 0
E42: BIE50 | F42: 20 a 59 años | G42: =SUM(H42:L42) -> 0
...
