Workbook
Name temp: 'CLUES JS1'!$B$5:$D$96

Sheet METAS UNIDADES URBANAS
A1: Subsecretaria de Prevención y Promoción de la Salud
A2: Centro Nacional para la Salud de la Infancia y la Adolescencia
A3: Programa de Vacunación Universal
A4: Metas de Vacuna Anti Influenza Estacional Temporada Invernal 2025-2026
A5: Entidad Federativa: | D5: QUERÉTARO | U5: Jurisdicción Sanitaria: | X5: 1
A6: Unidad de Salud: | D6: DEPARTAMENTO DE VACUNAS | L6: Municipio: | N6: QUERÉTARO | T6: Institución: | V6: SECRETARÍA DE SALUD
A10: BIOLÓGICO | C10: DOSIS / GRUPO POBLACIONAL | G10: NHGQ | H10: HENM | I10: UMME UMQ | J10: JURICA | K10: MENCHACA | L10: SAN ANTONIO DE LA PUNTA | M10: SAN PABLO | N10: CARRILLO PUERTO | O10: LOMA BONITA | P10: PEDRO ESCOBEDO | Q10: SANTA MARÍA MAGDALENA | R10: TLACOTE EL BAJO | S10: LÁZARO CÁRDENAS | T10: SAN PEDRITO PEÑUELAS | U10: MENCHACA NORTE | V10: SAN JOSÉ EL ALTO | W10: SANTA ROSA JÁUREGUI | X10: SATÉLITE | Y10: SAN PEDRO MÁRTIR | Z10: LOMAS DE CASABLANCA | AA10: TOTAL
A11: 225 Aplicación de Antiinfluenza Estacional | B11: Población blanco | C11: Primera dosis | F11: 6 a 11 meses | J11: 100 | K11: 35 | L11: 40 | M11: 90 | N11: 50 | O11: 90 | P11: 2813 | Q11: 45 | R11: 40 | S11: 190 | T11: 245 | U11: 195 | V11: 90 | W11: 165 | X11: 290 | Y11: 157 | Z11: 305 | AA11: =SUM(I11:Z11) -> 4940
F12: 12 a 23 meses | J12: 62 | K12: 30 | L12: 35 | M12: 65 | N12: 35 | O12: 45 | P12: 3396 | Q12: 50 | R12: 35 | S12: 97 | T12: 105 | U12: 90 | V12: 65 | W12: 105 | X12: 180 | Y12: 123 | Z12: 195 | AA12: =SUM(I12:Z12) -> 4713
F13: 24 a 35 meses | J13: 15 | K13: 5 | L13: 5 | M13: 5 | N13: 10 | O13: 10 | P13: 72 | Q13: 5 | R13: 10 | S13: 15 | T13: 15 | U13: 10 | V13: 10 | W13: 5 | X13: 15 | Y13: 10 | Z13: 15 | AA13: =SUM(I13:Z13) -> 232
F14: 36 a 47 meses | J14: 5 | K14: 3 | L14: 1 | M14: 5 | N14: 5 | O14: 5 | P14: 347 | Q14: 5 | R14: 2 | S14: 20 | T14: 25 | U14: 20 | V14: 10 | W14: 20 | X14: 20 | Y14: 15 | Z14: 20 | AA14: =SUM(I14:Z14) -> 528
F15: 48 a 59 meses | J15: 5 | K15: 2 | L15: 2 | M15: 5 | N15: 5 | O15: 5 | P15: 184 | Q15: 5 | R15: 2 | S15: 10 | T15: 10 | U15: 5 | V15: 5 | W15: 10 | X15: 15 | Y15: 10 | Z15: 15 | AA15: =SUM(I15:Z15) -> 295
C16: Segunda dosis | F16: 7 a 11 meses | J16: 100 | K16: 35 | L16: 40 | M16: 90 | N16: 50 | O16: 90 | P16: 2813 | Q16: 45 | R16: 40 | S16: 190 | T16: 245 | U16: 195 | V16: 90 | W16: 165 | X16: 290 | Y16: 157 | Z16: 305 | AA16: =SUM(I16:Z16) -> 4940
F17: 12 a 23 meses | J17: 62 | K17: 30 | L17: 35 | M17: 65 | N17: 35 | O17: 45 | P17: 3396 | Q17: 50 | R17: 35 | S17: 97 | T17: 105 | U17: 90 | V17: 65 | W17: 105 | X17: 180 | Y17: 123 | Z17: 195 | AA17: =SUM(I17:Z17) -> 4713
F18: 24 a 35 meses | J18: 15 | K18: 5 | L18: 5 | M18: 5 | N18: 10 | O18: 10 | P18: 72 | Q18: 5 | R18: 10 | S18: 15 | T18: 15 | U18: 10 | V18: 10 | W18: 5 | X18: 15 | Y18: 10 | Z18: 15 | AA18: =SUM(I18:Z18) -> 232
F19: 36 a 47 meses | J19: 5 | K19: 3 | L19: 1 | M19: 5 | N19: 5 | O19: 5 | P19: 347 | Q19: 5 | R19: 2 | S19: 20 | T19: 25 | U19: 20 | V19: 10 | W19: 20 | X19: 20 | Y19: 15 | Z19: 20 | AA19: =SUM(I19:Z19) -> 528
F20: 48 a 59 meses | J20: 5 | K20: 2 | L20: 2 | M20: 5 | N20: 5 | O20: 5 | P20: 184 | Q20: 5 | R20: 2 | S20: 10 | T20: 10 | U20: 5 | V20: 5 | W20: 10 | X20: 15 | Y20: 10 | Z20: 15 | AA20: =SUM(I20:Z20) -> 295
C21: Revacunación | F21: 18 a 23 meses | J21: 118 | K21: 30 | L21: 84 | M21: 73 | N21: 95 | O21: 90 | P21: 1822 | Q21: 82 | R21: 84 | S21: 179 | T21: 180 | U21: 76 | V21: 99 | W21: 123 | X21: 365 | Y21: 127 | Z21: 334 | AA21: =SUM(I21:Z21) -> 3961
F22: 24 a 35 meses | H22: 300 | J22: 120 | K22: 36 | L22: 76 | M22: 66 | N22: 90 | O22: 81 | P22: 4791 | Q22: 76 | R22: 86 | S22: 170 | T22: 179 | U22: 68 | V22: 84 | W22: 113 | X22: 326 | Y22: 117 | Z22: 315 | AA22: =SUM(I22:Z22) -> 6794
F23: 36 a 47 meses | J23: 100 | K23: 35 | L23: 69 | M23: 55 | N23: 75 | O23: 75 | P23: 5435 | Q23: 68 | R23: 89 | S23: 210 | T23: 350 | U23: 55 | V23: 74 | W23: 99 | X23: 290 | Y23: 110 | Z23: 308 | AA23: =SUM(I23:Z23) -> 7497
F24: 48 a 59 meses | H24: 200 | J24: 82 | K24: 25 | L24: 51 | M24: 60 | N24: 65 | O24: 60 | P24: 4439 | Q24: 75 | R24: 61 | S24: 150 | T24: 260 | U24: 50 | V24: 62 | W24: 85 | X24: 290 | Y24: 90 | Z24: 298 | AA24: =SUM(I24:Z24) -> 6203
F25: 60 años y más | J25: 160 | K25: 86 | L25: 88 | M25: 98 | N25: 109 | O25: 175 | P25: 16953 | Q25: 70 | R25: 105 | S25: 194 | T25: 287 | U25: 145 | V25: 587 | W25: 335 | X25: 1044 | Y25: 471 | Z25: 969 | AA25: =SUM(I25:Z25) -> 21876
B26: Población de riesgo de 5 a 59 años | C26: Grupos de riesgo | F26: EMBARAZADAS | J26: 41 | K26: 87 | L26: 52 | M26: 90 | N26: 101 | O26: 180 | P26: 789 | Q26: 85 | R26: 136 | S26: 191 | T26: 237 | U26: 252 | V26: 201 | W26: 289 | X26: 530 | Y26: 177 | Z26: 548 | AA26: =SUM(I26:Z26) -> 3986
F27: PERSONAL DE SALUD EN UNIDADES MÉDICAS | G27: 504 | J27: 5 | K27: 7 | L27: 8 | M27: 20 | N27: 13 | O27: 10 | P27: 127 | Q27: 8 | R27: 8 | S27: 21 | T27: 40 | U27: 22 | V27: 29 | W27: 39 | X27: 84 | Y27: 21 | Z27: 84 | AA27: =SUM(I27:Z27) -> 546
C28: Personas que viven con VIH/SIDA | F28: 5 A 9 AÑOS | P28: 13 | AA28: =SUM(I28:Z28) -> 13
F29: 10 A 19 AÑOS | P29: 18 | AA29: =SUM(I29:Z29) -> 18
F30: 20 A 59 AÑOS | P30: 173 | T30: 4 | W30: 1 | X30: 3 | Z30: 5 | AA30: =SUM(I30:Z30) -> 186
C31: Diabetes mellitus | F31: 5 A 9 AÑOS | P31: 60 | S31: 1 | T31: 1 | U31: 1 | V31: 1 | W31: 1 | X31: 1 | Y31: 1 | Z31: 1 | AA31: =SUM(I31:Z31) -> 68
F32: 10 A 19 AÑOS | J32: 1 | K32: 1 | L32: 1 | M32: 1 | N32: 1 | O32: 1 | P32: 401 | Q32: 1 | R32: 1 | S32: 1 | T32: 1 | U32: 1 | V32: 1 | W32: 1 | X32: 1 | Y32: 1 | Z32: 1 | AA32: =SUM(I32:Z32) -> 417
F33: 20 A 59 AÑOS | G33: 129 | I33: 200 | J33: 59 | K33: 44 | L33: 56 | M33: 43 | N33: 60 | O33: 67 | P33: 1871 | Q33: 66 | R33: 66 | S33: 80 | T33: 80 | U33: 80 | V33: 635 | W33: 60 | X33: 138 | Y33: 61 | Z33: 135 | AA33: =SUM(I33:Z33) -> 3801
C34: Obesidad mórbida | F34: 5 A 9 AÑOS | G34: 400 | J34: 20 | K34: 15 | L34: 10 | M34: 24 | N34: 15 | O34: 24 | P34: 527 | Q34: 10 | R34: 15 | S34: 29 | T34: 31 | U34: 29 | V34: 29 | W34: 20 | X34: 45 | Y34: 28 | Z34: 48 | AA34: =SUM(I34:Z34) -> 919
F35: 10 A 19 AÑOS | G35: 267 | J35: 45 | K35: 30 | L35: 35 | M35: 46 | N35: 25 | O35: 38 | P35: 1041 | Q35: 25 | R35: 28 | S35: 46 | T35: 50 | U35: 45 | V35: 46 | W35: 45 | X35: 65 | Y35: 40 | Z35: 68 | AA35: =SUM(I35:Z35) -> 1718
F36: 20 A 59 AÑOS | G36: 300 | H36: 1000 | J36: 65 | K36: 40 | L36: 47 | M36: 51 | N36: 60 | O36: 50 | P36: 203 | Q36: 35 | R36: 51 | S36: 55 | T36: 65 | U36: 57 | V36: 765 | W36: 50 | X36: 100 | Y36: 60 | Z36: 100 | AA36: =SUM(I36:Z36) -> 1854
C37: Personas con cardiopatías agudas o crónicas | F37: 5 A 9 AÑOS | P37: 134 | S37: 1 | T37: 1 | X37: 1 | Z37: 1 | AA37: =SUM(I37:Z37) -> 138
F38: 10 A 19 AÑOS | J38: 1 | K38: 1 | L38: 1 | M38: 1 | N38: 1 | O38: 1 | P38: 145 | Q38: 1 | R38: 1 | S38: 1 | T38: 1 | U38: 1 | V38: 1 | W38: 1 | X38: 5 | Y38: 1 | Z38: 5 | AA38: =SUM(I38:Z38) -> 169
F39: 20 A 59 AÑOS | J39: 40 | K39: 15 | L39: 10 | M39: 10 | N39: 15 | O39: 35 | P39: 2562 | Q39: 15 | R39: 15 | S39: 65 | T39: 65 | U39: 15 | V39: 15 | W39: 10 | X39: 72 | Y39: 24 | Z39: 70 | AA39: =SUM(I39:Z39) -> 3053
C40: Personas con enfermedad pulmonar crónica, incluye EPOC y asma | F40: 5 A 9 AÑOS | J40: 1 | O40: 1 | P40: 184 | S40: 1 | T40: 1 | X40: 1 | Z40: 1 | AA40: =SUM(I40:Z40) -> 190
F41: 10 A 19 AÑOS | J41: 5 | K41: 1 | L41: 1 | M41: 1 | N41: 5 | O41: 1 | P41: 318 | Q41: 1 | R41: 1 | S41: 5 | T41: 5 | U41: 2 | V41: 2 | W41: 2 | X41: 10 | Y41: 1 | Z41: 10 | AA41: =SUM(I41:Z41) -> 371
F42: 20 A 59 AÑOS | J42: 24 | K42: 17 | L42: 15 | M42: 19 | N42: 21 | O42: 32 | P42: 1424 | Q42: 18 | R42: 15 | S42: 47 | T42: 46 | U42: 27 | V42: 27 | W42: 29 | X42: 54 | Y42: 24 | Z42: 59 | AA42: =SUM(I42:Z42) -> 1898
C43: Personas con cáncer | F43: 5 A 9 AÑOS | P43: 55 | AA43: =SUM(I43:Z43) -> 55
...

Sheet METAS UNIDADES RURALES
A1: Subsecretaria de Prevención y Promoción de la Salud
A2: Centro Nacional para la Salud de la Infancia y la Adolescencia
A3: Programa de Vacunación Universal
A4: Metas de Vacuna Anti Influenza Estacional Temporada Invernal 2025-2026
A5: Entidad Federativa: | D5: QUERÉTARO | U5: Jurisdicción Sanitaria: | X5: 1
A6: Unidad de Salud: | D6: DEPARTAMENTO DE VACUNAS | L6: Municipio: | N6: QUERÉTARO | T6: Institución: | V6: SECRETARÍA DE SALUD
X8: Fecha: del _____ de__________al _____de_________20_____
A10: BIOLÓGICO | C10: DOSIS / GRUPO POBLACIONAL | G10: JOFRITO | H10: MONTENEGRO | I10: PIE DE GALLO | J10: SAN JOSÉ BUENAVISTA | K10: SAN MIGUELITO | L10: LA SOLANA | M10: TINAJA DE LA ESTANCIA | N10: UMME AMB1 | O10: UMME CERRO DE LA CRUZ | P10: UMME LA LUZ | Q10: UMME SAN PEDRITO | R10: UMME RANCHO LARGO | S10: LA GOTERA | T10: FAM SAN JOSÉ BUENAVISTA | U10: FAM PEDRO ESCOBEDO | V10: FAM EL MARQUES 2 | W10: UMME MF1 | X10: UMME AMB1 | Y10: UMME AMB2 | Z10: UMME MEDICO DENTAL | AA10: TOTAL
A11: 225 Aplicación de Antiinfluenza Estacional | B11: Población blanco | C11: Primera dosis | F11: 6 a 11 meses | G11: 25 | H11: 90 | I11: 50 | J11: 50 | K11: 46 | L11: 44 | M11: 22 | N11: 23 | O11: 25 | P11: 20 | Q11: 25 | R11: 29 | S11: 65 | T11: 20 | U11: 23 | V11: 25 | W11: 25 | AA11: =SUM(G11:Z11) -> 607
F12: 12 a 23 meses | G12: 20 | H12: 50 | I12: 31 | J12: 41 | K12: 42 | L12: 35 | M12: 15 | N12: 15 | O12: 15 | P12: 15 | Q12: 15 | R12: 15 | S12: 40 | T12: 15 | U12: 16 | V12: 18 | W12: 15 | AA12: =SUM(G12:Z12) -> 413
F13: 24 a 35 meses | G13: 3 | H13: 15 | I13: 5 | J13: 5 | K13: 5 | L13: 5 | M13: 2 | N13: 3 | O13: 5 | P13: 5 | Q13: 5 | R13: 5 | S13: 10 | T13: 5 | U13: 5 | V13: 5 | W13: 5 | AA13: =SUM(G13:Z13) -> 93
F14: 36 a 47 meses | G14: 5 | H14: 8 | I14: 5 | J14: 9 | K14: 1 | L14: 5 | M14: 2 | N14: 1 | O14: 1 | P14: 1 | Q14: 1 | R14: 1 | S14: 10 | T14: 1 | U14: 1 | V14: 1 | W14: 1 | AA14: =SUM(G14:Z14) -> 54
F15: 48 a 59 meses | G15: 2 | H15: 1 | I15: 1 | J15: 1 | K15: 2 | L15: 5 | M15: 1 | N15: 2 | O15: 5 | P15: 5 | Q15: 2 | R15: 2 | S15: 8 | T15: 2 | U15: 2 | V15: 2 | W15: 2 | AA15: =SUM(G15:Z15) -> 45
C16: Segunda dosis | F16: 7 a 11 meses | G16: 25 | H16: 90 | I16: 50 | J16: 50 | K16: 46 | L16: 44 | M16: 22 | N16: 23 | O16: 25 | P16: 20 | Q16: 25 | R16: 29 | S16: 65 | T16: 20 | U16: 23 | V16: 25 | W16: 25 | AA16: =SUM(G16:Z16) -> 607
F17: 12 a 23 meses | G17: 20 | H17: 50 | I17: 31 | J17: 41 | K17: 42 | L17: 35 | M17: 15 | N17: 15 | O17: 15 | P17: 15 | Q17: 15 | R17: 15 | S17: 40 | T17: 15 | U17: 16 | V17: 18 | W17: 15 | AA17: =SUM(G17:Z17) -> 413
F18: 24 a 35 meses | G18: 3 | H18: 15 | I18: 5 | J18: 5 | K18: 5 | L18: 5 | M18: 2 | N18: 3 | O18: 5 | P18: 5 | Q18: 5 | R18: 5 | S18: 10 | T18: 5 | U18: 5 | V18: 5 | W18: 5 | AA18: =SUM(G18:Z18) -> 93
F19: 36 a 47 meses | G19: 5 | H19: 8 | I19: 5 | J19: 9 | K19: 1 | L19: 5 | M19: 2 | N19: 1 | O19: 1 | P19: 1 | Q19: 1 | R19: 1 | S19: 10 | T19: 1 | U19: 1 | V19: 1 | W19: 1 | AA19: =SUM(G19:Z19) -> 54
F20: 48 a 59 meses | G20: 2 | H20: 1 | I20: 1 | J20: 1 | K20: 2 | L20: 5 | M20: 1 | N20: 2 | O20: 5 | P20: 5 | Q20: 2 | R20: 2 | S20: 8 | T20: 2 | U20: 2 | V20: 2 | W20: 2 | AA20: =SUM(G20:Z20) -> 45
C21: Revacunación | F21: 18 a 23 meses | G21: 50 | H21: 66 | I21: 57 | J21: 61 | K21: 56 | L21: 66 | M21: 32 | N21: 37 | O21: 41 | P21: 38 | Q21: 36 | R21: 36 | S21: 57 | T21: 37 | U21: 47 | V21: 47 | W21: 36 | AA21: =SUM(G21:Z21) -> 800
F22: 24 a 35 meses | G22: 41 | H22: 53 | I22: 45 | J22: 50 | K22: 53 | L22: 55 | M22: 28 | N22: 27 | O22: 33 | P22: 27 | Q22: 27 | R22: 37 | S22: 48 | T22: 46 | U22: 46 | V22: 46 | W22: 47 | AA22: =SUM(G22:Z22) -> 709
F23: 36 a 47 meses | G23: 35 | H23: 57 | I23: 36 | J23: 45 | K23: 45 | L23: 45 | M23: 29 | N23: 20 | O23: 30 | P23: 19 | Q23: 28 | R23: 28 | S23: 45 | T23: 45 | U23: 35 | V23: 35 | W23: 25 | AA23: =SUM(G23:Z23) -> 602
F24: 48 a 59 meses | G24: 36 | H24: 45 | I24: 33 | J24: 30 | K24: 35 | L24: 35 | M24: 20 | N24: 25 | O24: 25 | P24: 21 | Q24: 16 | R24: 16 | S24: 40 | T24: 35 | U24: 25 | V24: 25 | W24: 24 | AA24: =SUM(G24:Z24) -> 486
F25: 60 años y más | G25: 90 | H25: 79 | I25: 101 | J25: 95 | K25: 93 | L25: 92 | M25: 39 | N25: 34 | O25: 30 | P25: 37 | Q25: 37 | R25: 37 | S25: 97 | T25: 77 | U25: 73 | V25: 79 | W25: 35 | AA25: =SUM(G25:Z25) -> 1125
B26: Población de riesgo de 5 a 59 años | C26: Grupos de riesgo | F26: EMBARAZADAS | G26: 68 | H26: 65 | I26: 56 | J26: 45 | K26: 70 | L26: 68 | M26: 21 | N26: 35 | O26: 24 | P26: 35 | Q26: 35 | R26: 35 | S26: 67 | T26: 43 | U26: 44 | V26: 38 | W26: 20 | AA26: =SUM(G26:Z26) -> 769
F27: PERSONAL DE SALUD EN UNIDADES MÉDICAS | G27: 5 | H27: 4 | I27: 6 | J27: 5 | K27: 8 | L27: 5 | M27: 5 | N27: 3 | O27: 3 | P27: 2 | Q27: 5 | R27: 5 | S27: 7 | T27: 5 | U27: 5 | V27: 5 | W27: 5 | AA27: =SUM(G27:Z27) -> 83
C28: Personas que viven con VIH/SIDA | F28: 5 A 9 AÑOS | AA28: =SUM(G28:Z28) -> 0
F29: 10 A 19 AÑOS | AA29: =SUM(G29:Z29) -> 0
F30: 20 A 59 AÑOS | AA30: =SUM(G30:Z30) -> 0
C31: Diabetes mellitus | F31: 5 A 9 AÑOS | AA31: =SUM(G31:Z31) -> 0
F32: 10 A 19 AÑOS | H32: 1 | S32: 5 | T32: 1 | U32: 1 | V32: 1 | AA32: =SUM(G32:Z32) -> 9
F33: 20 A 59 AÑOS | G33: 50 | H33: 74 | I33: 74 | J33: 43 | K33: 44 | L33: 53 | M33: 31 | N33: 49 | O33: 30 | P33: 42 | Q33: 43 | R33: 35 | S33: 60 | T33: 63 | U33: 66 | V33: 66 | W33: 35 | AA33: =SUM(G33:Z33) -> 858
C34: Obesidad mórbida | F34: 5 A 9 AÑOS | G34: 9 | H34: 14 | I34: 11 | J34: 10 | K34: 10 | L34: 10 | M34: 5 | N34: 5 | O34: 5 | P34: 5 | Q34: 5 | R34: 5 | S34: 15 | T34: 5 | U34: 5 | V34: 5 | W34: 5 | AA34: =SUM(G34:Z34) -> 129
F35: 10 A 19 AÑOS | G35: 15 | H35: 24 | I35: 25 | J35: 22 | K35: 24 | L35: 26 | M35: 18 | N35: 10 | O35: 10 | P35: 10 | Q35: 10 | R35: 10 | S35: 21 | T35: 20 | U35: 20 | V35: 20 | W35: 10 | AA35: =SUM(G35:Z35) -> 295
F36: 20 A 59 AÑOS | G36: 20 | H36: 29 | I36: 41 | J36: 30 | K36: 46 | L36: 40 | M36: 15 | N36: 15 | O36: 20 | P36: 25 | Q36: 15 | R36: 15 | S36: 55 | T36: 60 | U36: 62 | V36: 64 | W36: 15 | AA36: =SUM(G36:Z36) -> 567
C37: Personas con cardiopatías agudas o crónicas | F37: 5 A 9 AÑOS | AA37: =SUM(G37:Z37) -> 0
F38: 10 A 19 AÑOS | H38: 1 | S38: 1 | AA38: =SUM(G38:Z38) -> 2
F39: 20 A 59 AÑOS | G39: 10 | H39: 10 | I39: 10 | J39: 10 | K39: 10 | L39: 10 | M39: 5 | N39: 10 | O39: 5 | P39: 5 | Q39: 5 | R39: 5 | S39: 27 | T39: 10 | U39: 10 | V39: 10 | W39: 5 | AA39: =SUM(G39:Z39) -> 157
C40: Personas con enfermedad pulmonar crónica, incluye EPOC y asma | F40: 5 A 9 AÑOS | AA40: =SUM(G40:Z40) -> 0
F41: 10 A 19 AÑOS | G41: 1 | H41: 1 | I41: 1 | J41: 1 | K41: 1 | L41: 1 | M41: 1 | N41: 1 | O41: 1 | P41: 1 | Q41: 1 | R41: 1 | S41: 1 | T41: 1 | U41: 1 | V41: 1 | W41: 1 | AA41: =SUM(G41:Z41) -> 17
F42: 20 A 59 AÑOS | G42: 13 | H42: 15 | I42: 12 | J42: 12 | K42: 12 | L42: 12 | M42: 11 | N42: 5 | O42: 5 | P42: 5 | Q42: 5 | R42: 5 | S42: 25 | T42: 10 | U42: 10 | V42: 10 | W42: 5 | AA42: =SUM(G42:Z42) -> 172
...

Sheet Comparación
A4: Población | C4: DOSIS / GRUPO POBLACIONAL | F4: GRUPO POBLACIONAL | G4: TOTAL | H4: METAS 2025-2026 | I4: DIFERENCIA
A5: 225 Aplicación de Antiinfluenza Estacional | B5: Población blanco | C5: Primera dosis | F5: 6 a 11 meses | G5: =SUM('METAS UNIDADES RURALES'!AA11,'METAS UNIDADES URBANAS'!AA11) -> 5547 | H5: 5547 | I5: =H5-G5 -> 0
F6: 12 a 23 meses | G6: =SUM('METAS UNIDADES RURALES'!AA12,'METAS UNIDADES URBANAS'!AA12) -> 5126 | H6: 5126 | I6: =H6-G6 -> 0
F7: 24 a 35 meses | G7: =SUM('METAS UNIDADES RURALES'!AA13,'METAS UNIDADES URBANAS'!AA13) -> 325 | H7: 325 | I7: =H7-G7 -> 0
F8: 36 a 47 meses | G8: =SUM('METAS UNIDADES RURALES'!AA14,'METAS UNIDADES URBANAS'!AA14) -> 582 | H8: 582 | I8: =H8-G8 -> 0
F9: 48 a 59 meses | G9: =SUM('METAS UNIDADES RURALES'!AA15,'METAS UNIDADES URBANAS'!AA15) -> 340 | H9: 340 | I9: =H9-G9 -> 0
C10: Segunda dosis | F10: 7 a 11 meses | G10: =SUM('METAS UNIDADES RURALES'!AA16,'METAS UNIDADES URBANAS'!AA16) -> 5547 | H10: 5547 | I10: =H10-G10 -> 0
F11: 12 a 23 meses | G11: =SUM('METAS UNIDADES RURALES'!AA17,'METAS UNIDADES URBANAS'!AA17) -> 5126 | H11: 5126 | I11: =H11-G11 -> 0
F12: 24 a 35 meses | G12: =SUM('METAS UNIDADES RURALES'!AA18,'METAS UNIDADES URBANAS'!AA18) -> 325 | H12: 325 | I12: =H12-G12 -> 0
F13: 36 a 47 meses | G13: =SUM('METAS UNIDADES RURALES'!AA19,'METAS UNIDADES URBANAS'!AA19) -> 582 | H13: 582 | I13: =H13-G13 -> 0
F14: 48 a 59 meses | G14: =SUM('METAS UNIDADES RURALES'!AA20,'METAS UNIDADES URBANAS'!AA20) -> 340 | H14: 340 | I14: =H14-G14 -> 0
C15: Revacunación | F15: 18 a 23 meses | G15: =SUM('METAS UNIDADES RURALES'!AA21,'METAS UNIDADES URBANAS'!AA21) -> 4761 | H15: 4761 | I15: =H15-G15 -> 0
F16: 24 a 35 meses | G16: =SUM('METAS UNIDADES RURALES'!AA22,'METAS UNIDADES URBANAS'!AA22) -> 7503 | H16: 7503 | I16: =H16-G16 -> 0
F17: 36 a 47 meses | G17: =SUM('METAS UNIDADES RURALES'!AA23,'METAS UNIDADES URBANAS'!AA23) -> 8099 | H17: 8099 | I17: =H17-G17 -> 0
F18: 48 a 59 meses | G18: =SUM('METAS UNIDADES RURALES'!AA24,'METAS UNIDADES URBANAS'!AA24) -> 6689 | H18: 6689 | I18: =H18-G18 -> 0
F19: 60 años y más | G19: =SUM('METAS UNIDADES RURALES'!AA25,'METAS UNIDADES URBANAS'!AA25) -> 23001 | H19: 23001 | I19: =H19-G19 -> 0
B20: Población de riesgo de 5 a 59 años | C20: Grupos de riesgo | F20: EMBARAZADAS | G20: =SUM('METAS UNIDADES RURALES'!AA26,'METAS UNIDADES URBANAS'!AA26) -> 4755 | H20: 4755 | I20: =H20-G20 -> 0
F21: PERSONAL DE SALUD EN UNIDADES MÉDICAS | G21: =SUM('METAS UNIDADES RURALES'!AA27,'METAS UNIDADES URBANAS'!AA27) -> 629 | H21: 629 | I21: =H21-G21 -> 0
C22: Personas que viven con VIH/SIDA | F22: 5 A 9 AÑOS | G22: =SUM('METAS UNIDADES RURALES'!AA28,'METAS UNIDADES URBANAS'!AA28) -> 13 | H22: 13 | I22: =H22-G22 -> 0
F23: 10 A 19 AÑOS | G23: =SUM('METAS UNIDADES RURALES'!AA29,'METAS UNIDADES URBANAS'!AA29) -> 18 | H23: 18 | I23: =H23-G23 -> 0
F24: 20 A 59 AÑOS | G24: =SUM('METAS UNIDADES RURALES'!AA30,'METAS UNIDADES URBANAS'!AA30) -> 186 | H24: 186 | I24: =H24-G24 -> 0
C25: Diabetes mellitus | F25: 5 A 9 AÑOS | G25: =SUM('METAS UNIDADES RURALES'!AA31,'METAS UNIDADES URBANAS'!AA31) -> 68 | H25: 68 | I25: =H25-G25 -> 0
F26: 10 A 19 AÑOS | G26: =SUM('METAS UNIDADES RURALES'!AA32,'METAS UNIDADES URBANAS'!AA32) -> 426 | H26: 426 | I26: =H26-G26 -> 0
F27: 20 A 59 AÑOS | G27: =SUM('METAS UNIDADES RURALES'!AA33,'METAS UNIDADES URBANAS'!AA33) -> 4659 | H27: 4659 | I27: =H27-G27 -> 0
C28: Obesidad mórbida | F28: 5 A 9 AÑOS | G28: =SUM('METAS UNIDADES RURALES'!AA34,'METAS UNIDADES URBANAS'!AA34) -> 1048 | H28: 1048 | I28: =H28-G28 -> 0
F29: 10 A 19 AÑOS | G29: =SUM('METAS UNIDADES RURALES'!AA35,'METAS UNIDADES URBANAS'!AA35) -> 2013 | H29: 2013 | I29: =H29-G29 -> 0
F30: 20 A 59 AÑOS | G30: =SUM('METAS UNIDADES RURALES'!AA36,'METAS UNIDADES URBANAS'!AA36) -> 2421 | H30: 2421 | I30: =H30-G30 -> 0
C31: Personas con cardiopatías agudas o crónicas | F31: 5 A 9 AÑOS | G31: =SUM('METAS UNIDADES RURALES'!AA37,'METAS UNIDADES URBANAS'!AA37) -> 138 | H31: 138 | I31: =H31-G31 -> 0
F32: 10 A 19 AÑOS | G32: =SUM('METAS UNIDADES RURALES'!AA38,'METAS UNIDADES URBANAS'!AA38) -> 171 | H32: 171 | I32: =H32-G32 -> 0
F33: 20 A 59 AÑOS | G33: =SUM('METAS UNIDADES RURALES'!AA39,'METAS UNIDADES URBANAS'!AA39) -> 3210 | H33: 3210 | I33: =H33-G33 -> 0
C34: Personas con enfermedad pulmonar crónica, incluye EPOC y asma | F34: 5 A 9 AÑOS | G34: =SUM('METAS UNIDADES RURALES'!AA40,'METAS UNIDADES URBANAS'!AA40) -> 190 | H34: 190 | I34: =H34-G34 -> 0
F35: 10 A 19 AÑOS | G35: =SUM('METAS UNIDADES RURALES'!AA41,'METAS UNIDADES URBANAS'!AA41) -> 388 | H35: 388 | I35: =H35-G35 -> 0
F36: 20 A 59 AÑOS | G36: =SUM('METAS UNIDADES RURALES'!AA42,'METAS UNIDADES URBANAS'!AA42) -> 2070 | H36: 2070 | I36: =H36-G36 -> 0
C37: Personas con cáncer | F37: 5 A 9 AÑOS | G37: =SUM('METAS UNIDADES RURALES'!AA43,'METAS UNIDADES URBANAS'!AA43) -> 55 | H37: 55 | I37: =H37-G37 -> 0
F38: 10 A 19 AÑOS | G38: =SUM('METAS UNIDADES RURALES'!AA44,'METAS UNIDADES URBANAS'!AA44) -> 104 | H38: 104 | I38: =H38-G38 -> 0
F39: 20 A 59 AÑOS | G39: =SUM('METAS UNIDADES RURALES'!AA45,'METAS UNIDADES URBANAS'!AA45) -> 570 | H39: 570 | I39: =H39-G39 -> 0
C40: Enfermedades cardiacas o pulmonares congénitas, u otros padecimientos crónicos que requieran consumo prolongado de salicilatos | F40: 5 a 9 años | G40: =SUM('METAS UNIDADES RURALES'!AA46,'METAS UNIDADES URBANAS'!AA46) -> 74 | H40: 74 | I40: =H40-G40 -> 0
F41: 10 a 19 años | G41: =SUM('METAS UNIDADES RURALES'!AA47,'METAS UNIDADES URBANAS'!AA47) -> 150 | H41: 150 | I41: =H41-G41 -> 0
C42: Personas con insuficiencia renal | F42: 5 a 9 años | G42: =SUM('METAS UNIDADES RURALES'!AA48,'METAS UNIDADES URBANAS'!AA48) -> 182 | H42: 182 | I42: =H42-G42 -> 0
F43: 10 a 19 años | G43: =SUM('METAS UNIDADES RURALES'!AA49,'METAS UNIDADES URBANAS'!AA49) -> 69 | H43: 69 | I43: =H43-G43 -> 0
...

Sheet DISTRIBUCIÓN DE JERINGA
A1: CLUE | B1: UNIDAD DE SALUD | C1: JERINGA 23X25 CAJAS (50 PIEZAS) | D1: JERINGA 22X32 CAJAS (50 PIEZAS) | E1: JERINGA 23X25 PIEZAS | F1: JERINGA 22X32 PIEZAS | G1: META | H1: META | I1: JERINGA 23X25 CAJAS (50 PIEZAS) | J1: JERINGA 23X25 CAJAS (50 PIEZAS) | K1: JERINGA 23X25 PIEZAS | L1: JERINGA 22X32 PIEZAS
A2: QTSSA001740 | B2: HENM | C2: =ROUNDDOWN(I2,0) -> 0 | D2: =ROUNDDOWN(J2,0) -> 30 | E2: =((G2)-(C2*50)) -> 0 | F2: =((H2)-(D2*50)) -> 0 | G2: 0 | H2: 1500 | I2: =G2/50 -> 0 | J2: =H2/50 -> 30
A3: =_xlfn.XLOOKUP(B3,'CLUES JS1'!$C$44:$C$85,'CLUES JS1'!$B$44:$B$85,"NO EXISTE",0) -> QTSSA001764 | B3: UMME QUERÉTARO | C3: =ROUNDDOWN(I3,0) -> 0 | D3: =ROUNDDOWN(J3,0) -> 4 | E3: =((G3)-(C3*50)) -> 0 | F3: =((H3)-(D3*50)) -> 0 | G3: 0 | H3: 200 | I3: =G3/50 -> 0 | J3: =H3/50 -> 4
A4: =_xlfn.XLOOKUP(B4,'CLUES JS1'!$C$44:$C$85,'CLUES JS1'!$B$44:$B$85,"NO EXISTE",0) -> QTSSA001793 | B4: JURICA | C4: =ROUNDDOWN(I4,0) -> 16 | D4: =ROUNDDOWN(J4,0) -> 11 | E4: =((G4)-(C4*50)) -> 46 | F4: =((H4)-(D4*50)) -> 24 | G4: 846 | H4: 574 | I4: =G4/50 -> 16.92 | J4: =H4/50 -> 11.48
A5: =_xlfn.XLOOKUP(B5,'CLUES JS1'!$C$44:$C$85,'CLUES JS1'!$B$44:$B$85,"NO EXISTE",0) -> QTSSA001810 | B5: MENCHACA | C5: =ROUNDDOWN(I5,0) -> 6 | D5: =ROUNDDOWN(J5,0) -> 8 | E5: =((G5)-(C5*50)) -> 33 | F5: =((H5)-(D5*50)) -> 7 | G5: 333 | H5: 407 | I5: =G5/50 -> 6.66 | J5: =H5/50 -> 8.14
A6: =_xlfn.XLOOKUP(B6,'CLUES JS1'!$C$44:$C$85,'CLUES JS1'!$B$44:$B$85,"NO EXISTE",0) -> QTSSA001822 | B6: SAN ANTONIO DE LA PUNTA | C6: =ROUNDDOWN(I6,0) -> 8 | D6: =ROUNDDOWN(J6,0) -> 7 | E6: =((G6)-(C6*50)) -> 46 | F6: =((H6)-(D6*50)) -> 4 | G6: 446 | H6: 354 | I6: =G6/50 -> 8.92 | J6: =H6/50 -> 7.08
A7: =_xlfn.XLOOKUP(B7,'CLUES JS1'!$C$44:$C$85,'CLUES JS1'!$B$44:$B$85,"NO EXISTE",0) -> QTSSA001834 | B7: SAN PABLO | C7: =ROUNDDOWN(I7,0) -> 11 | D7: =ROUNDDOWN(J7,0) -> 9 | E7: =((G7)-(C7*50)) -> 36 | F7: =((H7)-(D7*50)) -> 24 | G7: 586 | H7: 474 | I7: =G7/50 -> 11.72 | J7: =H7/50 -> 9.48
A8: =_xlfn.XLOOKUP(B8,'CLUES JS1'!$C$44:$C$85,'CLUES JS1'!$B$44:$B$85,"NO EXISTE",0) -> QTSSA001846 | B8: FELIPE CARRILLO PUERTO | C8: =ROUNDDOWN(I8,0) -> 11 | D8: =ROUNDDOWN(J8,0) -> 11 | E8: =((G8)-(C8*50)) -> 32 | F8: =((H8)-(D8*50)) -> 18 | G8: 582 | H8: 568 | I8: =G8/50 -> 11.64 | J8: =H8/50 -> 11.36
A9: =_xlfn.XLOOKUP(B9,'CLUES JS1'!$C$44:$C$85,'CLUES JS1'!$B$44:$B$85,"NO EXISTE",0) -> QTSSA001851 | B9: LOMA BONITA | C9: =ROUNDDOWN(I9,0) -> 12 | D9: =ROUNDDOWN(J9,0) -> 12 | E9: =((G9)-(C9*50)) -> 2 | F9: =((H9)-(D9*50)) -> 38 | G9: 602 | H9: 638 | I9: =G9/50 -> 12.04 | J9: =H9/50 -> 12.76
A10: =_xlfn.XLOOKUP(B10,'CLUES JS1'!$C$44:$C$85,'CLUES JS1'!$B$44:$B$85,"NO EXISTE",0) -> QTSSA001863 | B10: PEDRO ESCOBEDO | C10: =ROUNDDOWN(I10,0) -> 564 | D10: =ROUNDDOWN(J10,0) -> 888 | E10: =((G10)-(C10*50)) -> 1 | F10: =((H10)-(D10*50)) -> 25 | G10: 28201 | H10: 44425 | I10: =G10/50 -> 564.02 | J10: =H10/50 -> 888.5
A11: =_xlfn.XLOOKUP(B11,'CLUES JS1'!$C$44:$C$85,'CLUES JS1'!$B$44:$B$85,"NO EXISTE",0) -> QTSSA001904 | B11: JOFRITO | C11: =ROUNDDOWN(I11,0) -> 4 | D11: =ROUNDDOWN(J11,0) -> 6 | E11: =((G11)-(C11*50)) -> 39 | F11: =((H11)-(D11*50)) -> 11 | G11: 239 | H11: 311 | I11: =G11/50 -> 4.78 | J11: =H11/50 -> 6.22
A12: =_xlfn.XLOOKUP(B12,'CLUES JS1'!$C$44:$C$85,'CLUES JS1'!$B$44:$B$85,"NO EXISTE",0) -> QTSSA001916 | B12: MONTENEGRO | C12: =ROUNDDOWN(I12,0) -> 10 | D12: =ROUNDDOWN(J12,0) -> 6 | E12: =((G12)-(C12*50)) -> 39 | F12: =((H12)-(D12*50)) -> 31 | G12: 539 | H12: 331 | I12: =G12/50 -> 10.78 | J12: =H12/50 -> 6.62
A13: =_xlfn.XLOOKUP(B13,'CLUES JS1'!$C$44:$C$85,'CLUES JS1'!$B$44:$B$85,"NO EXISTE",0) -> QTSSA001921 | B13: PIE DE GALLO | C13: =ROUNDDOWN(I13,0) -> 6 | D13: =ROUNDDOWN(J13,0) -> 6 | E13: =((G13)-(C13*50)) -> 49 | F13: =((H13)-(D13*50)) -> 41 | G13: 349 | H13: 341 | I13: =G13/50 -> 6.98 | J13: =H13/50 -> 6.82
A14: =_xlfn.XLOOKUP(B14,'CLUES JS1'!$C$44:$C$85,'CLUES JS1'!$B$44:$B$85,"NO EXISTE",0) -> QTSSA001945 | B14: SAN JOSÉ BUENAVISTA | C14: =ROUNDDOWN(I14,0) -> 7 | D14: =ROUNDDOWN(J14,0) -> 5 | E14: =((G14)-(C14*50)) -> 36 | F14: =((H14)-(D14*50)) -> 44 | G14: 386 | H14: 294 | I14: =G14/50 -> 7.72 | J14: =H14/50 -> 5.88
... A22: =_xlfn.XLOOKUP(B22,'CLUES JS1'!$C$44:$C$85,'CLUES JS1'!$B$44:$B$85,"NO EXISTE",0) -> QTSSA002703 | B22: MENCHACA NORTE | C22: =ROUNDDOWN(I22,0) -> 8 | D22: =ROUNDDOWN(J22,0) -> 13 | E22: =((G22)-(C22*50)) -> 38 | F22: =((H22)-(D22*50)) -> 22 | G22: 438 | H22: 672 | I22: =G22/50 -> 8.76 | J22: =H22/50 -> 13.44
A23: QTSSA002901 | B23: NHGQ | C23: =ROUNDDOWN(I23,0) -> 0 | D23: =ROUNDDOWN(J23,0) -> 36 | E23: =((G23)-(C23*50)) -> 0 | F23: =((H23)-(D23*50)) -> 0 | G23: 0 | H23: 1800 | I23: =G23/50 -> 0 | J23: =H23/50 -> 36
A24: =_xlfn.XLOOKUP(B24,'CLUES JS1'!$C$44:$C$85,'CLUES JS1'!$B$44:$B$85,"NO EXISTE",0) -> QTSSA003553 | B24: UMME CERRO DE LA CRUZ | C24: =ROUNDDOWN(I24,0) -> 5 | D24: =ROUNDDOWN(J24,0) -> 3 | E24: =((G24)-(C24*50)) -> 44 | F24: =((H24)-(D24*50)) -> 36 | G24: 294 | H24: 186 | I24: =G24/50 -> 5.88 | J24: =H24/50 -> 3.72
A25: =_xlfn.XLOOKUP(B25,'CLUES JS1'!$C$44:$C$85,'CLUES JS1'!$B$44:$B$85,"NO EXISTE",0) -> QTSSA003562 | B25: UMME LA LUZ | C25: =ROUNDDOWN(I25,0) -> 1 | D25: =ROUNDDOWN(J25,0) -> 2 | E25: =((G25)-(C25*50)) -> 8 | F25: =((H25)-(D25*50)) -> 42 | G25: 58 | H25: 142 | I25: =G25/50 -> 1.16 | J25: =H25/50 -> 2.84
A26: =_xlfn.XLOOKUP(B26,'CLUES JS1'!$C$44:$C$85,'CLUES JS1'!$B$44:$B$85,"NO EXISTE",0) -> QTSSA003595 | B26: UMME SAN PEDRITO | C26: =ROUNDDOWN(I26,0) -> 4 | D26: =ROUNDDOWN(J26,0) -> 3 | E26: =((G26)-(C26*50)) -> 31 | F26: =((H26)-(D26*50)) -> 29 | G26: 231 | H26: 179 | I26: =G26/50 -> 4.62 | J26: =H26/50 -> 3.58
A27: =_xlfn.XLOOKUP(B27,'CLUES JS1'!$C$44:$C$85,'CLUES JS1'!$B$44:$B$85,"NO EXISTE",0) -> QTSSA003604 | B27: UMME RANCHO LARGO | C27: =ROUNDDOWN(I27,0) -> 4 | D27: =ROUNDDOWN(J27,0) -> 3 | E27: =((G27)-(C27*50)) -> 31 | F27: =((H27)-(D27*50)) -> 29 | G27: 231 | H27: 179 | I27: =G27/50 -> 4.62 | J27: =H27/50 -> 3.58
A28: =_xlfn.XLOOKUP(B28,'CLUES JS1'!$C$44:$C$85,'CLUES JS1'!$B$44:$B$85,"NO EXISTE",0) -> QTSSA003715 | B28: LA GOTERA | C28: =ROUNDDOWN(I28,0) -> 8 | D28: =ROUNDDOWN(J28,0) -> 8 | E28: =((G28)-(C28*50)) -> 46 | F28: =((H28)-(D28*50)) -> 4 | G28: 446 | H28: 404 | I28: =G28/50 -> 8.92 | J28: =H28/50 -> 8.08
A29: =_xlfn.XLOOKUP(B29,'CLUES JS1'!$C$44:$C$85,'CLUES JS1'!$B$44:$B$85,"NO EXISTE",0) -> QTSSA012240 | B29: SAN JOSÉ EL ALTO | C29: =ROUNDDOWN(I29,0) -> 13 | D29: =ROUNDDOWN(J29,0) -> 47 | E29: =((G29)-(C29*50)) -> 9 | F29: =((H29)-(D29*50)) -> 41 | G29: 659 | H29: 2391 | I29: =G29/50 -> 13.18 | J29: =H29/50 -> 47.82
A30: =_xlfn.XLOOKUP(B30,'CLUES JS1'!$C$44:$C$85,'CLUES JS1'!$B$44:$B$85,"NO EXISTE",0) -> QTSSA012276 | B30: FAM SAN JOSÉ BUENAVISTA | C30: =ROUNDDOWN(I30,0) -> 7 | D30: =ROUNDDOWN(J30,0) -> 5 | E30: =((G30)-(C30*50)) -> 16 | F30: =((H30)-(D30*50)) -> 34 | G30: 366 | H30: 284 | I30: =G30/50 -> 7.32 | J30: =H30/50 -> 5.68
A31: =_xlfn.XLOOKUP(B31,'CLUES JS1'!$C$44:$C$85,'CLUES JS1'!$B$44:$B$85,"NO EXISTE",0) -> QTSSA012281 | B31: FAM PEDRO ESCOBEDO | C31: =ROUNDDOWN(I31,0) -> 7 | D31: =ROUNDDOWN(J31,0) -> 5 | E31: =((G31)-(C31*50)) -> 16 | F31: =((H31)-(D31*50)) -> 34 | G31: 366 | H31: 284 | I31: =G31/50 -> 7.32 | J31: =H31/50 -> 5.68
A32: =_xlfn.XLOOKUP(B32,'CLUES JS1'!$C$44:$C$85,'CLUES JS1'!$B$44:$B$85,"NO EXISTE",0) -> QTSSA012544 | B32: FAM PALO ALTO | C32: =ROUNDDOWN(I32,0) -> 7 | D32: =ROUNDDOWN(J32,0) -> 5 | E32: =((G32)-(C32*50)) -> 16 | F32: =((H32)-(D32*50)) -> 34 | G32: 366 | H32: 284 | I32: =G32/50 -> 7.32 | J32: =H32/50 -> 5.68
A33: =_xlfn.XLOOKUP(B33,'CLUES JS1'!$C$44:$C$85,'CLUES JS1'!$B$44:$B$85,"NO EXISTE",0) -> QTSSA012556 | B33: UMME MF1 | C33: =ROUNDDOWN(I33,0) -> 5 | D33: =ROUNDDOWN(J33,0) -> 3 | E33: =((G33)-(C33*50)) -> 38 | F33: =((H33)-(D33*50)) -> 32 | G33: 288 | H33: 182 | I33: =G33/50 -> 5.76 | J33: =H33/50 -> 3.64
A34: =_xlfn.XLOOKUP(B34,'CLUES JS1'!$C$44:$C$85,'CLUES JS1'!$B$44:$B$85,"NO EXISTE",0) -> QTSSA012561 | B34: UMME AMBULANCIA 1 | C34: =ROUNDDOWN(I34,0) -> 4 | D34: =ROUNDDOWN(J34,0) -> 3 | E34: =((G34)-(C34*50)) -> 41 | F34: =((H34)-(D34*50)) -> 19 | G34: 241 | H34: 169 | I34: =G34/50 -> 4.82 | J34: =H34/50 -> 3.38
A35: =_xlfn.XLOOKUP(B35,'CLUES JS1'!$C$44:$C$85,'CLUES JS1'!$B$44:$B$85,"NO EXISTE",0) -> QTSSA012631 | B35: UMME MEDICO DENTAL | C35: =ROUNDDOWN(I35,0) -> 4 | D35: =ROUNDDOWN(J35,0) -> 3 | E35: =((G35)-(C35*50)) -> 33 | F35: =((H35)-(D35*50)) -> 27 | G35: 233 | H35: 177 | I35: =G35/50 -> 4.66 | J35: =H35/50 -> 3.54
... A39: =_xlfn.XLOOKUP(B39,'CLUES JS1'!$C$44:$C$85,'CLUES JS1'!$B$44:$B$85,"NO EXISTE",0) -> QTSSA012982 | B39: LOMAS DE CASA BLANCA | C39: =ROUNDDOWN(I39,0) -> 52 | D39: =ROUNDDOWN(J39,0) -> 48 | E39: =((G39)-(C39*50)) -> 6 | F39: =((H39)-(D39*50)) -> 44 | G39: 2606 | H39: 2444 | I39: =G39/50 -> 52.12 | J39: =H39/50 -> 48.88

Sheet RUTA 1
A1: CLUE | B1: UNIDAD DE SALUD | C1: JERINGA 23X25 CAJAS (50 PIEZAS) | D1: JERINGA 23X25 CAJAS (50 PIEZAS) | E1: JERINGA 23X25 PIEZAS | F1: JERINGA 22X32 PIEZAS | G1: FIRMA DE RECIBIDO
A2: =_xlfn.XLOOKUP(B2,'CLUES JS1'!$C$44:$C$85,'CLUES JS1'!$B$44:$B$85,"NO EXISTE",0) -> QTSSA001810 | B2: MENCHACA | C2: 6 | D2: 8 | E2: 33 | F2: 7
A3: =_xlfn.XLOOKUP(B3,'CLUES JS1'!$C$44:$C$85,'CLUES JS1'!$B$44:$B$85,"NO EXISTE",0) -> QTSSA001851 | B3: LOMA BONITA | C3: 12 | D3: 12 | E3: 2 | F3: 38
A4: =_xlfn.XLOOKUP(B4,'CLUES JS1'!$C$44:$C$85,'CLUES JS1'!$B$44:$B$85,"NO EXISTE",0) -> QTSSA002522 | B4: LÁZARO CÁRDENAS | C4: 34 | D4: 20 | E4: 23 | F4: 37
A5: =_xlfn.XLOOKUP(B5,'CLUES JS1'!$C$44:$C$85,'CLUES JS1'!$B$44:$B$85,"NO EXISTE",0) -> QTSSA002534 | B5: SAN PEDRITO PEÑUELAS | C5: 34 | D5: 21 | E5: 40 | F5: 20
A6: =_xlfn.XLOOKUP(B6,'CLUES JS1'!$C$44:$C$85,'CLUES JS1'!$B$44:$B$85,"NO EXISTE",0) -> QTSSA002703 | B6: MENCHACA NORTE | C6: 8 | D6: 13 | E6: 38 | F6: 22
A7: =_xlfn.XLOOKUP(B7,'CLUES JS1'!$C$44:$C$85,'CLUES JS1'!$B$44:$B$85,"NO EXISTE",0) -> QTSSA012240 | B7: SAN JOSÉ EL ALTO | C7: 13 | D7: 47 | E7: 9 | F7: 41
A8: =_xlfn.XLOOKUP(B8,'CLUES JS1'!$C$44:$C$85,'CLUES JS1'!$B$44:$B$85,"NO EXISTE",0) -> QTSSA012923 | B8: SATÉLITE | C8: 50 | D8: 47 | E8: 35 | F8: 35
A9: =_xlfn.XLOOKUP(B9,'CLUES JS1'!$C$44:$C$85,'CLUES JS1'!$B$44:$B$85,"NO EXISTE",0) -> QTSSA012976 | B9: SAN PEDRO MÁRTIR | C9: 20 | D9: 19 | E9: 32 | F9: 48

Sheet RUTA 2
A1: CLUE | B1: UNIDAD DE SALUD | C1: JERINGA 23X25 CAJAS (50 PIEZAS) | D1: JERINGA 23X25 CAJAS (50 PIEZAS) | E1: JERINGA 23X25 PIEZAS | F1: JERINGA 22X32 PIEZAS | G1: FIRMA DE RECIBIDO
A2: =_xlfn.XLOOKUP(B2,'CLUES JS1'!$C$44:$C$85,'CLUES JS1'!$B$44:$B$85,"NO EXISTE",0) -> QTSSA001904 | B2: JOFRITO | C2: 4 | D2: 6 | E2: 39 | F2: 11
A3: =_xlfn.XLOOKUP(B3,'CLUES JS1'!$C$44:$C$85,'CLUES JS1'!$B$44:$B$85,"NO EXISTE",0) -> QTSSA001916 | B3: MONTENEGRO | C3: 10 | D3: 6 | E3: 39 | F3: 31
A4: =_xlfn.XLOOKUP(B4,'CLUES JS1'!$C$44:$C$85,'CLUES JS1'!$B$44:$B$85,"NO EXISTE",0) -> QTSSA001921 | B4: PIE DE GALLO | C4: 6 | D4: 6 | E4: 49 | F4: 41
A5: =_xlfn.XLOOKUP(B5,'CLUES JS1'!$C$44:$C$85,'CLUES JS1'!$B$44:$B$85,"NO EXISTE",0) -> QTSSA001945 | B5: SAN JOSÉ BUENAVISTA | C5: 7 | D5: 5 | E5: 36 | F5: 44
A6: =_xlfn.XLOOKUP(B6,'CLUES JS1'!$C$44:$C$85,'CLUES JS1'!$B$44:$B$85,"NO EXISTE",0) -> QTSSA001962 | B6: SAN MIGUELITO | C6: 7 | D6: 7 | E6: 39 | F6: 21
A7: =_xlfn.XLOOKUP(B7,'CLUES JS1'!$C$44:$C$85,'CLUES JS1'!$B$44:$B$85,"NO EXISTE",0) -> QTSSA002003 | B7: LA SOLANA | C7: 8 | D7: 6 | E7: 42 | F7: 48
A8: =_xlfn.XLOOKUP(B8,'CLUES JS1'!$C$44:$C$85,'CLUES JS1'!$B$44:$B$85,"NO EXISTE",0) -> QTSSA003715 | B8: LA GOTERA | C8: 8 | D8: 8 | E8: 46 | F8: 4
A9: =_xlfn.XLOOKUP(B9,'CLUES JS1'!$C$44:$C$85,'CLUES JS1'!$B$44:$B$85,"NO EXISTE",0) -> QTSSA012655 | B9: SANTA ROSA JÁUREGUI | C9: 20 | D9: 18 | E9: 14 | F9: 46

Sheet RUTA 3
A1: CLUE | B1: UNIDAD DE SALUD | C1: JERINGA 23X25 CAJAS (50 PIEZAS) | D1: JERINGA 23X25 CAJAS (50 PIEZAS) | E1: JERINGA 23X25 PIEZAS | F1: JERINGA 22X32 PIEZAS | G1: FIRMA DE RECIBIDO
A2: =_xlfn.XLOOKUP(B2,'CLUES JS1'!$C$44:$C$85,'CLUES JS1'!$B$44:$B$85,"NO EXISTE",0) -> QTSSA001793 | B2: JURICA | C2: 16 | D2: 11 | E2: 46 | F2: 24
A3: =_xlfn.XLOOKUP(B3,'CLUES JS1'!$C$44:$C$85,'CLUES JS1'!$B$44:$B$85,"NO EXISTE",0) -> QTSSA001822 | B3: SAN ANTONIO DE LA PUNTA | C3: 8 | D3: 7 | E3: 46 | F3: 4
A4: =_xlfn.XLOOKUP(B4,'CLUES JS1'!$C$44:$C$85,'CLUES JS1'!$B$44:$B$85,"NO EXISTE",0) -> QTSSA001834 | B4: SAN PABLO | C4: 11 | D4: 9 | E4: 36 | F4: 24
A5: =_xlfn.XLOOKUP(B5,'CLUES JS1'!$C$44:$C$85,'CLUES JS1'!$B$44:$B$85,"NO EXISTE",0) -> QTSSA001846 | B5: FELIPE CARRILLO PUERTO | C5: 11 | D5: 11 | E5: 32 | F5: 18
A6: =_xlfn.XLOOKUP(B6,'CLUES JS1'!$C$44:$C$85,'CLUES JS1'!$B$44:$B$85,"NO EXISTE",0) -> QTSSA001974 | B6: SANTA MARÍA MAGDALENA | C6: 10 | D6: 7 | E6: 17 | F6: 23
A7: =_xlfn.XLOOKUP(B7,'CLUES JS1'!$C$44:$C$85,'CLUES JS1'!$B$44:$B$85,"NO EXISTE",0) -> QTSSA002015 | B7: TINAJA DE LA ESTANCIA | C7: 4 | D7: 3 | E7: 28 | F7: 32
A8: =_xlfn.XLOOKUP(B8,'CLUES JS1'!$C$44:$C$85,'CLUES JS1'!$B$44:$B$85,"NO EXISTE",0) -> QTSSA002020 | B8: TLACOTE EL BAJO | C8: 8 | D8: 9 | E8: 42 | F8: 18
A9: =_xlfn.XLOOKUP(B9,'CLUES JS1'!$C$44:$C$85,'CLUES JS1'!$B$44:$B$85,"NO EXISTE",0) -> QTSSA012982 | B9: LOMAS DE CASA BLANCA | C9: 52 | D9: 48 | E9: 6 | F9: 44

Sheet CARAVANAS
A1: CLUE | B1: UNIDAD DE SALUD | C1: JERINGA 23X25 CAJAS (50 PIEZAS) | D1: JERINGA 23X25 CAJAS (50 PIEZAS) | E1: JERINGA 23X25 PIEZAS | F1: JERINGA 22X32 PIEZAS | G1: FIRMA DE RECIBIDO
A2: QTSSA001764 | B2: UMME QUERÉTARO | C2: 0 | D2: 4 | E2: 0 | F2: 0
A3: =_xlfn.XLOOKUP(B3,'CLUES JS1'!$C$44:$C$85,'CLUES JS1'!$B$44:$B$85,"NO EXISTE",0) -> QTSSA003553 | B3: UMME CERRO DE LA CRUZ | C3: 5 | D3: 3 | E3: 44 | F3: 36
A4: =_xlfn.XLOOKUP(B4,'CLUES JS1'!$C$44:$C$85,'CLUES JS1'!$B$44:$B$85,"NO EXISTE",0) -> QTSSA003562 | B4: UMME LA LUZ | C4: 1 | D4: 2 | E4: 8 | F4: 42
A5: =_xlfn.XLOOKUP(B5,'CLUES JS1'!$C$44:$C$85,'CLUES JS1'!$B$44:$B$85,"NO EXISTE",0) -> QTSSA003595 | B5: UMME SAN PEDRITO | C5: 4 | D5: 3 | E5: 31 | F5: 29
A6: =_xlfn.XLOOKUP(B6,'CLUES JS1'!$C$44:$C$85,'CLUES JS1'!$B$44:$B$85,"NO EXISTE",0) -> QTSSA003604 | B6: UMME RANCHO LARGO | C6: 4 | D6: 3 | E6: 31 | F6: 29
A7: =_xlfn.XLOOKUP(B7,'CLUES JS1'!$C$44:$C$85,'CLUES JS1'!$B$44:$B$85,"NO EXISTE",0) -> QTSSA012276 | B7: FAM SAN JOSÉ BUENAVISTA | C7: 7 | D7: 5 | E7: 16 | F7: 34
A8: =_xlfn.XLOOKUP(B8,'CLUES JS1'!$C$44:$C$85,'CLUES JS1'!$B$44:$B$85,"NO EXISTE",0) -> QTSSA012281 | B8: FAM PEDRO ESCOBEDO | C8: 7 | D8: 5 | E8: 16 | F8: 34
A9: =_xlfn.XLOOKUP(B9,'CLUES JS1'!$C$44:$C$85,'CLUES JS1'!$B$44:$B$85,"NO EXISTE",0) -> QTSSA012544 | B9: FAM PALO ALTO | C9: 7 | D9: 5 | E9: 16 | F9: 34
A10: =_xlfn.XLOOKUP(B10,'CLUES JS1'!$C$44:$C$85,'CLUES JS1'!$B$44:$B$85,"NO EXISTE",0) -> QTSSA012556 | B10: UMME MF1 | C10: 5 | D10: 3 | E10: 38 | F10: 32
A11: =_xlfn.XLOOKUP(B11,'CLUES JS1'!$C$44:$C$85,'CLUES JS1'!$B$44:$B$85,"NO EXISTE",0) -> QTSSA012561 | B11: UMME AMBULANCIA 1 | C11: 4 | D11: 3 | E11: 41 | F11: 19
A12: =_xlfn.XLOOKUP(B12,'CLUES JS1'!$C$44:$C$85,'CLUES JS1'!$B$44:$B$85,"NO EXISTE",0) -> QTSSA012631 | B12: UMME MEDICO DENTAL | C12: 4 | D12: 3 | E12: 33 | F12: 27

Sheet CLUES JS1
A1: Sistema de Información en Salud
A2: Jurisdicción Sanitaria No1
A3: Estadística
E4: ABRIL 2024 | F4: HOJA 1 DE 2
A5: CLUES | C5: NOMBRE | D5: TIPO UNIDAD | E5: TIPOLOGIA
A7: CORREGIDORA | B7: QTSSA000830 | C7: SANTA BARBARA | D7: Unidad de Consulta Externa | E7: URBANO DE 05 NÚCLEOS BÁSICO | F7: H
B8: QTSSA000842 | C8: LOS ÁNGELES | D8: Unidad de Consulta Externa | E8: URBANO DE 01 NÚCLEOS BÁSICO | F8: D
B9: QTSSA000854 | C9: JOAQUIN HERRERA ( LA CUEVA ) | D9: Unidad de Consulta Externa | E9: RURAL DE 02 NÚCLEOS BÁSICOS | F9: B
B10: QTSSA000866 | C10: LOS OLVERA | D10: Unidad de Consulta Externa | E10: URBANO DE 02 NÚCLEOS BÁSICOS | F10: E
B11: QTSSA000883 | C11: SAN JOSÉ DE LOS OLVERA | D11: Unidad de Consulta Externa | E11: URBANO DE 02 NÚCLEOS BÁSICOS | F11: E
B12: QTSSA003640 | C12: PRESA DE BRAVO | D12: Unidad de Consulta Externa | E12: RURAL DE 02 NÚCLEOS BÁSICOS | F12: B
B13: QTSSA012252 | C13: LA NEGRETA | D13: Unidad de Consulta Externa | E13: URBANO DE 04 NÚCLEOS BÁSICOS | F13: G
B14: QTSSA012532 | C14: FAM CORREGIDORA | D14: Fortalecimiento a la atencion medica | E14: UNIDAD MÓVIL | F14: P
B15: QTSSA012602 | C15: EMILIANO ZAPATA | D15: Unidad de Consulta Externa | E15: URBANO DE 08 NÚCLEOS BÁSICOS | F15: K
B16: 9 | C16: C.S. 8 / FAM 1
A17: HUIMILPAN | B17: QTSSA000953 | C17: HUIMILPAN | D17: Unidad de Consulta Externa | E17: URBANO DE 08 NÚCLEOS BÁSICOS | F17: K
B18: QTSSA000970 | C18: APAPATARO | D18: Unidad de Consulta Externa | E18: RURAL DE 03 NÚCLEOS BÁSICOS Y MÁS | F18: C
B19: QTSSA000994 | C19: CEJA DE BRAVO | D19: Unidad de Consulta Externa | E19: RURAL DE 01 NÚCLEO BÁSICO | F19: A
B20: QTSSA001006 | C20: LOS CUES | D20: Unidad de Consulta Externa | E20: RURAL DE 01 NÚCLEO BÁSICO | F20: A
B21: QTSSA001011 | C21: LAGUNILLAS | D21: Unidad de Consulta Externa | E21: URBANO DE 03 NÚCLEOS BÁSICOS | F21: F
B22: QTSSA001023 | C22: EL MILAGRO | D22: Unidad de Consulta Externa | E22: RURAL DE 01 NÚCLEO BÁSICO | F22: A
B23: QTSSA001035 | C23: LA NORIA | D23: Unidad de Consulta Externa | E23: RURAL DE 01 NÚCLEO BÁSICO | F23: A
B24: QTSSA001040 | C24: SAN PEDRO HUIMILPAN | D24: Unidad de Consulta Externa | E24: RURAL DE 01 NÚCLEO BÁSICO | F24: A
B25: QTSSA003535 | C25: UMME EL VEGIL | D25: Unidad medica movil estatal | E25: UNIDAD MÓVIL | F25: P
B26: QTSSA003700 | C26: BUENAVISTA | D26: Unidad de Consulta Externa | E26: RURAL DE 02 NÚCLEOS BÁSICOS | F26: B
B27: QTSSA012573 | C27: UMME MEDICO FARMACIA 2 | D27: Unidad medica movil estatal | E27: UNIDAD MÓVIL | F27: P
B28: 11 | C28: C.S. 9 / UMME 2
A29: MARQUES | B29: QTSSA001315 | C29: LA CAÑADA | D29: Unidad de Consulta Externa | E29: RURAL DE 02 NÚCLEOS BÁSICOS | F29: B
B30: QTSSA001332 | C30: AMAZCALA | D30: Unidad de Consulta Externa | E30: URBANO DE 02 NÚCLEOS BÁSICOS | F30: E
B31: QTSSA001344 | C31: ATONGO | D31: Unidad de Consulta Externa | E31: URBANO DE 01 NÚCLEOS BÁSICO | F31: D
B32: QTSSA001356 | C32: SAN MIGUEL LÁZARO CÁRDENAS | D32: Unidad de Consulta Externa | E32: URBANO DE 02 NÚCLEOS BÁSICOS | F32: E
B33: QTSSA001390 | C33: LA GRIEGA | D33: Unidad de Consulta Externa | E33: URBANO DE 01 NÚCLEOS BÁSICOS | F33: D
B34: QTSSA001402 | C34: JESÚS MARÍA | D34: Unidad de Consulta Externa | E34: URBANO DE 02 NÚCLEOS BÁSICOS | F34: E
B35: QTSSA001426 | C35: PALO ALTO | D35: Unidad de Consulta Externa | E35: URBANO DE 01 NÚCLEOS BÁSICOS | F35: D
B36: QTSSA001431 | C36: EL PARAISO | D36: Unidad de Consulta Externa | E36: RURAL DE 01 NÚCLEO BÁSICO | F36: A
B37: QTSSA001933 | C37: SAN ISIDRO MIRANDA | D37: Unidad de Consulta Externa | E37: URBANO DE 01 NÚCLEOS BÁSICOS | F37: D
B38: QTSSA003571 | C38: CHICHIMEQUILLAS | D38: Unidad de Consulta Externa | E38: URBANO DE 05 NÚCLEOS BÁSICOS | F38: H
B39: QTSSA003580 | C39: NAVAJAS | D39: Unidad de Consulta Externa | E39: URBANA DE 02 NÚCLEOS BÁSICOS | F39: E
B40: QTSSA012264 | C40: FAM CHICHIMEQUILLAS | D40: Fortalecimiento a la atencion medica | E40: UNIDAD MÓVIL | F40: P
B41: QTSSA012643 | C41: ALFAJAYUCAN | D41: Unidad de Consulta Externa | E41: RURAL DE 02 NÚCLEOS BÁSICOS | F41: B
...
