Workbook

Sheet UMME QUERÉTARO
A1: SERVICIOS DE SALUD DEL ESTADO DE QUERÉTARO
A2: COORDINACION GENERAL
A3: SUBDIRECCION DE ADQUISICIONES
A5: SOLICITUD Y SURTIMIENTO DE LA CÁMARA DE FRÍO ESTATAL
A7: ORIGEN: | B7: JURISDICCIÓN SANITARIA N.1 | G7: AREA: | H7: VACUNAS
A8: DIRECCIÓN: | B8: Circuito Moises Solana S/N, Col. Vista Alegre, Santiago de Querétaro. Qro. | G8: FECHA DE ENVIO: | H8: =IF(GENERAL!H8=0," ",GENERAL!H8)
A9: DESTINO: | B9: UMME QUERÉTARO | G9: FOLIO ORACLE:
A10: DIRECCIÓN: | G10: MES A SURTIR: | H10: =GENERAL!H10 -> OCTUBRE
A12: NÚM | B12: CLAVE DE ARTÍCULO | C12: NOMBRE DEL ARTÍCULO | D12: PRESENTACIÓN | E12: FORMA | F12: CANTIDAD | K12: FIRMA DE RECEPCION
E13: FARMACÉUTICA | F13: SOLICITADO | G13: AUTORIZADO | H13: SURTIDO | I13: LOTE | J13: CADUCIDAD
A14: 25311.020-000-0146-03 | B14: 146 | C14: VACUNA ANTINEUMOCOCCICA 23 1DS | D14: UNIDOSIS | E14: Susp. Inyectable (Fco. Ampula) | G14: =IF(F14=0," ",F14) | H14: =IF(F14=0," ",F14) | M14: =SUM(F14+(F44*10)+(F32*10)+F22+F34+(F36*10)+F48) -> 0 | N14: JERINGA | O14: 2715 | P14: 22X32
M15: =SUM((F44/3)*20+F20) -> 0 | N15: JERINGA | O15: 2707 | P15: 23X25
A16: 25311.020-000-0148-01 | B16: 148 | C16: VACUNA ANTINEUMOCOCCICA 13 | D16: UNIDOSIS | E16: Susp. Inyectable (Jer. prellenada) | G16: =IF(F16=0," ",F16) | H16: =IF(F16=0," ",F16) | I16: =IF(GENERAL!I16=0," ",GENERAL!I16) | J16: =IF(GENERAL!J16=0," ",GENERAL!J16) | M16: =SUM(F24) -> 0 | N16: JERINGA | O16: 2699 | P16: 25X16
I17: =IF(GENERAL!I17=0," ",GENERAL!I17) | J17: =IF(GENERAL!J17=0," ",GENERAL!J17) | M17: =SUM(F26+F40) -> 0 | N17: JERINGA | O17: 2657 | P17: 27X13
A18: 25311.020-000-0150-05 | B18: 150 | C18: VACUNA ROTAVIRUS MONOVALENTE | D18: UNIDOSIS | E18: Susp. Inyectable (Jer. prellenada) | G18: =IF(F18=0," ",F18) | H18: =IF(F18=0," ",F18) | M18: =SUM(F28*10) -> 0 | N18: JERINGA | O18: 59 | P18: 30GX1/2
A20: 25311.020-000-6135-00 | B20: 6135 | C20: VACUNA HEXAVALENTE | D20: UNIDOSIS | E20: Susp. Inyectable (Fco. Ampula) | G20: =IF(F20=0," ",F20) | H20: =IF(F20=0," ",F20)
A22: 25311.020-000-2526-00 | B22: 2526 | C22: VACUNA HEPATITIS B MULTIDOSIS | D22: MULTIDOSIS | E22: Susp. Inyectable (Fco. Ampula) | G22: =IF(F22=0," ",F22) | H22: =IF(F22=0," ",F22)
A24: 25311.020-000-2527-00 | B24: 2527 | C24: VACUNA HEPATITIS B UNIDOSIS | D24: UNIDOSIS | E24: Susp. Inyectable (Fco. Ampula) | G24: =IF(F24=0," ",F24) | H24: =IF(F24=0," ",F24)
A26: 25311.020-000-3800-00 | B26: 3800 | C26: VACUNA DOBLE VIRAL (SR) | D26: MULTIDOSIS | E26: Fco. Amp Leofilizado+Diluy. | G26: =IF(F26=0," ",F26) | H26: =IF(F26=0," ",F26)
A28: 25311.020-000-3801-01 | B28: 3801 | C28: VACUNA BCG | D28: MULTIDOSIS | E28: Fco. Amp Leofilizado+Diluy. | G28: =IF(F28=0," ",F28) | H28: =IF(F28=0," ",F28)
A30: 25311.020-000-3802-00 | B30: 3802 | C30: VACUNA ANTIPOLIOMELITICA (SABIN) | D30: MULTIDOSIS | E30: Susp. (gotero de plastico) | G30: =IF(F30=0," ",F30) | H30: =IF(F30=0," ",F30)
A32: 25311.020-000-3805-00 | B32: 3805 | C32: VACUNA VACUNA DPT | D32: MULTIDOSIS | E32: Susp. Inyectable (Fco. Ampula) | G32: =IF(F32=0," ",F32) | H32: =IF(F32=0," ",F32)
I33: =IF(GENERAL!I33=0," ",GENERAL!I33) | J33: =IF(GENERAL!J33=0," ",GENERAL!J33)
A34: 25311.020-000-3808-02 | B34: 3808 | C34: VACUNA TDPA | D34: UNIDOSIS | E34: Susp. Inyectable (Fco. Ampula) | G34: =IF(F34=0," ",F34) | H34: =IF(F34=0," ",F34)
A36: 25311.020-000-3810-00 | B36: 3810 | C36: VACUNA TD | D36: MULTIDOSIS | E36: Susp. Inyectable (Fco. Ampula) | G36: =IF(F36=0," ",F36) | H36: =IF(F36=0," ",F36) | I36: =IF(GENERAL!I36=0," ",GENERAL!I36) | J36: =IF(GENERAL!J36=0," ",GENERAL!J36)
I37: =IF(GENERAL!I37=0," ",GENERAL!I37) | J37: =IF(GENERAL!J37=0," ",GENERAL!J37)
A38: 25311.020-000-6056-01 | B38: 6056 | C38: VACUNA ANTIVARICELA | D38: UNIDOSIS | E38: Fco. Amp Leofilizado+Diluy. | G38: =IF(F38=0," ",F38) | H38: =IF(F38=0," ",F38) | I38: =IF(GENERAL!I38=0," ",GENERAL!I38) | J38: =IF(GENERAL!J38=0," ",GENERAL!J38)
I39: =IF(GENERAL!I39=0," ",GENERAL!I39) | J39: =IF(GENERAL!J39=0," ",GENERAL!J39)
A40: 25311.020-000-3820-00 | B40: 3820 | C40: VACUNA TRIPLE VIRAL 1DS (SRP) | D40: UNIDOSIS | E40: Fco. Amp Leofilizado+Diluy. | G40: =IF(F40=0," ",F40) | H40: =IF(F40=0," ",F40)
A42: 25311.020-000-3821-00 | B42: 3821 | C42: VACUNATRIPLEVIRAL MULTI DOSIS | D42: MULTIDOSIS | E42: Fco. Amp Leofilizado+Diluy. | G42: =IF(F42=0," ",F42) | H42: =IF(F42=0," ",F42) | I42: =IF(GENERAL!I42=0," ",GENERAL!I42) | J42: =IF(GENERAL!J42=0," ",GENERAL!J42)
I43: =IF(GENERAL!I43=0," ",GENERAL!I43) | J43: =IF(GENERAL!J43=0," ",GENERAL!J43)
A44: 25311.020-000-3822-01 | B44: 3822 | C44: VACUNA ANTIINFLUENZA 10/D | D44: MULTIDOSIS | E44: Susp. Inyectable (Fco. Ampula) | G44: =IF(F44=0," ",F44) | H44: =IF(F44=0," ",F44) | I44: =IF(GENERAL!I44=0," ",GENERAL!I44) | J44: =IF(GENERAL!J44=0," ",GENERAL!J44)
I45: =IF(GENERAL!I45=0," ",GENERAL!I45) | J45: =IF(GENERAL!J45=0," ",GENERAL!J45)
A46: 25311.020-000-3832-00 | B46: 3832 | C46: VACUNA INMUNOGLOBULINA ANTITETANICA | D46: UNIDOSIS | E46: Susp. Inyectable (Fco. Ampula) | G46: =IF(F46=0," ",F46) | H46: =IF(F46=0," ",F46) | I46: =IF(GENERAL!I46=0," ",GENERAL!I46) | J46: =IF(GENERAL!J46=0," ",GENERAL!J46)
I47: =IF(GENERAL!I47=0," ",GENERAL!I47) | J47: =IF(GENERAL!J47=0," ",GENERAL!J47)
A48: 25311.020-000-6501-02 | B48: 6501 | C48: VACUNA VPH | D48: UNIDOSIS | E48: Susp. Inyectable (Fco. Ampula) | G48: =IF(F48=0," ",F48) | H48: =IF(F48=0," ",F48)
I49: =IF(GENERAL!I49=0," ",GENERAL!I49) | J49: =IF(GENERAL!J49=0," ",GENERAL!J49)
A50: 25331.020-X-0002-00-E | B50: 2 | C50: VACUNA ANTIAMARILICA | D50: UNIDOSIS | E50: Fco. Amp Leofilizado + Jer.prellenada. | G50: =IF(F50=0," ",F50) | H50: =IF(F50=0," ",F50) | I50: =IF(GENERAL!I50=0," ",GENERAL!I50) | J50: =IF(GENERAL!J50=0," ",GENERAL!J50)
I51: =IF(GENERAL!I51=0," ",GENERAL!I51) | J51: =IF(GENERAL!J51=0," ",GENERAL!J51)
A52: 25311.020-000-6502-00 | B52: 6502 | C52: VACUNA COVID-19 | D52: MULTIDOSIS | E52: Susp. Inyectable (Fco. Ampula) | G52: =IF(F52=0," ",F52) | H52: =IF(F52=0," ",F52) | I52: =IF(GENERAL!I52=0," ",GENERAL!I52) | J52: =IF(GENERAL!J52=0," ",GENERAL!J52)
...

Sheet JURICA
A1: SERVICIOS DE SALUD DEL ESTADO DE QUERÉTARO
A2: COORDINACION GENERAL
A3: SUBDIRECCION DE ADQUISICIONES
A5: SOLICITUD Y SURTIMIENTO DE LA CÁMARA DE FRÍO ESTATAL
A7: ORIGEN: | B7: JURISDICCIÓN SANITARIA N.1 | G7: AREA: | H7: VACUNAS
A8: DIRECCIÓN: | B8: Circuito Moises Solana S/N, Col. Vista Alegre, Santiago de Querétaro. Qro. | G8: FECHA DE ENVIO: | H8: =IF(GENERAL!H8=0," ",GENERAL!H8)
A9: DESTINO: | B9: C.S JURICA | G9: FOLIO ORACLE:
A10: DIRECCIÓN: | B10: Privada LiriosS/N, Pueblo de Jurica, Querétaro. | G10: MES A SURTIR: | H10: =GENERAL!H10 -> OCTUBRE
A12: NÚM | B12: CLAVE DE ARTÍCULO | C12: NOMBRE DEL ARTÍCULO | D12: PRESENTACIÓN | E12: FORMA | F12: CANTIDAD | K12: FIRMA DE RECEPCION
E13: FARMACÉUTICA | F13: SOLICITADO | G13: AUTORIZADO | H13: SURTIDO | I13: LOTE | J13: CADUCIDAD
A14: 25311.020-000-0146-03 | B14: 146 | C14: VACUNA ANTINEUMOCOCCICA 23 1DS | D14: UNIDOSIS | E14: Susp. Inyectable (Fco. Ampula) | G14: =IF(F14=0," ",F14) | H14: =IF(F14=0," ",F14) | I14: =IF(GENERAL!I14=0," ",GENERAL!I14) | J14: =IF(GENERAL!J14=0," ",GENERAL!J14) | M14: =SUM(F14+(F44*10)+(F32*10)+F22+F34+(F36*10)+F48) -> 0 | N14: JERINGA | O14: 2715 | P14: 22X32
M15: =SUM((F44/3)*20+F20) -> 0 | N15: JERINGA | O15: 2707 | P15: 23X25
A16: 25311.020-000-0148-01 | B16: 148 | C16: VACUNA ANTINEUMOCOCCICA 13 | D16: UNIDOSIS | E16: Susp. Inyectable (Jer. prellenada) | G16: =IF(F16=0," ",F16) | H16: =IF(F16=0," ",F16) | I16: =IF(GENERAL!I16=0," ",GENERAL!I16) | J16: =IF(GENERAL!J16=0," ",GENERAL!J16) | M16: =SUM(F24) -> 0 | N16: JERINGA | O16: 2699 | P16: 25X16
I17: =IF(GENERAL!I17=0," ",GENERAL!I17) | J17: =IF(GENERAL!J17=0," ",GENERAL!J17) | M17: =SUM(F26+F40) -> 0 | N17: JERINGA | O17: 2657 | P17: 27X13
A18: 25311.020-000-0150-05 | B18: 150 | C18: VACUNA ROTAVIRUS MONOVALENTE | D18: UNIDOSIS | E18: Susp. Inyectable (Jer. prellenada) | G18: =IF(F18=0," ",F18) | H18: =IF(F18=0," ",F18) | I18: =IF(GENERAL!I18=0," ",GENERAL!I18) | J18: =IF(GENERAL!J18=0," ",GENERAL!J18) | M18: =SUM(F28*10) -> 0 | N18: JERINGA | O18: 59 | P18: 30GX1/2
I19: =IF(GENERAL!I19=0," ",GENERAL!I19) | J19: =IF(GENERAL!J19=0," ",GENERAL!J19)
A20: 25311.020-000-6135-00 | B20: 6135 | C20: VACUNA HEXAVALENTE | D20: UNIDOSIS | E20: Susp. Inyectable (Fco. Ampula) | G20: =IF(F20=0," ",F20) | H20: =IF(F20=0," ",F20) | I20: =IF(GENERAL!I20=0," ",GENERAL!I20) | J20: =IF(GENERAL!J20=0," ",GENERAL!J20)
I21: =IF(GENERAL!I21=0," ",GENERAL!I21) | J21: =IF(GENERAL!J21=0," ",GENERAL!J21)
A22: 25311.020-000-2526-00 | B22: 2526 | C22: VACUNA HEPATITIS B MULTIDOSIS | D22: MULTIDOSIS | E22: Susp. Inyectable (Fco. Ampula) | G22: =IF(F22=0," ",F22) | H22: =IF(F22=0," ",F22) | I22: =IF(GENERAL!I22=0," ",GENERAL!I22) | J22: =IF(GENERAL!J22=0," ",GENERAL!J22)
I23: =IF(GENERAL!I23=0," ",GENERAL!I23) | J23: =IF(GENERAL!J23=0," ",GENERAL!J23)
A24: 25311.020-000-6187-00 | B24: 6187 | C24: VACUNA HEPATITIS A UNIDOSIS | D24: UNIDOSIS | E24: Susp. Inyectable (Fco. Ampula) | G24: =IF(F24=0," ",F24) | H24: =IF(F24=0," ",F24) | I24: =IF(GENERAL!I24=0," ",GENERAL!I24) | J24: =IF(GENERAL!J24=0," ",GENERAL!J24)
I25: =IF(GENERAL!I25=0," ",GENERAL!I25) | J25: =IF(GENERAL!J25=0," ",GENERAL!J25)
A26: 25311.020-000-3800-00 | B26: 3800 | C26: VACUNA DOBLE VIRAL (SR) | D26: MULTIDOSIS | E26: Fco. Amp Leofilizado+Diluy. | G26: =IF(F26=0," ",F26) | H26: =IF(F26=0," ",F26) | I26: =IF(GENERAL!I26=0," ",GENERAL!I26) | J26: =IF(GENERAL!J26=0," ",GENERAL!J26)
I27: =IF(GENERAL!I27=0," ",GENERAL!I27) | J27: =IF(GENERAL!J27=0," ",GENERAL!J27)
A28: 25311.020-000-3801-01 | B28: 3801 | C28: VACUNA BCG | D28: MULTIDOSIS | E28: Fco. Amp Leofilizado+Diluy. | G28: =IF(F28=0," ",F28) | H28: =IF(F28=0," ",F28) | I28: =IF(GENERAL!I28=0," ",GENERAL!I28) | J28: =IF(GENERAL!J28=0," ",GENERAL!J28)
I29: =IF(GENERAL!I29=0," ",GENERAL!I29) | J29: =IF(GENERAL!J29=0," ",GENERAL!J29)
A30: 25311.020-000-3802-00 | B30: 3802 | C30: VACUNA ANTIPOLIOMELITICA (SABIN) | D30: MULTIDOSIS | E30: Susp. (gotero de plastico) | G30: =IF(F30=0," ",F30) | H30: =IF(F30=0," ",F30) | I30: =IF(GENERAL!I30=0," ",GENERAL!I30) | J30: =IF(GENERAL!J30=0," ",GENERAL!J30)
I31: =IF(GENERAL!I31=0," ",GENERAL!I31) | J31: =IF(GENERAL!J31=0," ",GENERAL!J31)
A32: 25311.020-000-3805-00 | B32: 3805 | C32: VACUNA VACUNA DPT | D32: MULTIDOSIS | E32: Susp. Inyectable (Fco. Ampula) | G32: =IF(F32=0," ",F32) | H32: =IF(F32=0," ",F32) | I32: =IF(GENERAL!I32=0," ",GENERAL!I32) | J32: =IF(GENERAL!J32=0," ",GENERAL!J32)
A34: 25311.020-000-3808-02 | B34: 3808 | C34: VACUNA TDPA | D34: UNIDOSIS | E34: Susp. Inyectable (Fco. Ampula) | G34: =IF(F34=0," ",F34) | H34: =IF(F34=0," ",F34) | I34: =IF(GENERAL!I34=0," ",GENERAL!I34) | J34: =IF(GENERAL!J34=0," ",GENERAL!J34)
A36: 25311.020-000-3810-00 | B36: 3810 | C36: VACUNA TD | D36: MULTIDOSIS | E36: Susp. Inyectable (Fco. Ampula) | G36: =IF(F36=0," ",F36) | H36: =IF(F36=0," ",F36) | I36: =IF(GENERAL!I36=0," ",GENERAL!I36) | J36: =IF(GENERAL!J36=0," ",GENERAL!J36)
I37: =IF(GENERAL!I37=0," ",GENERAL!I37) | J37: =IF(GENERAL!J37=0," ",GENERAL!J37)
A38: 25311.020-000-6056-01 | B38: 6056 | C38: VACUNA ANTIVARICELA | D38: UNIDOSIS | E38: Fco. Amp Leofilizado+Diluy. | G38: =IF(F38=0," ",F38) | H38: =IF(F38=0," ",F38) | I38: =IF(GENERAL!I38=0," ",GENERAL!I38) | J38: =IF(GENERAL!J38=0," ",GENERAL!J38)
I39: =IF(GENERAL!I39=0," ",GENERAL!I39) | J39: =IF(GENERAL!J39=0," ",GENERAL!J39)
A40: 25311.020-000-3820-00 | B40: 3820 | C40: VACUNA TRIPLE VIRAL 1DS (SRP) | D40: UNIDOSIS | E40: Fco. Amp Leofilizado+Diluy. | G40: =IF(F40=0," ",F40) | H40: =IF(F40=0," ",F40) | I40: =IF(GENERAL!I40=0," ",GENERAL!I40) | J40: =IF(GENERAL!J40=0," ",GENERAL!J40)
I41: =IF(GENERAL!I41=0," ",GENERAL!I41) | J41: =IF(GENERAL!J41=0," ",GENERAL!J41)
A42: 25311.020-000-3821-00 | B42: 3821 | C42: VACUNATRIPLEVIRAL MULTI DOSIS | D42: MULTIDOSIS | E42: Fco. Amp Leofilizado+Diluy. | G42: =IF(F42=0," ",F42) | H42: =IF(F42=0," ",F42) | I42: =IF(GENERAL!I42=0," ",GENERAL!I42) | J42: =IF(GENERAL!J42=0," ",GENERAL!J42)
I43: =IF(GENERAL!I43=0," ",GENERAL!I43) | J43: =IF(GENERAL!J43=0," ",GENERAL!J43)
A44: 25311.020-000-6317-01 | B44: 6317 | C44: VACUNA ANTIINFLUENZA 10/D | D44: MULTIDOSIS | E44: Susp. Inyectable (Fco. Ampula) | G44: =IF(F44=0," ",F44) | H44: =IF(F44=0," ",F44) | I44: =IF(GENERAL!I44=0," ",GENERAL!I44) | J44: =IF(GENERAL!J44=0," ",GENERAL!J44)
I45: =IF(GENERAL!I45=0," ",GENERAL!I45) | J45: =IF(GENERAL!J45=0," ",GENERAL!J45)
...

Sheet MENCHACA
A1: SERVICIOS DE SALUD DEL ESTADO DE QUERÉTARO
A2: COORDINACION GENERAL
A3: SUBDIRECCION DE ADQUISICIONES
A5: SOLICITUD Y SURTIMIENTO DE LA CÁMARA DE FRÍO ESTATAL
A7: ORIGEN: | B7: JURISDICCIÓN SANITARIA N.1 | G7: AREA: | H7: VACUNAS
A8: DIRECCIÓN: | B8: Circuito Moises Solana S/N, Col. Vista Alegre, Santiago de Querétaro. Qro. | G8: FECHA DE ENVIO: | H8: =IF(GENERAL!H8=0," ",GENERAL!H8)
A9: DESTINO: | B9: C.S MENCHACA | G9: FOLIO ORACLE:
A10: DIRECCIÓN: | B10: Rio Lerma N.215, Menchaca, Querétaro. | G10: MES A SURTIR: | H10: =GENERAL!H10 -> OCTUBRE
A12: NÚM | B12: CLAVE DE ARTÍCULO | C12: NOMBRE DEL ARTÍCULO | D12: PRESENTACIÓN | E12: FORMA | F12: CANTIDAD | K12: FIRMA DE RECEPCION
E13: FARMACÉUTICA | F13: SOLICITADO | G13: AUTORIZADO | H13: SURTIDO | I13: LOTE | J13: CADUCIDAD
A14: 25311.020-000-0146-03 | B14: 146 | C14: VACUNA ANTINEUMOCOCCICA 23 1DS | D14: UNIDOSIS | E14: Susp. Inyectable (Fco. Ampula) | G14: =IF(F14=0," ",F14) | H14: =IF(F14=0," ",F14) | I14: =IF(GENERAL!I14=0," ",GENERAL!I14) | J14: =IF(GENERAL!J14=0," ",GENERAL!J14) | M14: =SUM(F14+(F44*10)+(F32*10)+F22+F34+(F36*10)+F48) -> 0 | N14: JERINGA | O14: 2715 | P14: 22X32
M15: =SUM((F44/3)*20+F20) -> 0 | N15: JERINGA | O15: 2707 | P15: 23X25
A16: 25311.020-000-0148-01 | B16: 148 | C16: VACUNA ANTINEUMOCOCCICA 13 | D16: UNIDOSIS | E16: Susp. Inyectable (Jer. prellenada) | G16: =IF(F16=0," ",F16) | H16: =IF(F16=0," ",F16) | I16: =IF(GENERAL!I16=0," ",GENERAL!I16) | J16: =IF(GENERAL!J16=0," ",GENERAL!J16) | M16: =SUM(F24) -> 0 | N16: JERINGA | O16: 2699 | P16: 25X16
I17: =IF(GENERAL!I17=0," ",GENERAL!I17) | J17: =IF(GENERAL!J17=0," ",GENERAL!J17) | M17: =SUM(F26+F40) -> 0 | N17: JERINGA | O17: 2657 | P17: 27X13
A18: 25311.020-000-0150-05 | B18: 150 | C18: VACUNA ROTAVIRUS MONOVALENTE | D18: UNIDOSIS | E18: Susp. Inyectable (Jer. prellenada) | G18: =IF(F18=0," ",F18) | H18: =IF(F18=0," ",F18) | I18: =IF(GENERAL!I18=0," ",GENERAL!I18) | J18: =IF(GENERAL!J18=0," ",GENERAL!J18) | M18: =SUM(F28*10) -> 0 | N18: JERINGA | O18: 59 | P18: 30GX1/2
A20: 25311.020-000-6135-00 | B20: 6135 | C20: VACUNA HEXAVALENTE | D20: UNIDOSIS | E20: Susp. Inyectable (Fco. Ampula) | G20: =IF(F20=0," ",F20) | H20: =IF(F20=0," ",F20) | I20: =IF(GENERAL!I20=0," ",GENERAL!I20) | J20: =IF(GENERAL!J20=0," ",GENERAL!J20)
I21: =IF(GENERAL!I21=0," ",GENERAL!I21) | J21: =IF(GENERAL!J21=0," ",GENERAL!J21)
A22: 25311.020-000-2526-00 | B22: 2526 | C22: VACUNA HEPATITIS B MULTIDOSIS | D22: MULTIDOSIS | E22: Susp. Inyectable (Fco. Ampula) | G22: =IF(F22=0," ",F22) | H22: =IF(F22=0," ",F22) | I22: =IF(GENERAL!I22=0," ",GENERAL!I22) | J22: =IF(GENERAL!J22=0," ",GENERAL!J22)
A24: 25311.020-000-6187-00 | B24: 6187 | C24: VACUNA HEPATITIS A UNIDOSIS | D24: UNIDOSIS | E24: Susp. Inyectable (Fco. Ampula) | G24: =IF(F24=0," ",F24) | H24: =IF(F24=0," ",F24) | I24: =IF(GENERAL!I24=0," ",GENERAL!I24) | J24: =IF(GENERAL!J24=0," ",GENERAL!J24)
A26: 25311.020-000-3800-00 | B26: 3800 | C26: VACUNA DOBLE VIRAL (SR) | D26: MULTIDOSIS | E26: Fco. Amp Leofilizado+Diluy. | G26: =IF(F26=0," ",F26) | H26: =IF(F26=0," ",F26) | I26: =IF(GENERAL!I26=0," ",GENERAL!I26) | J26: =IF(GENERAL!J26=0," ",GENERAL!J26)
A28: 25311.020-000-3801-01 | B28: 3801 | C28: VACUNA BCG | D28: MULTIDOSIS | E28: Fco. Amp Leofilizado+Diluy. | G28: =IF(F28=0," ",F28) | H28: =IF(F28=0," ",F28) | I28: =IF(GENERAL!I28=0," ",GENERAL!I28) | J28: =IF(GENERAL!J28=0," ",GENERAL!J28)
A30: 25311.020-000-3802-00 | B30: 3802 | C30: VACUNA ANTIPOLIOMELITICA (SABIN) | D30: MULTIDOSIS | E30: Susp. (gotero de plastico) | G30: =IF(F30=0," ",F30) | H30: =IF(F30=0," ",F30) | I30: =IF(GENERAL!I30=0," ",GENERAL!I30) | J30: =IF(GENERAL!J30=0," ",GENERAL!J30)
I31: =IF(GENERAL!I31=0," ",GENERAL!I31) | J31: =IF(GENERAL!J31=0," ",GENERAL!J31)
A32: 25311.020-000-3805-00 | B32: 3805 | C32: VACUNA VACUNA DPT | D32: MULTIDOSIS | E32: Susp. Inyectable (Fco. Ampula) | G32: =IF(F32=0," ",F32) | H32: =IF(F32=0," ",F32) | I32: =IF(GENERAL!I32=0," ",GENERAL!I32) | J32: =IF(GENERAL!J32=0," ",GENERAL!J32)
I33: =IF(GENERAL!I33=0," ",GENERAL!I33) | J33: =IF(GENERAL!J33=0," ",GENERAL!J33)
A34: 25311.020-000-3808-02 | B34: 3808 | C34: VACUNA TDPA | D34: UNIDOSIS | E34: Susp. Inyectable (Fco. Ampula) | G34: =IF(F34=0," ",F34) | H34: =IF(F34=0," ",F34) | I34: =IF(GENERAL!I34=0," ",GENERAL!I34) | J34: =IF(GENERAL!J34=0," ",GENERAL!J34)
A36: 25311.020-000-3810-00 | B36: 3810 | C36: VACUNA TD | D36: MULTIDOSIS | E36: Susp. Inyectable (Fco. Ampula) | G36: =IF(F36=0," ",F36) | H36: =IF(F36=0," ",F36) | I36: =IF(GENERAL!I36=0," ",GENERAL!I36) | J36: =IF(GENERAL!J36=0," ",GENERAL!J36)
I37: =IF(GENERAL!I37=0," ",GENERAL!I37) | J37: =IF(GENERAL!J37=0," ",GENERAL!J37)
A38: 25311.020-000-6056-01 | B38: 6056 | C38: VACUNA ANTIVARICELA | D38: UNIDOSIS | E38: Fco. Amp Leofilizado+Diluy. | G38: =IF(F38=0," ",F38) | H38: =IF(F38=0," ",F38) | I38: =IF(GENERAL!I38=0," ",GENERAL!I38) | J38: =IF(GENERAL!J38=0," ",GENERAL!J38)
A40: 25311.020-000-3820-00 | B40: 3820 | C40: VACUNA TRIPLE VIRAL 1DS (SRP) | D40: UNIDOSIS | E40: Fco. Amp Leofilizado+Diluy. | G40: =IF(F40=0," ",F40) | H40: =IF(F40=0," ",F40) | I40: =IF(GENERAL!I40=0," ",GENERAL!I40) | J40: =IF(GENERAL!J40=0," ",GENERAL!J40)
A42: 25311.020-000-3821-00 | B42: 3821 | C42: VACUNATRIPLEVIRAL MULTI DOSIS | D42: MULTIDOSIS | E42: Fco. Amp Leofilizado+Diluy. | G42: =IF(F42=0," ",F42) | H42: =IF(F42=0," ",F42) | I42: =IF(GENERAL!I42=0," ",GENERAL!I42) | J42: =IF(GENERAL!J42=0," ",GENERAL!J42)
I43: =IF(GENERAL!I43=0," ",GENERAL!I43) | J43: =IF(GENERAL!J43=0," ",GENERAL!J43)
A44: 25311.020-000-6317-01 | B44: 6317 | C44: VACUNA ANTIINFLUENZA 10/D | D44: MULTIDOSIS | E44: Susp. Inyectable (Fco. Ampula) | G44: =IF(F44=0," ",F44) | H44: =IF(F44=0," ",F44) | I44: =IF(GENERAL!I44=0," ",GENERAL!I44) | J44: =IF(GENERAL!J44=0," ",GENERAL!J44)
I45: =IF(GENERAL!I45=0," ",GENERAL!I45) | J45: =IF(GENERAL!J45=0," ",GENERAL!J45)
A46: 25311.020-000-3832-00 | B46: 3832 | C46: VACUNA INMUNOGLOBULINA ANTITETANICA | D46: UNIDOSIS | E46: Susp. Inyectable (Fco. Ampula) | G46: =IF(F46=0," ",F46) | H46: =IF(F46=0," ",F46) | I46: =IF(GENERAL!I46=0," ",GENERAL!I46) | J46: =IF(GENERAL!J46=0," ",GENERAL!J46)
A48: 25311.020-000-6501-02 | B48: 6501 | C48: VACUNA VPH | D48: UNIDOSIS | E48: Susp. Inyectable (Fco. Ampula) | G48: =IF(F48=0," ",F48) | H48: =IF(F48=0," ",F48) | I48: =IF(GENERAL!I48=0," ",GENERAL!I48) | J48: =IF(GENERAL!J48=0," ",GENERAL!J48)
A50: 25331.020-X-0002-00-E | B50: 2 | C50: VACUNA ANTIAMARILICA | D50: UNIDOSIS | E50: Fco. Amp Leofilizado + Jer.prellenada. | G50: =IF(F50=0," ",F50) | H50: =IF(F50=0," ",F50) | I50: =IF(GENERAL!I50=0," ",GENERAL!I50) | J50: =IF(GENERAL!J50=0," ",GENERAL!J50)
I51: =IF(GENERAL!I51=0," ",GENERAL!I51) | J51: =IF(GENERAL!J51=0," ",GENERAL!J51)
A52: 25311.020-000-6509-01 | B52: 6509 | C52: VACUNA VRS | D52: UNIDOSIS | E52: Susp. Inyectable (Fco. Ampula) | G52: =IF(F52=0," ",F52) | H52: =IF(F52=0," ",F52) | I52: =IF(GENERAL!I52=0," ",GENERAL!I52) | J52: =IF(GENERAL!J52=0," ",GENERAL!J52)
B54: CONDICIONES DE TRANSPORTE Y ALMACENAMIENTO: MANTENGASE EN TODO MOMENTO A TEMPERATURA ENTRE 2°C - 8 °C
...

Sheet SAN ANTONIO DE LA PUNTA
A1: SERVICIOS DE SALUD DEL ESTADO DE QUERÉTARO
A2: COORDINACION GENERAL
A3: SUBDIRECCION DE ADQUISICIONES
A5: SOLICITUD Y SURTIMIENTO DE LA CÁMARA DE FRÍO ESTATAL
A7: ORIGEN: | B7: JURISDICCIÓN SANITARIA N.1 | G7: AREA: | H7: VACUNAS
A8: DIRECCIÓN: | B8: Circuito Moises Solana S/N, Col. Vista Alegre, Santiago de Querétaro. Qro. | G8: FECHA DE ENVIO: | H8: =IF(GENERAL!H8=0," ",GENERAL!H8)
A9: DESTINO: | B9: C.S SAN ANTONIO DE LA PUNTA | G9: FOLIO ORACLE:
A10: DIRECCIÓN: | B10: Hacienda La Gloria N.103, Las Tereas, San Antonio de la Punta, Querétaro. | G10: MES A SURTIR: | H10: =GENERAL!H10 -> OCTUBRE
A12: NÚM | B12: CLAVE DE ARTÍCULO | C12: NOMBRE DEL ARTÍCULO | D12: PRESENTACIÓN | E12: FORMA | F12: CANTIDAD | K12: FIRMA DE RECEPCION
E13: FARMACÉUTICA | F13: SOLICITADO | G13: AUTORIZADO | H13: SURTIDO | I13: LOTE | J13: CADUCIDAD
A14: 25311.020-000-0146-03 | B14: 146 | C14: VACUNA ANTINEUMOCOCCICA 23 1DS | D14: UNIDOSIS | E14: Susp. Inyectable (Fco. Ampula) | G14: =IF(F14=0," ",F14) | H14: =IF(F14=0," ",F14) | I14: =IF(GENERAL!I14=0," ",GENERAL!I14) | J14: =IF(GENERAL!J14=0," ",GENERAL!J14) | M14: =SUM(F14+(F44*10)+(F32*10)+F22+F34+(F36*10)+F48) -> 0 | N14: JERINGA | O14: 2715 | P14: 22X32
M15: =SUM((F44/3)*20+F20) -> 0 | N15: JERINGA | O15: 2707 | P15: 23X25
A16: 25311.020-000-0148-01 | B16: 148 | C16: VACUNA ANTINEUMOCOCCICA 13 | D16: UNIDOSIS | E16: Susp. Inyectable (Jer. prellenada) | G16: =IF(F16=0," ",F16) | H16: =IF(F16=0," ",F16) | I16: =IF(GENERAL!I16=0," ",GENERAL!I16) | J16: =IF(GENERAL!J16=0," ",GENERAL!J16) | M16: =SUM(F24) -> 0 | N16: JERINGA | O16: 2699 | P16: 25X16
I17: =IF(GENERAL!I17=0," ",GENERAL!I17) | J17: =IF(GENERAL!J17=0," ",GENERAL!J17) | M17: =SUM(F26+F40) -> 0 | N17: JERINGA | O17: 2657 | P17: 27X13
A18: 25311.020-000-0150-05 | B18: 150 | C18: VACUNA ROTAVIRUS MONOVALENTE | D18: UNIDOSIS | E18: Susp. Inyectable (Jer. prellenada) | G18: =IF(F18=0," ",F18) | H18: =IF(F18=0," ",F18) | I18: =IF(GENERAL!I18=0," ",GENERAL!I18) | J18: =IF(GENERAL!J18=0," ",GENERAL!J18) | M18: =SUM(F28*10) -> 0 | N18: JERINGA | O18: 59 | P18: 30GX1/2
I19: =IF(GENERAL!I19=0," ",GENERAL!I19) | J19: =IF(GENERAL!J19=0," ",GENERAL!J19)
A20: 25311.020-000-6135-00 | B20: 6135 | C20: VACUNA HEXAVALENTE | D20: UNIDOSIS | E20: Susp. Inyectable (Fco. Ampula) | G20: =IF(F20=0," ",F20) | H20: =IF(F20=0," ",F20) | I20: =IF(GENERAL!I20=0," ",GENERAL!I20) | J20: =IF(GENERAL!J20=0," ",GENERAL!J20)
I21: =IF(GENERAL!I21=0," ",GENERAL!I21) | J21: =IF(GENERAL!J21=0," ",GENERAL!J21)
A22: 25311.020-000-2526-00 | B22: 2526 | C22: VACUNA HEPATITIS B MULTIDOSIS | D22: MULTIDOSIS | E22: Susp. Inyectable (Fco. Ampula) | G22: =IF(F22=0," ",F22) | H22: =IF(F22=0," ",F22) | I22: =IF(GENERAL!I22=0," ",GENERAL!I22) | J22: =IF(GENERAL!J22=0," ",GENERAL!J22)
A24: 25311.020-000-6187-00 | B24: 6187 | C24: VACUNA HEPATITIS A UNIDOSIS | D24: UNIDOSIS | E24: Susp. Inyectable (Fco. Ampula) | G24: =IF(F24=0," ",F24) | H24: =IF(F24=0," ",F24) | I24: =IF(GENERAL!I24=0," ",GENERAL!I24) | J24: =IF(GENERAL!J24=0," ",GENERAL!J24)
A26: 25311.020-000-3800-00 | B26: 3800 | C26: VACUNA DOBLE VIRAL (SR) | D26: MULTIDOSIS | E26: Fco. Amp Leofilizado+Diluy. | G26: =IF(F26=0," ",F26) | H26: =IF(F26=0," ",F26) | I26: =IF(GENERAL!I26=0," ",GENERAL!I26) | J26: =IF(GENERAL!J26=0," ",GENERAL!J26)
A28: 25311.020-000-3801-01 | B28: 3801 | C28: VACUNA BCG | D28: MULTIDOSIS | E28: Fco. Amp Leofilizado+Diluy. | G28: =IF(F28=0," ",F28) | H28: =IF(F28=0," ",F28) | I28: =IF(GENERAL!I28=0," ",GENERAL!I28) | J28: =IF(GENERAL!J28=0," ",GENERAL!J28)
A30: 25311.020-000-3802-00 | B30: 3802 | C30: VACUNA ANTIPOLIOMELITICA (SABIN) | D30: MULTIDOSIS | E30: Susp. (gotero de plastico) | G30: =IF(F30=0," ",F30) | H30: =IF(F30=0," ",F30) | I30: =IF(GENERAL!I30=0," ",GENERAL!I30) | J30: =IF(GENERAL!J30=0," ",GENERAL!J30)
I31: =IF(GENERAL!I31=0," ",GENERAL!I31) | J31: =IF(GENERAL!J31=0," ",GENERAL!J31)
A32: 25311.020-000-3805-00 | B32: 3805 | C32: VACUNA VACUNA DPT | D32: MULTIDOSIS | E32: Susp. Inyectable (Fco. Ampula) | G32: =IF(F32=0," ",F32) | H32: =IF(F32=0," ",F32) | I32: =IF(GENERAL!I32=0," ",GENERAL!I32) | J32: =IF(GENERAL!J32=0," ",GENERAL!J32)
I33: =IF(GENERAL!I33=0," ",GENERAL!I33) | J33: =IF(GENERAL!J33=0," ",GENERAL!J33)
A34: 25311.020-000-3808-02 | B34: 3808 | C34: VACUNA TDPA | D34: UNIDOSIS | E34: Susp. Inyectable (Fco. Ampula) | G34: =IF(F34=0," ",F34) | H34: =IF(F34=0," ",F34) | I34: =IF(GENERAL!I34=0," ",GENERAL!I34) | J34: =IF(GENERAL!J34=0," ",GENERAL!J34)
I35: =IF(GENERAL!I35=0," ",GENERAL!I35) | J35: =IF(GENERAL!J35=0," ",GENERAL!J35)
A36: 25311.020-000-3810-00 | B36: 3810 | C36: VACUNA TD | D36: MULTIDOSIS | E36: Susp. Inyectable (Fco. Ampula) | G36: =IF(F36=0," ",F36) | H36: =IF(F36=0," ",F36) | I36: =IF(GENERAL!I36=0," ",GENERAL!I36) | J36: =IF(GENERAL!J36=0," ",GENERAL!J36)
I37: =IF(GENERAL!I37=0," ",GENERAL!I37) | J37: =IF(GENERAL!J37=0," ",GENERAL!J37)
A38: 25311.020-000-6056-01 | B38: 6056 | C38: VACUNA ANTIVARICELA | D38: UNIDOSIS | E38: Fco. Amp Leofilizado+Diluy. | G38: =IF(F38=0," ",F38) | H38: =IF(F38=0," ",F38) | I38: =IF(GENERAL!I38=0," ",GENERAL!I38) | J38: =IF(GENERAL!J38=0," ",GENERAL!J38)
A40: 25311.020-000-3820-00 | B40: 3820 | C40: VACUNA TRIPLE VIRAL 1DS (SRP) | D40: UNIDOSIS | E40: Fco. Amp Leofilizado+Diluy. | G40: =IF(F40=0," ",F40) | H40: =IF(F40=0," ",F40) | I40: =IF(GENERAL!I40=0," ",GENERAL!I40) | J40: =IF(GENERAL!J40=0," ",GENERAL!J40)
A42: 25311.020-000-3821-00 | B42: 3821 | C42: VACUNATRIPLEVIRAL MULTI DOSIS | D42: MULTIDOSIS | E42: Fco. Amp Leofilizado+Diluy. | G42: =IF(F42=0," ",F42) | H42: =IF(F42=0," ",F42) | I42: =IF(GENERAL!I42=0," ",GENERAL!I42) | J42: =IF(GENERAL!J42=0," ",GENERAL!J42)
I43: =IF(GENERAL!I43=0," ",GENERAL!I43) | J43: =IF(GENERAL!J43=0," ",GENERAL!J43)
A44: 25311.020-000-6317-01 | B44: 6317 | C44: VACUNA ANTIINFLUENZA 10/D | D44: MULTIDOSIS | E44: Susp. Inyectable (Fco. Ampula) | G44: =IF(F44=0," ",F44) | H44: =IF(F44=0," ",F44) | I44: =IF(GENERAL!I44=0," ",GENERAL!I44) | J44: =IF(GENERAL!J44=0," ",GENERAL!J44)
I45: =IF(GENERAL!I45=0," ",GENERAL!I45) | J45: =IF(GENERAL!J45=0," ",GENERAL!J45)
A46: 25311.020-000-3832-00 | B46: 3832 | C46: VACUNA INMUNOGLOBULINA ANTITETANICA | D46: UNIDOSIS | E46: Susp. Inyectable (Fco. Ampula) | G46: =IF(F46=0," ",F46) | H46: =IF(F46=0," ",F46) | I46: =IF(GENERAL!I46=0," ",GENERAL!I46) | J46: =IF(GENERAL!J46=0," ",GENERAL!J46)
A48: 25311.020-000-6501-02 | B48: 6501 | C48: VACUNA VPH | D48: UNIDOSIS | E48: Susp. Inyectable (Fco. Ampula) | G48: =IF(F48=0," ",F48) | H48: =IF(F48=0," ",F48) | I48: =IF(GENERAL!I48=0," ",GENERAL!I48) | J48: =IF(GENERAL!J48=0," ",GENERAL!J48)
A50: 25331.020-X-0002-00-E | B50: 2 | C50: VACUNA ANTIAMARILICA | D50: UNIDOSIS | E50: Fco. Amp Leofilizado + Jer.prellenada. | G50: =IF(F50=0," ",F50) | H50: =IF(F50=0," ",F50) | I50: =IF(GENERAL!I50=0," ",GENERAL!I50) | J50: =IF(GENERAL!J50=0," ",GENERAL!J50)
I51: =IF(GENERAL!I51=0," ",GENERAL!I51) | J51: =IF(GENERAL!J51=0," ",GENERAL!J51)
...

Sheet SAN PABLO
A1: SERVICIOS DE SALUD DEL ESTADO DE QUERÉTARO
A2: COORDINACION GENERAL
A3: SUBDIRECCION DE ADQUISICIONES
A5: SOLICITUD Y SURTIMIENTO DE LA CÁMARA DE FRÍO ESTATAL
A7: ORIGEN: | B7: JURISDICCIÓN SANITARIA N.1 | G7: AREA: | H7: VACUNAS
A8: DIRECCIÓN: | B8: Circuito Moises Solana S/N, Col. Vista Alegre, Santiago de Querétaro. Qro. | G8: FECHA DE ENVIO: | H8: =IF(GENERAL!H8=0," ",GENERAL!H8)
A9: DESTINO: | B9: C.S SAN PABLO | G9: FOLIO ORACLE:
A10: DIRECCIÓN: | B10: Camino Real N.21, San Pablo, Querétaro. | G10: MES A SURTIR: | H10: =GENERAL!H10 -> OCTUBRE
A12: NÚM | B12: CLAVE DE ARTÍCULO | C12: NOMBRE DEL ARTÍCULO | D12: PRESENTACIÓN | E12: FORMA | F12: CANTIDAD | K12: FIRMA DE RECEPCION
E13: FARMACÉUTICA | F13: SOLICITADO | G13: AUTORIZADO | H13: SURTIDO | I13: LOTE | J13: CADUCIDAD
A14: 25311.020-000-0146-03 | B14: 146 | C14: VACUNA ANTINEUMOCOCCICA 23 1DS | D14: UNIDOSIS | E14: Susp. Inyectable (Fco. Ampula) | G14: =IF(F14=0," ",F14) | H14: =IF(F14=0," ",F14) | I14: =IF(GENERAL!I14=0," ",GENERAL!I14) | J14: =IF(GENERAL!J14=0," ",GENERAL!J14) | M14: =SUM(F14+(F44*10)+(F32*10)+F22+F34+(F36*10)+F48) -> 0 | N14: JERINGA | O14: 2715 | P14: 22X32
M15: =SUM((F44/3)*20+F20) -> 0 | N15: JERINGA | O15: 2707 | P15: 23X25
A16: 25311.020-000-0148-01 | B16: 148 | C16: VACUNA ANTINEUMOCOCCICA 13 | D16: UNIDOSIS | E16: Susp. Inyectable (Jer. prellenada) | G16: =IF(F16=0," ",F16) | H16: =IF(F16=0," ",F16) | I16: =IF(GENERAL!I16=0," ",GENERAL!I16) | J16: =IF(GENERAL!J16=0," ",GENERAL!J16) | M16: =SUM(F24) -> 0 | N16: JERINGA | O16: 2699 | P16: 25X16
I17: =IF(GENERAL!I17=0," ",GENERAL!I17) | J17: =IF(GENERAL!J17=0," ",GENERAL!J17) | M17: =SUM(F26+F40) -> 0 | N17: JERINGA | O17: 2657 | P17: 27X13
A18: 25311.020-000-0150-05 | B18: 150 | C18: VACUNA ROTAVIRUS MONOVALENTE | D18: UNIDOSIS | E18: Susp. Inyectable (Jer. prellenada) | G18: =IF(F18=0," ",F18) | H18: =IF(F18=0," ",F18) | I18: =IF(GENERAL!I18=0," ",GENERAL!I18) | J18: =IF(GENERAL!J18=0," ",GENERAL!J18) | M18: =SUM(F28*10) -> 0 | N18: JERINGA | O18: 59 | P18: 30GX1/2
I19: =IF(GENERAL!I19=0," ",GENERAL!I19) | J19: =IF(GENERAL!J19=0," ",GENERAL!J19)
A20: 25311.020-000-6135-00 | B20: 6135 | C20: VACUNA HEXAVALENTE | D20: UNIDOSIS | E20: Susp. Inyectable (Fco. Ampula) | G20: =IF(F20=0," ",F20) | H20: =IF(F20=0," ",F20) | I20: =IF(GENERAL!I20=0," ",GENERAL!I20) | J20: =IF(GENERAL!J20=0," ",GENERAL!J20)
I21: =IF(GENERAL!I21=0," ",GENERAL!I21) | J21: =IF(GENERAL!J21=0," ",GENERAL!J21)
A22: 25311.020-000-2526-00 | B22: 2526 | C22: VACUNA HEPATITIS B MULTIDOSIS | D22: MULTIDOSIS | E22: Susp. Inyectable (Fco. Ampula) | G22: =IF(F22=0," ",F22) | H22: =IF(F22=0," ",F22) | I22: =IF(GENERAL!I22=0," ",GENERAL!I22) | J22: =IF(GENERAL!J22=0," ",GENERAL!J22)
A24: 25311.020-000-6187-00 | B24: 6187 | C24: VACUNA HEPATITIS A UNIDOSIS | D24: UNIDOSIS | E24: Susp. Inyectable (Fco. Ampula) | G24: =IF(F24=0," ",F24) | H24: =IF(F24=0," ",F24) | I24: =IF(GENERAL!I24=0," ",GENERAL!I24) | J24: =IF(GENERAL!J24=0," ",GENERAL!J24)
I25: =IF(GENERAL!I25=0," ",GENERAL!I25) | J25: =IF(GENERAL!J25=0," ",GENERAL!J25)
A26: 25311.020-000-3800-00 | B26: 3800 | C26: VACUNA DOBLE VIRAL (SR) | D26: MULTIDOSIS | E26: Fco. Amp Leofilizado+Diluy. | G26: =IF(F26=0," ",F26) | H26: =IF(F26=0," ",F26) | I26: =IF(GENERAL!I26=0," ",GENERAL!I26) | J26: =IF(GENERAL!J26=0," ",GENERAL!J26)
A28: 25311.020-000-3801-01 | B28: 3801 | C28: VACUNA BCG | D28: MULTIDOSIS | E28: Fco. Amp Leofilizado+Diluy. | G28: =IF(F28=0," ",F28) | H28: =IF(F28=0," ",F28) | I28: =IF(GENERAL!I28=0," ",GENERAL!I28) | J28: =IF(GENERAL!J28=0," ",GENERAL!J28)
I29: =IF(GENERAL!I29=0," ",GENERAL!I29) | J29: =IF(GENERAL!J29=0," ",GENERAL!J29)
A30: 25311.020-000-3802-00 | B30: 3802 | C30: VACUNA ANTIPOLIOMELITICA (SABIN) | D30: MULTIDOSIS | E30: Susp. (gotero de plastico) | G30: =IF(F30=0," ",F30) | H30: =IF(F30=0," ",F30) | I30: =IF(GENERAL!I30=0," ",GENERAL!I30) | J30: =IF(GENERAL!J30=0," ",GENERAL!J30)
A32: 25311.020-000-3805-00 | B32: 3805 | C32: VACUNA VACUNA DPT | D32: MULTIDOSIS | E32: Susp. Inyectable (Fco. Ampula) | G32: =IF(F32=0," ",F32) | H32: =IF(F32=0," ",F32) | I32: =IF(GENERAL!I32=0," ",GENERAL!I32) | J32: =IF(GENERAL!J32=0," ",GENERAL!J32)
A34: 25311.020-000-3808-02 | B34: 3808 | C34: VACUNA TDPA | D34: UNIDOSIS | E34: Susp. Inyectable (Fco. Ampula) | G34: =IF(F34=0," ",F34) | H34: =IF(F34=0," ",F34) | I34: =IF(GENERAL!I34=0," ",GENERAL!I34) | J34: =IF(GENERAL!J34=0," ",GENERAL!J34)
A36: 25311.020-000-3810-00 | B36: 3810 | C36: VACUNA TD | D36: MULTIDOSIS | E36: Susp. Inyectable (Fco. Ampula) | G36: =IF(F36=0," ",F36) | H36: =IF(F36=0," ",F36) | I36: =IF(GENERAL!I36=0," ",GENERAL!I36) | J36: =IF(GENERAL!J36=0," ",GENERAL!J36)
A38: 25311.020-000-6056-01 | B38: 6056 | C38: VACUNA ANTIVARICELA | D38: UNIDOSIS | E38: Fco. Amp Leofilizado+Diluy. | G38: =IF(F38=0," ",F38) | H38: =IF(F38=0," ",F38) | I38: =IF(GENERAL!I38=0," ",GENERAL!I38) | J38: =IF(GENERAL!J38=0," ",GENERAL!J38)
I39: =IF(GENERAL!I39=0," ",GENERAL!I39) | J39: =IF(GENERAL!J39=0," ",GENERAL!J39)
A40: 25311.020-000-3820-00 | B40: 3820 | C40: VACUNA TRIPLE VIRAL 1DS (SRP) | D40: UNIDOSIS | E40: Fco. Amp Leofilizado+Diluy. | G40: =IF(F40=0," ",F40) | H40: =IF(F40=0," ",F40) | I40: =IF(GENERAL!I40=0," ",GENERAL!I40) | J40: =IF(GENERAL!J40=0," ",GENERAL!J40)
I41: =IF(GENERAL!I41=0," ",GENERAL!I41) | J41: =IF(GENERAL!J41=0," ",GENERAL!J41)
A42: 25311.020-000-3821-00 | B42: 3821 | C42: VACUNATRIPLEVIRAL MULTI DOSIS | D42: MULTIDOSIS | E42: Fco. Amp Leofilizado+Diluy. | G42: =IF(F42=0," ",F42) | H42: =IF(F42=0," ",F42) | I42: =IF(GENERAL!I42=0," ",GENERAL!I42) | J42: =IF(GENERAL!J42=0," ",GENERAL!J42)
I43: =IF(GENERAL!I43=0," ",GENERAL!I43) | J43: =IF(GENERAL!J43=0," ",GENERAL!J43)
A44: 25311.020-000-6317-01 | B44: 6317 | C44: VACUNA ANTIINFLUENZA 10/D | D44: MULTIDOSIS | E44: Susp. Inyectable (Fco. Ampula) | G44: =IF(F44=0," ",F44) | H44: =IF(F44=0," ",F44) | I44: =IF(GENERAL!I44=0," ",GENERAL!I44) | J44: =IF(GENERAL!J44=0," ",GENERAL!J44)
I45: =IF(GENERAL!I45=0," ",GENERAL!I45) | J45: =IF(GENERAL!J45=0," ",GENERAL!J45)
A46: 25311.020-000-3832-00 | B46: 3832 | C46: VACUNA INMUNOGLOBULINA ANTITETANICA | D46: UNIDOSIS | E46: Susp. Inyectable (Fco. Ampula) | G46: =IF(F46=0," ",F46) | H46: =IF(F46=0," ",F46) | I46: =IF(GENERAL!I46=0," ",GENERAL!I46) | J46: =IF(GENERAL!J46=0," ",GENERAL!J46)
A48: 25311.020-000-6501-02 | B48: 6501 | C48: VACUNA VPH | D48: UNIDOSIS | E48: Susp. Inyectable (Fco. Ampula) | G48: =IF(F48=0," ",F48) | H48: =IF(F48=0," ",F48) | I48: =IF(GENERAL!I48=0," ",GENERAL!I48) | J48: =IF(GENERAL!J48=0," ",GENERAL!J48)
A50: 25331.020-X-0002-00-E | B50: 2 | C50: VACUNA ANTIAMARILICA | D50: UNIDOSIS | E50: Fco. Amp Leofilizado + Jer.prellenada. | G50: =IF(F50=0," ",F50) | H50: =IF(F50=0," ",F50) | I50: =IF(GENERAL!I50=0," ",GENERAL!I50) | J50: =IF(GENERAL!J50=0," ",GENERAL!J50)
I51: =IF(GENERAL!I51=0," ",GENERAL!I51) | J51: =IF(GENERAL!J51=0," ",GENERAL!J51)
...

Sheet CARRILLO
A1: SERVICIOS DE SALUD DEL ESTADO DE QUERÉTARO
A2: COORDINACION GENERAL
A3: SUBDIRECCION DE ADQUISICIONES
A5: SOLICITUD Y SURTIMIENTO DE LA CÁMARA DE FRÍO ESTATAL
A7: ORIGEN: | B7: JURISDICCIÓN SANITARIA N.1 | G7: AREA: | H7: VACUNAS
A8: DIRECCIÓN: | B8: Circuito Moises Solana S/N, Col. Vista Alegre, Santiago de Querétaro. Qro. | G8: FECHA DE ENVIO: | H8: =IF(GENERAL!H8=0," ",GENERAL!H8)
A9: DESTINO: | B9: C.S FELIPE CARRILLO PUERTO | G9: FOLIO ORACLE:
A10: DIRECCIÓN: | B10: Plata S/N, El Progreso, Carrillo Puerto | G10: MES A SURTIR: | H10: =GENERAL!H10 -> OCTUBRE
A12: NÚM | B12: CLAVE DE ARTÍCULO | C12: NOMBRE DEL ARTÍCULO | D12: PRESENTACIÓN | E12: FORMA | F12: CANTIDAD | K12: FIRMA DE RECEPCION
E13: FARMACÉUTICA | F13: SOLICITADO | G13: AUTORIZADO | H13: SURTIDO | I13: LOTE | J13: CADUCIDAD
A14: 25311.020-000-0146-03 | B14: 146 | C14: VACUNA ANTINEUMOCOCCICA 23 1DS | D14: UNIDOSIS | E14: Susp. Inyectable (Fco. Ampula) | G14: =IF(F14=0," ",F14) | H14: =IF(F14=0," ",F14) | I14: =IF(GENERAL!I14=0," ",GENERAL!I14) | J14: =IF(GENERAL!J14=0," ",GENERAL!J14) | M14: =SUM(F14+(F44*10)+(F32*10)+F22+F34+(F36*10)+F48) -> 0 | N14: JERINGA | O14: 2715 | P14: 22X32
M15: =SUM((F44/3)*20+F20) -> 0 | N15: JERINGA | O15: 2707 | P15: 23X25
A16: 25311.020-000-0148-01 | B16: 148 | C16: VACUNA ANTINEUMOCOCCICA 13 | D16: UNIDOSIS | E16: Susp. Inyectable (Jer. prellenada) | G16: =IF(F16=0," ",F16) | H16: =IF(F16=0," ",F16) | I16: =IF(GENERAL!I16=0," ",GENERAL!I16) | J16: =IF(GENERAL!J16=0," ",GENERAL!J16) | M16: =SUM(F24) -> 0 | N16: JERINGA | O16: 2699 | P16: 25X16
I17: =IF(GENERAL!I17=0," ",GENERAL!I17) | J17: =IF(GENERAL!J17=0," ",GENERAL!J17) | M17: =SUM(F26+F40) -> 0 | N17: JERINGA | O17: 2657 | P17: 27X13
A18: 25311.020-000-0150-05 | B18: 150 | C18: VACUNA ROTAVIRUS MONOVALENTE | D18: UNIDOSIS | E18: Susp. Inyectable (Jer. prellenada) | G18: =IF(F18=0," ",F18) | H18: =IF(F18=0," ",F18) | I18: =IF(GENERAL!I18=0," ",GENERAL!I18) | J18: =IF(GENERAL!J18=0," ",GENERAL!J18) | M18: =SUM(F28*10) -> 0 | N18: JERINGA | O18: 59 | P18: 30GX1/2
I19: =IF(GENERAL!I19=0," ",GENERAL!I19) | J19: =IF(GENERAL!J19=0," ",GENERAL!J19)
A20: 25311.020-000-6135-00 | B20: 6135 | C20: VACUNA HEXAVALENTE | D20: UNIDOSIS | E20: Susp. Inyectable (Fco. Ampula) | G20: =IF(F20=0," ",F20) | H20: =IF(F20=0," ",F20) | I20: =IF(GENERAL!I20=0," ",GENERAL!I20) | J20: =IF(GENERAL!J20=0," ",GENERAL!J20)
I21: =IF(GENERAL!I21=0," ",GENERAL!I21) | J21: =IF(GENERAL!J21=0," ",GENERAL!J21)
A22: 25311.020-000-2526-00 | B22: 2526 | C22: VACUNA HEPATITIS B MULTIDOSIS | D22: MULTIDOSIS | E22: Susp. Inyectable (Fco. Ampula) | G22: =IF(F22=0," ",F22) | H22: =IF(F22=0," ",F22) | I22: =IF(GENERAL!I22=0," ",GENERAL!I22) | J22: =IF(GENERAL!J22=0," ",GENERAL!J22)
A24: 25311.020-000-6187-00 | B24: 6187 | C24: VACUNA HEPATITIS A UNIDOSIS | D24: UNIDOSIS | E24: Susp. Inyectable (Fco. Ampula) | G24: =IF(F24=0," ",F24) | H24: =IF(F24=0," ",F24) | I24: =IF(GENERAL!I24=0," ",GENERAL!I24) | J24: =IF(GENERAL!J24=0," ",GENERAL!J24)
A26: 25311.020-000-3800-00 | B26: 3800 | C26: VACUNA DOBLE VIRAL (SR) | D26: MULTIDOSIS | E26: Fco. Amp Leofilizado+Diluy. | G26: =IF(F26=0," ",F26) | H26: =IF(F26=0," ",F26) | I26: =IF(GENERAL!I26=0," ",GENERAL!I26) | J26: =IF(GENERAL!J26=0," ",GENERAL!J26)
A28: 25311.020-000-3801-01 | B28: 3801 | C28: VACUNA BCG | D28: MULTIDOSIS | E28: Fco. Amp Leofilizado+Diluy. | G28: =IF(F28=0," ",F28) | H28: =IF(F28=0," ",F28) | I28: =IF(GENERAL!I28=0," ",GENERAL!I28) | J28: =IF(GENERAL!J28=0," ",GENERAL!J28)
I29: =IF(GENERAL!I29=0," ",GENERAL!I29) | J29: =IF(GENERAL!J29=0," ",GENERAL!J29)
A30: 25311.020-000-3802-00 | B30: 3802 | C30: VACUNA ANTIPOLIOMELITICA (SABIN) | D30: MULTIDOSIS | E30: Susp. (gotero de plastico) | G30: =IF(F30=0," ",F30) | H30: =IF(F30=0," ",F30) | I30: =IF(GENERAL!I30=0," ",GENERAL!I30) | J30: =IF(GENERAL!J30=0," ",GENERAL!J30)
I31: =IF(GENERAL!I31=0," ",GENERAL!I31) | J31: =IF(GENERAL!J31=0," ",GENERAL!J31)
A32: 25311.020-000-3805-00 | B32: 3805 | C32: VACUNA VACUNA DPT | D32: MULTIDOSIS | E32: Susp. Inyectable (Fco. Ampula) | G32: =IF(F32=0," ",F32) | H32: =IF(F32=0," ",F32) | I32: =IF(GENERAL!I32=0," ",GENERAL!I32) | J32: =IF(GENERAL!J32=0," ",GENERAL!J32)
A34: 25311.020-000-3808-02 | B34: 3808 | C34: VACUNA TDPA | D34: UNIDOSIS | E34: Susp. Inyectable (Fco. Ampula) | G34: =IF(F34=0," ",F34) | H34: =IF(F34=0," ",F34) | I34: =IF(GENERAL!I34=0," ",GENERAL!I34) | J34: =IF(GENERAL!J34=0," ",GENERAL!J34)
A36: 25311.020-000-3810-00 | B36: 3810 | C36: VACUNA TD | D36: MULTIDOSIS | E36: Susp. Inyectable (Fco. Ampula) | G36: =IF(F36=0," ",F36) | H36: =IF(F36=0," ",F36) | I36: =IF(GENERAL!I36=0," ",GENERAL!I36) | J36: =IF(GENERAL!J36=0," ",GENERAL!J36)
A38: 25311.020-000-6056-01 | B38: 6056 | C38: VACUNA ANTIVARICELA | D38: UNIDOSIS | E38: Fco. Amp Leofilizado+Diluy. | G38: =IF(F38=0," ",F38) | H38: =IF(F38=0," ",F38) | I38: =IF(GENERAL!I38=0," ",GENERAL!I38) | J38: =IF(GENERAL!J38=0," ",GENERAL!J38)
A40: 25311.020-000-3820-00 | B40: 3820 | C40: VACUNA TRIPLE VIRAL 1DS (SRP) | D40: UNIDOSIS | E40: Fco. Amp Leofilizado+Diluy. | G40: =IF(F40=0," ",F40) | H40: =IF(F40=0," ",F40) | I40: =IF(GENERAL!I40=0," ",GENERAL!I40) | J40: =IF(GENERAL!J40=0," ",GENERAL!J40)
A42: 25311.020-000-3821-00 | B42: 3821 | C42: VACUNATRIPLEVIRAL MULTI DOSIS | D42: MULTIDOSIS | E42: Fco. Amp Leofilizado+Diluy. | G42: =IF(F42=0," ",F42) | H42: =IF(F42=0," ",F42) | I42: =IF(GENERAL!I42=0," ",GENERAL!I42) | J42: =IF(GENERAL!J42=0," ",GENERAL!J42)
I43: =IF(GENERAL!I43=0," ",GENERAL!I43) | J43: =IF(GENERAL!J43=0," ",GENERAL!J43)
A44: 25311.020-000-6317-01 | B44: 6317 | C44: VACUNA ANTIINFLUENZA 10/D | D44: MULTIDOSIS | E44: Susp. Inyectable (Fco. Ampula) | G44: =IF(F44=0," ",F44) | H44: =IF(F44=0," ",F44) | I44: =IF(GENERAL!I44=0," ",GENERAL!I44) | J44: =IF(GENERAL!J44=0," ",GENERAL!J44)
I45: =IF(GENERAL!I45=0," ",GENERAL!I45) | J45: =IF(GENERAL!J45=0," ",GENERAL!J45)
A46: 25311.020-000-3832-00 | B46: 3832 | C46: VACUNA INMUNOGLOBULINA ANTITETANICA | D46: UNIDOSIS | E46: Susp. Inyectable (Fco. Ampula) | G46: =IF(F46=0," ",F46) | H46: =IF(F46=0," ",F46) | I46: =IF(GENERAL!I46=0," ",GENERAL!I46) | J46: =IF(GENERAL!J46=0," ",GENERAL!J46)
A48: 25311.020-000-6501-02 | B48: 6501 | C48: VACUNA VPH | D48: UNIDOSIS | E48: Susp. Inyectable (Fco. Ampula) | G48: =IF(F48=0," ",F48) | H48: =IF(F48=0," ",F48) | I48: =IF(GENERAL!I48=0," ",GENERAL!I48) | J48: =IF(GENERAL!J48=0," ",GENERAL!J48)
I49: =IF(GENERAL!I49=0," ",GENERAL!I49) | J49: =IF(GENERAL!J49=0," ",GENERAL!J49)
A50: 25331.020-X-0002-00-E | B50: 2 | C50: VACUNA ANTIAMARILICA | D50: UNIDOSIS | E50: Fco. Amp Leofilizado + Jer.prellenada. | G50: =IF(F50=0," ",F50) | H50: =IF(F50=0," ",F50) | I50: =IF(GENERAL!I50=0," ",GENERAL!I50) | J50: =IF(GENERAL!J50=0," ",GENERAL!J50)
I51: =IF(GENERAL!I51=0," ",GENERAL!I51) | J51: =IF(GENERAL!J51=0," ",GENERAL!J51)
A52: 25311.020-000-6509-01 | B52: 6509 | C52: VACUNA VRS | D52: UNIDOSIS | E52: Susp. Inyectable (Fco. Ampula) | G52: =IF(F52=0," ",F52) | H52: =IF(F52=0," ",F52) | I52: =IF(GENERAL!I52=0," ",GENERAL!I52) | J52: =IF(GENERAL!J52=0," ",GENERAL!J52)
...

Sheet LOMA BONITA
A1: SERVICIOS DE SALUD DEL ESTADO DE QUERÉTARO
A2: COORDINACION GENERAL
A3: SUBDIRECCION DE ADQUISICIONES
A5: SOLICITUD Y SURTIMIENTO DE LA CÁMARA DE FRÍO ESTATAL
A7: ORIGEN: | B7: JURISDICCIÓN SANITARIA N.1 | G7: AREA: | H7: VACUNAS
A8: DIRECCIÓN: | B8: Circuito Moises Solana S/N, Col. Vista Alegre, Santiago de Querétaro. Qro. | G8: FECHA DE ENVIO: | H8: =IF(GENERAL!H8=0," ",GENERAL!H8)
A9: DESTINO: | B9: C.S LOMA BONITA | G9: FOLIO ORACLE:
A10: DIRECCIÓN: | B10: Creston N.232, Sátelite, Querétaro. | G10: MES A SURTIR: | H10: =GENERAL!H10 -> OCTUBRE
A12: NÚM | B12: CLAVE DE ARTÍCULO | C12: NOMBRE DEL ARTÍCULO | D12: PRESENTACIÓN | E12: FORMA | F12: CANTIDAD | K12: FIRMA DE RECEPCION
E13: FARMACÉUTICA | F13: SOLICITADO | G13: AUTORIZADO | H13: SURTIDO | I13: LOTE | J13: CADUCIDAD
A14: 25311.020-000-0146-03 | B14: 146 | C14: VACUNA ANTINEUMOCOCCICA 23 1DS | D14: UNIDOSIS | E14: Susp. Inyectable (Fco. Ampula) | G14: =IF(F14=0," ",F14) | H14: =IF(F14=0," ",F14) | I14: =IF(GENERAL!I14=0," ",GENERAL!I14) | J14: =IF(GENERAL!J14=0," ",GENERAL!J14) | M14: =SUM(F14+(F44*10)+(F32*10)+F22+F34+(F36*10)+F48) -> 0 | N14: JERINGA | O14: 2715 | P14: 22X32
I15: =IF(GENERAL!I15=0," ",GENERAL!I15) | J15: =IF(GENERAL!J15=0," ",GENERAL!J15) | M15: =SUM((F44/3)*20+F20) -> 0 | N15: JERINGA | O15: 2707 | P15: 23X25
A16: 25311.020-000-0148-01 | B16: 148 | C16: VACUNA ANTINEUMOCOCCICA 13 | D16: UNIDOSIS | E16: Susp. Inyectable (Jer. prellenada) | G16: =IF(F16=0," ",F16) | H16: =IF(F16=0," ",F16) | I16: =IF(GENERAL!I16=0," ",GENERAL!I16) | J16: =IF(GENERAL!J16=0," ",GENERAL!J16) | M16: =SUM(F24) -> 0 | N16: JERINGA | O16: 2699 | P16: 25X16
I17: =IF(GENERAL!I17=0," ",GENERAL!I17) | J17: =IF(GENERAL!J17=0," ",GENERAL!J17) | M17: =SUM(F26+F40) -> 0 | N17: JERINGA | O17: 2657 | P17: 27X13
A18: 25311.020-000-0150-05 | B18: 150 | C18: VACUNA ROTAVIRUS MONOVALENTE | D18: UNIDOSIS | E18: Susp. Inyectable (Jer. prellenada) | G18: =IF(F18=0," ",F18) | H18: =IF(F18=0," ",F18) | I18: =IF(GENERAL!I18=0," ",GENERAL!I18) | J18: =IF(GENERAL!J18=0," ",GENERAL!J18) | M18: =SUM(F28*10) -> 0 | N18: JERINGA | O18: 59 | P18: 30GX1/2
A20: 25311.020-000-6135-00 | B20: 6135 | C20: VACUNA HEXAVALENTE | D20: UNIDOSIS | E20: Susp. Inyectable (Fco. Ampula) | G20: =IF(F20=0," ",F20) | H20: =IF(F20=0," ",F20) | I20: =IF(GENERAL!I20=0," ",GENERAL!I20) | J20: =IF(GENERAL!J20=0," ",GENERAL!J20)
I21: =IF(GENERAL!I21=0," ",GENERAL!I21) | J21: =IF(GENERAL!J21=0," ",GENERAL!J21)
A22: 25311.020-000-2526-00 | B22: 2526 | C22: VACUNA HEPATITIS B MULTIDOSIS | D22: MULTIDOSIS | E22: Susp. Inyectable (Fco. Ampula) | G22: =IF(F22=0," ",F22) | H22: =IF(F22=0," ",F22) | I22: =IF(GENERAL!I22=0," ",GENERAL!I22) | J22: =IF(GENERAL!J22=0," ",GENERAL!J22)
I23: =IF(GENERAL!I23=0," ",GENERAL!I23) | J23: =IF(GENERAL!J23=0," ",GENERAL!J23)
A24: 25311.020-000-6187-00 | B24: 6187 | C24: VACUNA HEPATITIS A UNIDOSIS | D24: UNIDOSIS | E24: Susp. Inyectable (Fco. Ampula) | G24: =IF(F24=0," ",F24) | H24: =IF(F24=0," ",F24) | I24: =IF(GENERAL!I24=0," ",GENERAL!I24) | J24: =IF(GENERAL!J24=0," ",GENERAL!J24)
I25: =IF(GENERAL!I25=0," ",GENERAL!I25) | J25: =IF(GENERAL!J25=0," ",GENERAL!J25)
A26: 25311.020-000-3800-00 | B26: 3800 | C26: VACUNA DOBLE VIRAL (SR) | D26: MULTIDOSIS | E26: Fco. Amp Leofilizado+Diluy. | G26: =IF(F26=0," ",F26) | H26: =IF(F26=0," ",F26) | I26: =IF(GENERAL!I26=0," ",GENERAL!I26) | J26: =IF(GENERAL!J26=0," ",GENERAL!J26)
I27: =IF(GENERAL!I27=0," ",GENERAL!I27) | J27: =IF(GENERAL!J27=0," ",GENERAL!J27)
A28: 25311.020-000-3801-01 | B28: 3801 | C28: VACUNA BCG | D28: MULTIDOSIS | E28: Fco. Amp Leofilizado+Diluy. | G28: =IF(F28=0," ",F28) | H28: =IF(F28=0," ",F28) | I28: =IF(GENERAL!I28=0," ",GENERAL!I28) | J28: =IF(GENERAL!J28=0," ",GENERAL!J28)
I29: =IF(GENERAL!I29=0," ",GENERAL!I29) | J29: =IF(GENERAL!J29=0," ",GENERAL!J29)
A30: 25311.020-000-3802-00 | B30: 3802 | C30: VACUNA ANTIPOLIOMELITICA (SABIN) | D30: MULTIDOSIS | E30: Susp. (gotero de plastico) | G30: =IF(F30=0," ",F30) | H30: =IF(F30=0," ",F30) | I30: =IF(GENERAL!I30=0," ",GENERAL!I30) | J30: =IF(GENERAL!J30=0," ",GENERAL!J30)
I31: =IF(GENERAL!I31=0," ",GENERAL!I31) | J31: =IF(GENERAL!J31=0," ",GENERAL!J31)
A32: 25311.020-000-3805-00 | B32: 3805 | C32: VACUNA VACUNA DPT | D32: MULTIDOSIS | E32: Susp. Inyectable (Fco. Ampula) | G32: =IF(F32=0," ",F32) | H32: =IF(F32=0," ",F32) | I32: =IF(GENERAL!I32=0," ",GENERAL!I32) | J32: =IF(GENERAL!J32=0," ",GENERAL!J32)
I33: =IF(GENERAL!I33=0," ",GENERAL!I33) | J33: =IF(GENERAL!J33=0," ",GENERAL!J33)
A34: 25311.020-000-3808-02 | B34: 3808 | C34: VACUNA TDPA | D34: UNIDOSIS | E34: Susp. Inyectable (Fco. Ampula) | G34: =IF(F34=0," ",F34) | H34: =IF(F34=0," ",F34) | I34: =IF(GENERAL!I34=0," ",GENERAL!I34) | J34: =IF(GENERAL!J34=0," ",GENERAL!J34)
I35: =IF(GENERAL!I35=0," ",GENERAL!I35) | J35: =IF(GENERAL!J35=0," ",GENERAL!J35)
A36: 25311.020-000-3810-00 | B36: 3810 | C36: VACUNA TD | D36: MULTIDOSIS | E36: Susp. Inyectable (Fco. Ampula) | G36: =IF(F36=0," ",F36) | H36: =IF(F36=0," ",F36) | I36: =IF(GENERAL!I36=0," ",GENERAL!I36) | J36: =IF(GENERAL!J36=0," ",GENERAL!J36)
I37: =IF(GENERAL!I37=0," ",GENERAL!I37) | J37: =IF(GENERAL!J37=0," ",GENERAL!J37)
A38: 25311.020-000-6056-01 | B38: 6056 | C38: VACUNA ANTIVARICELA | D38: UNIDOSIS | E38: Fco. Amp Leofilizado+Diluy. | G38: =IF(F38=0," ",F38) | H38: =IF(F38=0," ",F38) | I38: =IF(GENERAL!I38=0," ",GENERAL!I38) | J38: =IF(GENERAL!J38=0," ",GENERAL!J38)
I39: =IF(GENERAL!I39=0," ",GENERAL!I39) | J39: =IF(GENERAL!J39=0," ",GENERAL!J39)
A40: 25311.020-000-3820-00 | B40: 3820 | C40: VACUNA TRIPLE VIRAL 1DS (SRP) | D40: UNIDOSIS | E40: Fco. Amp Leofilizado+Diluy. | G40: =IF(F40=0," ",F40) | H40: =IF(F40=0," ",F40) | I40: =IF(GENERAL!I40=0," ",GENERAL!I40) | J40: =IF(GENERAL!J40=0," ",GENERAL!J40)
I41: =IF(GENERAL!I41=0," ",GENERAL!I41) | J41: =IF(GENERAL!J41=0," ",GENERAL!J41)
A42: 25311.020-000-3821-00 | B42: 3821 | C42: VACUNATRIPLEVIRAL MULTI DOSIS | D42: MULTIDOSIS | E42: Fco. Amp Leofilizado+Diluy. | G42: =IF(F42=0," ",F42) | H42: =IF(F42=0," ",F42) | I42: =IF(GENERAL!I42=0," ",GENERAL!I42) | J42: =IF(GENERAL!J42=0," ",GENERAL!J42)
I43: =IF(GENERAL!I43=0," ",GENERAL!I43) | J43: =IF(GENERAL!J43=0," ",GENERAL!J43)
A44: 25311.020-000-6317-01 | B44: 6317 | C44: VACUNA ANTIINFLUENZA 10/D | D44: MULTIDOSIS | E44: Susp. Inyectable (Fco. Ampula) | G44: =IF(F44=0," ",F44) | H44: =IF(F44=0," ",F44) | I44: =IF(GENERAL!I44=0," ",GENERAL!I44) | J44: =IF(GENERAL!J44=0," ",GENERAL!J44)
...

Sheet PEDRO ESCOBEDO
A1: SERVICIOS DE SALUD DEL ESTADO DE QUERÉTARO
A2: COORDINACION GENERAL
A3: SUBDIRECCION DE ADQUISICIONES
A5: SOLICITUD Y SURTIMIENTO DE LA CÁMARA DE FRÍO ESTATAL
A7: ORIGEN: | G7: AREA: | H7: VACUNAS
A8: DIRECCIÓN: | G8: FECHA DE ENVIO: | H8: =IF(GENERAL!H8=0," ",GENERAL!H8)
A9: DESTINO: | G9: FOLIO ORACLE:
A10: DIRECCIÓN: | G10: MES A SURTIR:
A12: NÚM | B12: CLAVE DE ARTÍCULO | C12: NOMBRE DEL ARTÍCULO | D12: PRESENTACIÓN | E12: FORMA | F12: CANTIDAD | K12: FIRMA DE RECEPCION
E13: FARMACÉUTICA | F13: SOLICITADO | G13: AUTORIZADO | H13: SURTIDO | I13: LOTE | J13: CADUCIDAD
A14: 25311.020-000-6508-01 | B14: 6508 | C14: VACUNA ANTINEUMOCOCCICA 20 | D14: UNIDOSIS | E14: Susp. Inyectable (Fco. Ampula) | G14: =IF(F14=0," ",F14) | H14: =IF(F14=0," ",F14) | I14: =IF(GENERAL!I14=0," ",GENERAL!I14) | J14: =IF(GENERAL!J14=0," ",GENERAL!J14) | M14: =SUM(F14+(F44*10)+(F32*10)+F22+F34+(F36*10)+F48) -> 0 | N14: JERINGA | O14: 2715 | P14: 22X32
M15: =SUM((F44/3)*20+F20) -> 0 | N15: JERINGA | O15: 2707 | P15: 23X25
A16: 25311.020-000-0148-01 | B16: 148 | C16: VACUNA ANTINEUMOCOCCICA 13 | D16: UNIDOSIS | E16: Susp. Inyectable (Jer. prellenada) | G16: =IF(F16=0," ",F16) | H16: =IF(F16=0," ",F16) | I16: =IF(GENERAL!I16=0," ",GENERAL!I16) | J16: =IF(GENERAL!J16=0," ",GENERAL!J16) | M16: =SUM(F24) -> 0 | N16: JERINGA | O16: 2699 | P16: 25X16
I17: =IF(GENERAL!I17=0," ",GENERAL!I17) | J17: =IF(GENERAL!J17=0," ",GENERAL!J17) | M17: =SUM(F26+F40) -> 0 | N17: JERINGA | O17: 2657 | P17: 27X13
A18: 25311.020-000-0150-05 | B18: 150 | C18: VACUNA ROTAVIRUS MONOVALENTE | D18: UNIDOSIS | E18: Susp. Inyectable (Jer. prellenada) | G18: =IF(F18=0," ",F18) | H18: =IF(F18=0," ",F18) | I18: =IF(GENERAL!I18=0," ",GENERAL!I18) | J18: =IF(GENERAL!J18=0," ",GENERAL!J18) | M18: =SUM(F28*10) -> 0 | N18: JERINGA | O18: 59 | P18: 30GX1/2
A20: 25311.020-000-6135-00 | B20: 6135 | C20: VACUNA HEXAVALENTE | D20: UNIDOSIS | E20: Susp. Inyectable (Fco. Ampula) | G20: =IF(F20=0," ",F20) | H20: =IF(F20=0," ",F20) | I20: =IF(GENERAL!I20=0," ",GENERAL!I20) | J20: =IF(GENERAL!J20=0," ",GENERAL!J20)
A22: 25311.020-000-2526-00 | B22: 2526 | C22: VACUNA HEPATITIS B MULTIDOSIS | D22: MULTIDOSIS | E22: Susp. Inyectable (Fco. Ampula) | G22: =IF(F22=0," ",F22) | H22: =IF(F22=0," ",F22) | I22: =IF(GENERAL!I22=0," ",GENERAL!I22) | J22: =IF(GENERAL!J22=0," ",GENERAL!J22)
A24: 25311.020-000-6187-00 | B24: 6187 | C24: VACUNA HEPATITIS A UNIDOSIS | D24: UNIDOSIS | E24: Susp. Inyectable (Fco. Ampula) | G24: =IF(F24=0," ",F24) | H24: =IF(F24=0," ",F24) | I24: =IF(GENERAL!I24=0," ",GENERAL!I24) | J24: =IF(GENERAL!J24=0," ",GENERAL!J24)
A26: 25311.020-000-3800-00 | B26: 3800 | C26: VACUNA DOBLE VIRAL (SR) | D26: MULTIDOSIS | E26: Fco. Amp Leofilizado+Diluy. | G26: =IF(F26=0," ",F26) | H26: =IF(F26=0," ",F26) | I26: =IF(GENERAL!I26=0," ",GENERAL!I26) | J26: =IF(GENERAL!J26=0," ",GENERAL!J26)
A28: 25311.020-000-3801-01 | B28: 3801 | C28: VACUNA BCG | D28: MULTIDOSIS | E28: Fco. Amp Leofilizado+Diluy. | G28: =IF(F28=0," ",F28) | H28: =IF(F28=0," ",F28) | I28: =IF(GENERAL!I28=0," ",GENERAL!I28) | J28: =IF(GENERAL!J28=0," ",GENERAL!J28)
A30: 25311.020-000-3805-00 | B30: 3805 | C30: VACUNA VACUNA DPT | D30: MULTIDOSIS | E30: Susp. Inyectable (Fco. Ampula) | G30: =IF(F30=0," ",F30) | H30: =IF(F30=0," ",F30) | I30: =IF(GENERAL!I30=0," ",GENERAL!I30) | J30: =IF(GENERAL!J30=0," ",GENERAL!J30)
A32: 25311.020-000-3808-02 | B32: 3808 | C32: VACUNA TDPA | D32: UNIDOSIS | E32: Susp. Inyectable (Fco. Ampula) | G32: =IF(F32=0," ",F32) | H32: =IF(F32=0," ",F32) | I32: =IF(GENERAL!I32=0," ",GENERAL!I32) | J32: =IF(GENERAL!J32=0," ",GENERAL!J32)
A34: 25311.020-000-3810-00 | B34: 3810 | C34: VACUNA TD | D34: MULTIDOSIS | E34: Susp. Inyectable (Fco. Ampula) | G34: =IF(F34=0," ",F34) | H34: =IF(F34=0," ",F34) | I34: =IF(GENERAL!I34=0," ",GENERAL!I34) | J34: =IF(GENERAL!J34=0," ",GENERAL!J34)
A36: 25311.020-000-6056-01 | B36: 6056 | C36: VACUNA ANTIVARICELA | D36: UNIDOSIS | E36: Fco. Amp Leofilizado+Diluy. | G36: =IF(F36=0," ",F36) | H36: =IF(F36=0," ",F36) | I36: =IF(GENERAL!I36=0," ",GENERAL!I36) | J36: =IF(GENERAL!J36=0," ",GENERAL!J36)
A38: 25311.020-000-3820-00 | B38: 3820 | C38: VACUNA TRIPLE VIRAL 1DS (SRP) | D38: UNIDOSIS | E38: Fco. Amp Leofilizado+Diluy. | G38: =IF(F38=0," ",F38) | H38: =IF(F38=0," ",F38) | I38: =IF(GENERAL!I38=0," ",GENERAL!I38) | J38: =IF(GENERAL!J38=0," ",GENERAL!J38)
A40: 25311.020-000-3821-00 | B40: 3821 | C40: VACUNATRIPLEVIRAL MULTI DOSIS | D40: MULTIDOSIS | E40: Fco. Amp Leofilizado+Diluy. | G40: =IF(F40=0," ",F40) | H40: =IF(F40=0," ",F40) | I40: =IF(GENERAL!I40=0," ",GENERAL!I40) | J40: =IF(GENERAL!J40=0," ",GENERAL!J40)
A42: 25311.020-000-6317-01 | B42: 6317 | C42: VACUNA ANTIINFLUENZA 10/D | D42: MULTIDOSIS | E42: Susp. Inyectable (Fco. Ampula) | G42: =IF(F42=0," ",F42) | H42: =IF(F42=0," ",F42) | I42: =IF(GENERAL!I42=0," ",GENERAL!I42) | J42: =IF(GENERAL!J42=0," ",GENERAL!J42)
I43: =IF(GENERAL!I43=0," ",GENERAL!I43) | J43: =IF(GENERAL!J43=0," ",GENERAL!J43)
A44: 25311.020-000-3832-00 | B44: 3832 | C44: VACUNA INMUNOGLOBULINA ANTITETANICA | D44: UNIDOSIS | E44: Susp. Inyectable (Fco. Ampula) | G44: =IF(F44=0," ",F44) | H44: =IF(F44=0," ",F44) | I44: =IF(GENERAL!I44=0," ",GENERAL!I44) | J44: =IF(GENERAL!J44=0," ",GENERAL!J44)
I45: =IF(GENERAL!I45=0," ",GENERAL!I45) | J45: =IF(GENERAL!J45=0," ",GENERAL!J45)
A46: 25311.020-000-6501-02 | B46: 6501 | C46: VACUNA VPH | D46: UNIDOSIS | E46: Susp. Inyectable (Fco. Ampula) | G46: =IF(F46=0," ",F46) | H46: =IF(F46=0," ",F46) | I46: =IF(GENERAL!I46=0," ",GENERAL!I46) | J46: =IF(GENERAL!J46=0," ",GENERAL!J46)
A48: 25331.020-X-0002-00-E | B48: 2 | C48: VACUNA ANTIAMARILICA | D48: UNIDOSIS | E48: Fco. Amp Leofilizado + Jer.prellenada. | G48: =IF(F48=0," ",F48) | H48: =IF(F48=0," ",F48) | I48: =IF(GENERAL!I48=0," ",GENERAL!I48) | J48: =IF(GENERAL!J48=0," ",GENERAL!J48)
A50: 25311.020-000-6502-00 | B50: 6502 | C50: VACUNA COVID-19 MODERNA | D50: MULTIDOSIS | E50: Susp. Inyectable (Fco. Ampula) | G50: =IF(F50=0," ",F50) | H50: =IF(F50=0," ",F50) | I50: =IF(GENERAL!I50=0," ",GENERAL!I50) | J50: =IF(GENERAL!J50=0," ",GENERAL!J50)
I51: =IF(GENERAL!I51=0," ",GENERAL!I51) | J51: =IF(GENERAL!J51=0," ",GENERAL!J51)
A52: 25311.020-000-6506-00 | B52: 6506 | C52: VACUNA COVID-19 PFIZER | D52: MULTIDOSIS | E52: Susp. Inyectable (Fco. Ampula)
A54: 25311.020-000-6509-01 | B54: 6509 | C54: VACUNA VRS | D54: UNIDOSIS | E54: Susp. Inyectable (Fco. Ampula) | G54: =IF(F54=0," ",F54) | H54: =IF(F54=0," ",F54) | I54: =IF(GENERAL!I52=0," ",GENERAL!I52) | J54: =IF(GENERAL!J52=0," ",GENERAL!J52)
B56: CONDICIONES DE TRANSPORTE Y ALMACENAMIENTO: MANTENGASE EN TODO MOMENTO A TEMPERATURA ENTRE 2°C - 8 °C
C58: TEMPERATURA A LA RECEPCIÓN: | G58: FECHA DE RECEPCIÓN:
A60: OBSERVACIONES:
A67: L.E LIZBETH URIBE PANTOJA | H67: ING. ISRAEL RUIZ BARCENAS
...

Sheet JOFRITO
A1: SERVICIOS DE SALUD DEL ESTADO DE QUERÉTARO
A2: COORDINACION GENERAL
A3: SUBDIRECCION DE ADQUISICIONES
A5: SOLICITUD Y SURTIMIENTO DE LA CÁMARA DE FRÍO ESTATAL
A7: ORIGEN: | B7: JURISDICCIÓN SANITARIA N.1 | G7: AREA: | H7: VACUNAS
A8: DIRECCIÓN: | B8: Circuito Moises Solana S/N, Col. Vista Alegre, Santiago de Querétaro. Qro. | G8: FECHA DE ENVIO: | H8: =IF(GENERAL!H8=0," ",GENERAL!H8)
A9: DESTINO: | B9: C.S JOFRITO | G9: FOLIO ORACLE:
A10: DIRECCIÓN: | B10: Camino Real S/N, Jofrito, Querétaro. | G10: MES A SURTIR: | H10: =GENERAL!H10 -> OCTUBRE
A12: NÚM | B12: CLAVE DE ARTÍCULO | C12: NOMBRE DEL ARTÍCULO | D12: PRESENTACIÓN | E12: FORMA | F12: CANTIDAD | K12: FIRMA DE RECEPCION
E13: FARMACÉUTICA | F13: SOLICITADO | G13: AUTORIZADO | H13: SURTIDO | I13: LOTE | J13: CADUCIDAD
A14: 25311.020-000-0146-03 | B14: 146 | C14: VACUNA ANTINEUMOCOCCICA 23 1DS | D14: UNIDOSIS | E14: Susp. Inyectable (Fco. Ampula) | G14: =IF(F14=0," ",F14) | H14: =IF(F14=0," ",F14) | I14: =IF(GENERAL!I14=0," ",GENERAL!I14) | J14: =IF(GENERAL!J14=0," ",GENERAL!J14) | M14: =SUM(F14+(F44*10)+(F32*10)+F22+F34+(F36*10)+F48) -> 0 | N14: JERINGA | O14: 2715 | P14: 22X32
I15: =IF(GENERAL!I15=0," ",GENERAL!I15) | J15: =IF(GENERAL!J15=0," ",GENERAL!J15) | M15: =SUM((F44/3)*20+F20) -> 0 | N15: JERINGA | O15: 2707 | P15: 23X25
A16: 25311.020-000-0148-01 | B16: 148 | C16: VACUNA ANTINEUMOCOCCICA 13 | D16: UNIDOSIS | E16: Susp. Inyectable (Jer. prellenada) | G16: =IF(F16=0," ",F16) | H16: =IF(F16=0," ",F16) | I16: =IF(GENERAL!I16=0," ",GENERAL!I16) | J16: =IF(GENERAL!J16=0," ",GENERAL!J16) | M16: =SUM(F24) -> 0 | N16: JERINGA | O16: 2699 | P16: 25X16
I17: =IF(GENERAL!I17=0," ",GENERAL!I17) | J17: =IF(GENERAL!J17=0," ",GENERAL!J17) | M17: =SUM(F26+F40) -> 0 | N17: JERINGA | O17: 2657 | P17: 27X13
A18: 25311.020-000-0150-05 | B18: 150 | C18: VACUNA ROTAVIRUS MONOVALENTE | D18: UNIDOSIS | E18: Susp. Inyectable (Jer. prellenada) | G18: =IF(F18=0," ",F18) | H18: =IF(F18=0," ",F18) | I18: =IF(GENERAL!I18=0," ",GENERAL!I18) | J18: =IF(GENERAL!J18=0," ",GENERAL!J18) | M18: =SUM(F28*10) -> 0 | N18: JERINGA | O18: 59 | P18: 30GX1/2
I19: =IF(GENERAL!I19=0," ",GENERAL!I19) | J19: =IF(GENERAL!J19=0," ",GENERAL!J19)
A20: 25311.020-000-6135-00 | B20: 6135 | C20: VACUNA HEXAVALENTE | D20: UNIDOSIS | E20: Susp. Inyectable (Fco. Ampula) | G20: =IF(F20=0," ",F20) | H20: =IF(F20=0," ",F20) | I20: =IF(GENERAL!I20=0," ",GENERAL!I20) | J20: =IF(GENERAL!J20=0," ",GENERAL!J20)
I21: =IF(GENERAL!I21=0," ",GENERAL!I21) | J21: =IF(GENERAL!J21=0," ",GENERAL!J21)
A22: 25311.020-000-2526-00 | B22: 2526 | C22: VACUNA HEPATITIS B MULTIDOSIS | D22: MULTIDOSIS | E22: Susp. Inyectable (Fco. Ampula) | G22: =IF(F22=0," ",F22) | H22: =IF(F22=0," ",F22) | I22: =IF(GENERAL!I22=0," ",GENERAL!I22) | J22: =IF(GENERAL!J22=0," ",GENERAL!J22)
A24: 25311.020-000-6187-00 | B24: 6187 | C24: VACUNA HEPATITIS A UNIDOSIS | D24: UNIDOSIS | E24: Susp. Inyectable (Fco. Ampula) | G24: =IF(F24=0," ",F24) | H24: =IF(F24=0," ",F24) | I24: =IF(GENERAL!I24=0," ",GENERAL!I24) | J24: =IF(GENERAL!J24=0," ",GENERAL!J24)
A26: 25311.020-000-3800-00 | B26: 3800 | C26: VACUNA DOBLE VIRAL (SR) | D26: MULTIDOSIS | E26: Fco. Amp Leofilizado+Diluy. | G26: =IF(F26=0," ",F26) | H26: =IF(F26=0," ",F26) | I26: =IF(GENERAL!I26=0," ",GENERAL!I26) | J26: =IF(GENERAL!J26=0," ",GENERAL!J26)
A28: 25311.020-000-3801-01 | B28: 3801 | C28: VACUNA BCG | D28: MULTIDOSIS | E28: Fco. Amp Leofilizado+Diluy. | G28: =IF(F28=0," ",F28) | H28: =IF(F28=0," ",F28) | I28: =IF(GENERAL!I28=0," ",GENERAL!I28) | J28: =IF(GENERAL!J28=0," ",GENERAL!J28)
A30: 25311.020-000-3802-00 | B30: 3802 | C30: VACUNA ANTIPOLIOMELITICA (SABIN) | D30: MULTIDOSIS | E30: Susp. (gotero de plastico) | G30: =IF(F30=0," ",F30) | H30: =IF(F30=0," ",F30) | I30: =IF(GENERAL!I30=0," ",GENERAL!I30) | J30: =IF(GENERAL!J30=0," ",GENERAL!J30)
I31: =IF(GENERAL!I31=0," ",GENERAL!I31) | J31: =IF(GENERAL!J31=0," ",GENERAL!J31)
A32: 25311.020-000-3805-00 | B32: 3805 | C32: VACUNA VACUNA DPT | D32: MULTIDOSIS | E32: Susp. Inyectable (Fco. Ampula) | G32: =IF(F32=0," ",F32) | H32: =IF(F32=0," ",F32) | I32: =IF(GENERAL!I32=0," ",GENERAL!I32) | J32: =IF(GENERAL!J32=0," ",GENERAL!J32)
I33: =IF(GENERAL!I33=0," ",GENERAL!I33) | J33: =IF(GENERAL!J33=0," ",GENERAL!J33)
A34: 25311.020-000-3808-02 | B34: 3808 | C34: VACUNA TDPA | D34: UNIDOSIS | E34: Susp. Inyectable (Fco. Ampula) | G34: =IF(F34=0," ",F34) | H34: =IF(F34=0," ",F34) | I34: =IF(GENERAL!I34=0," ",GENERAL!I34) | J34: =IF(GENERAL!J34=0," ",GENERAL!J34)
I35: =IF(GENERAL!I35=0," ",GENERAL!I35) | J35: =IF(GENERAL!J35=0," ",GENERAL!J35)
A36: 25311.020-000-3810-00 | B36: 3810 | C36: VACUNA TD | D36: MULTIDOSIS | E36: Susp. Inyectable (Fco. Ampula) | G36: =IF(F36=0," ",F36) | H36: =IF(F36=0," ",F36) | I36: =IF(GENERAL!I36=0," ",GENERAL!I36) | J36: =IF(GENERAL!J36=0," ",GENERAL!J36)
I37: =IF(GENERAL!I37=0," ",GENERAL!I37) | J37: =IF(GENERAL!J37=0," ",GENERAL!J37)
A38: 25311.020-000-6056-01 | B38: 6056 | C38: VACUNA ANTIVARICELA | D38: UNIDOSIS | E38: Fco. Amp Leofilizado+Diluy. | G38: =IF(F38=0," ",F38) | H38: =IF(F38=0," ",F38) | I38: =IF(GENERAL!I38=0," ",GENERAL!I38) | J38: =IF(GENERAL!J38=0," ",GENERAL!J38)
I39: =IF(GENERAL!I39=0," ",GENERAL!I39) | J39: =IF(GENERAL!J39=0," ",GENERAL!J39)
A40: 25311.020-000-3820-00 | B40: 3820 | C40: VACUNA TRIPLE VIRAL 1DS (SRP) | D40: UNIDOSIS | E40: Fco. Amp Leofilizado+Diluy. | G40: =IF(F40=0," ",F40) | H40: =IF(F40=0," ",F40) | I40: =IF(GENERAL!I40=0," ",GENERAL!I40) | J40: =IF(GENERAL!J40=0," ",GENERAL!J40)
I41: =IF(GENERAL!I41=0," ",GENERAL!I41) | J41: =IF(GENERAL!J41=0," ",GENERAL!J41)
A42: 25311.020-000-3821-00 | B42: 3821 | C42: VACUNATRIPLEVIRAL MULTI DOSIS | D42: MULTIDOSIS | E42: Fco. Amp Leofilizado+Diluy. | G42: =IF(F42=0," ",F42) | H42: =IF(F42=0," ",F42) | I42: =IF(GENERAL!I42=0," ",GENERAL!I42) | J42: =IF(GENERAL!J42=0," ",GENERAL!J42)
I43: =IF(GENERAL!I43=0," ",GENERAL!I43) | J43: =IF(GENERAL!J43=0," ",GENERAL!J43)
