Workbook

Sheet ANÁLIS DE META-LOGRO
A1: Subsecretaria de Prevención y Promoción de la Salud
A2: Centro Nacional para la Salud de la Infancia y la Adolescencia
A3: Programa de Vacunación Universal
A4: Meta-Logro de Vacuna Anti Influenza Estacional Temporada Invernal 2026-2027
A5: CS JOFRITO DE PRUEBA (QTSSA000000)
A8: Población | C8: DOSIS / GRUPO POBLACIONAL | G8: LOGRO | H8: META | I8: % | K8: Barra de avance
A9: 225 Aplicación de Antiinfluenza Estacional | B9: Población blanco | C9: Primera dosis | F9: 6 a 11 meses | G9: =SUM(OCTUBRE:ABRIL!L8) -> 31 | H9: 40 | I9: =IFERROR(G9/H9," ") | K9: =IFERROR(G9/H9,0) -> 0 | L9: =IF(I9=" "," ",IF(I9>100%,"🚫Meta rebasada🚫"," "))
F10: 12 a 23 meses | G10: =SUM(OCTUBRE:ABRIL!L9) -> 49 | H10: 60 | I10: =IFERROR(G10/H10," ") | K10: =IFERROR(G10/H10,0) -> 0 | L10: =IF(I10=" "," ",IF(I10>100%,"🚫Meta rebasada🚫"," "))
F11: 24 a 35 meses | G11: =SUM(OCTUBRE:ABRIL!L10) -> 43 | H11: 50 | I11: =IFERROR(G11/H11," ") | K11: =IFERROR(G11/H11,0) -> 0 | L11: =IF(I11=" "," ",IF(I11>100%,"🚫Meta rebasada🚫"," "))
F12: 36 a 47 meses | G12: =SUM(OCTUBRE:ABRIL!L11) -> 36 | H12: 45 | I12: =IFERROR(G12/H12," ") | K12: =IFERROR(G12/H12,0) -> 0 | L12: =IF(I12=" "," ",IF(I12>100%,"🚫Meta rebasada🚫"," "))
F13: 48 a 59 meses | G13: =SUM(OCTUBRE:ABRIL!L12) -> 27 | H13: 35 | I13: =IFERROR(G13/H13," ") | K13: =IFERROR(G13/H13,0) -> 0 | L13: =IF(I13=" "," ",IF(I13>100%,"🚫Meta rebasada🚫"," "))
C14: Segunda dosis | F14: 7 a 11 meses | G14: =SUM(OCTUBRE:ABRIL!L13) -> 17 | H14: 30 | I14: =IFERROR(G14/H14," ") | K14: =IFERROR(G14/H14,0) -> 0 | L14: =IF(I14=" "," ",IF(I14>100%,"🚫Meta rebasada🚫"," "))
F15: 12 a 23 meses | G15: =SUM(OCTUBRE:ABRIL!L14) -> 17 | H15: 25 | I15: =IFERROR(G15/H15," ") | K15: =IFERROR(G15/H15,0) -> 0 | L15: =IF(I15=" "," ",IF(I15>100%,"🚫Meta rebasada🚫"," "))
F16: 24 a 35 meses | G16: =SUM(OCTUBRE:ABRIL!L15) -> 18 | H16: 20 | I16: =IFERROR(G16/H16," ") | K16: =IFERROR(G16/H16,0) -> 0 | L16: =IF(I16=" "," ",IF(I16>100%,"🚫Meta rebasada🚫"," "))
F17: 36 a 47 meses | G17: =SUM(OCTUBRE:ABRIL!L16) -> 18 | H17: 18 | I17: =IFERROR(G17/H17," ") | K17: =IFERROR(G17/H17,0) -> 0 | L17: =IF(I17=" "," ",IF(I17>100%,"🚫Meta rebasada🚫"," "))
F18: 48 a 59 meses | G18: =SUM(OCTUBRE:ABRIL!L17) -> 12 | H18: 15 | I18: =IFERROR(G18/H18," ") | K18: =IFERROR(G18/H18,0) -> 0 | L18: =IF(I18=" "," ",IF(I18>100%,"🚫Meta rebasada🚫"," "))
C19: Revacunación | F19: 18 a 23 meses | G19: =SUM(OCTUBRE:ABRIL!L18) -> 16 | H19: 22 | I19: =IFERROR(G19/H19," ") | K19: =IFERROR(G19/H19,0) -> 0 | L19: =IF(I19=" "," ",IF(I19>100%,"🚫Meta rebasada🚫"," "))
F20: 24 a 35 meses | G20: =SUM(OCTUBRE:ABRIL!L19) -> 14 | H20: 20 | I20: =IFERROR(G20/H20," ") | K20: =IFERROR(G20/H20,0) -> 0 | L20: =IF(I20=" "," ",IF(I20>100%,"🚫Meta rebasada🚫"," "))
F21: 36 a 47 meses | G21: =SUM(OCTUBRE:ABRIL!L20) -> 12 | H21: 16 | I21: =IFERROR(G21/H21," ") | K21: =IFERROR(G21/H21,0) -> 0 | L21: =IF(I21=" "," ",IF(I21>100%,"🚫Meta rebasada🚫"," "))
F22: 48 a 59 meses | G22: =SUM(OCTUBRE:ABRIL!L21) -> 10 | H22: 14 | I22: =IFERROR(G22/H22," ") | K22: =IFERROR(G22/H22,0) -> 0 | L22: =IF(I22=" "," ",IF(I22>100%,"🚫Meta rebasada🚫"," "))
F23: 60 años y más | G23: =SUM(OCTUBRE:ABRIL!L22) -> 50 | H23: 60 | I23: =IFERROR(G23/H23," ") | K23: =IFERROR(G23/H23,0) -> 0 | L23: =IF(I23=" "," ",IF(I23>100%,"🚫Meta rebasada🚫"," "))
B24: Población de riesgo de 5 a 59 años | C24: Grupos de riesgo | F24: EMBARAZADAS | G24: =SUM(OCTUBRE:ABRIL!L23) -> 9 | H24: 12 | I24: =IFERROR(G24/H24," ") | K24: =IFERROR(G24/H24,0) -> 0 | L24: =IF(I24=" "," ",IF(I24>100%,"🚫Meta rebasada🚫"," "))
F25: PERSONAL DE SALUD EN UNIDADES MÉDICAS | G25: =SUM(OCTUBRE:ABRIL!L24) -> 70 | H25: 80 | I25: =IFERROR(G25/H25," ") | K25: =IFERROR(G25/H25,0) -> 0 | L25: =IF(I25=" "," ",IF(I25>100%,"🚫Meta rebasada🚫"," "))
C26: Personas que viven con VIH/SIDA | F26: 5 a 9 años | G26: =SUM(OCTUBRE:ABRIL!L25) -> 4 | H26: 6 | I26: =IFERROR(G26/H26," ") | K26: =IFERROR(G26/H26,0) -> 0 | L26: =IF(I26=" "," ",IF(I26>100%,"🚫Meta rebasada🚫"," "))
F27: 10 a 19 años | G27: =SUM(OCTUBRE:ABRIL!L26) -> 11 | H27: 8 | I27: =IFERROR(G27/H27," ") | K27: =IFERROR(G27/H27,0) -> 0 | L27: =IF(I27=" "," ",IF(I27>100%,"🚫Meta rebasada🚫"," "))
F28: 20 a 59 años | G28: =SUM(OCTUBRE:ABRIL!L27) -> 11 | H28: 10 | I28: =IFERROR(G28/H28," ") | K28: =IFERROR(G28/H28,0) -> 0 | L28: =IF(I28=" "," ",IF(I28>100%,"🚫Meta rebasada🚫"," "))
C29: Diabetes mellitus | F29: 5 a 9 años | G29: =SUM(OCTUBRE:ABRIL!L28) -> 1 | H29: 5 | I29: =IFERROR(G29/H29," ") | K29: =IFERROR(G29/H29,0) -> 0 | L29: =IF(I29=" "," ",IF(I29>100%,"🚫Meta rebasada🚫"," "))
F30: 10 a 19 años | G30: =SUM(OCTUBRE:ABRIL!L29) -> 4 | H30: 7 | I30: =IFERROR(G30/H30," ") | K30: =IFERROR(G30/H30,0) -> 0 | L30: =IF(I30=" "," ",IF(I30>100%,"🚫Meta rebasada🚫"," "))
F31: 20 a 59 años | G31: =SUM(OCTUBRE:ABRIL!L30) -> 8 | H31: 9 | I31: =IFERROR(G31/H31," ") | K31: =IFERROR(G31/H31,0) -> 0 | L31: =IF(I31=" "," ",IF(I31>100%,"🚫Meta rebasada🚫"," "))
C32: Obesidad mórbida | F32: 5 a 9 años | G32: =SUM(OCTUBRE:ABRIL!L31) -> 0 | H32: 4 | I32: =IFERROR(G32/H32," ") | K32: =IFERROR(G32/H32,0) -> 0 | L32: =IF(I32=" "," ",IF(I32>100%,"🚫Meta rebasada🚫"," "))
F33: 10 a 19 años | G33: =SUM(OCTUBRE:ABRIL!L32) -> 0 | H33: 5 | I33: =IFERROR(G33/H33," ") | K33: =IFERROR(G33/H33,0) -> 0 | L33: =IF(I33=" "," ",IF(I33>100%,"🚫Meta rebasada🚫"," "))
F34: 20 a 59 años | G34: =SUM(OCTUBRE:ABRIL!L33) -> 2 | H34: 6 | I34: =IFERROR(G34/H34," ") | K34: =IFERROR(G34/H34,0) -> 0 | L34: =IF(I34=" "," ",IF(I34>100%,"🚫Meta rebasada🚫"," "))
C35: Personas con cardiopatías agudas o crónicas | F35: 5 a 9 años | G35: =SUM(OCTUBRE:ABRIL!L34) -> 0 | H35: 3 | I35: =IFERROR(G35/H35," ") | K35: =IFERROR(G35/H35,0) -> 0 | L35: =IF(I35=" "," ",IF(I35>100%,"🚫Meta rebasada🚫"," "))
F36: 10 a 19 años | G36: =SUM(OCTUBRE:ABRIL!L35) -> 0 | H36: 4 | I36: =IFERROR(G36/H36," ") | K36: =IFERROR(G36/H36,0) -> 0 | L36: =IF(I36=" "," ",IF(I36>100%,"🚫Meta rebasada🚫"," "))
F37: 20 a 59 años | G37: =SUM(OCTUBRE:ABRIL!L36) -> 1 | H37: 5 | I37: =IFERROR(G37/H37," ") | K37: =IFERROR(G37/H37,0) -> 0 | L37: =IF(I37=" "," ",IF(I37>100%,"🚫Meta rebasada🚫"," "))
C38: Personas con enfermedad pulmonar crónica, incluye EPOC y asma | F38: 5 a 9 años | G38: =SUM(OCTUBRE:ABRIL!L37) -> 6 | H38: 6 | I38: =IFERROR(G38/H38," ") | K38: =IFERROR(G38/H38,0) -> 0 | L38: =IF(I38=" "," ",IF(I38>100%,"🚫Meta rebasada🚫"," "))
F39: 10 a 19 años | G39: =SUM(OCTUBRE:ABRIL!L38) -> 0 | H39: 3 | I39: =IFERROR(G39/H39," ") | K39: =IFERROR(G39/H39,0) -> 0 | L39: =IF(I39=" "," ",IF(I39>100%,"🚫Meta rebasada🚫"," "))
F40: 20 a 59 años | G40: =SUM(OCTUBRE:ABRIL!L39) -> 0 | H40: 4 | I40: =IFERROR(G40/H40," ") | K40: =IFERROR(G40/H40,0) -> 0 | L40: =IF(I40=" "," ",IF(I40>100%,"🚫Meta rebasada🚫"," "))
C41: Personas con cáncer | F41: 5 a 9 años | G41: =SUM(OCTUBRE:ABRIL!L40) -> 0 | H41: 5 | I41: =IFERROR(G41/H41," ") | K41: =IFERROR(G41/H41,0) -> 0 | L41: =IF(I41=" "," ",IF(I41>100%,"🚫Meta rebasada🚫"," "))
F42: 10 a 19 años | G42: =SUM(OCTUBRE:ABRIL!L41) -> 0 | H42: 2 | I42: =IFERROR(G42/H42," ") | K42: =IFERROR(G42/H42,0) -> 0 | L42: =IF(I42=" "," ",IF(I42>100%,"🚫Meta rebasada🚫"," "))
...

Sheet OCTUBRE
C1: Subsecretaria de Prevención y Promoción de la Salud
C2: Centro Nacional para la Salud de la Infancia y la Adolescencia
C3: Programa de Vacunación Universal
C4: ='ANÁLIS DE META-LOGRO'!A5 -> Meta-Logro de Vacuna Anti Influenza Estacional Temporada Invernal 2025-2026 por Unidad de Salud
C5: Temporada Invernal 2026-2027 · OCTUBRE
A7: Población | C7: DOSIS / GRUPO POBLACIONAL | G7: SEMANA 1 | H7: SEMANA 2 | I7: SEMANA 3 | J7: SEMANA 4 | K7: SEMANA 5 | L7: TOTAL
A8: 225 Aplicación de Antiinfluenza Estacional | B8: Población blanco | C8: Primera dosis | F8: 6 a 11 meses | G8: 1 | H8: 3 | I8: 3 | J8: 2 | K8: 3 | L8: =SUM(G8:K8) -> 0
F9: 12 a 23 meses | G9: 6 | H9: 3 | I9: 5 | J9: 6 | K9: 4 | L9: =SUM(G9:K9) -> 0
F10: 24 a 35 meses | G10: 3 | H10: 5 | I10: 2 | J10: 2 | K10: 4 | L10: =SUM(G10:K10) -> 0
F11: 36 a 47 meses | G11: 2 | H11: 2 | I11: 4 | J11: 4 | K11: 3 | L11: =SUM(G11:K11) -> 0
F12: 48 a 59 meses | G12: 3 | H12: 2 | I12: 3 | J12: 3 | K12: 3 | L12: =SUM(G12:K12) -> 0
C13: Segunda dosis | F13: 7 a 11 meses | G13: 2 | H13: 2 | I13: 3 | J13: 1 | K13: 1 | L13: =SUM(G13:K13) -> 0
F14: 12 a 23 meses | G14: 1 | H14: 2 | I14: 2 | J14: 2 | K14: 1 | L14: =SUM(G14:K14) -> 0
F15: 24 a 35 meses | G15: 2 | H15: 2 | I15: 2 | J15: 2 | K15: 1 | L15: =SUM(G15:K15) -> 0
F16: 36 a 47 meses | G16: 2 | H16: 1 | I16: 2 | J16: 2 | K16: 1 | L16: =SUM(G16:K16) -> 0
F17: 48 a 59 meses | G17: 1 | H17: 1 | I17: 1 | J17: 2 | K17: 1 | L17: =SUM(G17:K17) -> 0
C18: Revacunación | F18: 18 a 23 meses | G18: 2 | H18: 1 | I18: 1 | J18: 2 | K18: 1 | L18: =SUM(G18:K18) -> 0
F19: 24 a 35 meses | G19: 2 | H19: 1 | I19: 1 | J19: 1 | K19: 1 | L19: =SUM(G19:K19) -> 0
F20: 36 a 47 meses | G20: 1 | H20: 1 | I20: 1 | J20: 1 | K20: 1 | L20: =SUM(G20:K20) -> 0
F21: 48 a 59 meses | G21: 1 | H21: 1 | J21: 1 | K21: 1 | L21: =SUM(G21:K21) -> 0
F22: 60 años y más | G22: 4 | H22: 3 | I22: 5 | J22: 6 | K22: 2 | L22: =SUM(G22:K22) -> 0
B23: Población de riesgo de 5 a 59 años | C23: Grupos de riesgo | F23: EMBARAZADAS | G23: 1 | H23: 1 | I23: 1 | J23: 1 | K23: 1 | L23: =SUM(G23:K23) -> 0
F24: PERSONAL DE SALUD EN UNIDADES MÉDICAS | G24: 7 | H24: 6 | I24: 7 | J24: 4 | K24: 7 | L24: =SUM(G24:K24) -> 0
C25: Personas que viven con VIH/SIDA | F25: 5 a 9 años | K25: 1 | L25: =SUM(G25:K25) -> 0
F26: 10 a 19 años | G26: 1 | H26: 1 | I26: 1 | J26: 1 | K26: 1 | L26: =SUM(G26:K26) -> 0
F27: 20 a 59 años | G27: 1 | H27: 1 | I27: 1 | J27: 1 | K27: 1 | L27: =SUM(G27:K27) -> 0
C28: Diabetes mellitus | F28: 5 a 9 años | K28: 1 | L28: =SUM(G28:K28) -> 0
F29: 10 a 19 años | G29: 1 | H29: 1 | J29: 1 | L29: =SUM(G29:K29) -> 0
F30: 20 a 59 años | H30: 1 | I30: 1 | J30: 1 | K30: 1 | L30: =SUM(G30:K30) -> 0
C31: Obesidad mórbida | F31: 5 a 9 años | L31: =SUM(G31:K31) -> 0
F32: 10 a 19 años | L32: =SUM(G32:K32) -> 0
F33: 20 a 59 años | K33: 1 | L33: =SUM(G33:K33) -> 0
C34: Personas con cardiopatías agudas o crónicas | F34: 5 a 9 años | L34: =SUM(G34:K34) -> 0
F35: 10 a 19 años | L35: =SUM(G35:K35) -> 0
F36: 20 a 59 años | J36: 1 | L36: =SUM(G36:K36) -> 0
C37: Personas con enfermedad pulmonar crónica, incluye EPOC y asma | F37: 5 a 9 años | G37: 1 | I37: 1 | J37: 1 | L37: =SUM(G37:K37) -> 0
F38: 10 a 19 años | L38: =SUM(G38:K38) -> 0
F39: 20 a 59 años | L39: =SUM(G39:K39) -> 0
C40: Personas con cáncer | F40: 5 a 9 años | L40: =SUM(G40:K40) -> 0
F41: 10 a 19 años | L41: =SUM(G41:K41) -> 0
...

Sheet NOVIEMBRE
C1: Subsecretaria de Prevención y Promoción de la Salud
C2: Centro Nacional para la Salud de la Infancia y la Adolescencia
C3: Programa de Vacunación Universal
C4: ='ANÁLIS DE META-LOGRO'!A5 -> Meta-Logro de Vacuna Anti Influenza Estacional Temporada Invernal 2025-2026 por Unidad de Salud
C5: Temporada Invernal 2026-2027 · NOVIEMBRE
A7: Población | C7: DOSIS / GRUPO POBLACIONAL | G7: SEMANA 1 | H7: SEMANA 2 | I7: SEMANA 3 | J7: SEMANA 4 | K7: SEMANA 5 | L7: TOTAL
A8: 225 Aplicación de Antiinfluenza Estacional | B8: Población blanco | C8: Primera dosis | F8: 6 a 11 meses | G8: 2 | H8: 3 | I8: 2 | J8: 3 | L8: =SUM(G8:K8) -> 0
F9: 12 a 23 meses | G9: 3 | H9: 4 | I9: 3 | J9: 6 | L9: =SUM(G9:K9) -> 0
F10: 24 a 35 meses | G10: 5 | H10: 5 | I10: 5 | J10: 5 | L10: =SUM(G10:K10) -> 0
F11: 36 a 47 meses | G11: 5 | H11: 5 | I11: 4 | J11: 2 | L11: =SUM(G11:K11) -> 0
F12: 48 a 59 meses | G12: 2 | H12: 2 | I12: 2 | J12: 3 | L12: =SUM(G12:K12) -> 0
C13: Segunda dosis | F13: 7 a 11 meses | G13: 3 | H13: 1 | I13: 1 | J13: 1 | L13: =SUM(G13:K13) -> 0
F14: 12 a 23 meses | G14: 2 | H14: 1 | I14: 2 | J14: 1 | L14: =SUM(G14:K14) -> 0
F15: 24 a 35 meses | G15: 1 | H15: 2 | I15: 1 | J15: 2 | L15: =SUM(G15:K15) -> 0
F16: 36 a 47 meses | G16: 1 | H16: 2 | I16: 2 | J16: 2 | L16: =SUM(G16:K16) -> 0
F17: 48 a 59 meses | G17: 1 | H17: 1 | I17: 1 | J17: 1 | L17: =SUM(G17:K17) -> 0
C18: Revacunación | F18: 18 a 23 meses | G18: 1 | H18: 2 | I18: 2 | J18: 1 | L18: =SUM(G18:K18) -> 0
F19: 24 a 35 meses | G19: 1 | H19: 2 | I19: 1 | J19: 1 | L19: =SUM(G19:K19) -> 0
F20: 36 a 47 meses | G20: 1 | H20: 1 | I20: 1 | J20: 2 | L20: =SUM(G20:K20) -> 0
F21: 48 a 59 meses | G21: 1 | H21: 1 | I21: 1 | J21: 1 | L21: =SUM(G21:K21) -> 0
F22: 60 años y más | G22: 4 | H22: 5 | I22: 6 | J22: 6 | L22: =SUM(G22:K22) -> 0
B23: Población de riesgo de 5 a 59 años | C23: Grupos de riesgo | F23: EMBARAZADAS | G23: 1 | H23: 1 | I23: 1 | J23: 1 | L23: =SUM(G23:K23) -> 0
F24: PERSONAL DE SALUD EN UNIDADES MÉDICAS | G24: 8 | H24: 8 | I24: 6 | J24: 4 | L24: =SUM(G24:K24) -> 0
C25: Personas que viven con VIH/SIDA | F25: 5 a 9 años | H25: 1 | I25: 1 | L25: =SUM(G25:K25) -> 0
F26: 10 a 19 años | G26: 1 | H26: 1 | I26: 1 | J26: 1 | L26: =SUM(G26:K26) -> 0
F27: 20 a 59 años | G27: 1 | H27: 1 | I27: 1 | J27: 1 | L27: =SUM(G27:K27) -> 0
C28: Diabetes mellitus | F28: 5 a 9 años | L28: =SUM(G28:K28) -> 0
F29: 10 a 19 años | L29: =SUM(G29:K29) -> 0
F30: 20 a 59 años | G30: 1 | H30: 1 | J30: 1 | L30: =SUM(G30:K30) -> 0
C31: Obesidad mórbida | F31: 5 a 9 años | L31: =SUM(G31:K31) -> 0
F32: 10 a 19 años | L32: =SUM(G32:K32) -> 0
F33: 20 a 59 años | G33: 1 | L33: =SUM(G33:K33) -> 0
C34: Personas con cardiopatías agudas o crónicas | F34: 5 a 9 años | L34: =SUM(G34:K34) -> 0
F35: 10 a 19 años | L35: =SUM(G35:K35) -> 0
F36: 20 a 59 años | L36: =SUM(G36:K36) -> 0
C37: Personas con enfermedad pulmonar crónica, incluye EPOC y asma | F37: 5 a 9 años | G37: 1 | J37: 1 | L37: =SUM(G37:K37) -> 0
F38: 10 a 19 años | L38: =SUM(G38:K38) -> 0
F39: 20 a 59 años | L39: =SUM(G39:K39) -> 0
C40: Personas con cáncer | F40: 5 a 9 años | L40: =SUM(G40:K40) -> 0
F41: 10 a 19 años | L41: =SUM(G41:K41) -> 0
...

Sheet DICIEMBRE
C1: Subsecretaria de Prevención y Promoción de la Salud
C2: Centro Nacional para la Salud de la Infancia y la Adolescencia
C3: Programa de Vacunación Universal
C4: ='ANÁLIS DE META-LOGRO'!A5 -> Meta-Logro de Vacuna Anti Influenza Estacional Temporada Invernal 2025-2026 por Unidad de Salud
C5: Temporada Invernal 2026-2027 · DICIEMBRE
A7: Población | C7: DOSIS / GRUPO POBLACIONAL | G7: SEMANA 1 | H7: SEMANA 2 | I7: SEMANA 3 | J7: SEMANA 4 | K7: SEMANA 5 | L7: TOTAL
A8: 225 Aplicación de Antiinfluenza Estacional | B8: Población blanco | C8: Primera dosis | F8: 6 a 11 meses | G8: 3 | H8: 3 | K8: 3 | L8: =SUM(G8:K8) -> 0
F9: 12 a 23 meses | G9: 4 | H9: 3 | K9: 2 | L9: =SUM(G9:K9) -> 0
F10: 24 a 35 meses | G10: 3 | H10: 4 | L10: =SUM(G10:K10) -> 0
F11: 36 a 47 meses | G11: 2 | H11: 3 | L11: =SUM(G11:K11) -> 0
F12: 48 a 59 meses | G12: 1 | H12: 3 | L12: =SUM(G12:K12) -> 0
C13: Segunda dosis | F13: 7 a 11 meses | G13: 1 | H13: 1 | L13: =SUM(G13:K13) -> 0
F14: 12 a 23 meses | G14: 1 | H14: 2 | L14: =SUM(G14:K14) -> 0
F15: 24 a 35 meses | G15: 1 | H15: 2 | L15: =SUM(G15:K15) -> 0
F16: 36 a 47 meses | G16: 1 | H16: 2 | L16: =SUM(G16:K16) -> 0
F17: 48 a 59 meses | G17: 1 | H17: 1 | L17: =SUM(G17:K17) -> 0
C18: Revacunación | F18: 18 a 23 meses | G18: 1 | H18: 2 | L18: =SUM(G18:K18) -> 0
F19: 24 a 35 meses | G19: 1 | H19: 2 | L19: =SUM(G19:K19) -> 0
F20: 36 a 47 meses | G20: 1 | H20: 1 | L20: =SUM(G20:K20) -> 0
F21: 48 a 59 meses | G21: 1 | H21: 1 | L21: =SUM(G21:K21) -> 0
F22: 60 años y más | G22: 6 | H22: 3 | L22: =SUM(G22:K22) -> 0
B23: Población de riesgo de 5 a 59 años | C23: Grupos de riesgo | F23: EMBARAZADAS | L23: =SUM(G23:K23) -> 0
F24: PERSONAL DE SALUD EN UNIDADES MÉDICAS | G24: 7 | H24: 6 | L24: =SUM(G24:K24) -> 0
C25: Personas que viven con VIH/SIDA | F25: 5 a 9 años | H25: 1 | L25: =SUM(G25:K25) -> 0
F26: 10 a 19 años | G26: 1 | H26: 1 | L26: =SUM(G26:K26) -> 0
F27: 20 a 59 años | G27: 1 | H27: 1 | L27: =SUM(G27:K27) -> 0
C28: Diabetes mellitus | F28: 5 a 9 años | L28: =SUM(G28:K28) -> 0
F29: 10 a 19 años | H29: 1 | L29: =SUM(G29:K29) -> 0
F30: 20 a 59 años | G30: 1 | L30: =SUM(G30:K30) -> 0
C31: Obesidad mórbida | F31: 5 a 9 años | L31: =SUM(G31:K31) -> 0
F32: 10 a 19 años | L32: =SUM(G32:K32) -> 0
F33: 20 a 59 años | L33: =SUM(G33:K33) -> 0
C34: Personas con cardiopatías agudas o crónicas | F34: 5 a 9 años | L34: =SUM(G34:K34) -> 0
F35: 10 a 19 años | L35: =SUM(G35:K35) -> 0
F36: 20 a 59 años | L36: =SUM(G36:K36) -> 0
C37: Personas con enfermedad pulmonar crónica, incluye EPOC y asma | F37: 5 a 9 años | G37: 1 | L37: =SUM(G37:K37) -> 0
F38: 10 a 19 años | L38: =SUM(G38:K38) -> 0
F39: 20 a 59 años | L39: =SUM(G39:K39) -> 0
C40: Personas con cáncer | F40: 5 a 9 años | L40: =SUM(G40:K40) -> 0
F41: 10 a 19 años | L41: =SUM(G41:K41) -> 0
...

Sheet ENERO
C1: Subsecretaria de Prevención y Promoción de la Salud
C2: Centro Nacional para la Salud de la Infancia y la Adolescencia
C3: Programa de Vacunación Universal
C4: ='ANÁLIS DE META-LOGRO'!A5 -> Meta-Logro de Vacuna Anti Influenza Estacional Temporada Invernal 2025-2026 por Unidad de Salud
C5: Temporada Invernal 2026-2027 · ENERO
A7: Población | C7: DOSIS / GRUPO POBLACIONAL | G7: SEMANA 1 | H7: SEMANA 2 | I7: SEMANA 3 | J7: SEMANA 4 | K7: SEMANA 5 | L7: TOTAL
A8: 225 Aplicación de Antiinfluenza Estacional | B8: Población blanco | C8: Primera dosis | F8: 6 a 11 meses | L8: =SUM(G8:K8) -> 0
F9: 12 a 23 meses | L9: =SUM(G9:K9) -> 0
F10: 24 a 35 meses | L10: =SUM(G10:K10) -> 0
F11: 36 a 47 meses | L11: =SUM(G11:K11) -> 0
F12: 48 a 59 meses | L12: =SUM(G12:K12) -> 0
C13: Segunda dosis | F13: 7 a 11 meses | L13: =SUM(G13:K13) -> 0
F14: 12 a 23 meses | L14: =SUM(G14:K14) -> 0
F15: 24 a 35 meses | L15: =SUM(G15:K15) -> 0
F16: 36 a 47 meses | L16: =SUM(G16:K16) -> 0
F17: 48 a 59 meses | L17: =SUM(G17:K17) -> 0
C18: Revacunación | F18: 18 a 23 meses | L18: =SUM(G18:K18) -> 0
F19: 24 a 35 meses | L19: =SUM(G19:K19) -> 0
F20: 36 a 47 meses | L20: =SUM(G20:K20) -> 0
F21: 48 a 59 meses | L21: =SUM(G21:K21) -> 0
F22: 60 años y más | L22: =SUM(G22:K22) -> 0
B23: Población de riesgo de 5 a 59 años | C23: Grupos de riesgo | F23: EMBARAZADAS | L23: =SUM(G23:K23) -> 0
F24: PERSONAL DE SALUD EN UNIDADES MÉDICAS | L24: =SUM(G24:K24) -> 0
C25: Personas que viven con VIH/SIDA | F25: 5 a 9 años | L25: =SUM(G25:K25) -> 0
F26: 10 a 19 años | L26: =SUM(G26:K26) -> 0
F27: 20 a 59 años | L27: =SUM(G27:K27) -> 0
C28: Diabetes mellitus | F28: 5 a 9 años | L28: =SUM(G28:K28) -> 0
F29: 10 a 19 años | L29: =SUM(G29:K29) -> 0
F30: 20 a 59 años | L30: =SUM(G30:K30) -> 0
C31: Obesidad mórbida | F31: 5 a 9 años | L31: =SUM(G31:K31) -> 0
F32: 10 a 19 años | L32: =SUM(G32:K32) -> 0
F33: 20 a 59 años | L33: =SUM(G33:K33) -> 0
C34: Personas con cardiopatías agudas o crónicas | F34: 5 a 9 años | L34: =SUM(G34:K34) -> 0
F35: 10 a 19 años | L35: =SUM(G35:K35) -> 0
F36: 20 a 59 años | L36: =SUM(G36:K36) -> 0
C37: Personas con enfermedad pulmonar crónica, incluye EPOC y asma | F37: 5 a 9 años | L37: =SUM(G37:K37) -> 0
F38: 10 a 19 años | L38: =SUM(G38:K38) -> 0
F39: 20 a 59 años | L39: =SUM(G39:K39) -> 0
C40: Personas con cáncer | F40: 5 a 9 años | L40: =SUM(G40:K40) -> 0
F41: 10 a 19 años | L41: =SUM(G41:K41) -> 0
...

Sheet FEBRERO
C1: Subsecretaria de Prevención y Promoción de la Salud
C2: Centro Nacional para la Salud de la Infancia y la Adolescencia
C3: Programa de Vacunación Universal
C4: ='ANÁLIS DE META-LOGRO'!A5 -> Meta-Logro de Vacuna Anti Influenza Estacional Temporada Invernal 2025-2026 por Unidad de Salud
C5: Temporada Invernal 2026-2027 · FEBRERO
A7: Población | C7: DOSIS / GRUPO POBLACIONAL | G7: SEMANA 1 | H7: SEMANA 2 | I7: SEMANA 3 | J7: SEMANA 4 | K7: SEMANA 5 | L7: TOTAL
A8: 225 Aplicación de Antiinfluenza Estacional | B8: Población blanco | C8: Primera dosis | F8: 6 a 11 meses | L8: =SUM(G8:K8) -> 0
F9: 12 a 23 meses | L9: =SUM(G9:K9) -> 0
F10: 24 a 35 meses | L10: =SUM(G10:K10) -> 0
F11: 36 a 47 meses | L11: =SUM(G11:K11) -> 0
F12: 48 a 59 meses | L12: =SUM(G12:K12) -> 0
C13: Segunda dosis | F13: 7 a 11 meses | L13: =SUM(G13:K13) -> 0
F14: 12 a 23 meses | L14: =SUM(G14:K14) -> 0
F15: 24 a 35 meses | L15: =SUM(G15:K15) -> 0
F16: 36 a 47 meses | L16: =SUM(G16:K16) -> 0
F17: 48 a 59 meses | L17: =SUM(G17:K17) -> 0
C18: Revacunación | F18: 18 a 23 meses | L18: =SUM(G18:K18) -> 0
F19: 24 a 35 meses | L19: =SUM(G19:K19) -> 0
F20: 36 a 47 meses | L20: =SUM(G20:K20) -> 0
F21: 48 a 59 meses | L21: =SUM(G21:K21) -> 0
F22: 60 años y más | L22: =SUM(G22:K22) -> 0
B23: Población de riesgo de 5 a 59 años | C23: Grupos de riesgo | F23: EMBARAZADAS | L23: =SUM(G23:K23) -> 0
F24: PERSONAL DE SALUD EN UNIDADES MÉDICAS | L24: =SUM(G24:K24) -> 0
C25: Personas que viven con VIH/SIDA | F25: 5 a 9 años | L25: =SUM(G25:K25) -> 0
F26: 10 a 19 años | L26: =SUM(G26:K26) -> 0
F27: 20 a 59 años | L27: =SUM(G27:K27) -> 0
C28: Diabetes mellitus | F28: 5 a 9 años | L28: =SUM(G28:K28) -> 0
F29: 10 a 19 años | L29: =SUM(G29:K29) -> 0
F30: 20 a 59 años | L30: =SUM(G30:K30) -> 0
C31: Obesidad mórbida | F31: 5 a 9 años | L31: =SUM(G31:K31) -> 0
F32: 10 a 19 años | L32: =SUM(G32:K32) -> 0
F33: 20 a 59 años | L33: =SUM(G33:K33) -> 0
C34: Personas con cardiopatías agudas o crónicas | F34: 5 a 9 años | L34: =SUM(G34:K34) -> 0
F35: 10 a 19 años | L35: =SUM(G35:K35) -> 0
F36: 20 a 59 años | L36: =SUM(G36:K36) -> 0
C37: Personas con enfermedad pulmonar crónica, incluye EPOC y asma | F37: 5 a 9 años | L37: =SUM(G37:K37) -> 0
F38: 10 a 19 años | L38: =SUM(G38:K38) -> 0
F39: 20 a 59 años | L39: =SUM(G39:K39) -> 0
C40: Personas con cáncer | F40: 5 a 9 años | L40: =SUM(G40:K40) -> 0
F41: 10 a 19 años | L41: =SUM(G41:K41) -> 0
...

Sheet MARZO
C1: Subsecretaria de Prevención y Promoción de la Salud
C2: Centro Nacional para la Salud de la Infancia y la Adolescencia
C3: Programa de Vacunación Universal
C4: ='ANÁLIS DE META-LOGRO'!A5 -> Meta-Logro de Vacuna Anti Influenza Estacional Temporada Invernal 2025-2026 por Unidad de Salud
C5: Temporada Invernal 2026-2027 · MARZO
A7: Población | C7: DOSIS / GRUPO POBLACIONAL | G7: SEMANA 1 | H7: SEMANA 2 | I7: SEMANA 3 | J7: SEMANA 4 | K7: SEMANA 5 | L7: TOTAL
A8: 225 Aplicación de Antiinfluenza Estacional | B8: Población blanco | C8: Primera dosis | F8: 6 a 11 meses | L8: =SUM(G8:K8) -> 0
F9: 12 a 23 meses | L9: =SUM(G9:K9) -> 0
F10: 24 a 35 meses | L10: =SUM(G10:K10) -> 0
F11: 36 a 47 meses | L11: =SUM(G11:K11) -> 0
F12: 48 a 59 meses | L12: =SUM(G12:K12) -> 0
C13: Segunda dosis | F13: 7 a 11 meses | L13: =SUM(G13:K13) -> 0
F14: 12 a 23 meses | L14: =SUM(G14:K14) -> 0
F15: 24 a 35 meses | L15: =SUM(G15:K15) -> 0
F16: 36 a 47 meses | L16: =SUM(G16:K16) -> 0
F17: 48 a 59 meses | L17: =SUM(G17:K17) -> 0
C18: Revacunación | F18: 18 a 23 meses | L18: =SUM(G18:K18) -> 0
F19: 24 a 35 meses | L19: =SUM(G19:K19) -> 0
F20: 36 a 47 meses | L20: =SUM(G20:K20) -> 0
F21: 48 a 59 meses | L21: =SUM(G21:K21) -> 0
F22: 60 años y más | L22: =SUM(G22:K22) -> 0
B23: Población de riesgo de 5 a 59 años | C23: Grupos de riesgo | F23: EMBARAZADAS | L23: =SUM(G23:K23) -> 0
F24: PERSONAL DE SALUD EN UNIDADES MÉDICAS | L24: =SUM(G24:K24) -> 0
C25: Personas que viven con VIH/SIDA | F25: 5 a 9 años | L25: =SUM(G25:K25) -> 0
F26: 10 a 19 años | L26: =SUM(G26:K26) -> 0
F27: 20 a 59 años | L27: =SUM(G27:K27) -> 0
C28: Diabetes mellitus | F28: 5 a 9 años | L28: =SUM(G28:K28) -> 0
F29: 10 a 19 años | L29: =SUM(G29:K29) -> 0
F30: 20 a 59 años | L30: =SUM(G30:K30) -> 0
C31: Obesidad mórbida | F31: 5 a 9 años | L31: =SUM(G31:K31) -> 0
F32: 10 a 19 años | L32: =SUM(G32:K32) -> 0
F33: 20 a 59 años | L33: =SUM(G33:K33) -> 0
C34: Personas con cardiopatías agudas o crónicas | F34: 5 a 9 años | L34: =SUM(G34:K34) -> 0
F35: 10 a 19 años | L35: =SUM(G35:K35) -> 0
F36: 20 a 59 años | L36: =SUM(G36:K36) -> 0
C37: Personas con enfermedad pulmonar crónica, incluye EPOC y asma | F37: 5 a 9 años | L37: =SUM(G37:K37) -> 0
F38: 10 a 19 años | L38: =SUM(G38:K38) -> 0
F39: 20 a 59 años | L39: =SUM(G39:K39) -> 0
C40: Personas con cáncer | F40: 5 a 9 años | L40: =SUM(G40:K40) -> 0
F41: 10 a 19 años | L41: =SUM(G41:K41) -> 0
...

Sheet ABRIL
C1: Subsecretaria de Prevención y Promoción de la Salud
C2: Centro Nacional para la Salud de la Infancia y la Adolescencia
C3: Programa de Vacunación Universal
C4: ='ANÁLIS DE META-LOGRO'!A5 -> Meta-Logro de Vacuna Anti Influenza Estacional Temporada Invernal 2025-2026 por Unidad de Salud
C5: Temporada Invernal 2026-2027 · ABRIL
A7: Población | C7: DOSIS / GRUPO POBLACIONAL | G7: SEMANA 1 | H7: SEMANA 2 | I7: SEMANA 3 | J7: SEMANA 4 | K7: SEMANA 5 | L7: TOTAL
A8: 225 Aplicación de Antiinfluenza Estacional | B8: Población blanco | C8: Primera dosis | F8: 6 a 11 meses | L8: =SUM(G8:K8) -> 0
F9: 12 a 23 meses | L9: =SUM(G9:K9) -> 0
F10: 24 a 35 meses | L10: =SUM(G10:K10) -> 0
F11: 36 a 47 meses | L11: =SUM(G11:K11) -> 0
F12: 48 a 59 meses | L12: =SUM(G12:K12) -> 0
C13: Segunda dosis | F13: 7 a 11 meses | L13: =SUM(G13:K13) -> 0
F14: 12 a 23 meses | L14: =SUM(G14:K14) -> 0
F15: 24 a 35 meses | L15: =SUM(G15:K15) -> 0
F16: 36 a 47 meses | L16: =SUM(G16:K16) -> 0
F17: 48 a 59 meses | L17: =SUM(G17:K17) -> 0
C18: Revacunación | F18: 18 a 23 meses | L18: =SUM(G18:K18) -> 0
F19: 24 a 35 meses | L19: =SUM(G19:K19) -> 0
F20: 36 a 47 meses | L20: =SUM(G20:K20) -> 0
F21: 48 a 59 meses | L21: =SUM(G21:K21) -> 0
F22: 60 años y más | L22: =SUM(G22:K22) -> 0
B23: Población de riesgo de 5 a 59 años | C23: Grupos de riesgo | F23: EMBARAZADAS | L23: =SUM(G23:K23) -> 0
F24: PERSONAL DE SALUD EN UNIDADES MÉDICAS | L24: =SUM(G24:K24) -> 0
C25: Personas que viven con VIH/SIDA | F25: 5 a 9 años | L25: =SUM(G25:K25) -> 0
F26: 10 a 19 años | L26: =SUM(G26:K26) -> 0
F27: 20 a 59 años | L27: =SUM(G27:K27) -> 0
C28: Diabetes mellitus | F28: 5 a 9 años | L28: =SUM(G28:K28) -> 0
F29: 10 a 19 años | L29: =SUM(G29:K29) -> 0
F30: 20 a 59 años | L30: =SUM(G30:K30) -> 0
C31: Obesidad mórbida | F31: 5 a 9 años | L31: =SUM(G31:K31) -> 0
F32: 10 a 19 años | L32: =SUM(G32:K32) -> 0
F33: 20 a 59 años | L33: =SUM(G33:K33) -> 0
C34: Personas con cardiopatías agudas o crónicas | F34: 5 a 9 años | L34: =SUM(G34:K34) -> 0
F35: 10 a 19 años | L35: =SUM(G35:K35) -> 0
F36: 20 a 59 años | L36: =SUM(G36:K36) -> 0
C37: Personas con enfermedad pulmonar crónica, incluye EPOC y asma | F37: 5 a 9 años | L37: =SUM(G37:K37) -> 0
F38: 10 a 19 años | L38: =SUM(G38:K38) -> 0
F39: 20 a 59 años | L39: =SUM(G39:K39) -> 0
C40: Personas con cáncer | F40: 5 a 9 años | L40: =SUM(G40:K40) -> 0
F41: 10 a 19 años | L41: =SUM(G41:K41) -> 0
...
